Workbook

Sheet extra_Diverses
A1: Diverses | B1: 2025
A2: Responsible: | B2: =HYPERLINK("mailto:sylvia.richter@eawag.ch?subject=[Lab results]", "sylvia.richter@eawag.ch")
A3: Samples: | B3: =HYPERLINK("Q:\Abteilungsprojekte\eng\EngData\AOS\Allgemein\LabSamples2025.xlsx#Diverses!A1","LabSamples2025.xlsx")
B4: =HYPERLINK("Q:\Abteilungsprojekte\eng\EngData\AOS\Allgemein\LabSamples2025_Diverses_extra.xlsx#extra_Diverses!A1","LabSamples2025_Diverses_extra.xlsx")
A5: Sample ID | C5: Site | G5: Sample | I5: SampleInfo | J5: Comment | K5: DOC | O5: TOC | S5: TIC | W5: Nsol | AA5: Ntot | AE5: Cl | AI5: NO2-N | AM5: Br | AQ5: NO3-N | AU5: PO4-P | AY5: SO4 | BC5: Na | BG5: NH4-N | BK5: K | BO5: Ca | BS5: Mg | BW5: Ptot | CA5: Urea | CE5: CODsol | CI5: CODtot | CM5: Alkalinity | CQ5: Conductivity | CU5: pH | CY5: Dissolved Oxygen | DC5: Turbidity | DG5: TSS | DK5: VSS | DO5: Lactic Acid | DS5: Formic Acid | DW5: Acetic Acid | EA5: Propionic Acid | EE5: Isobutyric Acid | EI5: Butyric Acid | EM5: Isovaleric Acid | EQ5: Valeric Acid | EU5: Micropollutants | EZ5: ConcatID | FA5: ConcatID_X | FB5: ConcatID_Y | FC5: MatchX | FD5: MatchY
A6: Project ID | B6: Number | C6: Room | D6: Area | E6: Setup | F6: Component | G6: Date | H6: Time | K6: Final value | L6: Method | M6: Filtration | N6: Dilution | O6: Final value | P6: Method | Q6: Filtration | R6: Dilution | S6: Final value | T6: Method | U6: Filtration | V6: Dilution | W6: Final value | X6: Method | Y6: Filtration | Z6: Dilution | AA6: Final value | AB6: Method | AC6: Filtration | AD6: Dilution | AE6: Final value | AF6: Method | AG6: Filtration | AH6: Dilution | AI6: Final value | AJ6: Method | AK6: Filtration | AL6: Dilution | AM6: Final value | AN6: Method | AO6: Filtration | AP6: Dilution | AQ6: Final value | AR6: Method | AS6: Filtration | AT6: Dilution | AU6: Final value | AV6: Method | AW6: Filtration | AX6: Dilution | AY6: Final value | AZ6: Method | BA6: Filtration | BB6: Dilution | BC6: Final value | BD6: Method | BE6: Filtration | BF6: Dilution | BG6: Final value | BH6: Method | BI6: Filtration | BJ6: Dilution | BK6: Final value | BL6: Method | BM6: Filtration | BN6: Dilution | BO6: Final value | BP6: Method | BQ6: Filtration | BR6: Dilution | BS6: Final value | BT6: Method | BU6: Filtration | BV6: Dilution | BW6: Final value | BX6: Method | BY6: Filtration | BZ6: Dilution | CA6: Final value | CB6: Method | CC6: Filtration | CD6: Dilution | CE6: Final value | CF6: Method | CG6: Filtration | CH6: Dilution | CI6: Final value | CJ6: Method | CK6: Filtration | CL6: Dilution | CM6: Final value | CN6: Method | CO6: Filtration | CP6: Dilution | CQ6: Final value | CR6: Method | CS6: Filtration | CT6: Dilution | CU6: Final value | CV6: Method | CW6: Filtration | CX6: Dilution | CY6: Final value | CZ6: Method | DA6: Filtration | DB6: Dilution | DC6: Final value | DD6: Method | DE6: Filtration | DF6: Dilution | DG6: Final value | DH6: Method | DI6: Filtration | DJ6: Dilution | DK6: Final value | DL6: Method | DM6: Filtration | DN6: Dilution | DO6: Final value | DP6: Method | DQ6: Filtration | DR6: Dilution | DS6: Final value | DT6: Method | DU6: Filtration | DV6: Dilution | DW6: Final value | DX6: Method | DY6: Filtration | DZ6: Dilution | EA6: Final value | EB6: Method | EC6: Filtration | ED6: Dilution | EE6: Final value | EF6: Method | EG6: Filtration | EH6: Dilution | EI6: Final value | EJ6: Method | EK6: Filtration | EL6: Dilution | EM6: Final value | EN6: Method | EO6: Filtration | EP6: Dilution | EQ6: Final value | ER6: Method | ES6: Filtration | ET6: Dilution | EU6: Final value | EV6: Method | EW6: Filtration | EX6: Dilution
A7: [##] | B7: [yysss] | G7: [dd.mm.yyyy] | H7: [HH:MM:SS] | K7: mg/L | O7: mg/L | S7: mg/L | W7: mg/L | AA7: mg/L | AE7: mg/L | AI7: mg/L | AM7: mg/L | AQ7: mg/L | AU7: mg/L | AY7: mg/L | BC7: mg/L | BG7: mg/L | BK7: mg/L | BO7: mg/L | BS7: mg/L | BW7: mg/L | CA7: mgN/L | CE7: mg/L | CI7: mg/L | CM7: mmol/L | CQ7: microS/cm | CU7: 1 | CY7: mg/L | DC7: NTU | DG7: mg/L | DK7: mg/L | DO7: mg/L | DS7: mg/L | DW7: mg/L | EA7: mg/L | EE7: mg/L | EI7: mg/L | EM7: mg/L | EQ7: mg/L | EU7: ng/L
A8: Text | B8: Text | C8: Dropdown | D8: Dropdown | E8: Dropdown | F8: Dropdown | G8: Text | H8: Text | K8: Text | L8: Dropdown | M8: Dropdown | N8: Text | O8: Text | P8: Dropdown | Q8: Dropdown | R8: Text | S8: Text | T8: Dropdown | U8: Dropdown | V8: Text | W8: Text | X8: Dropdown | Y8: Dropdown | Z8: Text | AA8: Text | AB8: Dropdown | AC8: Dropdown | AD8: Text | AE8: Text | AF8: Dropdown | AG8: Dropdown | AH8: Text | AI8: Text | AJ8: Dropdown | AK8: Dropdown | AL8: Text | AM8: Text | AN8: Dropdown | AO8: Dropdown | AP8: Text | AQ8: Text | AR8: Dropdown | AS8: Dropdown | AT8: Text | AU8: Text | AV8: Dropdown | AW8: Dropdown | AX8: Text | AY8: Text | AZ8: Dropdown | BA8: Dropdown | BB8: Text | BC8: Text | BD8: Dropdown | BE8: Dropdown | BF8: Text | BG8: Text | BH8: Dropdown | BI8: Dropdown | BJ8: Text | BK8: Text | BL8: Dropdown | BM8: Dropdown | BN8: Text | BO8: Text | BP8: Dropdown | BQ8: Dropdown | BR8: Text | BS8: Text | BT8: Dropdown | BU8: Dropdown | BV8: Text | BW8: Text | BX8: Dropdown | BY8: Dropdown | BZ8: Text | CA8: Text | CB8: Dropdown | CC8: Dropdown | CD8: Text | CE8: Text | CF8: Dropdown | CG8: Dropdown | CH8: Text | CI8: Text | CJ8: Dropdown | CK8: Dropdown | CL8: Text | CM8: Text | CN8: Dropdown | CO8: Dropdown | CP8: Text | CQ8: Text | CR8: Dropdown | CS8: Dropdown | CT8: Text | CU8: Text | CV8: Dropdown | CW8: Dropdown | CX8: Text | CY8: Text | CZ8: Dropdown | DA8: Dropdown | DB8: Text | DC8: Text | DD8: Dropdown | DE8: Dropdown | DF8: Text | DG8: Text | DH8: Dropdown | DI8: Dropdown | DJ8: Text | DK8: Text | DL8: Dropdown | DM8: Dropdown | DN8: Text | DO8: Text | DP8: Dropdown | DQ8: Dropdown | DR8: Text | DS8: Text | DT8: Dropdown | DU8: Dropdown | DV8: Text | DW8: Text | DX8: Dropdown | DY8: Dropdown | DZ8: Text | EA8: Text | EB8: Dropdown | EC8: Dropdown | ED8: Text | EE8: Text | EF8: Dropdown | EG8: Dropdown | EH8: Text | EI8: Text | EJ8: Dropdown | EK8: Dropdown | EL8: Text | EM8: Text | EN8: Dropdown | EO8: Dropdown | EP8: Text | EQ8: Text | ER8: Dropdown | ES8: Dropdown | ET8: Text | EU8: Text | EV8: Dropdown | EW8: Dropdown | EX8: Text
C9: =IF(ISNUMBER(FC9),INDIRECT("SamplesX!C"&FC9),IF(ISNUMBER(FD9),INDIRECT("SamplesY!C"&FD9),"")) | D9: =IF(ISNUMBER(FC9),INDIRECT("SamplesX!D"&FC9),IF(ISNUMBER(FD9),INDIRECT("SamplesY!D"&FD9),"")) | E9: =IF(ISNUMBER(FC9),INDIRECT("SamplesX!E"&FC9),IF(ISNUMBER(FD9),INDIRECT("SamplesY!E"&FD9),"")) | F9: =IF(ISNUMBER(FC9),INDIRECT("SamplesX!F"&FC9),IF(ISNUMBER(FD9),INDIRECT("SamplesY!F"&FD9),"")) | G9: =IF(ISNUMBER(FC9),INDIRECT("SamplesX!G"&FC9),IF(ISNUMBER(FD9),INDIRECT("SamplesY!G"&FD9),"")) | H9: =IF(ISNUMBER(FC9),INDIRECT("SamplesX!H"&FC9),IF(ISNUMBER(FD9),INDIRECT("SamplesY!H"&FD9),"")) | M9: None | P9: Shimadzu TOC-L | Q9: None | T9: Shimadzu TOC-L | U9: None | Y9: None | AC9: None | AF9: IC Anionen | AG9: None | AK9: None | AN9: IC Anionen | AO9: None | AS9: None | AW9: None | AZ9: IC Anionen | BA9: None | BD9: IC Kationen | BE9: None | BI9: None | BL9: IC Kationen | BM9: None | BP9: IC Kationen | BQ9: None | BT9: IC Kationen | BU9: None | BY9: None | CC9: None | CG9: None | CK9: None | CN9: SOP 45-34 | CO9: None | CS9: None | CW9: None | CZ9: WTW Multimeter 3430 with FDO 925 | DA9: None | DE9: None | DH9: SOP 45-09 | DI9: None | DL9: SOP 45-09 (SOP muss noch angepasst werden für VSS) | DM9: None | DP9: IC Organic Acids | DQ9: None | DT9: IC Organic Acids | DU9: None | DX9: IC Organic Acids | DY9: None | EB9: IC Organic Acids | EC9: None | EF9: IC Organic Acids | EG9: None | EJ9: IC Organic Acids | EK9: None | EN9: IC Organic Acids | EO9: None | ER9: IC Organic Acids | ES9: None | EV9: LC-MS | EW9: None | EZ9: =CONCATENATE(A9,B9) | FA9: =CONCATENATE(SamplesX!A9,SamplesX!B9) | FB9: =CONCATENATE(SamplesY!A9,SamplesY!B9) | FC9: =MATCH(EZ9,FA1:FA1008,0) | FD9: =MATCH(EZ9,FB1:FB1008,0)
C10: =IF(ISNUMBER(FC10),INDIRECT("SamplesX!C"&FC10),IF(ISNUMBER(FD10),INDIRECT("SamplesY!C"&FD10),"")) | D10: =IF(ISNUMBER(FC10),INDIRECT("SamplesX!D"&FC10),IF(ISNUMBER(FD10),INDIRECT("SamplesY!D"&FD10),"")) | E10: =IF(ISNUMBER(FC10),INDIRECT("SamplesX!E"&FC10),IF(ISNUMBER(FD10),INDIRECT("SamplesY!E"&FD10),"")) | F10: =IF(ISNUMBER(FC10),INDIRECT("SamplesX!F"&FC10),IF(ISNUMBER(FD10),INDIRECT("SamplesY!F"&FD10),"")) | G10: =IF(ISNUMBER(FC10),INDIRECT("SamplesX!G"&FC10),IF(ISNUMBER(FD10),INDIRECT("SamplesY!G"&FD10),"")) | H10: =IF(ISNUMBER(FC10),INDIRECT("SamplesX!H"&FC10),IF(ISNUMBER(FD10),INDIRECT("SamplesY!H"&FD10),"")) | M10: None | P10: Shimadzu TOC-L | Q10: None | T10: Shimadzu TOC-L | U10: None | Y10: None | AC10: None | AF10: IC Anionen | AG10: None | AK10: None | AN10: IC Anionen | AO10: None | AS10: None | AW10: None | AZ10: IC Anionen | BA10: None | BD10: IC Kationen | BE10: None | BI10: None | BL10: IC Kationen | BM10: None | BP10: IC Kationen | BQ10: None | BT10: IC Kationen | BU10: None | BY10: None | CC10: None | CG10: None | CK10: None | CN10: SOP 45-34 | CO10: None | CS10: None | CW10: None | CZ10: WTW Multimeter 3430 with FDO 925 | DA10: None | DE10: None | DH10: SOP 45-09 | DI10: None | DL10: SOP 45-09 (SOP muss noch angepasst werden für VSS) | DM10: None | DP10: IC Organic Acids | DQ10: None | DT10: IC Organic Acids | DU10: None | DX10: IC Organic Acids | DY10: None | EB10: IC Organic Acids | EC10: None | EF10: IC Organic Acids | EG10: None | EJ10: IC Organic Acids | EK10: None | EN10: IC Organic Acids | EO10: None | ER10: IC Organic Acids | ES10: None | EV10: LC-MS | EW10: None | EZ10: =CONCATENATE(A10,B10) | FA10: =CONCATENATE(SamplesX!A10,SamplesX!B10) | FB10: =CONCATENATE(SamplesY!A10,SamplesY!B10) | FC10: =MATCH(EZ10,FA1:FA1008,0) | FD10: =MATCH(EZ10,FB1:FB1008,0)
C11: =IF(ISNUMBER(FC11),INDIRECT("SamplesX!C"&FC11),IF(ISNUMBER(FD11),INDIRECT("SamplesY!C"&FD11),"")) | D11: =IF(ISNUMBER(FC11),INDIRECT("SamplesX!D"&FC11),IF(ISNUMBER(FD11),INDIRECT("SamplesY!D"&FD11),"")) | E11: =IF(ISNUMBER(FC11),INDIRECT("SamplesX!E"&FC11),IF(ISNUMBER(FD11),INDIRECT("SamplesY!E"&FD11),"")) | F11: =IF(ISNUMBER(FC11),INDIRECT("SamplesX!F"&FC11),IF(ISNUMBER(FD11),INDIRECT("SamplesY!F"&FD11),"")) | G11: =IF(ISNUMBER(FC11),INDIRECT("SamplesX!G"&FC11),IF(ISNUMBER(FD11),INDIRECT("SamplesY!G"&FD11),"")) | H11: =IF(ISNUMBER(FC11),INDIRECT("SamplesX!H"&FC11),IF(ISNUMBER(FD11),INDIRECT("SamplesY!H"&FD11),"")) | M11: None | P11: Shimadzu TOC-L | Q11: None | T11: Shimadzu TOC-L | U11: None | Y11: None | AC11: None | AF11: IC Anionen | AG11: None | AK11: None | AN11: IC Anionen | AO11: None | AS11: None | AW11: None | AZ11: IC Anionen | BA11: None | BD11: IC Kationen | BE11: None | BI11: None | BL11: IC Kationen | BM11: None | BP11: IC Kationen | BQ11: None | BT11: IC Kationen | BU11: None | BY11: None | CC11: None | CG11: None | CK11: None | CN11: SOP 45-34 | CO11: None | CS11: None | CW11: None | CZ11: WTW Multimeter 3430 with FDO 925 | DA11: None | DE11: None | DH11: SOP 45-09 | DI11: None | DL11: SOP 45-09 (SOP muss noch angepasst werden für VSS) | DM11: None | DP11: IC Organic Acids | DQ11: None | DT11: IC Organic Acids | DU11: None | DX11: IC Organic Acids | DY11: None | EB11: IC Organic Acids | EC11: None | EF11: IC Organic Acids | EG11: None | EJ11: IC Organic Acids | EK11: None | EN11: IC Organic Acids | EO11: None | ER11: IC Organic Acids | ES11: None | EV11: LC-MS | EW11: None | EZ11: =CONCATENATE(A11,B11) | FA11: =CONCATENATE(SamplesX!A11,SamplesX!B11) | FB11: =CONCATENATE(SamplesY!A11,SamplesY!B11) | FC11: =MATCH(EZ11,FA1:FA1008,0) | FD11: =MATCH(EZ11,FB1:FB1008,0)
C12: =IF(ISNUMBER(FC12),INDIRECT("SamplesX!C"&FC12),IF(ISNUMBER(FD12),INDIRECT("SamplesY!C"&FD12),"")) | D12: =IF(ISNUMBER(FC12),INDIRECT("SamplesX!D"&FC12),IF(ISNUMBER(FD12),INDIRECT("SamplesY!D"&FD12),"")) | E12: =IF(ISNUMBER(FC12),INDIRECT("SamplesX!E"&FC12),IF(ISNUMBER(FD12),INDIRECT("SamplesY!E"&FD12),"")) | F12: =IF(ISNUMBER(FC12),INDIRECT("SamplesX!F"&FC12),IF(ISNUMBER(FD12),INDIRECT("SamplesY!F"&FD12),"")) | G12: =IF(ISNUMBER(FC12),INDIRECT("SamplesX!G"&FC12),IF(ISNUMBER(FD12),INDIRECT("SamplesY!G"&FD12),"")) | H12: =IF(ISNUMBER(FC12),INDIRECT("SamplesX!H"&FC12),IF(ISNUMBER(FD12),INDIRECT("SamplesY!H"&FD12),"")) | M12: None | P12: Shimadzu TOC-L | Q12: None | T12: Shimadzu TOC-L | U12: None | Y12: None | AC12: None | AF12: IC Anionen | AG12: None | AK12: None | AN12: IC Anionen | AO12: None | AS12: None | AW12: None | AZ12: IC Anionen | BA12: None | BD12: IC Kationen | BE12: None | BI12: None | BL12: IC Kationen | BM12: None | BP12: IC Kationen | BQ12: None | BT12: IC Kationen | BU12: None | BY12: None | CC12: None | CG12: None | CK12: None | CN12: SOP 45-34 | CO12: None | CS12: None | CW12: None | CZ12: WTW Multimeter 3430 with FDO 925 | DA12: None | DE12: None | DH12: SOP 45-09 | DI12: None | DL12: SOP 45-09 (SOP muss noch angepasst werden für VSS) | DM12: None | DP12: IC Organic Acids | DQ12: None | DT12: IC Organic Acids | DU12: None | DX12: IC Organic Acids | DY12: None | EB12: IC Organic Acids | EC12: None | EF12: IC Organic Acids | EG12: None | EJ12: IC Organic Acids | EK12: None | EN12: IC Organic Acids | EO12: None | ER12: IC Organic Acids | ES12: None | EV12: LC-MS | EW12: None | EZ12: =CONCATENATE(A12,B12) | FA12: =CONCATENATE(SamplesX!A12,SamplesX!B12) | FB12: =CONCATENATE(SamplesY!A12,SamplesY!B12) | FC12: =MATCH(EZ12,FA1:FA1008,0) | FD12: =MATCH(EZ12,FB1:FB1008,0)
C13: =IF(ISNUMBER(FC13),INDIRECT("SamplesX!C"&FC13),IF(ISNUMBER(FD13),INDIRECT("SamplesY!C"&FD13),"")) | D13: =IF(ISNUMBER(FC13),INDIRECT("SamplesX!D"&FC13),IF(ISNUMBER(FD13),INDIRECT("SamplesY!D"&FD13),"")) | E13: =IF(ISNUMBER(FC13),INDIRECT("SamplesX!E"&FC13),IF(ISNUMBER(FD13),INDIRECT("SamplesY!E"&FD13),"")) | F13: =IF(ISNUMBER(FC13),INDIRECT("SamplesX!F"&FC13),IF(ISNUMBER(FD13),INDIRECT("SamplesY!F"&FD13),"")) | G13: =IF(ISNUMBER(FC13),INDIRECT("SamplesX!G"&FC13),IF(ISNUMBER(FD13),INDIRECT("SamplesY!G"&FD13),"")) | H13: =IF(ISNUMBER(FC13),INDIRECT("SamplesX!H"&FC13),IF(ISNUMBER(FD13),INDIRECT("SamplesY!H"&FD13),"")) | M13: None | P13: Shimadzu TOC-L | Q13: None | T13: Shimadzu TOC-L | U13: None | Y13: None | AC13: None | AF13: IC Anionen | AG13: None | AK13: None | AN13: IC Anionen | AO13: None | AS13: None | AW13: None | AZ13: IC Anionen | BA13: None | BD13: IC Kationen | BE13: None | BI13: None | BL13: IC Kationen | BM13: None | BP13: IC Kationen | BQ13: None | BT13: IC Kationen | BU13: None | BY13: None | CC13: None | CG13: None | CK13: None | CN13: SOP 45-34 | CO13: None | CS13: None | CW13: None | CZ13: WTW Multimeter 3430 with FDO 925 | DA13: None | DE13: None | DH13: SOP 45-09 | DI13: None | DL13: SOP 45-09 (SOP muss noch angepasst werden für VSS) | DM13: None | DP13: IC Organic Acids | DQ13: None | DT13: IC Organic Acids | DU13: None | DX13: IC Organic Acids | DY13: None | EB13: IC Organic Acids | EC13: None | EF13: IC Organic Acids | EG13: None | EJ13: IC Organic Acids | EK13: None | EN13: IC Organic Acids | EO13: None | ER13: IC Organic Acids | ES13: None | EV13: LC-MS | EW13: None | EZ13: =CONCATENATE(A13,B13) | FA13: =CONCATENATE(SamplesX!A13,SamplesX!B13) | FB13: =CONCATENATE(SamplesY!A13,SamplesY!B13) | FC13: =MATCH(EZ13,FA1:FA1008,0) | FD13: =MATCH(EZ13,FB1:FB1008,0)
C14: =IF(ISNUMBER(FC14),INDIRECT("SamplesX!C"&FC14),IF(ISNUMBER(FD14),INDIRECT("SamplesY!C"&FD14),"")) | D14: =IF(ISNUMBER(FC14),INDIRECT("SamplesX!D"&FC14),IF(ISNUMBER(FD14),INDIRECT("SamplesY!D"&FD14),"")) | E14: =IF(ISNUMBER(FC14),INDIRECT("SamplesX!E"&FC14),IF(ISNUMBER(FD14),INDIRECT("SamplesY!E"&FD14),"")) | F14: =IF(ISNUMBER(FC14),INDIRECT("SamplesX!F"&FC14),IF(ISNUMBER(FD14),INDIRECT("SamplesY!F"&FD14),"")) | G14: =IF(ISNUMBER(FC14),INDIRECT("SamplesX!G"&FC14),IF(ISNUMBER(FD14),INDIRECT("SamplesY!G"&FD14),"")) | H14: =IF(ISNUMBER(FC14),INDIRECT("SamplesX!H"&FC14),IF(ISNUMBER(FD14),INDIRECT("SamplesY!H"&FD14),"")) | M14: None | P14: Shimadzu TOC-L | Q14: None | T14: Shimadzu TOC-L | U14: None | Y14: None | AC14: None | AF14: IC Anionen | AG14: None | AK14: None | AN14: IC Anionen | AO14: None | AS14: None | AW14: None | AZ14: IC Anionen | BA14: None | BD14: IC Kationen | BE14: None | BI14: None | BL14: IC Kationen | BM14: None | BP14: IC Kationen | BQ14: None | BT14: IC Kationen | BU14: None | BY14: None | CC14: None | CG14: None | CK14: None | CN14: SOP 45-34 | CO14: None | CS14: None | CW14: None | CZ14: WTW Multimeter 3430 with FDO 925 | DA14: None | DE14: None | DH14: SOP 45-09 | DI14: None | DL14: SOP 45-09 (SOP muss noch angepasst werden für VSS) | DM14: None | DP14: IC Organic Acids | DQ14: None | DT14: IC Organic Acids | DU14: None | DX14: IC Organic Acids | DY14: None | EB14: IC Organic Acids | EC14: None | EF14: IC Organic Acids | EG14: None | EJ14: IC Organic Acids | EK14: None | EN14: IC Organic Acids | EO14: None | ER14: IC Organic Acids | ES14: None | EV14: LC-MS | EW14: None | EZ14: =CONCATENATE(A14,B14) | FA14: =CONCATENATE(SamplesX!A14,SamplesX!B14) | FB14: =CONCATENATE(SamplesY!A14,SamplesY!B14) | FC14: =MATCH(EZ14,FA1:FA1008,0) | FD14: =MATCH(EZ14,FB1:FB1008,0)
C15: =IF(ISNUMBER(FC15),INDIRECT("SamplesX!C"&FC15),IF(ISNUMBER(FD15),INDIRECT("SamplesY!C"&FD15),"")) | D15: =IF(ISNUMBER(FC15),INDIRECT("SamplesX!D"&FC15),IF(ISNUMBER(FD15),INDIRECT("SamplesY!D"&FD15),"")) | E15: =IF(ISNUMBER(FC15),INDIRECT("SamplesX!E"&FC15),IF(ISNUMBER(FD15),INDIRECT("SamplesY!E"&FD15),"")) | F15: =IF(ISNUMBER(FC15),INDIRECT("SamplesX!F"&FC15),IF(ISNUMBER(FD15),INDIRECT("SamplesY!F"&FD15),"")) | G15: =IF(ISNUMBER(FC15),INDIRECT("SamplesX!G"&FC15),IF(ISNUMBER(FD15),INDIRECT("SamplesY!G"&FD15),"")) | H15: =IF(ISNUMBER(FC15),INDIRECT("SamplesX!H"&FC15),IF(ISNUMBER(FD15),INDIRECT("SamplesY!H"&FD15),"")) | M15: None | P15: Shimadzu TOC-L | Q15: None | T15: Shimadzu TOC-L | U15: None | Y15: None | AC15: None | AF15: IC Anionen | AG15: None | AK15: None | AN15: IC Anionen | AO15: None | AS15: None | AW15: None | AZ15: IC Anionen | BA15: None | BD15: IC Kationen | BE15: None | BI15: None | BL15: IC Kationen | BM15: None | BP15: IC Kationen | BQ15: None | BT15: IC Kationen | BU15: None | BY15: None | CC15: None | CG15: None | CK15: None | CN15: SOP 45-34 | CO15: None | CS15: None | CW15: None | CZ15: WTW Multimeter 3430 with FDO 925 | DA15: None | DE15: None | DH15: SOP 45-09 | DI15: None | DL15: SOP 45-09 (SOP muss noch angepasst werden für VSS) | DM15: None | DP15: IC Organic Acids | DQ15: None | DT15: IC Organic Acids | DU15: None | DX15: IC Organic Acids | DY15: None | EB15: IC Organic Acids | EC15: None | EF15: IC Organic Acids | EG15: None | EJ15: IC Organic Acids | EK15: None | EN15: IC Organic Acids | EO15: None | ER15: IC Organic Acids | ES15: None | EV15: LC-MS | EW15: None | EZ15: =CONCATENATE(A15,B15) | FA15: =CONCATENATE(SamplesX!A15,SamplesX!B15) | FB15: =CONCATENATE(SamplesY!A15,SamplesY!B15) | FC15: =MATCH(EZ15,FA1:FA1008,0) | FD15: =MATCH(EZ15,FB1:FB1008,0)
C16: =IF(ISNUMBER(FC16),INDIRECT("SamplesX!C"&FC16),IF(ISNUMBER(FD16),INDIRECT("SamplesY!C"&FD16),"")) | D16: =IF(ISNUMBER(FC16),INDIRECT("SamplesX!D"&FC16),IF(ISNUMBER(FD16),INDIRECT("SamplesY!D"&FD16),"")) | E16: =IF(ISNUMBER(FC16),INDIRECT("SamplesX!E"&FC16),IF(ISNUMBER(FD16),INDIRECT("SamplesY!E"&FD16),"")) | F16: =IF(ISNUMBER(FC16),INDIRECT("SamplesX!F"&FC16),IF(ISNUMBER(FD16),INDIRECT("SamplesY!F"&FD16),"")) | G16: =IF(ISNUMBER(FC16),INDIRECT("SamplesX!G"&FC16),IF(ISNUMBER(FD16),INDIRECT("SamplesY!G"&FD16),"")) | H16: =IF(ISNUMBER(FC16),INDIRECT("SamplesX!H"&FC16),IF(ISNUMBER(FD16),INDIRECT("SamplesY!H"&FD16),"")) | M16: None | P16: Shimadzu TOC-L | Q16: None | T16: Shimadzu TOC-L | U16: None | Y16: None | AC16: None | AF16: IC Anionen | AG16: None | AK16: None | AN16: IC Anionen | AO16: None | AS16: None | AW16: None | AZ16: IC Anionen | BA16: None | BD16: IC Kationen | BE16: None | BI16: None | BL16: IC Kationen | BM16: None | BP16: IC Kationen | BQ16: None | BT16: IC Kationen | BU16: None | BY16: None | CC16: None | CG16: None | CK16: None | CN16: SOP 45-34 | CO16: None | CS16: None | CW16: None | CZ16: WTW Multimeter 3430 with FDO 925 | DA16: None | DE16: None | DH16: SOP 45-09 | DI16: None | DL16: SOP 45-09 (SOP muss noch angepasst werden für VSS) | DM16: None | DP16: IC Organic Acids | DQ16: None | DT16: IC Organic Acids | DU16: None | DX16: IC Organic Acids | DY16: None | EB16: IC Organic Acids | EC16: None | EF16: IC Organic Acids | EG16: None | EJ16: IC Organic Acids | EK16: None | EN16: IC Organic Acids | EO16: None | ER16: IC Organic Acids | ES16: None | EV16: LC-MS | EW16: None | EZ16: =CONCATENATE(A16,B16) | FA16: =CONCATENATE(SamplesX!A16,SamplesX!B16) | FB16: =CONCATENATE(SamplesY!A16,SamplesY!B16) | FC16: =MATCH(EZ16,FA1:FA1008,0) | FD16: =MATCH(EZ16,FB1:FB1008,0)
C17: =IF(ISNUMBER(FC17),INDIRECT("SamplesX!C"&FC17),IF(ISNUMBER(FD17),INDIRECT("SamplesY!C"&FD17),"")) | D17: =IF(ISNUMBER(FC17),INDIRECT("SamplesX!D"&FC17),IF(ISNUMBER(FD17),INDIRECT("SamplesY!D"&FD17),"")) | E17: =IF(ISNUMBER(FC17),INDIRECT("SamplesX!E"&FC17),IF(ISNUMBER(FD17),INDIRECT("SamplesY!E"&FD17),"")) | F17: =IF(ISNUMBER(FC17),INDIRECT("SamplesX!F"&FC17),IF(ISNUMBER(FD17),INDIRECT("SamplesY!F"&FD17),"")) | G17: =IF(ISNUMBER(FC17),INDIRECT("SamplesX!G"&FC17),IF(ISNUMBER(FD17),INDIRECT("SamplesY!G"&FD17),"")) | H17: =IF(ISNUMBER(FC17),INDIRECT("SamplesX!H"&FC17),IF(ISNUMBER(FD17),INDIRECT("SamplesY!H"&FD17),"")) | M17: None | P17: Shimadzu TOC-L | Q17: None | T17: Shimadzu TOC-L | U17: None | Y17: None | AC17: None | AF17: IC Anionen | AG17: None | AK17: None | AN17: IC Anionen | AO17: None | AS17: None | AW17: None | AZ17: IC Anionen | BA17: None | BD17: IC Kationen | BE17: None | BI17: None | BL17: IC Kationen | BM17: None | BP17: IC Kationen | BQ17: None | BT17: IC Kationen | BU17: None | BY17: None | CC17: None | CG17: None | CK17: None | CN17: SOP 45-34 | CO17: None | CS17: None | CW17: None | CZ17: WTW Multimeter 3430 with FDO 925 | DA17: None | DE17: None | DH17: SOP 45-09 | DI17: None | DL17: SOP 45-09 (SOP muss noch angepasst werden für VSS) | DM17: None | DP17: IC Organic Acids | DQ17: None | DT17: IC Organic Acids | DU17: None | DX17: IC Organic Acids | DY17: None | EB17: IC Organic Acids | EC17: None | EF17: IC Organic Acids | EG17: None | EJ17: IC Organic Acids | EK17: None | EN17: IC Organic Acids | EO17: None | ER17: IC Organic Acids | ES17: None | EV17: LC-MS | EW17: None | EZ17: =CONCATENATE(A17,B17) | FA17: =CONCATENATE(SamplesX!A17,SamplesX!B17) | FB17: =CONCATENATE(SamplesY!A17,SamplesY!B17) | FC17: =MATCH(EZ17,FA1:FA1008,0) | FD17: =MATCH(EZ17,FB1:FB1008,0)
C18: =IF(ISNUMBER(FC18),INDIRECT("SamplesX!C"&FC18),IF(ISNUMBER(FD18),INDIRECT("SamplesY!C"&FD18),"")) | D18: =IF(ISNUMBER(FC18),INDIRECT("SamplesX!D"&FC18),IF(ISNUMBER(FD18),INDIRECT("SamplesY!D"&FD18),"")) | E18: =IF(ISNUMBER(FC18),INDIRECT("SamplesX!E"&FC18),IF(ISNUMBER(FD18),INDIRECT("SamplesY!E"&FD18),"")) | F18: =IF(ISNUMBER(FC18),INDIRECT("SamplesX!F"&FC18),IF(ISNUMBER(FD18),INDIRECT("SamplesY!F"&FD18),"")) | G18: =IF(ISNUMBER(FC18),INDIRECT("SamplesX!G"&FC18),IF(ISNUMBER(FD18),INDIRECT("SamplesY!G"&FD18),"")) | H18: =IF(ISNUMBER(FC18),INDIRECT("SamplesX!H"&FC18),IF(ISNUMBER(FD18),INDIRECT("SamplesY!H"&FD18),"")) | M18: None | P18: Shimadzu TOC-L | Q18: None | T18: Shimadzu TOC-L | U18: None | Y18: None | AC18: None | AF18: IC Anionen | AG18: None | AK18: None | AN18: IC Anionen | AO18: None | AS18: None | AW18: None | AZ18: IC Anionen | BA18: None | BD18: IC Kationen | BE18: None | BI18: None | BL18: IC Kationen | BM18: None | BP18: IC Kationen | BQ18: None | BT18: IC Kationen | BU18: None | BY18: None | CC18: None | CG18: None | CK18: None | CN18: SOP 45-34 | CO18: None | CS18: None | CW18: None | CZ18: WTW Multimeter 3430 with FDO 925 | DA18: None | DE18: None | DH18: SOP 45-09 | DI18: None | DL18: SOP 45-09 (SOP muss noch angepasst werden für VSS) | DM18: None | DP18: IC Organic Acids | DQ18: None | DT18: IC Organic Acids | DU18: None | DX18: IC Organic Acids | DY18: None | EB18: IC Organic Acids | EC18: None | EF18: IC Organic Acids | EG18: None | EJ18: IC Organic Acids | EK18: None | EN18: IC Organic Acids | EO18: None | ER18: IC Organic Acids | ES18: None | EV18: LC-MS | EW18: None | EZ18: =CONCATENATE(A18,B18) | FA18: =CONCATENATE(SamplesX!A18,SamplesX!B18) | FB18: =CONCATENATE(SamplesY!A18,SamplesY!B18) | FC18: =MATCH(EZ18,FA1:FA1008,0) | FD18: =MATCH(EZ18,FB1:FB1008,0)
C19: =IF(ISNUMBER(FC19),INDIRECT("SamplesX!C"&FC19),IF(ISNUMBER(FD19),INDIRECT("SamplesY!C"&FD19),"")) | D19: =IF(ISNUMBER(FC19),INDIRECT("SamplesX!D"&FC19),IF(ISNUMBER(FD19),INDIRECT("SamplesY!D"&FD19),"")) | E19: =IF(ISNUMBER(FC19),INDIRECT("SamplesX!E"&FC19),IF(ISNUMBER(FD19),INDIRECT("SamplesY!E"&FD19),"")) | F19: =IF(ISNUMBER(FC19),INDIRECT("SamplesX!F"&FC19),IF(ISNUMBER(FD19),INDIRECT("SamplesY!F"&FD19),"")) | G19: =IF(ISNUMBER(FC19),INDIRECT("SamplesX!G"&FC19),IF(ISNUMBER(FD19),INDIRECT("SamplesY!G"&FD19),"")) | H19: =IF(ISNUMBER(FC19),INDIRECT("SamplesX!H"&FC19),IF(ISNUMBER(FD19),INDIRECT("SamplesY!H"&FD19),"")) | M19: None | P19: Shimadzu TOC-L | Q19: None | T19: Shimadzu TOC-L | U19: None | Y19: None | AC19: None | AF19: IC Anionen | AG19: None | AK19: None | AN19: IC Anionen | AO19: None | AS19: None | AW19: None | AZ19: IC Anionen | BA19: None | BD19: IC Kationen | BE19: None | BI19: None | BL19: IC Kationen | BM19: None | BP19: IC Kationen | BQ19: None | BT19: IC Kationen | BU19: None | BY19: None | CC19: None | CG19: None | CK19: None | CN19: SOP 45-34 | CO19: None | CS19: None | CW19: None | CZ19: WTW Multimeter 3430 with FDO 925 | DA19: None | DE19: None | DH19: SOP 45-09 | DI19: None | DL19: SOP 45-09 (SOP muss noch angepasst werden für VSS) | DM19: None | DP19: IC Organic Acids | DQ19: None | DT19: IC Organic Acids | DU19: None | DX19: IC Organic Acids | DY19: None | EB19: IC Organic Acids | EC19: None | EF19: IC Organic Acids | EG19: None | EJ19: IC Organic Acids | EK19: None | EN19: IC Organic Acids | EO19: None | ER19: IC Organic Acids | ES19: None | EV19: LC-MS | EW19: None | EZ19: =CONCATENATE(A19,B19) | FA19: =CONCATENATE(SamplesX!A19,SamplesX!B19) | FB19: =CONCATENATE(SamplesY!A19,SamplesY!B19) | FC19: =MATCH(EZ19,FA1:FA1008,0) | FD19: =MATCH(EZ19,FB1:FB1008,0)
C20: =IF(ISNUMBER(FC20),INDIRECT("SamplesX!C"&FC20),IF(ISNUMBER(FD20),INDIRECT("SamplesY!C"&FD20),"")) | D20: =IF(ISNUMBER(FC20),INDIRECT("SamplesX!D"&FC20),IF(ISNUMBER(FD20),INDIRECT("SamplesY!D"&FD20),"")) | E20: =IF(ISNUMBER(FC20),INDIRECT("SamplesX!E"&FC20),IF(ISNUMBER(FD20),INDIRECT("SamplesY!E"&FD20),"")) | F20: =IF(ISNUMBER(FC20),INDIRECT("SamplesX!F"&FC20),IF(ISNUMBER(FD20),INDIRECT("SamplesY!F"&FD20),"")) | G20: =IF(ISNUMBER(FC20),INDIRECT("SamplesX!G"&FC20),IF(ISNUMBER(FD20),INDIRECT("SamplesY!G"&FD20),"")) | H20: =IF(ISNUMBER(FC20),INDIRECT("SamplesX!H"&FC20),IF(ISNUMBER(FD20),INDIRECT("SamplesY!H"&FD20),"")) | M20: None | P20: Shimadzu TOC-L | Q20: None | T20: Shimadzu TOC-L | U20: None | Y20: None | AC20: None | AF20: IC Anionen | AG20: None | AK20: None | AN20: IC Anionen | AO20: None | AS20: None | AW20: None | AZ20: IC Anionen | BA20: None | BD20: IC Kationen | BE20: None | BI20: None | BL20: IC Kationen | BM20: None | BP20: IC Kationen | BQ20: None | BT20: IC Kationen | BU20: None | BY20: None | CC20: None | CG20: None | CK20: None | CN20: SOP 45-34 | CO20: None | CS20: None | CW20: None | CZ20: WTW Multimeter 3430 with FDO 925 | DA20: None | DE20: None | DH20: SOP 45-09 | DI20: None | DL20: SOP 45-09 (SOP muss noch angepasst werden für VSS) | DM20: None | DP20: IC Organic Acids | DQ20: None | DT20: IC Organic Acids | DU20: None | DX20: IC Organic Acids | DY20: None | EB20: IC Organic Acids | EC20: None | EF20: IC Organic Acids | EG20: None | EJ20: IC Organic Acids | EK20: None | EN20: IC Organic Acids | EO20: None | ER20: IC Organic Acids | ES20: None | EV20: LC-MS | EW20: None | EZ20: =CONCATENATE(A20,B20) | FA20: =CONCATENATE(SamplesX!A20,SamplesX!B20) | FB20: =CONCATENATE(SamplesY!A20,SamplesY!B20) | FC20: =MATCH(EZ20,FA1:FA1008,0) | FD20: =MATCH(EZ20,FB1:FB1008,0)
C21: =IF(ISNUMBER(FC21),INDIRECT("SamplesX!C"&FC21),IF(ISNUMBER(FD21),INDIRECT("SamplesY!C"&FD21),"")) | D21: =IF(ISNUMBER(FC21),INDIRECT("SamplesX!D"&FC21),IF(ISNUMBER(FD21),INDIRECT("SamplesY!D"&FD21),"")) | E21: =IF(ISNUMBER(FC21),INDIRECT("SamplesX!E"&FC21),IF(ISNUMBER(FD21),INDIRECT("SamplesY!E"&FD21),"")) | F21: =IF(ISNUMBER(FC21),INDIRECT("SamplesX!F"&FC21),IF(ISNUMBER(FD21),INDIRECT("SamplesY!F"&FD21),"")) | G21: =IF(ISNUMBER(FC21),INDIRECT("SamplesX!G"&FC21),IF(ISNUMBER(FD21),INDIRECT("SamplesY!G"&FD21),"")) | H21: =IF(ISNUMBER(FC21),INDIRECT("SamplesX!H"&FC21),IF(ISNUMBER(FD21),INDIRECT("SamplesY!H"&FD21),"")) | M21: None | P21: Shimadzu TOC-L | Q21: None | T21: Shimadzu TOC-L | U21: None | Y21: None | AC21: None | AF21: IC Anionen | AG21: None | AK21: None | AN21: IC Anionen | AO21: None | AS21: None | AW21: None | AZ21: IC Anionen | BA21: None | BD21: IC Kationen | BE21: None | BI21: None | BL21: IC Kationen | BM21: None | BP21: IC Kationen | BQ21: None | BT21: IC Kationen | BU21: None | BY21: None | CC21: None | CG21: None | CK21: None | CN21: SOP 45-34 | CO21: None | CS21: None | CW21: None | CZ21: WTW Multimeter 3430 with FDO 925 | DA21: None | DE21: None | DH21: SOP 45-09 | DI21: None | DL21: SOP 45-09 (SOP muss noch angepasst werden für VSS) | DM21: None | DP21: IC Organic Acids | DQ21: None | DT21: IC Organic Acids | DU21: None | DX21: IC Organic Acids | DY21: None | EB21: IC Organic Acids | EC21: None | EF21: IC Organic Acids | EG21: None | EJ21: IC Organic Acids | EK21: None | EN21: IC Organic Acids | EO21: None | ER21: IC Organic Acids | ES21: None | EV21: LC-MS | EW21: None | EZ21: =CONCATENATE(A21,B21) | FA21: =CONCATENATE(SamplesX!A21,SamplesX!B21) | FB21: =CONCATENATE(SamplesY!A21,SamplesY!B21) | FC21: =MATCH(EZ21,FA1:FA1008,0) | FD21: =MATCH(EZ21,FB1:FB1008,0)
C22: =IF(ISNUMBER(FC22),INDIRECT("SamplesX!C"&FC22),IF(ISNUMBER(FD22),INDIRECT("SamplesY!C"&FD22),"")) | D22: =IF(ISNUMBER(FC22),INDIRECT("SamplesX!D"&FC22),IF(ISNUMBER(FD22),INDIRECT("SamplesY!D"&FD22),"")) | E22: =IF(ISNUMBER(FC22),INDIRECT("SamplesX!E"&FC22),IF(ISNUMBER(FD22),INDIRECT("SamplesY!E"&FD22),"")) | F22: =IF(ISNUMBER(FC22),INDIRECT("SamplesX!F"&FC22),IF(ISNUMBER(FD22),INDIRECT("SamplesY!F"&FD22),"")) | G22: =IF(ISNUMBER(FC22),INDIRECT("SamplesX!G"&FC22),IF(ISNUMBER(FD22),INDIRECT("SamplesY!G"&FD22),"")) | H22: =IF(ISNUMBER(FC22),INDIRECT("SamplesX!H"&FC22),IF(ISNUMBER(FD22),INDIRECT("SamplesY!H"&FD22),"")) | M22: None | P22: Shimadzu TOC-L | Q22: None | T22: Shimadzu TOC-L | U22: None | Y22: None | AC22: None | AF22: IC Anionen | AG22: None | AK22: None | AN22: IC Anionen | AO22: None | AS22: None | AW22: None | AZ22: IC Anionen | BA22: None | BD22: IC Kationen | BE22: None | BI22: None | BL22: IC Kationen | BM22: None | BP22: IC Kationen | BQ22: None | BT22: IC Kationen | BU22: None | BY22: None | CC22: None | CG22: None | CK22: None | CN22: SOP 45-34 | CO22: None | CS22: None | CW22: None | CZ22: WTW Multimeter 3430 with FDO 925 | DA22: None | DE22: None | DH22: SOP 45-09 | DI22: None | DL22: SOP 45-09 (SOP muss noch angepasst werden für VSS) | DM22: None | DP22: IC Organic Acids | DQ22: None | DT22: IC Organic Acids | DU22: None | DX22: IC Organic Acids | DY22: None | EB22: IC Organic Acids | EC22: None | EF22: IC Organic Acids | EG22: None | EJ22: IC Organic Acids | EK22: None | EN22: IC Organic Acids | EO22: None | ER22: IC Organic Acids | ES22: None | EV22: LC-MS | EW22: None | EZ22: =CONCATENATE(A22,B22) | FA22: =CONCATENATE(SamplesX!A22,SamplesX!B22) | FB22: =CONCATENATE(SamplesY!A22,SamplesY!B22) | FC22: =MATCH(EZ22,FA1:FA1008,0) | FD22: =MATCH(EZ22,FB1:FB1008,0)
C23: =IF(ISNUMBER(FC23),INDIRECT("SamplesX!C"&FC23),IF(ISNUMBER(FD23),INDIRECT("SamplesY!C"&FD23),"")) | D23: =IF(ISNUMBER(FC23),INDIRECT("SamplesX!D"&FC23),IF(ISNUMBER(FD23),INDIRECT("SamplesY!D"&FD23),"")) | E23: =IF(ISNUMBER(FC23),INDIRECT("SamplesX!E"&FC23),IF(ISNUMBER(FD23),INDIRECT("SamplesY!E"&FD23),"")) | F23: =IF(ISNUMBER(FC23),INDIRECT("SamplesX!F"&FC23),IF(ISNUMBER(FD23),INDIRECT("SamplesY!F"&FD23),"")) | G23: =IF(ISNUMBER(FC23),INDIRECT("SamplesX!G"&FC23),IF(ISNUMBER(FD23),INDIRECT("SamplesY!G"&FD23),"")) | H23: =IF(ISNUMBER(FC23),INDIRECT("SamplesX!H"&FC23),IF(ISNUMBER(FD23),INDIRECT("SamplesY!H"&FD23),"")) | M23: None | P23: Shimadzu TOC-L | Q23: None | T23: Shimadzu TOC-L | U23: None | Y23: None | AC23: None | AF23: IC Anionen | AG23: None | AK23: None | AN23: IC Anionen | AO23: None | AS23: None | AW23: None | AZ23: IC Anionen | BA23: None | BD23: IC Kationen | BE23: None | BI23: None | BL23: IC Kationen | BM23: None | BP23: IC Kationen | BQ23: None | BT23: IC Kationen | BU23: None | BY23: None | CC23: None | CG23: None | CK23: None | CN23: SOP 45-34 | CO23: None | CS23: None | CW23: None | CZ23: WTW Multimeter 3430 with FDO 925 | DA23: None | DE23: None | DH23: SOP 45-09 | DI23: None | DL23: SOP 45-09 (SOP muss noch angepasst werden für VSS) | DM23: None | DP23: IC Organic Acids | DQ23: None | DT23: IC Organic Acids | DU23: None | DX23: IC Organic Acids | DY23: None | EB23: IC Organic Acids | EC23: None | EF23: IC Organic Acids | EG23: None | EJ23: IC Organic Acids | EK23: None | EN23: IC Organic Acids | EO23: None | ER23: IC Organic Acids | ES23: None | EV23: LC-MS | EW23: None | EZ23: =CONCATENATE(A23,B23) | FA23: =CONCATENATE(SamplesX!A23,SamplesX!B23) | FB23: =CONCATENATE(SamplesY!A23,SamplesY!B23) | FC23: =MATCH(EZ23,FA1:FA1008,0) | FD23: =MATCH(EZ23,FB1:FB1008,0)
C24: =IF(ISNUMBER(FC24),INDIRECT("SamplesX!C"&FC24),IF(ISNUMBER(FD24),INDIRECT("SamplesY!C"&FD24),"")) | D24: =IF(ISNUMBER(FC24),INDIRECT("SamplesX!D"&FC24),IF(ISNUMBER(FD24),INDIRECT("SamplesY!D"&FD24),"")) | E24: =IF(ISNUMBER(FC24),INDIRECT("SamplesX!E"&FC24),IF(ISNUMBER(FD24),INDIRECT("SamplesY!E"&FD24),"")) | F24: =IF(ISNUMBER(FC24),INDIRECT("SamplesX!F"&FC24),IF(ISNUMBER(FD24),INDIRECT("SamplesY!F"&FD24),"")) | G24: =IF(ISNUMBER(FC24),INDIRECT("SamplesX!G"&FC24),IF(ISNUMBER(FD24),INDIRECT("SamplesY!G"&FD24),"")) | H24: =IF(ISNUMBER(FC24),INDIRECT("SamplesX!H"&FC24),IF(ISNUMBER(FD24),INDIRECT("SamplesY!H"&FD24),"")) | M24: None | P24: Shimadzu TOC-L | Q24: None | T24: Shimadzu TOC-L | U24: None | Y24: None | AC24: None | AF24: IC Anionen | AG24: None | AK24: None | AN24: IC Anionen | AO24: None | AS24: None | AW24: None | AZ24: IC Anionen | BA24: None | BD24: IC Kationen | BE24: None | BI24: None | BL24: IC Kationen | BM24: None | BP24: IC Kationen | BQ24: None | BT24: IC Kationen | BU24: None | BY24: None | CC24: None | CG24: None | CK24: None | CN24: SOP 45-34 | CO24: None | CS24: None | CW24: None | CZ24: WTW Multimeter 3430 with FDO 925 | DA24: None | DE24: None | DH24: SOP 45-09 | DI24: None | DL24: SOP 45-09 (SOP muss noch angepasst werden für VSS) | DM24: None | DP24: IC Organic Acids | DQ24: None | DT24: IC Organic Acids | DU24: None | DX24: IC Organic Acids | DY24: None | EB24: IC Organic Acids | EC24: None | EF24: IC Organic Acids | EG24: None | EJ24: IC Organic Acids | EK24: None | EN24: IC Organic Acids | EO24: None | ER24: IC Organic Acids | ES24: None | EV24: LC-MS | EW24: None | EZ24: =CONCATENATE(A24,B24) | FA24: =CONCATENATE(SamplesX!A24,SamplesX!B24) | FB24: =CONCATENATE(SamplesY!A24,SamplesY!B24) | FC24: =MATCH(EZ24,FA1:FA1008,0) | FD24: =MATCH(EZ24,FB1:FB1008,0)
C25: =IF(ISNUMBER(FC25),INDIRECT("SamplesX!C"&FC25),IF(ISNUMBER(FD25),INDIRECT("SamplesY!C"&FD25),"")) | D25: =IF(ISNUMBER(FC25),INDIRECT("SamplesX!D"&FC25),IF(ISNUMBER(FD25),INDIRECT("SamplesY!D"&FD25),"")) | E25: =IF(ISNUMBER(FC25),INDIRECT("SamplesX!E"&FC25),IF(ISNUMBER(FD25),INDIRECT("SamplesY!E"&FD25),"")) | F25: =IF(ISNUMBER(FC25),INDIRECT("SamplesX!F"&FC25),IF(ISNUMBER(FD25),INDIRECT("SamplesY!F"&FD25),"")) | G25: =IF(ISNUMBER(FC25),INDIRECT("SamplesX!G"&FC25),IF(ISNUMBER(FD25),INDIRECT("SamplesY!G"&FD25),"")) | H25: =IF(ISNUMBER(FC25),INDIRECT("SamplesX!H"&FC25),IF(ISNUMBER(FD25),INDIRECT("SamplesY!H"&FD25),"")) | M25: None | P25: Shimadzu TOC-L | Q25: None | T25: Shimadzu TOC-L | U25: None | Y25: None | AC25: None | AF25: IC Anionen | AG25: None | AK25: None | AN25: IC Anionen | AO25: None | AS25: None | AW25: None | AZ25: IC Anionen | BA25: None | BD25: IC Kationen | BE25: None | BI25: None | BL25: IC Kationen | BM25: None | BP25: IC Kationen | BQ25: None | BT25: IC Kationen | BU25: None | BY25: None | CC25: None | CG25: None | CK25: None | CN25: SOP 45-34 | CO25: None | CS25: None | CW25: None | CZ25: WTW Multimeter 3430 with FDO 925 | DA25: None | DE25: None | DH25: SOP 45-09 | DI25: None | DL25: SOP 45-09 (SOP muss noch angepasst werden für VSS) | DM25: None | DP25: IC Organic Acids | DQ25: None | DT25: IC Organic Acids | DU25: None | DX25: IC Organic Acids | DY25: None | EB25: IC Organic Acids | EC25: None | EF25: IC Organic Acids | EG25: None | EJ25: IC Organic Acids | EK25: None | EN25: IC Organic Acids | EO25: None | ER25: IC Organic Acids | ES25: None | EV25: LC-MS | EW25: None | EZ25: =CONCATENATE(A25,B25) | FA25: =CONCATENATE(SamplesX!A25,SamplesX!B25) | FB25: =CONCATENATE(SamplesY!A25,SamplesY!B25) | FC25: =MATCH(EZ25,FA1:FA1008,0) | FD25: =MATCH(EZ25,FB1:FB1008,0)
C26: =IF(ISNUMBER(FC26),INDIRECT("SamplesX!C"&FC26),IF(ISNUMBER(FD26),INDIRECT("SamplesY!C"&FD26),"")) | D26: =IF(ISNUMBER(FC26),INDIRECT("SamplesX!D"&FC26),IF(ISNUMBER(FD26),INDIRECT("SamplesY!D"&FD26),"")) | E26: =IF(ISNUMBER(FC26),INDIRECT("SamplesX!E"&FC26),IF(ISNUMBER(FD26),INDIRECT("SamplesY!E"&FD26),"")) | F26: =IF(ISNUMBER(FC26),INDIRECT("SamplesX!F"&FC26),IF(ISNUMBER(FD26),INDIRECT("SamplesY!F"&FD26),"")) | G26: =IF(ISNUMBER(FC26),INDIRECT("SamplesX!G"&FC26),IF(ISNUMBER(FD26),INDIRECT("SamplesY!G"&FD26),"")) | H26: =IF(ISNUMBER(FC26),INDIRECT("SamplesX!H"&FC26),IF(ISNUMBER(FD26),INDIRECT("SamplesY!H"&FD26),"")) | M26: None | P26: Shimadzu TOC-L | Q26: None | T26: Shimadzu TOC-L | U26: None | Y26: None | AC26: None | AF26: IC Anionen | AG26: None | AK26: None | AN26: IC Anionen | AO26: None | AS26: None | AW26: None | AZ26: IC Anionen | BA26: None | BD26: IC Kationen | BE26: None | BI26: None | BL26: IC Kationen | BM26: None | BP26: IC Kationen | BQ26: None | BT26: IC Kationen | BU26: None | BY26: None | CC26: None | CG26: None | CK26: None | CN26: SOP 45-34 | CO26: None | CS26: None | CW26: None | CZ26: WTW Multimeter 3430 with FDO 925 | DA26: None | DE26: None | DH26: SOP 45-09 | DI26: None | DL26: SOP 45-09 (SOP muss noch angepasst werden für VSS) | DM26: None | DP26: IC Organic Acids | DQ26: None | DT26: IC Organic Acids | DU26: None | DX26: IC Organic Acids | DY26: None | EB26: IC Organic Acids | EC26: None | EF26: IC Organic Acids | EG26: None | EJ26: IC Organic Acids | EK26: None | EN26: IC Organic Acids | EO26: None | ER26: IC Organic Acids | ES26: None | EV26: LC-MS | EW26: None | EZ26: =CONCATENATE(A26,B26) | FA26: =CONCATENATE(SamplesX!A26,SamplesX!B26) | FB26: =CONCATENATE(SamplesY!A26,SamplesY!B26) | FC26: =MATCH(EZ26,FA1:FA1008,0) | FD26: =MATCH(EZ26,FB1:FB1008,0)
C27: =IF(ISNUMBER(FC27),INDIRECT("SamplesX!C"&FC27),IF(ISNUMBER(FD27),INDIRECT("SamplesY!C"&FD27),"")) | D27: =IF(ISNUMBER(FC27),INDIRECT("SamplesX!D"&FC27),IF(ISNUMBER(FD27),INDIRECT("SamplesY!D"&FD27),"")) | E27: =IF(ISNUMBER(FC27),INDIRECT("SamplesX!E"&FC27),IF(ISNUMBER(FD27),INDIRECT("SamplesY!E"&FD27),"")) | F27: =IF(ISNUMBER(FC27),INDIRECT("SamplesX!F"&FC27),IF(ISNUMBER(FD27),INDIRECT("SamplesY!F"&FD27),"")) | G27: =IF(ISNUMBER(FC27),INDIRECT("SamplesX!G"&FC27),IF(ISNUMBER(FD27),INDIRECT("SamplesY!G"&FD27),"")) | H27: =IF(ISNUMBER(FC27),INDIRECT("SamplesX!H"&FC27),IF(ISNUMBER(FD27),INDIRECT("SamplesY!H"&FD27),"")) | M27: None | P27: Shimadzu TOC-L | Q27: None | T27: Shimadzu TOC-L | U27: None | Y27: None | AC27: None | AF27: IC Anionen | AG27: None | AK27: None | AN27: IC Anionen | AO27: None | AS27: None | AW27: None | AZ27: IC Anionen | BA27: None | BD27: IC Kationen | BE27: None | BI27: None | BL27: IC Kationen | BM27: None | BP27: IC Kationen | BQ27: None | BT27: IC Kationen | BU27: None | BY27: None | CC27: None | CG27: None | CK27: None | CN27: SOP 45-34 | CO27: None | CS27: None | CW27: None | CZ27: WTW Multimeter 3430 with FDO 925 | DA27: None | DE27: None | DH27: SOP 45-09 | DI27: None | DL27: SOP 45-09 (SOP muss noch angepasst werden für VSS) | DM27: None | DP27: IC Organic Acids | DQ27: None | DT27: IC Organic Acids | DU27: None | DX27: IC Organic Acids | DY27: None | EB27: IC Organic Acids | EC27: None | EF27: IC Organic Acids | EG27: None | EJ27: IC Organic Acids | EK27: None | EN27: IC Organic Acids | EO27: None | ER27: IC Organic Acids | ES27: None | EV27: LC-MS | EW27: None | EZ27: =CONCATENATE(A27,B27) | FA27: =CONCATENATE(SamplesX!A27,SamplesX!B27) | FB27: =CONCATENATE(SamplesY!A27,SamplesY!B27) | FC27: =MATCH(EZ27,FA1:FA1008,0) | FD27: =MATCH(EZ27,FB1:FB1008,0)
C28: =IF(ISNUMBER(FC28),INDIRECT("SamplesX!C"&FC28),IF(ISNUMBER(FD28),INDIRECT("SamplesY!C"&FD28),"")) | D28: =IF(ISNUMBER(FC28),INDIRECT("SamplesX!D"&FC28),IF(ISNUMBER(FD28),INDIRECT("SamplesY!D"&FD28),"")) | E28: =IF(ISNUMBER(FC28),INDIRECT("SamplesX!E"&FC28),IF(ISNUMBER(FD28),INDIRECT("SamplesY!E"&FD28),"")) | F28: =IF(ISNUMBER(FC28),INDIRECT("SamplesX!F"&FC28),IF(ISNUMBER(FD28),INDIRECT("SamplesY!F"&FD28),"")) | G28: =IF(ISNUMBER(FC28),INDIRECT("SamplesX!G"&FC28),IF(ISNUMBER(FD28),INDIRECT("SamplesY!G"&FD28),"")) | H28: =IF(ISNUMBER(FC28),INDIRECT("SamplesX!H"&FC28),IF(ISNUMBER(FD28),INDIRECT("SamplesY!H"&FD28),"")) | M28: None | P28: Shimadzu TOC-L | Q28: None | T28: Shimadzu TOC-L | U28: None | Y28: None | AC28: None | AF28: IC Anionen | AG28: None | AK28: None | AN28: IC Anionen | AO28: None | AS28: None | AW28: None | AZ28: IC Anionen | BA28: None | BD28: IC Kationen | BE28: None | BI28: None | BL28: IC Kationen | BM28: None | BP28: IC Kationen | BQ28: None | BT28: IC Kationen | BU28: None | BY28: None | CC28: None | CG28: None | CK28: None | CN28: SOP 45-34 | CO28: None | CS28: None | CW28: None | CZ28: WTW Multimeter 3430 with FDO 925 | DA28: None | DE28: None | DH28: SOP 45-09 | DI28: None | DL28: SOP 45-09 (SOP muss noch angepasst werden für VSS) | DM28: None | DP28: IC Organic Acids | DQ28: None | DT28: IC Organic Acids | DU28: None | DX28: IC Organic Acids | DY28: None | EB28: IC Organic Acids | EC28: None | EF28: IC Organic Acids | EG28: None | EJ28: IC Organic Acids | EK28: None | EN28: IC Organic Acids | EO28: None | ER28: IC Organic Acids | ES28: None | EV28: LC-MS | EW28: None | EZ28: =CONCATENATE(A28,B28) | FA28: =CONCATENATE(SamplesX!A28,SamplesX!B28) | FB28: =CONCATENATE(SamplesY!A28,SamplesY!B28) | FC28: =MATCH(EZ28,FA1:FA1008,0) | FD28: =MATCH(EZ28,FB1:FB1008,0)
C29: =IF(ISNUMBER(FC29),INDIRECT("SamplesX!C"&FC29),IF(ISNUMBER(FD29),INDIRECT("SamplesY!C"&FD29),"")) | D29: =IF(ISNUMBER(FC29),INDIRECT("SamplesX!D"&FC29),IF(ISNUMBER(FD29),INDIRECT("SamplesY!D"&FD29),"")) | E29: =IF(ISNUMBER(FC29),INDIRECT("SamplesX!E"&FC29),IF(ISNUMBER(FD29),INDIRECT("SamplesY!E"&FD29),"")) | F29: =IF(ISNUMBER(FC29),INDIRECT("SamplesX!F"&FC29),IF(ISNUMBER(FD29),INDIRECT("SamplesY!F"&FD29),"")) | G29: =IF(ISNUMBER(FC29),INDIRECT("SamplesX!G"&FC29),IF(ISNUMBER(FD29),INDIRECT("SamplesY!G"&FD29),"")) | H29: =IF(ISNUMBER(FC29),INDIRECT("SamplesX!H"&FC29),IF(ISNUMBER(FD29),INDIRECT("SamplesY!H"&FD29),"")) | M29: None | P29: Shimadzu TOC-L | Q29: None | T29: Shimadzu TOC-L | U29: None | Y29: None | AC29: None | AF29: IC Anionen | AG29: None | AK29: None | AN29: IC Anionen | AO29: None | AS29: None | AW29: None | AZ29: IC Anionen | BA29: None | BD29: IC Kationen | BE29: None | BI29: None | BL29: IC Kationen | BM29: None | BP29: IC Kationen | BQ29: None | BT29: IC Kationen | BU29: None | BY29: None | CC29: None | CG29: None | CK29: None | CN29: SOP 45-34 | CO29: None | CS29: None | CW29: None | CZ29: WTW Multimeter 3430 with FDO 925 | DA29: None | DE29: None | DH29: SOP 45-09 | DI29: None | DL29: SOP 45-09 (SOP muss noch angepasst werden für VSS) | DM29: None | DP29: IC Organic Acids | DQ29: None | DT29: IC Organic Acids | DU29: None | DX29: IC Organic Acids | DY29: None | EB29: IC Organic Acids | EC29: None | EF29: IC Organic Acids | EG29: None | EJ29: IC Organic Acids | EK29: None | EN29: IC Organic Acids | EO29: None | ER29: IC Organic Acids | ES29: None | EV29: LC-MS | EW29: None | EZ29: =CONCATENATE(A29,B29) | FA29: =CONCATENATE(SamplesX!A29,SamplesX!B29) | FB29: =CONCATENATE(SamplesY!A29,SamplesY!B29) | FC29: =MATCH(EZ29,FA1:FA1008,0) | FD29: =MATCH(EZ29,FB1:FB1008,0)
C30: =IF(ISNUMBER(FC30),INDIRECT("SamplesX!C"&FC30),IF(ISNUMBER(FD30),INDIRECT("SamplesY!C"&FD30),"")) | D30: =IF(ISNUMBER(FC30),INDIRECT("SamplesX!D"&FC30),IF(ISNUMBER(FD30),INDIRECT("SamplesY!D"&FD30),"")) | E30: =IF(ISNUMBER(FC30),INDIRECT("SamplesX!E"&FC30),IF(ISNUMBER(FD30),INDIRECT("SamplesY!E"&FD30),"")) | F30: =IF(ISNUMBER(FC30),INDIRECT("SamplesX!F"&FC30),IF(ISNUMBER(FD30),INDIRECT("SamplesY!F"&FD30),"")) | G30: =IF(ISNUMBER(FC30),INDIRECT("SamplesX!G"&FC30),IF(ISNUMBER(FD30),INDIRECT("SamplesY!G"&FD30),"")) | H30: =IF(ISNUMBER(FC30),INDIRECT("SamplesX!H"&FC30),IF(ISNUMBER(FD30),INDIRECT("SamplesY!H"&FD30),"")) | M30: None | P30: Shimadzu TOC-L | Q30: None | T30: Shimadzu TOC-L | U30: None | Y30: None | AC30: None | AF30: IC Anionen | AG30: None | AK30: None | AN30: IC Anionen | AO30: None | AS30: None | AW30: None | AZ30: IC Anionen | BA30: None | BD30: IC Kationen | BE30: None | BI30: None | BL30: IC Kationen | BM30: None | BP30: IC Kationen | BQ30: None | BT30: IC Kationen | BU30: None | BY30: None | CC30: None | CG30: None | CK30: None | CN30: SOP 45-34 | CO30: None | CS30: None | CW30: None | CZ30: WTW Multimeter 3430 with FDO 925 | DA30: None | DE30: None | DH30: SOP 45-09 | DI30: None | DL30: SOP 45-09 (SOP muss noch angepasst werden für VSS) | DM30: None | DP30: IC Organic Acids | DQ30: None | DT30: IC Organic Acids | DU30: None | DX30: IC Organic Acids | DY30: None | EB30: IC Organic Acids | EC30: None | EF30: IC Organic Acids | EG30: None | EJ30: IC Organic Acids | EK30: None | EN30: IC Organic Acids | EO30: None | ER30: IC Organic Acids | ES30: None | EV30: LC-MS | EW30: None | EZ30: =CONCATENATE(A30,B30) | FA30: =CONCATENATE(SamplesX!A30,SamplesX!B30) | FB30: =CONCATENATE(SamplesY!A30,SamplesY!B30) | FC30: =MATCH(EZ30,FA1:FA1008,0) | FD30: =MATCH(EZ30,FB1:FB1008,0)
C31: =IF(ISNUMBER(FC31),INDIRECT("SamplesX!C"&FC31),IF(ISNUMBER(FD31),INDIRECT("SamplesY!C"&FD31),"")) | D31: =IF(ISNUMBER(FC31),INDIRECT("SamplesX!D"&FC31),IF(ISNUMBER(FD31),INDIRECT("SamplesY!D"&FD31),"")) | E31: =IF(ISNUMBER(FC31),INDIRECT("SamplesX!E"&FC31),IF(ISNUMBER(FD31),INDIRECT("SamplesY!E"&FD31),"")) | F31: =IF(ISNUMBER(FC31),INDIRECT("SamplesX!F"&FC31),IF(ISNUMBER(FD31),INDIRECT("SamplesY!F"&FD31),"")) | G31: =IF(ISNUMBER(FC31),INDIRECT("SamplesX!G"&FC31),IF(ISNUMBER(FD31),INDIRECT("SamplesY!G"&FD31),"")) | H31: =IF(ISNUMBER(FC31),INDIRECT("SamplesX!H"&FC31),IF(ISNUMBER(FD31),INDIRECT("SamplesY!H"&FD31),"")) | M31: None | P31: Shimadzu TOC-L | Q31: None | T31: Shimadzu TOC-L | U31: None | Y31: None | AC31: None | AF31: IC Anionen | AG31: None | AK31: None | AN31: IC Anionen | AO31: None | AS31: None | AW31: None | AZ31: IC Anionen | BA31: None | BD31: IC Kationen | BE31: None | BI31: None | BL31: IC Kationen | BM31: None | BP31: IC Kationen | BQ31: None | BT31: IC Kationen | BU31: None | BY31: None | CC31: None | CG31: None | CK31: None | CN31: SOP 45-34 | CO31: None | CS31: None | CW31: None | CZ31: WTW Multimeter 3430 with FDO 925 | DA31: None | DE31: None | DH31: SOP 45-09 | DI31: None | DL31: SOP 45-09 (SOP muss noch angepasst werden für VSS) | DM31: None | DP31: IC Organic Acids | DQ31: None | DT31: IC Organic Acids | DU31: None | DX31: IC Organic Acids | DY31: None | EB31: IC Organic Acids | EC31: None | EF31: IC Organic Acids | EG31: None | EJ31: IC Organic Acids | EK31: None | EN31: IC Organic Acids | EO31: None | ER31: IC Organic Acids | ES31: None | EV31: LC-MS | EW31: None | EZ31: =CONCATENATE(A31,B31) | FA31: =CONCATENATE(SamplesX!A31,SamplesX!B31) | FB31: =CONCATENATE(SamplesY!A31,SamplesY!B31) | FC31: =MATCH(EZ31,FA1:FA1008,0) | FD31: =MATCH(EZ31,FB1:FB1008,0)
C32: =IF(ISNUMBER(FC32),INDIRECT("SamplesX!C"&FC32),IF(ISNUMBER(FD32),INDIRECT("SamplesY!C"&FD32),"")) | D32: =IF(ISNUMBER(FC32),INDIRECT("SamplesX!D"&FC32),IF(ISNUMBER(FD32),INDIRECT("SamplesY!D"&FD32),"")) | E32: =IF(ISNUMBER(FC32),INDIRECT("SamplesX!E"&FC32),IF(ISNUMBER(FD32),INDIRECT("SamplesY!E"&FD32),"")) | F32: =IF(ISNUMBER(FC32),INDIRECT("SamplesX!F"&FC32),IF(ISNUMBER(FD32),INDIRECT("SamplesY!F"&FD32),"")) | G32: =IF(ISNUMBER(FC32),INDIRECT("SamplesX!G"&FC32),IF(ISNUMBER(FD32),INDIRECT("SamplesY!G"&FD32),"")) | H32: =IF(ISNUMBER(FC32),INDIRECT("SamplesX!H"&FC32),IF(ISNUMBER(FD32),INDIRECT("SamplesY!H"&FD32),"")) | M32: None | P32: Shimadzu TOC-L | Q32: None | T32: Shimadzu TOC-L | U32: None | Y32: None | AC32: None | AF32: IC Anionen | AG32: None | AK32: None | AN32: IC Anionen | AO32: None | AS32: None | AW32: None | AZ32: IC Anionen | BA32: None | BD32: IC Kationen | BE32: None | BI32: None | BL32: IC Kationen | BM32: None | BP32: IC Kationen | BQ32: None | BT32: IC Kationen | BU32: None | BY32: None | CC32: None | CG32: None | CK32: None | CN32: SOP 45-34 | CO32: None | CS32: None | CW32: None | CZ32: WTW Multimeter 3430 with FDO 925 | DA32: None | DE32: None | DH32: SOP 45-09 | DI32: None | DL32: SOP 45-09 (SOP muss noch angepasst werden für VSS) | DM32: None | DP32: IC Organic Acids | DQ32: None | DT32: IC Organic Acids | DU32: None | DX32: IC Organic Acids | DY32: None | EB32: IC Organic Acids | EC32: None | EF32: IC Organic Acids | EG32: None | EJ32: IC Organic Acids | EK32: None | EN32: IC Organic Acids | EO32: None | ER32: IC Organic Acids | ES32: None | EV32: LC-MS | EW32: None | EZ32: =CONCATENATE(A32,B32) | FA32: =CONCATENATE(SamplesX!A32,SamplesX!B32) | FB32: =CONCATENATE(SamplesY!A32,SamplesY!B32) | FC32: =MATCH(EZ32,FA1:FA1008,0) | FD32: =MATCH(EZ32,FB1:FB1008,0)
C33: =IF(ISNUMBER(FC33),INDIRECT("SamplesX!C"&FC33),IF(ISNUMBER(FD33),INDIRECT("SamplesY!C"&FD33),"")) | D33: =IF(ISNUMBER(FC33),INDIRECT("SamplesX!D"&FC33),IF(ISNUMBER(FD33),INDIRECT("SamplesY!D"&FD33),"")) | E33: =IF(ISNUMBER(FC33),INDIRECT("SamplesX!E"&FC33),IF(ISNUMBER(FD33),INDIRECT("SamplesY!E"&FD33),"")) | F33: =IF(ISNUMBER(FC33),INDIRECT("SamplesX!F"&FC33),IF(ISNUMBER(FD33),INDIRECT("SamplesY!F"&FD33),"")) | G33: =IF(ISNUMBER(FC33),INDIRECT("SamplesX!G"&FC33),IF(ISNUMBER(FD33),INDIRECT("SamplesY!G"&FD33),"")) | H33: =IF(ISNUMBER(FC33),INDIRECT("SamplesX!H"&FC33),IF(ISNUMBER(FD33),INDIRECT("SamplesY!H"&FD33),"")) | M33: None | P33: Shimadzu TOC-L | Q33: None | T33: Shimadzu TOC-L | U33: None | Y33: None | AC33: None | AF33: IC Anionen | AG33: None | AK33: None | AN33: IC Anionen | AO33: None | AS33: None | AW33: None | AZ33: IC Anionen | BA33: None | BD33: IC Kationen | BE33: None | BI33: None | BL33: IC Kationen | BM33: None | BP33: IC Kationen | BQ33: None | BT33: IC Kationen | BU33: None | BY33: None | CC33: None | CG33: None | CK33: None | CN33: SOP 45-34 | CO33: None | CS33: None | CW33: None | CZ33: WTW Multimeter 3430 with FDO 925 | DA33: None | DE33: None | DH33: SOP 45-09 | DI33: None | DL33: SOP 45-09 (SOP muss noch angepasst werden für VSS) | DM33: None | DP33: IC Organic Acids | DQ33: None | DT33: IC Organic Acids | DU33: None | DX33: IC Organic Acids | DY33: None | EB33: IC Organic Acids | EC33: None | EF33: IC Organic Acids | EG33: None | EJ33: IC Organic Acids | EK33: None | EN33: IC Organic Acids | EO33: None | ER33: IC Organic Acids | ES33: None | EV33: LC-MS | EW33: None | EZ33: =CONCATENATE(A33,B33) | FA33: =CONCATENATE(SamplesX!A33,SamplesX!B33) | FB33: =CONCATENATE(SamplesY!A33,SamplesY!B33) | FC33: =MATCH(EZ33,FA1:FA1008,0) | FD33: =MATCH(EZ33,FB1:FB1008,0)
C34: =IF(ISNUMBER(FC34),INDIRECT("SamplesX!C"&FC34),IF(ISNUMBER(FD34),INDIRECT("SamplesY!C"&FD34),"")) | D34: =IF(ISNUMBER(FC34),INDIRECT("SamplesX!D"&FC34),IF(ISNUMBER(FD34),INDIRECT("SamplesY!D"&FD34),"")) | E34: =IF(ISNUMBER(FC34),INDIRECT("SamplesX!E"&FC34),IF(ISNUMBER(FD34),INDIRECT("SamplesY!E"&FD34),"")) | F34: =IF(ISNUMBER(FC34),INDIRECT("SamplesX!F"&FC34),IF(ISNUMBER(FD34),INDIRECT("SamplesY!F"&FD34),"")) | G34: =IF(ISNUMBER(FC34),INDIRECT("SamplesX!G"&FC34),IF(ISNUMBER(FD34),INDIRECT("SamplesY!G"&FD34),"")) | H34: =IF(ISNUMBER(FC34),INDIRECT("SamplesX!H"&FC34),IF(ISNUMBER(FD34),INDIRECT("SamplesY!H"&FD34),"")) | M34: None | P34: Shimadzu TOC-L | Q34: None | T34: Shimadzu TOC-L | U34: None | Y34: None | AC34: None | AF34: IC Anionen | AG34: None | AK34: None | AN34: IC Anionen | AO34: None | AS34: None | AW34: None | AZ34: IC Anionen | BA34: None | BD34: IC Kationen | BE34: None | BI34: None | BL34: IC Kationen | BM34: None | BP34: IC Kationen | BQ34: None | BT34: IC Kationen | BU34: None | BY34: None | CC34: None | CG34: None | CK34: None | CN34: SOP 45-34 | CO34: None | CS34: None | CW34: None | CZ34: WTW Multimeter 3430 with FDO 925 | DA34: None | DE34: None | DH34: SOP 45-09 | DI34: None | DL34: SOP 45-09 (SOP muss noch angepasst werden für VSS) | DM34: None | DP34: IC Organic Acids | DQ34: None | DT34: IC Organic Acids | DU34: None | DX34: IC Organic Acids | DY34: None | EB34: IC Organic Acids | EC34: None | EF34: IC Organic Acids | EG34: None | EJ34: IC Organic Acids | EK34: None | EN34: IC Organic Acids | EO34: None | ER34: IC Organic Acids | ES34: None | EV34: LC-MS | EW34: None | EZ34: =CONCATENATE(A34,B34) | FA34: =CONCATENATE(SamplesX!A34,SamplesX!B34) | FB34: =CONCATENATE(SamplesY!A34,SamplesY!B34) | FC34: =MATCH(EZ34,FA1:FA1008,0) | FD34: =MATCH(EZ34,FB1:FB1008,0)
C35: =IF(ISNUMBER(FC35),INDIRECT("SamplesX!C"&FC35),IF(ISNUMBER(FD35),INDIRECT("SamplesY!C"&FD35),"")) | D35: =IF(ISNUMBER(FC35),INDIRECT("SamplesX!D"&FC35),IF(ISNUMBER(FD35),INDIRECT("SamplesY!D"&FD35),"")) | E35: =IF(ISNUMBER(FC35),INDIRECT("SamplesX!E"&FC35),IF(ISNUMBER(FD35),INDIRECT("SamplesY!E"&FD35),"")) | F35: =IF(ISNUMBER(FC35),INDIRECT("SamplesX!F"&FC35),IF(ISNUMBER(FD35),INDIRECT("SamplesY!F"&FD35),"")) | G35: =IF(ISNUMBER(FC35),INDIRECT("SamplesX!G"&FC35),IF(ISNUMBER(FD35),INDIRECT("SamplesY!G"&FD35),"")) | H35: =IF(ISNUMBER(FC35),INDIRECT("SamplesX!H"&FC35),IF(ISNUMBER(FD35),INDIRECT("SamplesY!H"&FD35),"")) | M35: None | P35: Shimadzu TOC-L | Q35: None | T35: Shimadzu TOC-L | U35: None | Y35: None | AC35: None | AF35: IC Anionen | AG35: None | AK35: None | AN35: IC Anionen | AO35: None | AS35: None | AW35: None | AZ35: IC Anionen | BA35: None | BD35: IC Kationen | BE35: None | BI35: None | BL35: IC Kationen | BM35: None | BP35: IC Kationen | BQ35: None | BT35: IC Kationen | BU35: None | BY35: None | CC35: None | CG35: None | CK35: None | CN35: SOP 45-34 | CO35: None | CS35: None | CW35: None | CZ35: WTW Multimeter 3430 with FDO 925 | DA35: None | DE35: None | DH35: SOP 45-09 | DI35: None | DL35: SOP 45-09 (SOP muss noch angepasst werden für VSS) | DM35: None | DP35: IC Organic Acids | DQ35: None | DT35: IC Organic Acids | DU35: None | DX35: IC Organic Acids | DY35: None | EB35: IC Organic Acids | EC35: None | EF35: IC Organic Acids | EG35: None | EJ35: IC Organic Acids | EK35: None | EN35: IC Organic Acids | EO35: None | ER35: IC Organic Acids | ES35: None | EV35: LC-MS | EW35: None | EZ35: =CONCATENATE(A35,B35) | FA35: =CONCATENATE(SamplesX!A35,SamplesX!B35) | FB35: =CONCATENATE(SamplesY!A35,SamplesY!B35) | FC35: =MATCH(EZ35,FA1:FA1008,0) | FD35: =MATCH(EZ35,FB1:FB1008,0)
C36: =IF(ISNUMBER(FC36),INDIRECT("SamplesX!C"&FC36),IF(ISNUMBER(FD36),INDIRECT("SamplesY!C"&FD36),"")) | D36: =IF(ISNUMBER(FC36),INDIRECT("SamplesX!D"&FC36),IF(ISNUMBER(FD36),INDIRECT("SamplesY!D"&FD36),"")) | E36: =IF(ISNUMBER(FC36),INDIRECT("SamplesX!E"&FC36),IF(ISNUMBER(FD36),INDIRECT("SamplesY!E"&FD36),"")) | F36: =IF(ISNUMBER(FC36),INDIRECT("SamplesX!F"&FC36),IF(ISNUMBER(FD36),INDIRECT("SamplesY!F"&FD36),"")) | G36: =IF(ISNUMBER(FC36),INDIRECT("SamplesX!G"&FC36),IF(ISNUMBER(FD36),INDIRECT("SamplesY!G"&FD36),"")) | H36: =IF(ISNUMBER(FC36),INDIRECT("SamplesX!H"&FC36),IF(ISNUMBER(FD36),INDIRECT("SamplesY!H"&FD36),"")) | M36: None | P36: Shimadzu TOC-L | Q36: None | T36: Shimadzu TOC-L | U36: None | Y36: None | AC36: None | AF36: IC Anionen | AG36: None | AK36: None | AN36: IC Anionen | AO36: None | AS36: None | AW36: None | AZ36: IC Anionen | BA36: None | BD36: IC Kationen | BE36: None | BI36: None | BL36: IC Kationen | BM36: None | BP36: IC Kationen | BQ36: None | BT36: IC Kationen | BU36: None | BY36: None | CC36: None | CG36: None | CK36: None | CN36: SOP 45-34 | CO36: None | CS36: None | CW36: None | CZ36: WTW Multimeter 3430 with FDO 925 | DA36: None | DE36: None | DH36: SOP 45-09 | DI36: None | DL36: SOP 45-09 (SOP muss noch angepasst werden für VSS) | DM36: None | DP36: IC Organic Acids | DQ36: None | DT36: IC Organic Acids | DU36: None | DX36: IC Organic Acids | DY36: None | EB36: IC Organic Acids | EC36: None | EF36: IC Organic Acids | EG36: None | EJ36: IC Organic Acids | EK36: None | EN36: IC Organic Acids | EO36: None | ER36: IC Organic Acids | ES36: None | EV36: LC-MS | EW36: None | EZ36: =CONCATENATE(A36,B36) | FA36: =CONCATENATE(SamplesX!A36,SamplesX!B36) | FB36: =CONCATENATE(SamplesY!A36,SamplesY!B36) | FC36: =MATCH(EZ36,FA1:FA1008,0) | FD36: =MATCH(EZ36,FB1:FB1008,0)
C37: =IF(ISNUMBER(FC37),INDIRECT("SamplesX!C"&FC37),IF(ISNUMBER(FD37),INDIRECT("SamplesY!C"&FD37),"")) | D37: =IF(ISNUMBER(FC37),INDIRECT("SamplesX!D"&FC37),IF(ISNUMBER(FD37),INDIRECT("SamplesY!D"&FD37),"")) | E37: =IF(ISNUMBER(FC37),INDIRECT("SamplesX!E"&FC37),IF(ISNUMBER(FD37),INDIRECT("SamplesY!E"&FD37),"")) | F37: =IF(ISNUMBER(FC37),INDIRECT("SamplesX!F"&FC37),IF(ISNUMBER(FD37),INDIRECT("SamplesY!F"&FD37),"")) | G37: =IF(ISNUMBER(FC37),INDIRECT("SamplesX!G"&FC37),IF(ISNUMBER(FD37),INDIRECT("SamplesY!G"&FD37),"")) | H37: =IF(ISNUMBER(FC37),INDIRECT("SamplesX!H"&FC37),IF(ISNUMBER(FD37),INDIRECT("SamplesY!H"&FD37),"")) | M37: None | P37: Shimadzu TOC-L | Q37: None | T37: Shimadzu TOC-L | U37: None | Y37: None | AC37: None | AF37: IC Anionen | AG37: None | AK37: None | AN37: IC Anionen | AO37: None | AS37: None | AW37: None | AZ37: IC Anionen | BA37: None | BD37: IC Kationen | BE37: None | BI37: None | BL37: IC Kationen | BM37: None | BP37: IC Kationen | BQ37: None | BT37: IC Kationen | BU37: None | BY37: None | CC37: None | CG37: None | CK37: None | CN37: SOP 45-34 | CO37: None | CS37: None | CW37: None | CZ37: WTW Multimeter 3430 with FDO 925 | DA37: None | DE37: None | DH37: SOP 45-09 | DI37: None | DL37: SOP 45-09 (SOP muss noch angepasst werden für VSS) | DM37: None | DP37: IC Organic Acids | DQ37: None | DT37: IC Organic Acids | DU37: None | DX37: IC Organic Acids | DY37: None | EB37: IC Organic Acids | EC37: None | EF37: IC Organic Acids | EG37: None | EJ37: IC Organic Acids | EK37: None | EN37: IC Organic Acids | EO37: None | ER37: IC Organic Acids | ES37: None | EV37: LC-MS | EW37: None | EZ37: =CONCATENATE(A37,B37) | FA37: =CONCATENATE(SamplesX!A37,SamplesX!B37) | FB37: =CONCATENATE(SamplesY!A37,SamplesY!B37) | FC37: =MATCH(EZ37,FA1:FA1008,0) | FD37: =MATCH(EZ37,FB1:FB1008,0)
