Workbook

Sheet UrineNitrification
A1: UrineNitrification | B1: 2025
A2: Responsible: | B2: =HYPERLINK("mailto:bettina.sterkele@eawag.ch?subject=[Lab results]", "bettina.sterkele@eawag.ch")
A3: Samples: | B3: =HYPERLINK("Q:\Abteilungsprojekte\eng\EngData\AOS\Allgemein\LabSamples2025.xlsx#UrineNitrification!A1","LabSamples2025.xlsx")
A5: Sample ID | C5: Site | G5: Sample | I5: SampleInfo | J5: Comment | K5: DOC | O5: TOC | S5: TIC | W5: Nsol | AA5: Ntot | AE5: Cl | AI5: NO2-N | AM5: Br | AQ5: NO3-N | AU5: PO4-P | AY5: SO4 | BC5: Na | BG5: NH4-N | BK5: K | BO5: Ca | BS5: Mg | BW5: Ptot | CA5: Urea | CE5: CODsol | CI5: CODtot | CM5: Alkalinity | CQ5: Conductivity | CU5: pH | CY5: Dissolved Oxygen | DC5: Turbidity | DG5: TSS | DK5: VSS | DO5: Lactic Acid | DS5: Formic Acid | DW5: Acetic Acid | EA5: Propionic Acid | EE5: Isobutyric Acid | EI5: Butyric Acid | EM5: Isovaleric Acid | EQ5: Valeric Acid | EU5: Micropollutants | EZ5: ConcatID | FA5: ConcatID_X | FC5: MatchX
A6: Project ID | B6: Number | C6: Room | D6: Area | E6: Setup | F6: Component | G6: Date | H6: Time | K6: Final value | L6: Method | M6: Filtration | N6: Dilution | O6: Final value | P6: Method | Q6: Filtration | R6: Dilution | S6: Final value | T6: Method | U6: Filtration | V6: Dilution | W6: Final value | X6: Method | Y6: Filtration | Z6: Dilution | AA6: Final value | AB6: Method | AC6: Filtration | AD6: Dilution | AE6: Final value | AF6: Method | AG6: Filtration | AH6: Dilution | AI6: Final value | AJ6: Method | AK6: Filtration | AL6: Dilution | AM6: Final value | AN6: Method | AO6: Filtration | AP6: Dilution | AQ6: Final value | AR6: Method | AS6: Filtration | AT6: Dilution | AU6: Final value | AV6: Method | AW6: Filtration | AX6: Dilution | AY6: Final value | AZ6: Method | BA6: Filtration | BB6: Dilution | BC6: Final value | BD6: Method | BE6: Filtration | BF6: Dilution | BG6: Final value | BH6: Method | BI6: Filtration | BJ6: Dilution | BK6: Final value | BL6: Method | BM6: Filtration | BN6: Dilution | BO6: Final value | BP6: Method | BQ6: Filtration | BR6: Dilution | BS6: Final value | BT6: Method | BU6: Filtration | BV6: Dilution | BW6: Final value | BX6: Method | BY6: Filtration | BZ6: Dilution | CA6: Final value | CB6: Method | CC6: Filtration | CD6: Dilution | CE6: Final value | CF6: Method | CG6: Filtration | CH6: Dilution | CI6: Final value | CJ6: Method | CK6: Filtration | CL6: Dilution | CM6: Final value | CN6: Method | CO6: Filtration | CP6: Dilution | CQ6: Final value | CR6: Method | CS6: Filtration | CT6: Dilution | CU6: Final value | CV6: Method | CW6: Filtration | CX6: Dilution | CY6: Final value | CZ6: Method | DA6: Filtration | DB6: Dilution | DC6: Final value | DD6: Method | DE6: Filtration | DF6: Dilution | DG6: Final value | DH6: Method | DI6: Filtration | DJ6: Dilution | DK6: Final value | DL6: Method | DM6: Filtration | DN6: Dilution | DO6: Final value | DP6: Method | DQ6: Filtration | DR6: Dilution | DS6: Final value | DT6: Method | DU6: Filtration | DV6: Dilution | DW6: Final value | DX6: Method | DY6: Filtration | DZ6: Dilution | EA6: Final value | EB6: Method | EC6: Filtration | ED6: Dilution | EE6: Final value | EF6: Method | EG6: Filtration | EH6: Dilution | EI6: Final value | EJ6: Method | EK6: Filtration | EL6: Dilution | EM6: Final value | EN6: Method | EO6: Filtration | EP6: Dilution | EQ6: Final value | ER6: Method | ES6: Filtration | ET6: Dilution | EU6: Final value | EV6: Method | EW6: Filtration | EX6: Dilution
A7: [##] | B7: [yysss] | G7: [dd.mm.yyyy] | H7: [HH:MM:SS] | K7: mg/L | O7: mg/L | S7: mg/L | W7: mg/L | AA7: mg/L | AE7: mg/L | AI7: mg/L | AM7: mg/L | AQ7: mg/L | AU7: mg/L | AY7: mg/L | BC7: mg/L | BG7: mg/L | BK7: mg/L | BO7: mg/L | BS7: mg/L | BW7: mg/L | CA7: mgN/L | CE7: mg/L | CI7: mg/L | CM7: mmol/L | CQ7: microS/cm | CU7: 1 | CY7: mg/L | DC7: NTU | DG7: mg/L | DK7: mg/L | DO7: mg/L | DS7: mg/L | DW7: mg/L | EA7: mg/L | EE7: mg/L | EI7: mg/L | EM7: mg/L | EQ7: mg/L | EU7: ng/L
A8: Text | B8: Text | C8: Dropdown | D8: Dropdown | E8: Dropdown | F8: Dropdown | G8: Text | H8: Text | K8: Text | L8: Dropdown | M8: Dropdown | N8: Text | O8: Text | P8: Dropdown | Q8: Dropdown | R8: Text | S8: Text | T8: Dropdown | U8: Dropdown | V8: Text | W8: Text | X8: Dropdown | Y8: Dropdown | Z8: Text | AA8: Text | AB8: Dropdown | AC8: Dropdown | AD8: Text | AE8: Text | AF8: Dropdown | AG8: Dropdown | AH8: Text | AI8: Text | AJ8: Dropdown | AK8: Dropdown | AL8: Text | AM8: Text | AN8: Dropdown | AO8: Dropdown | AP8: Text | AQ8: Text | AR8: Dropdown | AS8: Dropdown | AT8: Text | AU8: Text | AV8: Dropdown | AW8: Dropdown | AX8: Text | AY8: Text | AZ8: Dropdown | BA8: Dropdown | BB8: Text | BC8: Text | BD8: Dropdown | BE8: Dropdown | BF8: Text | BG8: Text | BH8: Dropdown | BI8: Dropdown | BJ8: Text | BK8: Text | BL8: Dropdown | BM8: Dropdown | BN8: Text | BO8: Text | BP8: Dropdown | BQ8: Dropdown | BR8: Text | BS8: Text | BT8: Dropdown | BU8: Dropdown | BV8: Text | BW8: Text | BX8: Dropdown | BY8: Dropdown | BZ8: Text | CA8: Text | CB8: Dropdown | CC8: Dropdown | CD8: Text | CE8: Text | CF8: Dropdown | CG8: Dropdown | CH8: Text | CI8: Text | CJ8: Dropdown | CK8: Dropdown | CL8: Text | CM8: Text | CN8: Dropdown | CO8: Dropdown | CP8: Text | CQ8: Text | CR8: Dropdown | CS8: Dropdown | CT8: Text | CU8: Text | CV8: Dropdown | CW8: Dropdown | CX8: Text | CY8: Text | CZ8: Dropdown | DA8: Dropdown | DB8: Text | DC8: Text | DD8: Dropdown | DE8: Dropdown | DF8: Text | DG8: Text | DH8: Dropdown | DI8: Dropdown | DJ8: Text | DK8: Text | DL8: Dropdown | DM8: Dropdown | DN8: Text | DO8: Text | DP8: Dropdown | DQ8: Dropdown | DR8: Text | DS8: Text | DT8: Dropdown | DU8: Dropdown | DV8: Text | DW8: Text | DX8: Dropdown | DY8: Dropdown | DZ8: Text | EA8: Text | EB8: Dropdown | EC8: Dropdown | ED8: Text | EE8: Text | EF8: Dropdown | EG8: Dropdown | EH8: Text | EI8: Text | EJ8: Dropdown | EK8: Dropdown | EL8: Text | EM8: Text | EN8: Dropdown | EO8: Dropdown | EP8: Text | EQ8: Text | ER8: Dropdown | ES8: Dropdown | ET8: Text | EU8: Text | EV8: Dropdown | EW8: Dropdown | EX8: Text
A9: NF | B9: 25001 | C9: =IF(ISNUMBER(FC9),INDIRECT("SamplesX!C"&FC9),IF(ISNUMBER(FD9),INDIRECT("SamplesY!C"&FD9),"")) | D9: =IF(ISNUMBER(FC9),INDIRECT("SamplesX!D"&FC9),IF(ISNUMBER(FD9),INDIRECT("SamplesY!D"&FD9),"")) | E9: =IF(ISNUMBER(FC9),INDIRECT("SamplesX!E"&FC9),IF(ISNUMBER(FD9),INDIRECT("SamplesY!E"&FD9),"")) | F9: =IF(ISNUMBER(FC9),INDIRECT("SamplesX!F"&FC9),IF(ISNUMBER(FD9),INDIRECT("SamplesY!F"&FD9),"")) | G9: =IF(ISNUMBER(FC9),INDIRECT("SamplesX!G"&FC9),IF(ISNUMBER(FD9),INDIRECT("SamplesY!G"&FD9),"")) | H9: =IF(ISNUMBER(FC9),INDIRECT("SamplesX!H"&FC9),IF(ISNUMBER(FD9),INDIRECT("SamplesY!H"&FD9),"")) | J9: FK: DOC values were measured by the AuA lab, due to instrument troubles | K9: 32.4 | L9: Shimadzu TOC-L | M9: None | N9: 10 | P9: Shimadzu TOC-L | Q9: None | T9: Shimadzu TOC-L | U9: None | Y9: None | AC9: None | AE9: <0.80 | AF9: IC Anionen | AG9: None | AI9: 0 | AJ9: Test strips MQuant 10007 | AK9: None | AN9: IC Anionen | AO9: None | AQ9: <0.18 | AR9: IC Anionen | AS9: None | AT9: 5 | AU9: <0.13 | AV9: IC Anionen | AW9: None | AY9: <0.80 | AZ9: IC Anionen | BA9: None | BC9: <1.00 | BD9: IC Kationen | BE9: None | BG9: 23.4 | BH9: IC Kationen | BI9: None | BJ9: 5 | BK9: <1.00 | BL9: IC Kationen | BM9: None | BO9: 3.11 | BP9: IC Kationen | BQ9: None | BS9: <0.50 | BT9: IC Kationen | BU9: None | BY9: None | CC9: None | CG9: None | CK9: None | CN9: SOP 45-34 | CO9: None | CS9: None | CU9: 8.58 | CV9: WTW pH340 | CW9: None | CZ9: WTW Multimeter 3430 with FDO 925 | DA9: None | DE9: None | DH9: SOP 45-09 | DI9: None | DL9: SOP 45-09 (SOP muss noch angepasst werden für VSS) | DM9: None | DP9: IC Organic Acids | DQ9: None | DT9: IC Organic Acids | DU9: None | DX9: IC Organic Acids | DY9: None | EB9: IC Organic Acids | EC9: None | EF9: IC Organic Acids | EG9: None | EJ9: IC Organic Acids | EK9: None | EN9: IC Organic Acids | EO9: None | ER9: IC Organic Acids | ES9: None | EV9: LC-MS | EW9: None | EZ9: =CONCATENATE(A9,B9) | FA9: =CONCATENATE(SamplesX!A9,SamplesX!B9) | FC9: =MATCH(EZ9,FA1:FA1008,0)
A10: NF | B10: 25002 | C10: =IF(ISNUMBER(FC10),INDIRECT("SamplesX!C"&FC10),IF(ISNUMBER(FD10),INDIRECT("SamplesY!C"&FD10),"")) | D10: =IF(ISNUMBER(FC10),INDIRECT("SamplesX!D"&FC10),IF(ISNUMBER(FD10),INDIRECT("SamplesY!D"&FD10),"")) | E10: =IF(ISNUMBER(FC10),INDIRECT("SamplesX!E"&FC10),IF(ISNUMBER(FD10),INDIRECT("SamplesY!E"&FD10),"")) | F10: =IF(ISNUMBER(FC10),INDIRECT("SamplesX!F"&FC10),IF(ISNUMBER(FD10),INDIRECT("SamplesY!F"&FD10),"")) | G10: =IF(ISNUMBER(FC10),INDIRECT("SamplesX!G"&FC10),IF(ISNUMBER(FD10),INDIRECT("SamplesY!G"&FD10),"")) | H10: =IF(ISNUMBER(FC10),INDIRECT("SamplesX!H"&FC10),IF(ISNUMBER(FD10),INDIRECT("SamplesY!H"&FD10),"")) | J10: FK: DOC values were measured by the AuA lab, due to instrument troubles | K10: 28.6 | L10: Shimadzu TOC-L | M10: None | N10: 10 | P10: Shimadzu TOC-L | Q10: None | T10: Shimadzu TOC-L | U10: None | Y10: None | AC10: None | AE10: <0.80 | AF10: IC Anionen | AG10: None | AI10: 0 | AJ10: Test strips MQuant 10007 | AK10: None | AN10: IC Anionen | AO10: None | AQ10: <0.18 | AR10: IC Anionen | AS10: None | AT10: 5 | AU10: <0.13 | AV10: IC Anionen | AW10: None | AY10: <0.80 | AZ10: IC Anionen | BA10: None | BC10: <1.00 | BD10: IC Kationen | BE10: None | BG10: 30.6 | BH10: IC Kationen | BI10: None | BJ10: 5 | BK10: <1.00 | BL10: IC Kationen | BM10: None | BO10: 3.33 | BP10: IC Kationen | BQ10: None | BS10: <0.50 | BT10: IC Kationen | BU10: None | BY10: None | CC10: None | CG10: None | CK10: None | CN10: SOP 45-34 | CO10: None | CS10: None | CU10: 8.71 | CV10: WTW pH340 | CW10: None | CZ10: WTW Multimeter 3430 with FDO 925 | DA10: None | DE10: None | DH10: SOP 45-09 | DI10: None | DL10: SOP 45-09 (SOP muss noch angepasst werden für VSS) | DM10: None | DP10: IC Organic Acids | DQ10: None | DT10: IC Organic Acids | DU10: None | DX10: IC Organic Acids | DY10: None | EB10: IC Organic Acids | EC10: None | EF10: IC Organic Acids | EG10: None | EJ10: IC Organic Acids | EK10: None | EN10: IC Organic Acids | EO10: None | ER10: IC Organic Acids | ES10: None | EV10: LC-MS | EW10: None | EZ10: =CONCATENATE(A10,B10) | FA10: =CONCATENATE(SamplesX!A10,SamplesX!B10) | FC10: =MATCH(EZ10,FA1:FA1008,0)
A11: NF | B11: 25003 | C11: =IF(ISNUMBER(FC11),INDIRECT("SamplesX!C"&FC11),IF(ISNUMBER(FD11),INDIRECT("SamplesY!C"&FD11),"")) | D11: =IF(ISNUMBER(FC11),INDIRECT("SamplesX!D"&FC11),IF(ISNUMBER(FD11),INDIRECT("SamplesY!D"&FD11),"")) | E11: =IF(ISNUMBER(FC11),INDIRECT("SamplesX!E"&FC11),IF(ISNUMBER(FD11),INDIRECT("SamplesY!E"&FD11),"")) | F11: =IF(ISNUMBER(FC11),INDIRECT("SamplesX!F"&FC11),IF(ISNUMBER(FD11),INDIRECT("SamplesY!F"&FD11),"")) | G11: =IF(ISNUMBER(FC11),INDIRECT("SamplesX!G"&FC11),IF(ISNUMBER(FD11),INDIRECT("SamplesY!G"&FD11),"")) | H11: =IF(ISNUMBER(FC11),INDIRECT("SamplesX!H"&FC11),IF(ISNUMBER(FD11),INDIRECT("SamplesY!H"&FD11),"")) | J11: FK: DOC values were measured by the AuA lab, due to instrument troubles | K11: 19.4 | L11: Shimadzu TOC-L | M11: None | N11: 10 | P11: Shimadzu TOC-L | Q11: None | T11: Shimadzu TOC-L | U11: None | Y11: None | AC11: None | AE11: <0.80 | AF11: IC Anionen | AG11: None | AI11: 0 | AJ11: Test strips MQuant 10007 | AK11: None | AN11: IC Anionen | AO11: None | AQ11: <0.18 | AR11: IC Anionen | AS11: None | AT11: 5 | AU11: 0.34 | AV11: IC Anionen | AW11: None | AY11: <0.80 | AZ11: IC Anionen | BA11: None | BC11: <1.00 | BD11: IC Kationen | BE11: None | BG11: 22.5 | BH11: IC Kationen | BI11: None | BJ11: 5 | BK11: <1.00 | BL11: IC Kationen | BM11: None | BO11: <2.00 | BP11: IC Kationen | BQ11: None | BS11: <0.50 | BT11: IC Kationen | BU11: None | BY11: None | CC11: None | CG11: None | CK11: None | CN11: SOP 45-34 | CO11: None | CS11: None | CU11: 9.11 | CV11: WTW pH340 | CW11: None | CZ11: WTW Multimeter 3430 with FDO 925 | DA11: None | DE11: None | DH11: SOP 45-09 | DI11: None | DL11: SOP 45-09 (SOP muss noch angepasst werden für VSS) | DM11: None | DP11: IC Organic Acids | DQ11: None | DT11: IC Organic Acids | DU11: None | DX11: IC Organic Acids | DY11: None | EB11: IC Organic Acids | EC11: None | EF11: IC Organic Acids | EG11: None | EJ11: IC Organic Acids | EK11: None | EN11: IC Organic Acids | EO11: None | ER11: IC Organic Acids | ES11: None | EV11: LC-MS | EW11: None | EZ11: =CONCATENATE(A11,B11) | FA11: =CONCATENATE(SamplesX!A11,SamplesX!B11) | FC11: =MATCH(EZ11,FA1:FA1008,0)
A12: NF | B12: 25004 | C12: =IF(ISNUMBER(FC12),INDIRECT("SamplesX!C"&FC12),IF(ISNUMBER(FD12),INDIRECT("SamplesY!C"&FD12),"")) | D12: =IF(ISNUMBER(FC12),INDIRECT("SamplesX!D"&FC12),IF(ISNUMBER(FD12),INDIRECT("SamplesY!D"&FD12),"")) | E12: =IF(ISNUMBER(FC12),INDIRECT("SamplesX!E"&FC12),IF(ISNUMBER(FD12),INDIRECT("SamplesY!E"&FD12),"")) | F12: =IF(ISNUMBER(FC12),INDIRECT("SamplesX!F"&FC12),IF(ISNUMBER(FD12),INDIRECT("SamplesY!F"&FD12),"")) | G12: =IF(ISNUMBER(FC12),INDIRECT("SamplesX!G"&FC12),IF(ISNUMBER(FD12),INDIRECT("SamplesY!G"&FD12),"")) | H12: =IF(ISNUMBER(FC12),INDIRECT("SamplesX!H"&FC12),IF(ISNUMBER(FD12),INDIRECT("SamplesY!H"&FD12),"")) | K12: 48.0 | L12: Shimadzu TOC-L | M12: None | P12: Shimadzu TOC-L | Q12: None | T12: Shimadzu TOC-L | U12: None | Y12: None | AC12: None | AE12: 5.41 | AF12: IC Anionen | AG12: None | AK12: None | AN12: IC Anionen | AO12: None | AQ12: <0.18 | AR12: IC Anionen | AS12: None | AU12: <0.13 | AV12: IC Anionen | AW12: None | AY12: <0.80 | AZ12: IC Anionen | BA12: None | BC12: 1.36 | BD12: IC Kationen | BE12: None | BG12: 30.6 | BH12: IC Kationen | BI12: None | BK12: 5.72 | BL12: IC Kationen | BM12: None | BO12: 2.67 | BP12: IC Kationen | BQ12: None | BS12: <0.50 | BT12: IC Kationen | BU12: None | BY12: None | CC12: None | CG12: None | CK12: None | CN12: SOP 45-34 | CO12: None | CS12: None | CW12: None | CZ12: WTW Multimeter 3430 with FDO 925 | DA12: None | DE12: None | DH12: SOP 45-09 | DI12: None | DL12: SOP 45-09 (SOP muss noch angepasst werden für VSS) | DM12: None | DP12: IC Organic Acids | DQ12: None | DT12: IC Organic Acids | DU12: None | DX12: IC Organic Acids | DY12: None | EB12: IC Organic Acids | EC12: None | EF12: IC Organic Acids | EG12: None | EJ12: IC Organic Acids | EK12: None | EN12: IC Organic Acids | EO12: None | ER12: IC Organic Acids | ES12: None | EV12: LC-MS | EW12: None | EZ12: =CONCATENATE(A12,B12) | FA12: =CONCATENATE(SamplesX!A12,SamplesX!B12) | FC12: =MATCH(EZ12,FA1:FA1008,0)
A13: NF | B13: 25005 | C13: =IF(ISNUMBER(FC13),INDIRECT("SamplesX!C"&FC13),IF(ISNUMBER(FD13),INDIRECT("SamplesY!C"&FD13),"")) | D13: =IF(ISNUMBER(FC13),INDIRECT("SamplesX!D"&FC13),IF(ISNUMBER(FD13),INDIRECT("SamplesY!D"&FD13),"")) | E13: =IF(ISNUMBER(FC13),INDIRECT("SamplesX!E"&FC13),IF(ISNUMBER(FD13),INDIRECT("SamplesY!E"&FD13),"")) | F13: =IF(ISNUMBER(FC13),INDIRECT("SamplesX!F"&FC13),IF(ISNUMBER(FD13),INDIRECT("SamplesY!F"&FD13),"")) | G13: =IF(ISNUMBER(FC13),INDIRECT("SamplesX!G"&FC13),IF(ISNUMBER(FD13),INDIRECT("SamplesY!G"&FD13),"")) | H13: =IF(ISNUMBER(FC13),INDIRECT("SamplesX!H"&FC13),IF(ISNUMBER(FD13),INDIRECT("SamplesY!H"&FD13),"")) | K13: 48.9 | L13: Shimadzu TOC-L | M13: None | P13: Shimadzu TOC-L | Q13: None | T13: Shimadzu TOC-L | U13: None | Y13: None | AC13: None | AE13: 6.81 | AF13: IC Anionen | AG13: None | AK13: None | AN13: IC Anionen | AO13: None | AQ13: <0.18 | AR13: IC Anionen | AS13: None | AU13: <0.13 | AV13: IC Anionen | AW13: None | AY13: <0.80 | AZ13: IC Anionen | BA13: None | BC13: 1.46 | BD13: IC Kationen | BE13: None | BG13: 31.6 | BH13: IC Kationen | BI13: None | BK13: 7.15 | BL13: IC Kationen | BM13: None | BO13: 2.89 | BP13: IC Kationen | BQ13: None | BS13: <0.50 | BT13: IC Kationen | BU13: None | BY13: None | CC13: None | CG13: None | CK13: None | CN13: SOP 45-34 | CO13: None | CS13: None | CW13: None | CZ13: WTW Multimeter 3430 with FDO 925 | DA13: None | DE13: None | DH13: SOP 45-09 | DI13: None | DL13: SOP 45-09 (SOP muss noch angepasst werden für VSS) | DM13: None | DP13: IC Organic Acids | DQ13: None | DT13: IC Organic Acids | DU13: None | DX13: IC Organic Acids | DY13: None | EB13: IC Organic Acids | EC13: None | EF13: IC Organic Acids | EG13: None | EJ13: IC Organic Acids | EK13: None | EN13: IC Organic Acids | EO13: None | ER13: IC Organic Acids | ES13: None | EV13: LC-MS | EW13: None | EZ13: =CONCATENATE(A13,B13) | FA13: =CONCATENATE(SamplesX!A13,SamplesX!B13) | FC13: =MATCH(EZ13,FA1:FA1008,0)
A14: NF | B14: 25006 | C14: =IF(ISNUMBER(FC14),INDIRECT("SamplesX!C"&FC14),IF(ISNUMBER(FD14),INDIRECT("SamplesY!C"&FD14),"")) | D14: =IF(ISNUMBER(FC14),INDIRECT("SamplesX!D"&FC14),IF(ISNUMBER(FD14),INDIRECT("SamplesY!D"&FD14),"")) | E14: =IF(ISNUMBER(FC14),INDIRECT("SamplesX!E"&FC14),IF(ISNUMBER(FD14),INDIRECT("SamplesY!E"&FD14),"")) | F14: =IF(ISNUMBER(FC14),INDIRECT("SamplesX!F"&FC14),IF(ISNUMBER(FD14),INDIRECT("SamplesY!F"&FD14),"")) | G14: =IF(ISNUMBER(FC14),INDIRECT("SamplesX!G"&FC14),IF(ISNUMBER(FD14),INDIRECT("SamplesY!G"&FD14),"")) | H14: =IF(ISNUMBER(FC14),INDIRECT("SamplesX!H"&FC14),IF(ISNUMBER(FD14),INDIRECT("SamplesY!H"&FD14),"")) | J14: keine Probe | L14: Shimadzu TOC-L | M14: None | P14: Shimadzu TOC-L | Q14: None | T14: Shimadzu TOC-L | U14: None | Y14: None | AC14: None | AF14: IC Anionen | AG14: None | AK14: None | AN14: IC Anionen | AO14: None | AR14: IC Anionen | AS14: None | AV14: IC Anionen | AW14: None | AZ14: IC Anionen | BA14: None | BD14: IC Kationen | BE14: None | BH14: IC Kationen | BI14: None | BL14: IC Kationen | BM14: None | BP14: IC Kationen | BQ14: None | BT14: IC Kationen | BU14: None | BY14: None | CC14: None | CG14: None | CK14: None | CN14: SOP 45-34 | CO14: None | CS14: None | CW14: None | CZ14: WTW Multimeter 3430 with FDO 925 | DA14: None | DE14: None | DH14: SOP 45-09 | DI14: None | DL14: SOP 45-09 (SOP muss noch angepasst werden für VSS) | DM14: None | DP14: IC Organic Acids | DQ14: None | DT14: IC Organic Acids | DU14: None | DX14: IC Organic Acids | DY14: None | EB14: IC Organic Acids | EC14: None | EF14: IC Organic Acids | EG14: None | EJ14: IC Organic Acids | EK14: None | EN14: IC Organic Acids | EO14: None | ER14: IC Organic Acids | ES14: None | EV14: LC-MS | EW14: None | EZ14: =CONCATENATE(A14,B14) | FA14: =CONCATENATE(SamplesX!A14,SamplesX!B14) | FC14: =MATCH(EZ14,FA1:FA1008,0)
A15: NF | B15: 25007 | C15: =IF(ISNUMBER(FC15),INDIRECT("SamplesX!C"&FC15),IF(ISNUMBER(FD15),INDIRECT("SamplesY!C"&FD15),"")) | D15: =IF(ISNUMBER(FC15),INDIRECT("SamplesX!D"&FC15),IF(ISNUMBER(FD15),INDIRECT("SamplesY!D"&FD15),"")) | E15: =IF(ISNUMBER(FC15),INDIRECT("SamplesX!E"&FC15),IF(ISNUMBER(FD15),INDIRECT("SamplesY!E"&FD15),"")) | F15: =IF(ISNUMBER(FC15),INDIRECT("SamplesX!F"&FC15),IF(ISNUMBER(FD15),INDIRECT("SamplesY!F"&FD15),"")) | G15: =IF(ISNUMBER(FC15),INDIRECT("SamplesX!G"&FC15),IF(ISNUMBER(FD15),INDIRECT("SamplesY!G"&FD15),"")) | H15: =IF(ISNUMBER(FC15),INDIRECT("SamplesX!H"&FC15),IF(ISNUMBER(FD15),INDIRECT("SamplesY!H"&FD15),"")) | K15: 43.6 | L15: Shimadzu TOC-L | M15: None | P15: Shimadzu TOC-L | Q15: None | T15: Shimadzu TOC-L | U15: None | Y15: None | AC15: None | AE15: 8.73 | AF15: IC Anionen | AG15: None | AK15: None | AN15: IC Anionen | AO15: None | AQ15: <0.18 | AR15: IC Anionen | AS15: None | AU15: <0.13 | AV15: IC Anionen | AW15: None | AY15: <0.80 | AZ15: IC Anionen | BA15: None | BC15: <1.00 | BD15: IC Kationen | BE15: None | BG15: 31.9 | BH15: IC Kationen | BI15: None | BK15: 9.63 | BL15: IC Kationen | BM15: None | BO15: 2.65 | BP15: IC Kationen | BQ15: None | BS15: <0.50 | BT15: IC Kationen | BU15: None | BY15: None | CC15: None | CG15: None | CK15: None | CN15: SOP 45-34 | CO15: None | CS15: None | CW15: None | CZ15: WTW Multimeter 3430 with FDO 925 | DA15: None | DE15: None | DH15: SOP 45-09 | DI15: None | DL15: SOP 45-09 (SOP muss noch angepasst werden für VSS) | DM15: None | DP15: IC Organic Acids | DQ15: None | DT15: IC Organic Acids | DU15: None | DX15: IC Organic Acids | DY15: None | EB15: IC Organic Acids | EC15: None | EF15: IC Organic Acids | EG15: None | EJ15: IC Organic Acids | EK15: None | EN15: IC Organic Acids | EO15: None | ER15: IC Organic Acids | ES15: None | EV15: LC-MS | EW15: None | EZ15: =CONCATENATE(A15,B15) | FA15: =CONCATENATE(SamplesX!A15,SamplesX!B15) | FC15: =MATCH(EZ15,FA1:FA1008,0)
A16: NF | B16: 25008 | C16: =IF(ISNUMBER(FC16),INDIRECT("SamplesX!C"&FC16),IF(ISNUMBER(FD16),INDIRECT("SamplesY!C"&FD16),"")) | D16: =IF(ISNUMBER(FC16),INDIRECT("SamplesX!D"&FC16),IF(ISNUMBER(FD16),INDIRECT("SamplesY!D"&FD16),"")) | E16: =IF(ISNUMBER(FC16),INDIRECT("SamplesX!E"&FC16),IF(ISNUMBER(FD16),INDIRECT("SamplesY!E"&FD16),"")) | F16: =IF(ISNUMBER(FC16),INDIRECT("SamplesX!F"&FC16),IF(ISNUMBER(FD16),INDIRECT("SamplesY!F"&FD16),"")) | G16: =IF(ISNUMBER(FC16),INDIRECT("SamplesX!G"&FC16),IF(ISNUMBER(FD16),INDIRECT("SamplesY!G"&FD16),"")) | H16: =IF(ISNUMBER(FC16),INDIRECT("SamplesX!H"&FC16),IF(ISNUMBER(FD16),INDIRECT("SamplesY!H"&FD16),"")) | K16: 36.6 | L16: Shimadzu TOC-L | M16: None | P16: Shimadzu TOC-L | Q16: None | T16: Shimadzu TOC-L | U16: None | Y16: None | AC16: None | AE16: 10.5 | AF16: IC Anionen | AG16: None | AK16: None | AN16: IC Anionen | AO16: None | AQ16: <0.18 | AR16: IC Anionen | AS16: None | AU16: <0.13 | AV16: IC Anionen | AW16: None | AY16: <0.80 | AZ16: IC Anionen | BA16: None | BC16: 1.99 | BD16: IC Kationen | BE16: None | BG16: 29.9 | BH16: IC Kationen | BI16: None | BK16: 10.3 | BL16: IC Kationen | BM16: None | BO16: 3.56 | BP16: IC Kationen | BQ16: None | BS16: <0.50 | BT16: IC Kationen | BU16: None | BY16: None | CC16: None | CG16: None | CK16: None | CN16: SOP 45-34 | CO16: None | CS16: None | CW16: None | CZ16: WTW Multimeter 3430 with FDO 925 | DA16: None | DE16: None | DH16: SOP 45-09 | DI16: None | DL16: SOP 45-09 (SOP muss noch angepasst werden für VSS) | DM16: None | DP16: IC Organic Acids | DQ16: None | DT16: IC Organic Acids | DU16: None | DX16: IC Organic Acids | DY16: None | EB16: IC Organic Acids | EC16: None | EF16: IC Organic Acids | EG16: None | EJ16: IC Organic Acids | EK16: None | EN16: IC Organic Acids | EO16: None | ER16: IC Organic Acids | ES16: None | EV16: LC-MS | EW16: None | EZ16: =CONCATENATE(A16,B16) | FA16: =CONCATENATE(SamplesX!A16,SamplesX!B16) | FC16: =MATCH(EZ16,FA1:FA1008,0)
A17: NF | B17: 25009 | C17: =IF(ISNUMBER(FC17),INDIRECT("SamplesX!C"&FC17),IF(ISNUMBER(FD17),INDIRECT("SamplesY!C"&FD17),"")) | D17: =IF(ISNUMBER(FC17),INDIRECT("SamplesX!D"&FC17),IF(ISNUMBER(FD17),INDIRECT("SamplesY!D"&FD17),"")) | E17: =IF(ISNUMBER(FC17),INDIRECT("SamplesX!E"&FC17),IF(ISNUMBER(FD17),INDIRECT("SamplesY!E"&FD17),"")) | F17: =IF(ISNUMBER(FC17),INDIRECT("SamplesX!F"&FC17),IF(ISNUMBER(FD17),INDIRECT("SamplesY!F"&FD17),"")) | G17: =IF(ISNUMBER(FC17),INDIRECT("SamplesX!G"&FC17),IF(ISNUMBER(FD17),INDIRECT("SamplesY!G"&FD17),"")) | H17: =IF(ISNUMBER(FC17),INDIRECT("SamplesX!H"&FC17),IF(ISNUMBER(FD17),INDIRECT("SamplesY!H"&FD17),"")) | K17: 37.5 | L17: Shimadzu TOC-L | M17: None | P17: Shimadzu TOC-L | Q17: None | T17: Shimadzu TOC-L | U17: None | Y17: None | AC17: None | AE17: 12.1 | AF17: IC Anionen | AG17: None | AK17: None | AN17: IC Anionen | AO17: None | AQ17: <0.18 | AR17: IC Anionen | AS17: None | AU17: <0.13 | AV17: IC Anionen | AW17: None | AY17: <0.80 | AZ17: IC Anionen | BA17: None | BC17: 2.14 | BD17: IC Kationen | BE17: None | BG17: 30.5 | BH17: IC Kationen | BI17: None | BK17: 13.0 | BL17: IC Kationen | BM17: None | BO17: 2.74 | BP17: IC Kationen | BQ17: None | BS17: <0.50 | BT17: IC Kationen | BU17: None | BY17: None | CC17: None | CG17: None | CK17: None | CN17: SOP 45-34 | CO17: None | CS17: None | CW17: None | CZ17: WTW Multimeter 3430 with FDO 925 | DA17: None | DE17: None | DH17: SOP 45-09 | DI17: None | DL17: SOP 45-09 (SOP muss noch angepasst werden für VSS) | DM17: None | DP17: IC Organic Acids | DQ17: None | DT17: IC Organic Acids | DU17: None | DX17: IC Organic Acids | DY17: None | EB17: IC Organic Acids | EC17: None | EF17: IC Organic Acids | EG17: None | EJ17: IC Organic Acids | EK17: None | EN17: IC Organic Acids | EO17: None | ER17: IC Organic Acids | ES17: None | EV17: LC-MS | EW17: None | EZ17: =CONCATENATE(A17,B17) | FA17: =CONCATENATE(SamplesX!A17,SamplesX!B17) | FC17: =MATCH(EZ17,FA1:FA1008,0)
A18: NF | B18: 25010 | C18: =IF(ISNUMBER(FC18),INDIRECT("SamplesX!C"&FC18),IF(ISNUMBER(FD18),INDIRECT("SamplesY!C"&FD18),"")) | D18: =IF(ISNUMBER(FC18),INDIRECT("SamplesX!D"&FC18),IF(ISNUMBER(FD18),INDIRECT("SamplesY!D"&FD18),"")) | E18: =IF(ISNUMBER(FC18),INDIRECT("SamplesX!E"&FC18),IF(ISNUMBER(FD18),INDIRECT("SamplesY!E"&FD18),"")) | F18: =IF(ISNUMBER(FC18),INDIRECT("SamplesX!F"&FC18),IF(ISNUMBER(FD18),INDIRECT("SamplesY!F"&FD18),"")) | G18: =IF(ISNUMBER(FC18),INDIRECT("SamplesX!G"&FC18),IF(ISNUMBER(FD18),INDIRECT("SamplesY!G"&FD18),"")) | H18: =IF(ISNUMBER(FC18),INDIRECT("SamplesX!H"&FC18),IF(ISNUMBER(FD18),INDIRECT("SamplesY!H"&FD18),"")) | K18: 42.8 | L18: Shimadzu TOC-L | M18: None | P18: Shimadzu TOC-L | Q18: None | T18: Shimadzu TOC-L | U18: None | Y18: None | AC18: None | AE18: 14.1 | AF18: IC Anionen | AG18: None | AK18: None | AN18: IC Anionen | AO18: None | AQ18: <0.18 | AR18: IC Anionen | AS18: None | AU18: <0.13 | AV18: IC Anionen | AW18: None | AY18: <0.80 | AZ18: IC Anionen | BA18: None | BC18: 1.96 | BD18: IC Kationen | BE18: None | BG18: 30.9 | BH18: IC Kationen | BI18: None | BK18: 15.1 | BL18: IC Kationen | BM18: None | BO18: 2.69 | BP18: IC Kationen | BQ18: None | BS18: <0.50 | BT18: IC Kationen | BU18: None | BY18: None | CC18: None | CG18: None | CK18: None | CN18: SOP 45-34 | CO18: None | CS18: None | CW18: None | CZ18: WTW Multimeter 3430 with FDO 925 | DA18: None | DE18: None | DH18: SOP 45-09 | DI18: None | DL18: SOP 45-09 (SOP muss noch angepasst werden für VSS) | DM18: None | DP18: IC Organic Acids | DQ18: None | DT18: IC Organic Acids | DU18: None | DX18: IC Organic Acids | DY18: None | EB18: IC Organic Acids | EC18: None | EF18: IC Organic Acids | EG18: None | EJ18: IC Organic Acids | EK18: None | EN18: IC Organic Acids | EO18: None | ER18: IC Organic Acids | ES18: None | EV18: LC-MS | EW18: None | EZ18: =CONCATENATE(A18,B18) | FA18: =CONCATENATE(SamplesX!A18,SamplesX!B18) | FC18: =MATCH(EZ18,FA1:FA1008,0)
A19: NF | B19: 25011 | C19: =IF(ISNUMBER(FC19),INDIRECT("SamplesX!C"&FC19),IF(ISNUMBER(FD19),INDIRECT("SamplesY!C"&FD19),"")) | D19: =IF(ISNUMBER(FC19),INDIRECT("SamplesX!D"&FC19),IF(ISNUMBER(FD19),INDIRECT("SamplesY!D"&FD19),"")) | E19: =IF(ISNUMBER(FC19),INDIRECT("SamplesX!E"&FC19),IF(ISNUMBER(FD19),INDIRECT("SamplesY!E"&FD19),"")) | F19: =IF(ISNUMBER(FC19),INDIRECT("SamplesX!F"&FC19),IF(ISNUMBER(FD19),INDIRECT("SamplesY!F"&FD19),"")) | G19: =IF(ISNUMBER(FC19),INDIRECT("SamplesX!G"&FC19),IF(ISNUMBER(FD19),INDIRECT("SamplesY!G"&FD19),"")) | H19: =IF(ISNUMBER(FC19),INDIRECT("SamplesX!H"&FC19),IF(ISNUMBER(FD19),INDIRECT("SamplesY!H"&FD19),"")) | K19: 37.2 | L19: Shimadzu TOC-L | M19: None | P19: Shimadzu TOC-L | Q19: None | T19: Shimadzu TOC-L | U19: None | Y19: None | AC19: None | AE19: 15.8 | AF19: IC Anionen | AG19: None | AK19: None | AN19: IC Anionen | AO19: None | AQ19: <0.18 | AR19: IC Anionen | AS19: None | AU19: <0.13 | AV19: IC Anionen | AW19: None | AY19: <0.80 | AZ19: IC Anionen | BA19: None | BC19: 2.13 | BD19: IC Kationen | BE19: None | BG19: 30.9 | BH19: IC Kationen | BI19: None | BK19: 16.6 | BL19: IC Kationen | BM19: None | BO19: 2.74 | BP19: IC Kationen | BQ19: None | BS19: <0.50 | BT19: IC Kationen | BU19: None | BY19: None | CC19: None | CG19: None | CK19: None | CN19: SOP 45-34 | CO19: None | CS19: None | CW19: None | CZ19: WTW Multimeter 3430 with FDO 925 | DA19: None | DE19: None | DH19: SOP 45-09 | DI19: None | DL19: SOP 45-09 (SOP muss noch angepasst werden für VSS) | DM19: None | DP19: IC Organic Acids | DQ19: None | DT19: IC Organic Acids | DU19: None | DX19: IC Organic Acids | DY19: None | EB19: IC Organic Acids | EC19: None | EF19: IC Organic Acids | EG19: None | EJ19: IC Organic Acids | EK19: None | EN19: IC Organic Acids | EO19: None | ER19: IC Organic Acids | ES19: None | EV19: LC-MS | EW19: None | EZ19: =CONCATENATE(A19,B19) | FA19: =CONCATENATE(SamplesX!A19,SamplesX!B19) | FC19: =MATCH(EZ19,FA1:FA1008,0)
A20: NF | B20: 25012 | C20: =IF(ISNUMBER(FC20),INDIRECT("SamplesX!C"&FC20),IF(ISNUMBER(FD20),INDIRECT("SamplesY!C"&FD20),"")) | D20: =IF(ISNUMBER(FC20),INDIRECT("SamplesX!D"&FC20),IF(ISNUMBER(FD20),INDIRECT("SamplesY!D"&FD20),"")) | E20: =IF(ISNUMBER(FC20),INDIRECT("SamplesX!E"&FC20),IF(ISNUMBER(FD20),INDIRECT("SamplesY!E"&FD20),"")) | F20: =IF(ISNUMBER(FC20),INDIRECT("SamplesX!F"&FC20),IF(ISNUMBER(FD20),INDIRECT("SamplesY!F"&FD20),"")) | G20: =IF(ISNUMBER(FC20),INDIRECT("SamplesX!G"&FC20),IF(ISNUMBER(FD20),INDIRECT("SamplesY!G"&FD20),"")) | H20: =IF(ISNUMBER(FC20),INDIRECT("SamplesX!H"&FC20),IF(ISNUMBER(FD20),INDIRECT("SamplesY!H"&FD20),"")) | K20: 37.9 | L20: Shimadzu TOC-L | M20: None | P20: Shimadzu TOC-L | Q20: None | T20: Shimadzu TOC-L | U20: None | Y20: None | AC20: None | AE20: 20.6 | AF20: IC Anionen | AG20: None | AK20: None | AN20: IC Anionen | AO20: None | AQ20: <0.18 | AR20: IC Anionen | AS20: None | AU20: <0.13 | AV20: IC Anionen | AW20: None | AY20: <0.80 | AZ20: IC Anionen | BA20: None | BC20: 1.72 | BD20: IC Kationen | BE20: None | BG20: 30.4 | BH20: IC Kationen | BI20: None | BK20: 21.7 | BL20: IC Kationen | BM20: None | BO20: 2.83 | BP20: IC Kationen | BQ20: None | BS20: <0.50 | BT20: IC Kationen | BU20: None | BY20: None | CC20: None | CG20: None | CK20: None | CN20: SOP 45-34 | CO20: None | CS20: None | CW20: None | CZ20: WTW Multimeter 3430 with FDO 925 | DA20: None | DE20: None | DH20: SOP 45-09 | DI20: None | DL20: SOP 45-09 (SOP muss noch angepasst werden für VSS) | DM20: None | DP20: IC Organic Acids | DQ20: None | DT20: IC Organic Acids | DU20: None | DX20: IC Organic Acids | DY20: None | EB20: IC Organic Acids | EC20: None | EF20: IC Organic Acids | EG20: None | EJ20: IC Organic Acids | EK20: None | EN20: IC Organic Acids | EO20: None | ER20: IC Organic Acids | ES20: None | EV20: LC-MS | EW20: None | EZ20: =CONCATENATE(A20,B20) | FA20: =CONCATENATE(SamplesX!A20,SamplesX!B20) | FC20: =MATCH(EZ20,FA1:FA1008,0)
A21: NF | B21: 25013 | C21: =IF(ISNUMBER(FC21),INDIRECT("SamplesX!C"&FC21),IF(ISNUMBER(FD21),INDIRECT("SamplesY!C"&FD21),"")) | D21: =IF(ISNUMBER(FC21),INDIRECT("SamplesX!D"&FC21),IF(ISNUMBER(FD21),INDIRECT("SamplesY!D"&FD21),"")) | E21: =IF(ISNUMBER(FC21),INDIRECT("SamplesX!E"&FC21),IF(ISNUMBER(FD21),INDIRECT("SamplesY!E"&FD21),"")) | F21: =IF(ISNUMBER(FC21),INDIRECT("SamplesX!F"&FC21),IF(ISNUMBER(FD21),INDIRECT("SamplesY!F"&FD21),"")) | G21: =IF(ISNUMBER(FC21),INDIRECT("SamplesX!G"&FC21),IF(ISNUMBER(FD21),INDIRECT("SamplesY!G"&FD21),"")) | H21: =IF(ISNUMBER(FC21),INDIRECT("SamplesX!H"&FC21),IF(ISNUMBER(FD21),INDIRECT("SamplesY!H"&FD21),"")) | K21: 46.3 | L21: Shimadzu TOC-L | M21: None | P21: Shimadzu TOC-L | Q21: None | T21: Shimadzu TOC-L | U21: None | Y21: None | AC21: None | AE21: 25.3 | AF21: IC Anionen | AG21: None | AI21: 0 | AJ21: Test strips MQuant 10007 | AK21: None | AN21: IC Anionen | AO21: None | AQ21: 0 | AR21: Test strips MQuant 10020 | AS21: None | AU21: <0.13 | AV21: IC Anionen | AW21: None | AY21: <0.80 | AZ21: IC Anionen | BA21: None | BC21: 1.67 | BD21: IC Kationen | BE21: None | BG21: 30.5 | BH21: IC Kationen | BI21: None | BK21: 32.3 | BL21: IC Kationen | BM21: None | BO21: 3.24 | BP21: IC Kationen | BQ21: None | BS21: <0.50 | BT21: IC Kationen | BU21: None | BY21: None | CC21: None | CG21: None | CK21: None | CN21: SOP 45-34 | CO21: None | CS21: None | CW21: None | CZ21: WTW Multimeter 3430 with FDO 925 | DA21: None | DE21: None | DH21: SOP 45-09 | DI21: None | DL21: SOP 45-09 (SOP muss noch angepasst werden für VSS) | DM21: None | DP21: IC Organic Acids | DQ21: None | DT21: IC Organic Acids | DU21: None | DX21: IC Organic Acids | DY21: None | EB21: IC Organic Acids | EC21: None | EF21: IC Organic Acids | EG21: None | EJ21: IC Organic Acids | EK21: None | EN21: IC Organic Acids | EO21: None | ER21: IC Organic Acids | ES21: None | EV21: LC-MS | EW21: None | EZ21: =CONCATENATE(A21,B21) | FA21: =CONCATENATE(SamplesX!A21,SamplesX!B21) | FC21: =MATCH(EZ21,FA1:FA1008,0)
A22: NF | B22: 25014 | C22: =IF(ISNUMBER(FC22),INDIRECT("SamplesX!C"&FC22),IF(ISNUMBER(FD22),INDIRECT("SamplesY!C"&FD22),"")) | D22: =IF(ISNUMBER(FC22),INDIRECT("SamplesX!D"&FC22),IF(ISNUMBER(FD22),INDIRECT("SamplesY!D"&FD22),"")) | E22: =IF(ISNUMBER(FC22),INDIRECT("SamplesX!E"&FC22),IF(ISNUMBER(FD22),INDIRECT("SamplesY!E"&FD22),"")) | F22: =IF(ISNUMBER(FC22),INDIRECT("SamplesX!F"&FC22),IF(ISNUMBER(FD22),INDIRECT("SamplesY!F"&FD22),"")) | G22: =IF(ISNUMBER(FC22),INDIRECT("SamplesX!G"&FC22),IF(ISNUMBER(FD22),INDIRECT("SamplesY!G"&FD22),"")) | H22: =IF(ISNUMBER(FC22),INDIRECT("SamplesX!H"&FC22),IF(ISNUMBER(FD22),INDIRECT("SamplesY!H"&FD22),"")) | J22: TIC Messung 10.7.25 | K22: 98.7 | L22: Shimadzu TOC-L | M22: None | P22: Shimadzu TOC-L | Q22: None | S22: 17.1 | T22: Shimadzu TOC-L | U22: None | Y22: None | AC22: None | AE22: 332 | AF22: IC Anionen | AG22: None | AH22: 5*4 | AK22: None | AN22: IC Anionen | AO22: None | AQ22: 0.85 | AR22: IC Anionen | AS22: None | AU22: <0.13 | AV22: IC Anionen | AW22: None | AY22: <0.80 | AZ22: IC Anionen | BA22: None | BC22: 1.71 | BD22: IC Kationen | BE22: None | BG22: 17.6 | BH22: IC Kationen | BI22: None | BK22: 351 | BL22: IC Kationen | BM22: None | BN22: 4*5 | BO22: 4.87 | BP22: IC Kationen | BQ22: None | BS22: <0.50 | BT22: IC Kationen | BU22: None | BY22: None | CC22: None | CG22: None | CK22: None | CN22: SOP 45-34 | CO22: None | CS22: None | CW22: None | CZ22: WTW Multimeter 3430 with FDO 925 | DA22: None | DE22: None | DH22: SOP 45-09 | DI22: None | DL22: SOP 45-09 (SOP muss noch angepasst werden für VSS) | DM22: None | DP22: IC Organic Acids | DQ22: None | DT22: IC Organic Acids | DU22: None | DX22: IC Organic Acids | DY22: None | EB22: IC Organic Acids | EC22: None | EF22: IC Organic Acids | EG22: None | EJ22: IC Organic Acids | EK22: None | EN22: IC Organic Acids | EO22: None | ER22: IC Organic Acids | ES22: None | EV22: LC-MS | EW22: None | EZ22: =CONCATENATE(A22,B22) | FA22: =CONCATENATE(SamplesX!A22,SamplesX!B22) | FC22: =MATCH(EZ22,FA1:FA1008,0)
A23: NF | B23: 25015 | C23: =IF(ISNUMBER(FC23),INDIRECT("SamplesX!C"&FC23),IF(ISNUMBER(FD23),INDIRECT("SamplesY!C"&FD23),"")) | D23: =IF(ISNUMBER(FC23),INDIRECT("SamplesX!D"&FC23),IF(ISNUMBER(FD23),INDIRECT("SamplesY!D"&FD23),"")) | E23: =IF(ISNUMBER(FC23),INDIRECT("SamplesX!E"&FC23),IF(ISNUMBER(FD23),INDIRECT("SamplesY!E"&FD23),"")) | F23: =IF(ISNUMBER(FC23),INDIRECT("SamplesX!F"&FC23),IF(ISNUMBER(FD23),INDIRECT("SamplesY!F"&FD23),"")) | G23: =IF(ISNUMBER(FC23),INDIRECT("SamplesX!G"&FC23),IF(ISNUMBER(FD23),INDIRECT("SamplesY!G"&FD23),"")) | H23: =IF(ISNUMBER(FC23),INDIRECT("SamplesX!H"&FC23),IF(ISNUMBER(FD23),INDIRECT("SamplesY!H"&FD23),"")) | J23: keine Probe | L23: Shimadzu TOC-L | M23: None | P23: Shimadzu TOC-L | Q23: None | T23: Shimadzu TOC-L | U23: None | Y23: None | AC23: None | AF23: IC Anionen | AG23: None | AK23: None | AN23: IC Anionen | AO23: None | AS23: None | AW23: None | AZ23: IC Anionen | BA23: None | BD23: IC Kationen | BE23: None | BH23: IC Kationen | BI23: None | BL23: IC Kationen | BM23: None | BP23: IC Kationen | BQ23: None | BT23: IC Kationen | BU23: None | BY23: None | CC23: None | CG23: None | CK23: None | CN23: SOP 45-34 | CO23: None | CS23: None | CW23: None | CZ23: WTW Multimeter 3430 with FDO 925 | DA23: None | DE23: None | DH23: SOP 45-09 | DI23: None | DL23: SOP 45-09 (SOP muss noch angepasst werden für VSS) | DM23: None | DP23: IC Organic Acids | DQ23: None | DT23: IC Organic Acids | DU23: None | DX23: IC Organic Acids | DY23: None | EB23: IC Organic Acids | EC23: None | EF23: IC Organic Acids | EG23: None | EJ23: IC Organic Acids | EK23: None | EN23: IC Organic Acids | EO23: None | ER23: IC Organic Acids | ES23: None | EV23: LC-MS | EW23: None | EZ23: =CONCATENATE(A23,B23) | FA23: =CONCATENATE(SamplesX!A23,SamplesX!B23) | FC23: =MATCH(EZ23,FA1:FA1008,0)
A24: NF | B24: 25016 | C24: =IF(ISNUMBER(FC24),INDIRECT("SamplesX!C"&FC24),IF(ISNUMBER(FD24),INDIRECT("SamplesY!C"&FD24),"")) | D24: =IF(ISNUMBER(FC24),INDIRECT("SamplesX!D"&FC24),IF(ISNUMBER(FD24),INDIRECT("SamplesY!D"&FD24),"")) | E24: =IF(ISNUMBER(FC24),INDIRECT("SamplesX!E"&FC24),IF(ISNUMBER(FD24),INDIRECT("SamplesY!E"&FD24),"")) | F24: =IF(ISNUMBER(FC24),INDIRECT("SamplesX!F"&FC24),IF(ISNUMBER(FD24),INDIRECT("SamplesY!F"&FD24),"")) | G24: =IF(ISNUMBER(FC24),INDIRECT("SamplesX!G"&FC24),IF(ISNUMBER(FD24),INDIRECT("SamplesY!G"&FD24),"")) | H24: =IF(ISNUMBER(FC24),INDIRECT("SamplesX!H"&FC24),IF(ISNUMBER(FD24),INDIRECT("SamplesY!H"&FD24),"")) | J24: TIC Messung 10.7.25 | K24: 16.8 | L24: Shimadzu TOC-L | M24: None | P24: Shimadzu TOC-L | Q24: None | S24: 12.3 | T24: Shimadzu TOC-L | U24: None | W24: 31.2 | X24: Shimadzu TOC-L | Y24: None | AC24: None | AE24: <0.80 | AF24: IC Anionen | AG24: None | AK24: None | AN24: IC Anionen | AO24: None | AQ24: <0.18 | AR24: IC Anionen | AS24: None | AU24: <0.13 | AV24: IC Anionen | AW24: None | AY24: <0.80 | AZ24: IC Anionen | BA24: None | BC24: <1.00 | BD24: IC Kationen | BE24: None | BG24: 21.7 | BH24: IC Kationen | BI24: None | BK24: <1.00 | BL24: IC Kationen | BM24: None | BO24: 2.36 | BP24: IC Kationen | BQ24: None | BS24: <0.50 | BT24: IC Kationen | BU24: None | BY24: None | CC24: None | CG24: None | CK24: None | CN24: SOP 45-34 | CO24: None | CS24: None | CW24: None | CZ24: WTW Multimeter 3430 with FDO 925 | DA24: None | DE24: None | DH24: SOP 45-09 | DI24: None | DL24: SOP 45-09 (SOP muss noch angepasst werden für VSS) | DM24: None | DP24: IC Organic Acids | DQ24: None | DT24: IC Organic Acids | DU24: None | DX24: IC Organic Acids | DY24: None | EB24: IC Organic Acids | EC24: None | EF24: IC Organic Acids | EG24: None | EJ24: IC Organic Acids | EK24: None | EN24: IC Organic Acids | EO24: None | ER24: IC Organic Acids | ES24: None | EV24: LC-MS | EW24: None | EZ24: =CONCATENATE(A24,B24) | FA24: =CONCATENATE(SamplesX!A24,SamplesX!B24) | FC24: =MATCH(EZ24,FA1:FA1008,0)
A25: NF | B25: 25017 | C25: =IF(ISNUMBER(FC25),INDIRECT("SamplesX!C"&FC25),IF(ISNUMBER(FD25),INDIRECT("SamplesY!C"&FD25),"")) | D25: =IF(ISNUMBER(FC25),INDIRECT("SamplesX!D"&FC25),IF(ISNUMBER(FD25),INDIRECT("SamplesY!D"&FD25),"")) | E25: =IF(ISNUMBER(FC25),INDIRECT("SamplesX!E"&FC25),IF(ISNUMBER(FD25),INDIRECT("SamplesY!E"&FD25),"")) | F25: =IF(ISNUMBER(FC25),INDIRECT("SamplesX!F"&FC25),IF(ISNUMBER(FD25),INDIRECT("SamplesY!F"&FD25),"")) | G25: =IF(ISNUMBER(FC25),INDIRECT("SamplesX!G"&FC25),IF(ISNUMBER(FD25),INDIRECT("SamplesY!G"&FD25),"")) | H25: =IF(ISNUMBER(FC25),INDIRECT("SamplesX!H"&FC25),IF(ISNUMBER(FD25),INDIRECT("SamplesY!H"&FD25),"")) | J25: TIC Messung 10.7.25 | K25: 10.4 | L25: Shimadzu TOC-L | M25: None | P25: Shimadzu TOC-L | Q25: None | S25: 18.6 | T25: Shimadzu TOC-L | U25: None | W25: 26.9 | X25: Shimadzu TOC-L | Y25: None | AC25: None | AE25: 2.34 | AF25: IC Anionen | AG25: None | AK25: None | AN25: IC Anionen | AO25: None | AQ25: <0.18 | AR25: IC Anionen | AS25: None | AU25: <0.13 | AV25: IC Anionen | AW25: None | AY25: <0.80 | AZ25: IC Anionen | BA25: None | BC25: 1.00 | BD25: IC Kationen | BE25: None | BG25: 20.9 | BH25: IC Kationen | BI25: None | BK25: 3.06 | BL25: IC Kationen | BM25: None | BO25: 2.50 | BP25: IC Kationen | BQ25: None | BS25: <0.50 | BT25: IC Kationen | BU25: None | BY25: None | CC25: None | CG25: None | CK25: None | CN25: SOP 45-34 | CO25: None | CS25: None | CW25: None | CZ25: WTW Multimeter 3430 with FDO 925 | DA25: None | DE25: None | DH25: SOP 45-09 | DI25: None | DL25: SOP 45-09 (SOP muss noch angepasst werden für VSS) | DM25: None | DP25: IC Organic Acids | DQ25: None | DT25: IC Organic Acids | DU25: None | DX25: IC Organic Acids | DY25: None | EB25: IC Organic Acids | EC25: None | EF25: IC Organic Acids | EG25: None | EJ25: IC Organic Acids | EK25: None | EN25: IC Organic Acids | EO25: None | ER25: IC Organic Acids | ES25: None | EV25: LC-MS | EW25: None | EZ25: =CONCATENATE(A25,B25) | FA25: =CONCATENATE(SamplesX!A25,SamplesX!B25) | FC25: =MATCH(EZ25,FA1:FA1008,0)
A26: NF | B26: 25018 | C26: =IF(ISNUMBER(FC26),INDIRECT("SamplesX!C"&FC26),IF(ISNUMBER(FD26),INDIRECT("SamplesY!C"&FD26),"")) | D26: =IF(ISNUMBER(FC26),INDIRECT("SamplesX!D"&FC26),IF(ISNUMBER(FD26),INDIRECT("SamplesY!D"&FD26),"")) | E26: =IF(ISNUMBER(FC26),INDIRECT("SamplesX!E"&FC26),IF(ISNUMBER(FD26),INDIRECT("SamplesY!E"&FD26),"")) | F26: =IF(ISNUMBER(FC26),INDIRECT("SamplesX!F"&FC26),IF(ISNUMBER(FD26),INDIRECT("SamplesY!F"&FD26),"")) | G26: =IF(ISNUMBER(FC26),INDIRECT("SamplesX!G"&FC26),IF(ISNUMBER(FD26),INDIRECT("SamplesY!G"&FD26),"")) | H26: =IF(ISNUMBER(FC26),INDIRECT("SamplesX!H"&FC26),IF(ISNUMBER(FD26),INDIRECT("SamplesY!H"&FD26),"")) | J26: TIC Messung 10.7.25 | K26: 18.3 | L26: Shimadzu TOC-L | M26: None | P26: Shimadzu TOC-L | Q26: None | S26: 15.2 | T26: Shimadzu TOC-L | U26: None | W26: 28.8 | X26: Shimadzu TOC-L | Y26: None | AC26: None | AE26: 3.01 | AF26: IC Anionen | AG26: None | AK26: None | AN26: IC Anionen | AO26: None | AQ26: <0.18 | AR26: IC Anionen | AS26: None | AU26: <0.13 | AV26: IC Anionen | AW26: None | AY26: <0.80 | AZ26: IC Anionen | BA26: None | BC26: <1.00 | BD26: IC Kationen | BE26: None | BG26: 21.2 | BH26: IC Kationen | BI26: None | BK26: 3.62 | BL26: IC Kationen | BM26: None | BO26: 2.48 | BP26: IC Kationen | BQ26: None | BS26: <0.50 | BT26: IC Kationen | BU26: None | BY26: None | CC26: None | CG26: None | CK26: None | CN26: SOP 45-34 | CO26: None | CS26: None | CW26: None | CZ26: WTW Multimeter 3430 with FDO 925 | DA26: None | DE26: None | DH26: SOP 45-09 | DI26: None | DL26: SOP 45-09 (SOP muss noch angepasst werden für VSS) | DM26: None | DP26: IC Organic Acids | DQ26: None | DT26: IC Organic Acids | DU26: None | DX26: IC Organic Acids | DY26: None | EB26: IC Organic Acids | EC26: None | EF26: IC Organic Acids | EG26: None | EJ26: IC Organic Acids | EK26: None | EN26: IC Organic Acids | EO26: None | ER26: IC Organic Acids | ES26: None | EV26: LC-MS | EW26: None | EZ26: =CONCATENATE(A26,B26) | FA26: =CONCATENATE(SamplesX!A26,SamplesX!B26) | FC26: =MATCH(EZ26,FA1:FA1008,0)
A27: NF | B27: 25019 | C27: =IF(ISNUMBER(FC27),INDIRECT("SamplesX!C"&FC27),IF(ISNUMBER(FD27),INDIRECT("SamplesY!C"&FD27),"")) | D27: =IF(ISNUMBER(FC27),INDIRECT("SamplesX!D"&FC27),IF(ISNUMBER(FD27),INDIRECT("SamplesY!D"&FD27),"")) | E27: =IF(ISNUMBER(FC27),INDIRECT("SamplesX!E"&FC27),IF(ISNUMBER(FD27),INDIRECT("SamplesY!E"&FD27),"")) | F27: =IF(ISNUMBER(FC27),INDIRECT("SamplesX!F"&FC27),IF(ISNUMBER(FD27),INDIRECT("SamplesY!F"&FD27),"")) | G27: =IF(ISNUMBER(FC27),INDIRECT("SamplesX!G"&FC27),IF(ISNUMBER(FD27),INDIRECT("SamplesY!G"&FD27),"")) | H27: =IF(ISNUMBER(FC27),INDIRECT("SamplesX!H"&FC27),IF(ISNUMBER(FD27),INDIRECT("SamplesY!H"&FD27),"")) | K27: 16.4 | L27: Shimadzu TOC-L | M27: None | P27: Shimadzu TOC-L | Q27: None | T27: Shimadzu TOC-L | U27: None | W27: 26.8 | X27: Shimadzu TOC-L | Y27: None | AC27: None | AE27: 3.80 | AF27: IC Anionen | AG27: None | AK27: None | AN27: IC Anionen | AO27: None | AQ27: <0.18 | AR27: IC Anionen | AS27: None | AU27: <0.13 | AV27: IC Anionen | AW27: None | AY27: <0.80 | AZ27: IC Anionen | BA27: None | BC27: 1.47 | BD27: IC Kationen | BE27: None | BG27: 21.0 | BH27: IC Kationen | BI27: None | BK27: 4.47 | BL27: IC Kationen | BM27: None | BO27: 2.41 | BP27: IC Kationen | BQ27: None | BS27: <0.50 | BT27: IC Kationen | BU27: None | BY27: None | CC27: None | CG27: None | CK27: None | CN27: SOP 45-34 | CO27: None | CS27: None | CW27: None | CZ27: WTW Multimeter 3430 with FDO 925 | DA27: None | DE27: None | DH27: SOP 45-09 | DI27: None | DL27: SOP 45-09 (SOP muss noch angepasst werden für VSS) | DM27: None | DP27: IC Organic Acids | DQ27: None | DT27: IC Organic Acids | DU27: None | DX27: IC Organic Acids | DY27: None | EB27: IC Organic Acids | EC27: None | EF27: IC Organic Acids | EG27: None | EJ27: IC Organic Acids | EK27: None | EN27: IC Organic Acids | EO27: None | ER27: IC Organic Acids | ES27: None | EV27: LC-MS | EW27: None | EZ27: =CONCATENATE(A27,B27) | FA27: =CONCATENATE(SamplesX!A27,SamplesX!B27) | FC27: =MATCH(EZ27,FA1:FA1008,0)
A28: NF | B28: 25020 | C28: =IF(ISNUMBER(FC28),INDIRECT("SamplesX!C"&FC28),IF(ISNUMBER(FD28),INDIRECT("SamplesY!C"&FD28),"")) | D28: =IF(ISNUMBER(FC28),INDIRECT("SamplesX!D"&FC28),IF(ISNUMBER(FD28),INDIRECT("SamplesY!D"&FD28),"")) | E28: =IF(ISNUMBER(FC28),INDIRECT("SamplesX!E"&FC28),IF(ISNUMBER(FD28),INDIRECT("SamplesY!E"&FD28),"")) | F28: =IF(ISNUMBER(FC28),INDIRECT("SamplesX!F"&FC28),IF(ISNUMBER(FD28),INDIRECT("SamplesY!F"&FD28),"")) | G28: =IF(ISNUMBER(FC28),INDIRECT("SamplesX!G"&FC28),IF(ISNUMBER(FD28),INDIRECT("SamplesY!G"&FD28),"")) | H28: =IF(ISNUMBER(FC28),INDIRECT("SamplesX!H"&FC28),IF(ISNUMBER(FD28),INDIRECT("SamplesY!H"&FD28),"")) | K28: 16.1 | L28: Shimadzu TOC-L | M28: None | P28: Shimadzu TOC-L | Q28: None | T28: Shimadzu TOC-L | U28: None | W28: 28.8 | X28: Shimadzu TOC-L | Y28: None | AC28: None | AE28: 4.56 | AF28: IC Anionen | AG28: None | AK28: None | AN28: IC Anionen | AO28: None | AQ28: <0.18 | AR28: IC Anionen | AS28: None | AU28: <0.13 | AV28: IC Anionen | AW28: None | AY28: <0.80 | AZ28: IC Anionen | BA28: None | BC28: <1.00 | BD28: IC Kationen | BE28: None | BG28: 21.3 | BH28: IC Kationen | BI28: None | BK28: 5.18 | BL28: IC Kationen | BM28: None | BO28: 2.46 | BP28: IC Kationen | BQ28: None | BS28: <0.50 | BT28: IC Kationen | BU28: None | BY28: None | CC28: None | CG28: None | CK28: None | CN28: SOP 45-34 | CO28: None | CS28: None | CW28: None | CZ28: WTW Multimeter 3430 with FDO 925 | DA28: None | DE28: None | DH28: SOP 45-09 | DI28: None | DL28: SOP 45-09 (SOP muss noch angepasst werden für VSS) | DM28: None | DP28: IC Organic Acids | DQ28: None | DT28: IC Organic Acids | DU28: None | DX28: IC Organic Acids | DY28: None | EB28: IC Organic Acids | EC28: None | EF28: IC Organic Acids | EG28: None | EJ28: IC Organic Acids | EK28: None | EN28: IC Organic Acids | EO28: None | ER28: IC Organic Acids | ES28: None | EV28: LC-MS | EW28: None | EZ28: =CONCATENATE(A28,B28) | FA28: =CONCATENATE(SamplesX!A28,SamplesX!B28) | FC28: =MATCH(EZ28,FA1:FA1008,0)
A29: NF | B29: 25021 | C29: =IF(ISNUMBER(FC29),INDIRECT("SamplesX!C"&FC29),IF(ISNUMBER(FD29),INDIRECT("SamplesY!C"&FD29),"")) | D29: =IF(ISNUMBER(FC29),INDIRECT("SamplesX!D"&FC29),IF(ISNUMBER(FD29),INDIRECT("SamplesY!D"&FD29),"")) | E29: =IF(ISNUMBER(FC29),INDIRECT("SamplesX!E"&FC29),IF(ISNUMBER(FD29),INDIRECT("SamplesY!E"&FD29),"")) | F29: =IF(ISNUMBER(FC29),INDIRECT("SamplesX!F"&FC29),IF(ISNUMBER(FD29),INDIRECT("SamplesY!F"&FD29),"")) | G29: =IF(ISNUMBER(FC29),INDIRECT("SamplesX!G"&FC29),IF(ISNUMBER(FD29),INDIRECT("SamplesY!G"&FD29),"")) | H29: =IF(ISNUMBER(FC29),INDIRECT("SamplesX!H"&FC29),IF(ISNUMBER(FD29),INDIRECT("SamplesY!H"&FD29),"")) | J29: TIC Messung 10.7.25 | K29: 17.2 | L29: Shimadzu TOC-L | M29: None | P29: Shimadzu TOC-L | Q29: None | T29: Shimadzu TOC-L | U29: None | W29: 26.0 | X29: Shimadzu TOC-L | Y29: None | AC29: None | AE29: 6.34 | AF29: IC Anionen | AG29: None | AK29: None | AN29: IC Anionen | AO29: None | AQ29: <0.18 | AR29: IC Anionen | AS29: None | AU29: <0.13 | AV29: IC Anionen | AW29: None | AY29: <0.80 | AZ29: IC Anionen | BA29: None | BC29: <1.00 | BD29: IC Kationen | BE29: None | BG29: 20.5 | BH29: IC Kationen | BI29: None | BK29: 6.88 | BL29: IC Kationen | BM29: None | BO29: 2.58 | BP29: IC Kationen | BQ29: None | BS29: <0.50 | BT29: IC Kationen | BU29: None | BY29: None | CC29: None | CG29: None | CK29: None | CN29: SOP 45-34 | CO29: None | CS29: None | CW29: None | CZ29: WTW Multimeter 3430 with FDO 925 | DA29: None | DE29: None | DH29: SOP 45-09 | DI29: None | DL29: SOP 45-09 (SOP muss noch angepasst werden für VSS) | DM29: None | DP29: IC Organic Acids | DQ29: None | DT29: IC Organic Acids | DU29: None | DX29: IC Organic Acids | DY29: None | EB29: IC Organic Acids | EC29: None | EF29: IC Organic Acids | EG29: None | EJ29: IC Organic Acids | EK29: None | EN29: IC Organic Acids | EO29: None | ER29: IC Organic Acids | ES29: None | EV29: LC-MS | EW29: None | EZ29: =CONCATENATE(A29,B29) | FA29: =CONCATENATE(SamplesX!A29,SamplesX!B29) | FC29: =MATCH(EZ29,FA1:FA1008,0)
A30: NF | B30: 25022 | C30: =IF(ISNUMBER(FC30),INDIRECT("SamplesX!C"&FC30),IF(ISNUMBER(FD30),INDIRECT("SamplesY!C"&FD30),"")) | D30: =IF(ISNUMBER(FC30),INDIRECT("SamplesX!D"&FC30),IF(ISNUMBER(FD30),INDIRECT("SamplesY!D"&FD30),"")) | E30: =IF(ISNUMBER(FC30),INDIRECT("SamplesX!E"&FC30),IF(ISNUMBER(FD30),INDIRECT("SamplesY!E"&FD30),"")) | F30: =IF(ISNUMBER(FC30),INDIRECT("SamplesX!F"&FC30),IF(ISNUMBER(FD30),INDIRECT("SamplesY!F"&FD30),"")) | G30: =IF(ISNUMBER(FC30),INDIRECT("SamplesX!G"&FC30),IF(ISNUMBER(FD30),INDIRECT("SamplesY!G"&FD30),"")) | H30: =IF(ISNUMBER(FC30),INDIRECT("SamplesX!H"&FC30),IF(ISNUMBER(FD30),INDIRECT("SamplesY!H"&FD30),"")) | J30: TIC Messung 10.7.25 | K30: 17.9 | L30: Shimadzu TOC-L | M30: None | P30: Shimadzu TOC-L | Q30: None | T30: Shimadzu TOC-L | U30: None | W30: 28.1 | X30: Shimadzu TOC-L | Y30: None | AC30: None | AE30: 7.38 | AF30: IC Anionen | AG30: None | AK30: None | AN30: IC Anionen | AO30: None | AQ30: <0.18 | AR30: IC Anionen | AS30: None | AU30: <0.13 | AV30: IC Anionen | AW30: None | AY30: <0.80 | AZ30: IC Anionen | BA30: None | BC30: <1.00 | BD30: IC Kationen | BE30: None | BG30: 20.9 | BH30: IC Kationen | BI30: None | BK30: 8.10 | BL30: IC Kationen | BM30: None | BO30: 2.56 | BP30: IC Kationen | BQ30: None | BS30: <0.50 | BT30: IC Kationen | BU30: None | BY30: None | CC30: None | CG30: None | CK30: None | CN30: SOP 45-34 | CO30: None | CS30: None | CW30: None | CZ30: WTW Multimeter 3430 with FDO 925 | DA30: None | DE30: None | DH30: SOP 45-09 | DI30: None | DL30: SOP 45-09 (SOP muss noch angepasst werden für VSS) | DM30: None | DP30: IC Organic Acids | DQ30: None | DT30: IC Organic Acids | DU30: None | DX30: IC Organic Acids | DY30: None | EB30: IC Organic Acids | EC30: None | EF30: IC Organic Acids | EG30: None | EJ30: IC Organic Acids | EK30: None | EN30: IC Organic Acids | EO30: None | ER30: IC Organic Acids | ES30: None | EV30: LC-MS | EW30: None | EZ30: =CONCATENATE(A30,B30) | FA30: =CONCATENATE(SamplesX!A30,SamplesX!B30) | FC30: =MATCH(EZ30,FA1:FA1008,0)
A31: NF | B31: 25023 | C31: =IF(ISNUMBER(FC31),INDIRECT("SamplesX!C"&FC31),IF(ISNUMBER(FD31),INDIRECT("SamplesY!C"&FD31),"")) | D31: =IF(ISNUMBER(FC31),INDIRECT("SamplesX!D"&FC31),IF(ISNUMBER(FD31),INDIRECT("SamplesY!D"&FD31),"")) | E31: =IF(ISNUMBER(FC31),INDIRECT("SamplesX!E"&FC31),IF(ISNUMBER(FD31),INDIRECT("SamplesY!E"&FD31),"")) | F31: =IF(ISNUMBER(FC31),INDIRECT("SamplesX!F"&FC31),IF(ISNUMBER(FD31),INDIRECT("SamplesY!F"&FD31),"")) | G31: =IF(ISNUMBER(FC31),INDIRECT("SamplesX!G"&FC31),IF(ISNUMBER(FD31),INDIRECT("SamplesY!G"&FD31),"")) | H31: =IF(ISNUMBER(FC31),INDIRECT("SamplesX!H"&FC31),IF(ISNUMBER(FD31),INDIRECT("SamplesY!H"&FD31),"")) | J31: TIC Messung 10.7.25 | K31: 22.2 | L31: Shimadzu TOC-L | M31: None | P31: Shimadzu TOC-L | Q31: None | T31: Shimadzu TOC-L | U31: None | W31: 29.3 | X31: Shimadzu TOC-L | Y31: None | AC31: None | AE31: 11.5 | AF31: IC Anionen | AG31: None | AK31: None | AN31: IC Anionen | AO31: None | AQ31: <0.18 | AR31: IC Anionen | AS31: None | AU31: <0.13 | AV31: IC Anionen | AW31: None | AY31: <0.80 | AZ31: IC Anionen | BA31: None | BC31: <1.00 | BD31: IC Kationen | BE31: None | BG31: 20.5 | BH31: IC Kationen | BI31: None | BK31: 12.1 | BL31: IC Kationen | BM31: None | BO31: 2.82 | BP31: IC Kationen | BQ31: None | BS31: <0.50 | BT31: IC Kationen | BU31: None | BY31: None | CC31: None | CG31: None | CK31: None | CN31: SOP 45-34 | CO31: None | CS31: None | CW31: None | CZ31: WTW Multimeter 3430 with FDO 925 | DA31: None | DE31: None | DH31: SOP 45-09 | DI31: None | DL31: SOP 45-09 (SOP muss noch angepasst werden für VSS) | DM31: None | DP31: IC Organic Acids | DQ31: None | DT31: IC Organic Acids | DU31: None | DX31: IC Organic Acids | DY31: None | EB31: IC Organic Acids | EC31: None | EF31: IC Organic Acids | EG31: None | EJ31: IC Organic Acids | EK31: None | EN31: IC Organic Acids | EO31: None | ER31: IC Organic Acids | ES31: None | EV31: LC-MS | EW31: None | EZ31: =CONCATENATE(A31,B31) | FA31: =CONCATENATE(SamplesX!A31,SamplesX!B31) | FC31: =MATCH(EZ31,FA1:FA1008,0)
A32: NF | B32: 25024 | C32: =IF(ISNUMBER(FC32),INDIRECT("SamplesX!C"&FC32),IF(ISNUMBER(FD32),INDIRECT("SamplesY!C"&FD32),"")) | D32: =IF(ISNUMBER(FC32),INDIRECT("SamplesX!D"&FC32),IF(ISNUMBER(FD32),INDIRECT("SamplesY!D"&FD32),"")) | E32: =IF(ISNUMBER(FC32),INDIRECT("SamplesX!E"&FC32),IF(ISNUMBER(FD32),INDIRECT("SamplesY!E"&FD32),"")) | F32: =IF(ISNUMBER(FC32),INDIRECT("SamplesX!F"&FC32),IF(ISNUMBER(FD32),INDIRECT("SamplesY!F"&FD32),"")) | G32: =IF(ISNUMBER(FC32),INDIRECT("SamplesX!G"&FC32),IF(ISNUMBER(FD32),INDIRECT("SamplesY!G"&FD32),"")) | H32: =IF(ISNUMBER(FC32),INDIRECT("SamplesX!H"&FC32),IF(ISNUMBER(FD32),INDIRECT("SamplesY!H"&FD32),"")) | J32: TIC Messung 10.7.25 | K32: 16.9 | L32: Shimadzu TOC-L | M32: None | P32: Shimadzu TOC-L | Q32: None | S32: 18.8 | T32: Shimadzu TOC-L | U32: None | W32: 28.8 | X32: Shimadzu TOC-L | Y32: None | AC32: None | AE32: 17.6 | AF32: IC Anionen | AG32: None | AK32: None | AN32: IC Anionen | AO32: None | AQ32: <0.18 | AR32: IC Anionen | AS32: None | AU32: <0.13 | AV32: IC Anionen | AW32: None | AY32: <0.80 | AZ32: IC Anionen | BA32: None | BC32: <1.00 | BD32: IC Kationen | BE32: None | BG32: 20.9 | BH32: IC Kationen | BI32: None | BK32: 18.3 | BL32: IC Kationen | BM32: None | BO32: 7.44 | BP32: IC Kationen | BQ32: None | BS32: <0.50 | BT32: IC Kationen | BU32: None | BY32: None | CC32: None | CG32: None | CK32: None | CN32: SOP 45-34 | CO32: None | CS32: None | CW32: None | CZ32: WTW Multimeter 3430 with FDO 925 | DA32: None | DE32: None | DH32: SOP 45-09 | DI32: None | DL32: SOP 45-09 (SOP muss noch angepasst werden für VSS) | DM32: None | DP32: IC Organic Acids | DQ32: None | DT32: IC Organic Acids | DU32: None | DX32: IC Organic Acids | DY32: None | EB32: IC Organic Acids | EC32: None | EF32: IC Organic Acids | EG32: None | EJ32: IC Organic Acids | EK32: None | EN32: IC Organic Acids | EO32: None | ER32: IC Organic Acids | ES32: None | EV32: LC-MS | EW32: None | EZ32: =CONCATENATE(A32,B32) | FA32: =CONCATENATE(SamplesX!A32,SamplesX!B32) | FC32: =MATCH(EZ32,FA1:FA1008,0)
A33: NF | B33: 25025 | C33: =IF(ISNUMBER(FC33),INDIRECT("SamplesX!C"&FC33),IF(ISNUMBER(FD33),INDIRECT("SamplesY!C"&FD33),"")) | D33: =IF(ISNUMBER(FC33),INDIRECT("SamplesX!D"&FC33),IF(ISNUMBER(FD33),INDIRECT("SamplesY!D"&FD33),"")) | E33: =IF(ISNUMBER(FC33),INDIRECT("SamplesX!E"&FC33),IF(ISNUMBER(FD33),INDIRECT("SamplesY!E"&FD33),"")) | F33: =IF(ISNUMBER(FC33),INDIRECT("SamplesX!F"&FC33),IF(ISNUMBER(FD33),INDIRECT("SamplesY!F"&FD33),"")) | G33: =IF(ISNUMBER(FC33),INDIRECT("SamplesX!G"&FC33),IF(ISNUMBER(FD33),INDIRECT("SamplesY!G"&FD33),"")) | H33: =IF(ISNUMBER(FC33),INDIRECT("SamplesX!H"&FC33),IF(ISNUMBER(FD33),INDIRECT("SamplesY!H"&FD33),"")) | J33: keine Probe | L33: Shimadzu TOC-L | M33: None | P33: Shimadzu TOC-L | Q33: None | T33: Shimadzu TOC-L | U33: None | X33: Shimadzu TOC-L | Y33: None | AC33: None | AF33: IC Anionen | AG33: None | AK33: None | AN33: IC Anionen | AO33: None | AS33: None | AW33: None | AZ33: IC Anionen | BA33: None | BD33: IC Kationen | BE33: None | BH33: IC Kationen | BI33: None | BL33: IC Kationen | BM33: None | BP33: IC Kationen | BQ33: None | BT33: IC Kationen | BU33: None | BY33: None | CC33: None | CG33: None | CK33: None | CN33: SOP 45-34 | CO33: None | CS33: None | CW33: None | CZ33: WTW Multimeter 3430 with FDO 925 | DA33: None | DE33: None | DH33: SOP 45-09 | DI33: None | DL33: SOP 45-09 (SOP muss noch angepasst werden für VSS) | DM33: None | DP33: IC Organic Acids | DQ33: None | DT33: IC Organic Acids | DU33: None | DX33: IC Organic Acids | DY33: None | EB33: IC Organic Acids | EC33: None | EF33: IC Organic Acids | EG33: None | EJ33: IC Organic Acids | EK33: None | EN33: IC Organic Acids | EO33: None | ER33: IC Organic Acids | ES33: None | EV33: LC-MS | EW33: None | EZ33: =CONCATENATE(A33,B33) | FA33: =CONCATENATE(SamplesX!A33,SamplesX!B33) | FC33: =MATCH(EZ33,FA1:FA1008,0)
A34: NF | B34: 25026 | C34: =IF(ISNUMBER(FC34),INDIRECT("SamplesX!C"&FC34),IF(ISNUMBER(FD34),INDIRECT("SamplesY!C"&FD34),"")) | D34: =IF(ISNUMBER(FC34),INDIRECT("SamplesX!D"&FC34),IF(ISNUMBER(FD34),INDIRECT("SamplesY!D"&FD34),"")) | E34: =IF(ISNUMBER(FC34),INDIRECT("SamplesX!E"&FC34),IF(ISNUMBER(FD34),INDIRECT("SamplesY!E"&FD34),"")) | F34: =IF(ISNUMBER(FC34),INDIRECT("SamplesX!F"&FC34),IF(ISNUMBER(FD34),INDIRECT("SamplesY!F"&FD34),"")) | G34: =IF(ISNUMBER(FC34),INDIRECT("SamplesX!G"&FC34),IF(ISNUMBER(FD34),INDIRECT("SamplesY!G"&FD34),"")) | H34: =IF(ISNUMBER(FC34),INDIRECT("SamplesX!H"&FC34),IF(ISNUMBER(FD34),INDIRECT("SamplesY!H"&FD34),"")) | J34: TIC Messung 10.7.25 | K34: 23.3 | L34: Shimadzu TOC-L | M34: None | P34: Shimadzu TOC-L | Q34: None | S34: 11.8 | T34: Shimadzu TOC-L | U34: None | W34: 27.8 | X34: Shimadzu TOC-L | Y34: None | AC34: None | AE34: <0.80 | AF34: IC Anionen | AG34: None | AK34: None | AN34: IC Anionen | AO34: None | AQ34: <0.18 | AR34: IC Anionen | AS34: None | AU34: <0.13 | AV34: IC Anionen | AW34: None | AY34: <0.80 | AZ34: IC Anionen | BA34: None | BC34: <1.00 | BD34: IC Kationen | BE34: None | BG34: 21.4 | BH34: IC Kationen | BI34: None | BK34: <1.00 | BL34: IC Kationen | BM34: None | BO34: 2.49 | BP34: IC Kationen | BQ34: None | BS34: <0.50 | BT34: IC Kationen | BU34: None | BY34: None | CC34: None | CG34: None | CK34: None | CN34: SOP 45-34 | CO34: None | CS34: None | CW34: None | CZ34: WTW Multimeter 3430 with FDO 925 | DA34: None | DE34: None | DH34: SOP 45-09 | DI34: None | DL34: SOP 45-09 (SOP muss noch angepasst werden für VSS) | DM34: None | DP34: IC Organic Acids | DQ34: None | DT34: IC Organic Acids | DU34: None | DX34: IC Organic Acids | DY34: None | EB34: IC Organic Acids | EC34: None | EF34: IC Organic Acids | EG34: None | EJ34: IC Organic Acids | EK34: None | EN34: IC Organic Acids | EO34: None | ER34: IC Organic Acids | ES34: None | EV34: LC-MS | EW34: None | EZ34: =CONCATENATE(A34,B34) | FA34: =CONCATENATE(SamplesX!A34,SamplesX!B34) | FC34: =MATCH(EZ34,FA1:FA1008,0)
