Workbook

Sheet extra_Hob
A1: Hob | B1: 2019
A2: Responsible: | B2: =HYPERLINK("mailto:bilbo.baggins@miskatonic.edu?subject=[Lab results]", "bilbo.baggins@miskatonic.edu")
A3: Samples: | B3: =HYPERLINK("C:\code\laboratoryspreadsheet\labspreadsheet\demo\remote_central\LabSamples2019.xlsx#Hob!A1","LabSamples2019.xlsx")
B4: =HYPERLINK("C:\code\laboratoryspreadsheet\labspreadsheet\demo\remote_Hobbit\LabSamples2019_Hob_extra.xlsx#extra_Hob!A1","LabSamples2019_Hob_extra.xlsx")
A5: Sample ID | C5: Site | G5: Sample | I5: SampleInfo | J5: Comment | K5: DOC | O5: TOC | S5: TIC | W5: Ntot | AA5: Cl | AE5: NO2-N | AI5: NO3-N | AM5: PO4-P | AQ5: SO4 | AU5: Na | AY5: NH4-N | BC5: K | BG5: Ca | BK5: Mg | BO5: Ptot | BS5: Urea | BW5: CODsol | CA5: CODtot | CE5: Alkalinity | CI5: Conductivity | CM5: pH | CQ5: Dissolved Oxygen | CU5: Turbidity | CY5: BOD5 | DC5: TSS | DG5: VSS | DK5: TCC | DO5: ICC | DS5: ATP | DW5: Nanodrop | EA5: TSS63 | EF5: ConcatID | EG5: ConcatID_X | EH5: ConcatID_Y | EI5: MatchX | EJ5: MatchY
A6: Project ID | B6: Number | C6: Room | D6: Area | E6: Setup | F6: Component | G6: Date | H6: Time | K6: Final value | L6: Method | M6: Filtration | N6: Dilution | O6: Final value | P6: Method | Q6: Filtration | R6: Dilution | S6: Final value | T6: Method | U6: Filtration | V6: Dilution | W6: Final value | X6: Method | Y6: Filtration | Z6: Dilution | AA6: Final value | AB6: Method | AC6: Filtration | AD6: Dilution | AE6: Final value | AF6: Method | AG6: Filtration | AH6: Dilution | AI6: Final value | AJ6: Method | AK6: Filtration | AL6: Dilution | AM6: Final value | AN6: Method | AO6: Filtration | AP6: Dilution | AQ6: Final value | AR6: Method | AS6: Filtration | AT6: Dilution | AU6: Final value | AV6: Method | AW6: Filtration | AX6: Dilution | AY6: Final value | AZ6: Method | BA6: Filtration | BB6: Dilution | BC6: Final value | BD6: Method | BE6: Filtration | BF6: Dilution | BG6: Final value | BH6: Method | BI6: Filtration | BJ6: Dilution | BK6: Final value | BL6: Method | BM6: Filtration | BN6: Dilution | BO6: Final value | BP6: Method | BQ6: Filtration | BR6: Dilution | BS6: Final value | BT6: Method | BU6: Filtration | BV6: Dilution | BW6: Final value | BX6: Method | BY6: Filtration | BZ6: Dilution | CA6: Final value | CB6: Method | CC6: Filtration | CD6: Dilution | CE6: Final value | CF6: Method | CG6: Filtration | CH6: Dilution | CI6: Final value | CJ6: Method | CK6: Filtration | CL6: Dilution | CM6: Final value | CN6: Method | CO6: Filtration | CP6: Dilution | CQ6: Final value | CR6: Method | CS6: Filtration | CT6: Dilution | CU6: Final value | CV6: Method | CW6: Filtration | CX6: Dilution | CY6: Final value | CZ6: Method | DA6: Filtration | DB6: Dilution | DC6: Final value | DD6: Method | DE6: Filtration | DF6: Dilution | DG6: Final value | DH6: Method | DI6: Filtration | DJ6: Dilution | DK6: Final value | DL6: Method | DM6: Filtration | DN6: Dilution | DO6: Final value | DP6: Method | DQ6: Filtration | DR6: Dilution | DS6: Final value | DT6: Method | DU6: Filtration | DV6: Dilution | DW6: Final value | DX6: Method | DY6: Filtration | DZ6: Dilution | EA6: Final value | EB6: Method | EC6: Filtration | ED6: Dilution
A7: [##] | B7: [yysss] | G7: [dd.mm.yyyy] | H7: [HH:MM:SS] | K7: mg/L | O7: mg/L | S7: mg/L | W7: mg/L | AA7: mg/L | AE7: mg/L | AI7: mg/L | AM7: mg/L | AQ7: mg/L | AU7: mg/L | AY7: mg/L | BC7: mg/L | BG7: mg/L | BK7: mg/L | BO7: mg/L | BS7: mgN/L | BW7: mg/L | CA7: mg/L | CE7: mmol/L | CI7: microS/cm | CM7: 1 | CQ7: mg/L | CU7: NTU | CY7: mg/L | DC7: mg/L | DG7: mg/L | DK7: #/mL | DO7: #/mL | DS7: gATP/gGAC | DW7: ng/ml | EA7: mg/L
A8: Text | B8: Text | C8: Dropdown | D8: Dropdown | E8: Dropdown | F8: Dropdown | G8: Text | H8: Text | K8: Text | L8: Dropdown | M8: Dropdown | N8: Text | O8: Text | P8: Dropdown | Q8: Dropdown | R8: Text | S8: Text | T8: Dropdown | U8: Dropdown | V8: Text | W8: Text | X8: Dropdown | Y8: Dropdown | Z8: Text | AA8: Text | AB8: Dropdown | AC8: Dropdown | AD8: Text | AE8: Text | AF8: Dropdown | AG8: Dropdown | AH8: Text | AI8: Text | AJ8: Dropdown | AK8: Dropdown | AL8: Text | AM8: Text | AN8: Dropdown | AO8: Dropdown | AP8: Text | AQ8: Text | AR8: Dropdown | AS8: Dropdown | AT8: Text | AU8: Text | AV8: Dropdown | AW8: Dropdown | AX8: Text | AY8: Text | AZ8: Dropdown | BA8: Dropdown | BB8: Text | BC8: Text | BD8: Dropdown | BE8: Dropdown | BF8: Text | BG8: Text | BH8: Dropdown | BI8: Dropdown | BJ8: Text | BK8: Text | BL8: Dropdown | BM8: Dropdown | BN8: Text | BO8: Text | BP8: Dropdown | BQ8: Dropdown | BR8: Text | BS8: Text | BT8: Dropdown | BU8: Dropdown | BV8: Text | BW8: Text | BX8: Dropdown | BY8: Dropdown | BZ8: Text | CA8: Text | CB8: Dropdown | CC8: Dropdown | CD8: Text | CE8: Text | CF8: Dropdown | CG8: Dropdown | CH8: Text | CI8: Text | CJ8: Dropdown | CK8: Dropdown | CL8: Text | CM8: Text | CN8: Dropdown | CO8: Dropdown | CP8: Text | CQ8: Text | CR8: Dropdown | CS8: Dropdown | CT8: Text | CU8: Text | CV8: Dropdown | CW8: Dropdown | CX8: Text | CY8: Text | CZ8: Dropdown | DA8: Dropdown | DB8: Text | DC8: Text | DD8: Dropdown | DE8: Dropdown | DF8: Text | DG8: Text | DH8: Dropdown | DI8: Dropdown | DJ8: Text | DK8: Text | DL8: Dropdown | DM8: Dropdown | DN8: Text | DO8: Text | DP8: Dropdown | DQ8: Dropdown | DR8: Text | DS8: Text | DT8: Dropdown | DU8: Dropdown | DV8: Text | DW8: Text | DX8: Dropdown | DY8: Dropdown | DZ8: Text | EA8: Text | EB8: Dropdown | EC8: Dropdown | ED8: Text
C9: =IF(ISNUMBER(EI9),INDIRECT("SamplesX!C"&EI9),IF(ISNUMBER(EJ9),INDIRECT("SamplesY!C"&EJ9),"")) | D9: =IF(ISNUMBER(EI9),INDIRECT("SamplesX!D"&EI9),IF(ISNUMBER(EJ9),INDIRECT("SamplesY!D"&EJ9),"")) | E9: =IF(ISNUMBER(EI9),INDIRECT("SamplesX!E"&EI9),IF(ISNUMBER(EJ9),INDIRECT("SamplesY!E"&EJ9),"")) | F9: =IF(ISNUMBER(EI9),INDIRECT("SamplesX!F"&EI9),IF(ISNUMBER(EJ9),INDIRECT("SamplesY!F"&EJ9),"")) | G9: =IF(ISNUMBER(EI9),INDIRECT("SamplesX!G"&EI9),IF(ISNUMBER(EJ9),INDIRECT("SamplesY!G"&EJ9),"")) | H9: =IF(ISNUMBER(EI9),INDIRECT("SamplesX!H"&EI9),IF(ISNUMBER(EJ9),INDIRECT("SamplesY!H"&EJ9),"")) | M9: None | P9: Shimadzu TOC-L | Q9: None | T9: Shimadzu TOC-L | U9: None | Y9: None | AB9: IC Anionen | AC9: None | AG9: None | AK9: None | AO9: None | AR9: IC Anionen | AS9: None | AV9: IC Kationen | AW9: None | BA9: None | BD9: IC Kationen | BE9: None | BH9: IC Kationen | BI9: None | BL9: IC Kationen | BM9: None | BQ9: None | BU9: None | BY9: None | CC9: None | CF9: Titration | CG9: None | CK9: None | CO9: None | CR9: WTW Multimeter 3430 with FDO 925 | CS9: None | CV9: HACH 2100AN IS Turbidimeter | CW9: None | CZ9: OxiTop | DA9: None | DD9: SOP 45-16 | DE9: None | DH9: SOP 45-16 | DI9: None | DL9: Flow Cytometry (SG) | DM9: None | DP9: Flow Cytometry (SG/PI) | DQ9: None | DT9: Luminometer | DU9: None | DX9: Nanodrop2000 | DY9: None | EB9: Retsch AS200 control | EC9: None | EF9: =CONCATENATE(A9,B9) | EG9: =CONCATENATE(SamplesX!A9,SamplesX!B9) | EH9: =CONCATENATE(SamplesY!A9,SamplesY!B9) | EI9: =MATCH(EF9,EG1:EG1008,0) | EJ9: =MATCH(EF9,EH1:EH1008,0)
C10: =IF(ISNUMBER(EI10),INDIRECT("SamplesX!C"&EI10),IF(ISNUMBER(EJ10),INDIRECT("SamplesY!C"&EJ10),"")) | D10: =IF(ISNUMBER(EI10),INDIRECT("SamplesX!D"&EI10),IF(ISNUMBER(EJ10),INDIRECT("SamplesY!D"&EJ10),"")) | E10: =IF(ISNUMBER(EI10),INDIRECT("SamplesX!E"&EI10),IF(ISNUMBER(EJ10),INDIRECT("SamplesY!E"&EJ10),"")) | F10: =IF(ISNUMBER(EI10),INDIRECT("SamplesX!F"&EI10),IF(ISNUMBER(EJ10),INDIRECT("SamplesY!F"&EJ10),"")) | G10: =IF(ISNUMBER(EI10),INDIRECT("SamplesX!G"&EI10),IF(ISNUMBER(EJ10),INDIRECT("SamplesY!G"&EJ10),"")) | H10: =IF(ISNUMBER(EI10),INDIRECT("SamplesX!H"&EI10),IF(ISNUMBER(EJ10),INDIRECT("SamplesY!H"&EJ10),"")) | M10: None | P10: Shimadzu TOC-L | Q10: None | T10: Shimadzu TOC-L | U10: None | Y10: None | AB10: IC Anionen | AC10: None | AG10: None | AK10: None | AO10: None | AR10: IC Anionen | AS10: None | AV10: IC Kationen | AW10: None | BA10: None | BD10: IC Kationen | BE10: None | BH10: IC Kationen | BI10: None | BL10: IC Kationen | BM10: None | BQ10: None | BU10: None | BY10: None | CC10: None | CF10: Titration | CG10: None | CK10: None | CO10: None | CR10: WTW Multimeter 3430 with FDO 925 | CS10: None | CV10: HACH 2100AN IS Turbidimeter | CW10: None | CZ10: OxiTop | DA10: None | DD10: SOP 45-16 | DE10: None | DH10: SOP 45-16 | DI10: None | DL10: Flow Cytometry (SG) | DM10: None | DP10: Flow Cytometry (SG/PI) | DQ10: None | DT10: Luminometer | DU10: None | DX10: Nanodrop2000 | DY10: None | EB10: Retsch AS200 control | EC10: None | EF10: =CONCATENATE(A10,B10) | EG10: =CONCATENATE(SamplesX!A10,SamplesX!B10) | EH10: =CONCATENATE(SamplesY!A10,SamplesY!B10) | EI10: =MATCH(EF10,EG1:EG1008,0) | EJ10: =MATCH(EF10,EH1:EH1008,0)
C11: =IF(ISNUMBER(EI11),INDIRECT("SamplesX!C"&EI11),IF(ISNUMBER(EJ11),INDIRECT("SamplesY!C"&EJ11),"")) | D11: =IF(ISNUMBER(EI11),INDIRECT("SamplesX!D"&EI11),IF(ISNUMBER(EJ11),INDIRECT("SamplesY!D"&EJ11),"")) | E11: =IF(ISNUMBER(EI11),INDIRECT("SamplesX!E"&EI11),IF(ISNUMBER(EJ11),INDIRECT("SamplesY!E"&EJ11),"")) | F11: =IF(ISNUMBER(EI11),INDIRECT("SamplesX!F"&EI11),IF(ISNUMBER(EJ11),INDIRECT("SamplesY!F"&EJ11),"")) | G11: =IF(ISNUMBER(EI11),INDIRECT("SamplesX!G"&EI11),IF(ISNUMBER(EJ11),INDIRECT("SamplesY!G"&EJ11),"")) | H11: =IF(ISNUMBER(EI11),INDIRECT("SamplesX!H"&EI11),IF(ISNUMBER(EJ11),INDIRECT("SamplesY!H"&EJ11),"")) | M11: None | P11: Shimadzu TOC-L | Q11: None | T11: Shimadzu TOC-L | U11: None | Y11: None | AB11: IC Anionen | AC11: None | AG11: None | AK11: None | AO11: None | AR11: IC Anionen | AS11: None | AV11: IC Kationen | AW11: None | BA11: None | BD11: IC Kationen | BE11: None | BH11: IC Kationen | BI11: None | BL11: IC Kationen | BM11: None | BQ11: None | BU11: None | BY11: None | CC11: None | CF11: Titration | CG11: None | CK11: None | CO11: None | CR11: WTW Multimeter 3430 with FDO 925 | CS11: None | CV11: HACH 2100AN IS Turbidimeter | CW11: None | CZ11: OxiTop | DA11: None | DD11: SOP 45-16 | DE11: None | DH11: SOP 45-16 | DI11: None | DL11: Flow Cytometry (SG) | DM11: None | DP11: Flow Cytometry (SG/PI) | DQ11: None | DT11: Luminometer | DU11: None | DX11: Nanodrop2000 | DY11: None | EB11: Retsch AS200 control | EC11: None | EF11: =CONCATENATE(A11,B11) | EG11: =CONCATENATE(SamplesX!A11,SamplesX!B11) | EH11: =CONCATENATE(SamplesY!A11,SamplesY!B11) | EI11: =MATCH(EF11,EG1:EG1008,0) | EJ11: =MATCH(EF11,EH1:EH1008,0)
C12: =IF(ISNUMBER(EI12),INDIRECT("SamplesX!C"&EI12),IF(ISNUMBER(EJ12),INDIRECT("SamplesY!C"&EJ12),"")) | D12: =IF(ISNUMBER(EI12),INDIRECT("SamplesX!D"&EI12),IF(ISNUMBER(EJ12),INDIRECT("SamplesY!D"&EJ12),"")) | E12: =IF(ISNUMBER(EI12),INDIRECT("SamplesX!E"&EI12),IF(ISNUMBER(EJ12),INDIRECT("SamplesY!E"&EJ12),"")) | F12: =IF(ISNUMBER(EI12),INDIRECT("SamplesX!F"&EI12),IF(ISNUMBER(EJ12),INDIRECT("SamplesY!F"&EJ12),"")) | G12: =IF(ISNUMBER(EI12),INDIRECT("SamplesX!G"&EI12),IF(ISNUMBER(EJ12),INDIRECT("SamplesY!G"&EJ12),"")) | H12: =IF(ISNUMBER(EI12),INDIRECT("SamplesX!H"&EI12),IF(ISNUMBER(EJ12),INDIRECT("SamplesY!H"&EJ12),"")) | M12: None | P12: Shimadzu TOC-L | Q12: None | T12: Shimadzu TOC-L | U12: None | Y12: None | AB12: IC Anionen | AC12: None | AG12: None | AK12: None | AO12: None | AR12: IC Anionen | AS12: None | AV12: IC Kationen | AW12: None | BA12: None | BD12: IC Kationen | BE12: None | BH12: IC Kationen | BI12: None | BL12: IC Kationen | BM12: None | BQ12: None | BU12: None | BY12: None | CC12: None | CF12: Titration | CG12: None | CK12: None | CO12: None | CR12: WTW Multimeter 3430 with FDO 925 | CS12: None | CV12: HACH 2100AN IS Turbidimeter | CW12: None | CZ12: OxiTop | DA12: None | DD12: SOP 45-16 | DE12: None | DH12: SOP 45-16 | DI12: None | DL12: Flow Cytometry (SG) | DM12: None | DP12: Flow Cytometry (SG/PI) | DQ12: None | DT12: Luminometer | DU12: None | DX12: Nanodrop2000 | DY12: None | EB12: Retsch AS200 control | EC12: None | EF12: =CONCATENATE(A12,B12) | EG12: =CONCATENATE(SamplesX!A12,SamplesX!B12) | EH12: =CONCATENATE(SamplesY!A12,SamplesY!B12) | EI12: =MATCH(EF12,EG1:EG1008,0) | EJ12: =MATCH(EF12,EH1:EH1008,0)
C13: =IF(ISNUMBER(EI13),INDIRECT("SamplesX!C"&EI13),IF(ISNUMBER(EJ13),INDIRECT("SamplesY!C"&EJ13),"")) | D13: =IF(ISNUMBER(EI13),INDIRECT("SamplesX!D"&EI13),IF(ISNUMBER(EJ13),INDIRECT("SamplesY!D"&EJ13),"")) | E13: =IF(ISNUMBER(EI13),INDIRECT("SamplesX!E"&EI13),IF(ISNUMBER(EJ13),INDIRECT("SamplesY!E"&EJ13),"")) | F13: =IF(ISNUMBER(EI13),INDIRECT("SamplesX!F"&EI13),IF(ISNUMBER(EJ13),INDIRECT("SamplesY!F"&EJ13),"")) | G13: =IF(ISNUMBER(EI13),INDIRECT("SamplesX!G"&EI13),IF(ISNUMBER(EJ13),INDIRECT("SamplesY!G"&EJ13),"")) | H13: =IF(ISNUMBER(EI13),INDIRECT("SamplesX!H"&EI13),IF(ISNUMBER(EJ13),INDIRECT("SamplesY!H"&EJ13),"")) | M13: None | P13: Shimadzu TOC-L | Q13: None | T13: Shimadzu TOC-L | U13: None | Y13: None | AB13: IC Anionen | AC13: None | AG13: None | AK13: None | AO13: None | AR13: IC Anionen | AS13: None | AV13: IC Kationen | AW13: None | BA13: None | BD13: IC Kationen | BE13: None | BH13: IC Kationen | BI13: None | BL13: IC Kationen | BM13: None | BQ13: None | BU13: None | BY13: None | CC13: None | CF13: Titration | CG13: None | CK13: None | CO13: None | CR13: WTW Multimeter 3430 with FDO 925 | CS13: None | CV13: HACH 2100AN IS Turbidimeter | CW13: None | CZ13: OxiTop | DA13: None | DD13: SOP 45-16 | DE13: None | DH13: SOP 45-16 | DI13: None | DL13: Flow Cytometry (SG) | DM13: None | DP13: Flow Cytometry (SG/PI) | DQ13: None | DT13: Luminometer | DU13: None | DX13: Nanodrop2000 | DY13: None | EB13: Retsch AS200 control | EC13: None | EF13: =CONCATENATE(A13,B13) | EG13: =CONCATENATE(SamplesX!A13,SamplesX!B13) | EH13: =CONCATENATE(SamplesY!A13,SamplesY!B13) | EI13: =MATCH(EF13,EG1:EG1008,0) | EJ13: =MATCH(EF13,EH1:EH1008,0)
C14: =IF(ISNUMBER(EI14),INDIRECT("SamplesX!C"&EI14),IF(ISNUMBER(EJ14),INDIRECT("SamplesY!C"&EJ14),"")) | D14: =IF(ISNUMBER(EI14),INDIRECT("SamplesX!D"&EI14),IF(ISNUMBER(EJ14),INDIRECT("SamplesY!D"&EJ14),"")) | E14: =IF(ISNUMBER(EI14),INDIRECT("SamplesX!E"&EI14),IF(ISNUMBER(EJ14),INDIRECT("SamplesY!E"&EJ14),"")) | F14: =IF(ISNUMBER(EI14),INDIRECT("SamplesX!F"&EI14),IF(ISNUMBER(EJ14),INDIRECT("SamplesY!F"&EJ14),"")) | G14: =IF(ISNUMBER(EI14),INDIRECT("SamplesX!G"&EI14),IF(ISNUMBER(EJ14),INDIRECT("SamplesY!G"&EJ14),"")) | H14: =IF(ISNUMBER(EI14),INDIRECT("SamplesX!H"&EI14),IF(ISNUMBER(EJ14),INDIRECT("SamplesY!H"&EJ14),"")) | M14: None | P14: Shimadzu TOC-L | Q14: None | T14: Shimadzu TOC-L | U14: None | Y14: None | AB14: IC Anionen | AC14: None | AG14: None | AK14: None | AO14: None | AR14: IC Anionen | AS14: None | AV14: IC Kationen | AW14: None | BA14: None | BD14: IC Kationen | BE14: None | BH14: IC Kationen | BI14: None | BL14: IC Kationen | BM14: None | BQ14: None | BU14: None | BY14: None | CC14: None | CF14: Titration | CG14: None | CK14: None | CO14: None | CR14: WTW Multimeter 3430 with FDO 925 | CS14: None | CV14: HACH 2100AN IS Turbidimeter | CW14: None | CZ14: OxiTop | DA14: None | DD14: SOP 45-16 | DE14: None | DH14: SOP 45-16 | DI14: None | DL14: Flow Cytometry (SG) | DM14: None | DP14: Flow Cytometry (SG/PI) | DQ14: None | DT14: Luminometer | DU14: None | DX14: Nanodrop2000 | DY14: None | EB14: Retsch AS200 control | EC14: None | EF14: =CONCATENATE(A14,B14) | EG14: =CONCATENATE(SamplesX!A14,SamplesX!B14) | EH14: =CONCATENATE(SamplesY!A14,SamplesY!B14) | EI14: =MATCH(EF14,EG1:EG1008,0) | EJ14: =MATCH(EF14,EH1:EH1008,0)
C15: =IF(ISNUMBER(EI15),INDIRECT("SamplesX!C"&EI15),IF(ISNUMBER(EJ15),INDIRECT("SamplesY!C"&EJ15),"")) | D15: =IF(ISNUMBER(EI15),INDIRECT("SamplesX!D"&EI15),IF(ISNUMBER(EJ15),INDIRECT("SamplesY!D"&EJ15),"")) | E15: =IF(ISNUMBER(EI15),INDIRECT("SamplesX!E"&EI15),IF(ISNUMBER(EJ15),INDIRECT("SamplesY!E"&EJ15),"")) | F15: =IF(ISNUMBER(EI15),INDIRECT("SamplesX!F"&EI15),IF(ISNUMBER(EJ15),INDIRECT("SamplesY!F"&EJ15),"")) | G15: =IF(ISNUMBER(EI15),INDIRECT("SamplesX!G"&EI15),IF(ISNUMBER(EJ15),INDIRECT("SamplesY!G"&EJ15),"")) | H15: =IF(ISNUMBER(EI15),INDIRECT("SamplesX!H"&EI15),IF(ISNUMBER(EJ15),INDIRECT("SamplesY!H"&EJ15),"")) | M15: None | P15: Shimadzu TOC-L | Q15: None | T15: Shimadzu TOC-L | U15: None | Y15: None | AB15: IC Anionen | AC15: None | AG15: None | AK15: None | AO15: None | AR15: IC Anionen | AS15: None | AV15: IC Kationen | AW15: None | BA15: None | BD15: IC Kationen | BE15: None | BH15: IC Kationen | BI15: None | BL15: IC Kationen | BM15: None | BQ15: None | BU15: None | BY15: None | CC15: None | CF15: Titration | CG15: None | CK15: None | CO15: None | CR15: WTW Multimeter 3430 with FDO 925 | CS15: None | CV15: HACH 2100AN IS Turbidimeter | CW15: None | CZ15: OxiTop | DA15: None | DD15: SOP 45-16 | DE15: None | DH15: SOP 45-16 | DI15: None | DL15: Flow Cytometry (SG) | DM15: None | DP15: Flow Cytometry (SG/PI) | DQ15: None | DT15: Luminometer | DU15: None | DX15: Nanodrop2000 | DY15: None | EB15: Retsch AS200 control | EC15: None | EF15: =CONCATENATE(A15,B15) | EG15: =CONCATENATE(SamplesX!A15,SamplesX!B15) | EH15: =CONCATENATE(SamplesY!A15,SamplesY!B15) | EI15: =MATCH(EF15,EG1:EG1008,0) | EJ15: =MATCH(EF15,EH1:EH1008,0)
C16: =IF(ISNUMBER(EI16),INDIRECT("SamplesX!C"&EI16),IF(ISNUMBER(EJ16),INDIRECT("SamplesY!C"&EJ16),"")) | D16: =IF(ISNUMBER(EI16),INDIRECT("SamplesX!D"&EI16),IF(ISNUMBER(EJ16),INDIRECT("SamplesY!D"&EJ16),"")) | E16: =IF(ISNUMBER(EI16),INDIRECT("SamplesX!E"&EI16),IF(ISNUMBER(EJ16),INDIRECT("SamplesY!E"&EJ16),"")) | F16: =IF(ISNUMBER(EI16),INDIRECT("SamplesX!F"&EI16),IF(ISNUMBER(EJ16),INDIRECT("SamplesY!F"&EJ16),"")) | G16: =IF(ISNUMBER(EI16),INDIRECT("SamplesX!G"&EI16),IF(ISNUMBER(EJ16),INDIRECT("SamplesY!G"&EJ16),"")) | H16: =IF(ISNUMBER(EI16),INDIRECT("SamplesX!H"&EI16),IF(ISNUMBER(EJ16),INDIRECT("SamplesY!H"&EJ16),"")) | M16: None | P16: Shimadzu TOC-L | Q16: None | T16: Shimadzu TOC-L | U16: None | Y16: None | AB16: IC Anionen | AC16: None | AG16: None | AK16: None | AO16: None | AR16: IC Anionen | AS16: None | AV16: IC Kationen | AW16: None | BA16: None | BD16: IC Kationen | BE16: None | BH16: IC Kationen | BI16: None | BL16: IC Kationen | BM16: None | BQ16: None | BU16: None | BY16: None | CC16: None | CF16: Titration | CG16: None | CK16: None | CO16: None | CR16: WTW Multimeter 3430 with FDO 925 | CS16: None | CV16: HACH 2100AN IS Turbidimeter | CW16: None | CZ16: OxiTop | DA16: None | DD16: SOP 45-16 | DE16: None | DH16: SOP 45-16 | DI16: None | DL16: Flow Cytometry (SG) | DM16: None | DP16: Flow Cytometry (SG/PI) | DQ16: None | DT16: Luminometer | DU16: None | DX16: Nanodrop2000 | DY16: None | EB16: Retsch AS200 control | EC16: None | EF16: =CONCATENATE(A16,B16) | EG16: =CONCATENATE(SamplesX!A16,SamplesX!B16) | EH16: =CONCATENATE(SamplesY!A16,SamplesY!B16) | EI16: =MATCH(EF16,EG1:EG1008,0) | EJ16: =MATCH(EF16,EH1:EH1008,0)
C17: =IF(ISNUMBER(EI17),INDIRECT("SamplesX!C"&EI17),IF(ISNUMBER(EJ17),INDIRECT("SamplesY!C"&EJ17),"")) | D17: =IF(ISNUMBER(EI17),INDIRECT("SamplesX!D"&EI17),IF(ISNUMBER(EJ17),INDIRECT("SamplesY!D"&EJ17),"")) | E17: =IF(ISNUMBER(EI17),INDIRECT("SamplesX!E"&EI17),IF(ISNUMBER(EJ17),INDIRECT("SamplesY!E"&EJ17),"")) | F17: =IF(ISNUMBER(EI17),INDIRECT("SamplesX!F"&EI17),IF(ISNUMBER(EJ17),INDIRECT("SamplesY!F"&EJ17),"")) | G17: =IF(ISNUMBER(EI17),INDIRECT("SamplesX!G"&EI17),IF(ISNUMBER(EJ17),INDIRECT("SamplesY!G"&EJ17),"")) | H17: =IF(ISNUMBER(EI17),INDIRECT("SamplesX!H"&EI17),IF(ISNUMBER(EJ17),INDIRECT("SamplesY!H"&EJ17),"")) | M17: None | P17: Shimadzu TOC-L | Q17: None | T17: Shimadzu TOC-L | U17: None | Y17: None | AB17: IC Anionen | AC17: None | AG17: None | AK17: None | AO17: None | AR17: IC Anionen | AS17: None | AV17: IC Kationen | AW17: None | BA17: None | BD17: IC Kationen | BE17: None | BH17: IC Kationen | BI17: None | BL17: IC Kationen | BM17: None | BQ17: None | BU17: None | BY17: None | CC17: None | CF17: Titration | CG17: None | CK17: None | CO17: None | CR17: WTW Multimeter 3430 with FDO 925 | CS17: None | CV17: HACH 2100AN IS Turbidimeter | CW17: None | CZ17: OxiTop | DA17: None | DD17: SOP 45-16 | DE17: None | DH17: SOP 45-16 | DI17: None | DL17: Flow Cytometry (SG) | DM17: None | DP17: Flow Cytometry (SG/PI) | DQ17: None | DT17: Luminometer | DU17: None | DX17: Nanodrop2000 | DY17: None | EB17: Retsch AS200 control | EC17: None | EF17: =CONCATENATE(A17,B17) | EG17: =CONCATENATE(SamplesX!A17,SamplesX!B17) | EH17: =CONCATENATE(SamplesY!A17,SamplesY!B17) | EI17: =MATCH(EF17,EG1:EG1008,0) | EJ17: =MATCH(EF17,EH1:EH1008,0)
C18: =IF(ISNUMBER(EI18),INDIRECT("SamplesX!C"&EI18),IF(ISNUMBER(EJ18),INDIRECT("SamplesY!C"&EJ18),"")) | D18: =IF(ISNUMBER(EI18),INDIRECT("SamplesX!D"&EI18),IF(ISNUMBER(EJ18),INDIRECT("SamplesY!D"&EJ18),"")) | E18: =IF(ISNUMBER(EI18),INDIRECT("SamplesX!E"&EI18),IF(ISNUMBER(EJ18),INDIRECT("SamplesY!E"&EJ18),"")) | F18: =IF(ISNUMBER(EI18),INDIRECT("SamplesX!F"&EI18),IF(ISNUMBER(EJ18),INDIRECT("SamplesY!F"&EJ18),"")) | G18: =IF(ISNUMBER(EI18),INDIRECT("SamplesX!G"&EI18),IF(ISNUMBER(EJ18),INDIRECT("SamplesY!G"&EJ18),"")) | H18: =IF(ISNUMBER(EI18),INDIRECT("SamplesX!H"&EI18),IF(ISNUMBER(EJ18),INDIRECT("SamplesY!H"&EJ18),"")) | M18: None | P18: Shimadzu TOC-L | Q18: None | T18: Shimadzu TOC-L | U18: None | Y18: None | AB18: IC Anionen | AC18: None | AG18: None | AK18: None | AO18: None | AR18: IC Anionen | AS18: None | AV18: IC Kationen | AW18: None | BA18: None | BD18: IC Kationen | BE18: None | BH18: IC Kationen | BI18: None | BL18: IC Kationen | BM18: None | BQ18: None | BU18: None | BY18: None | CC18: None | CF18: Titration | CG18: None | CK18: None | CO18: None | CR18: WTW Multimeter 3430 with FDO 925 | CS18: None | CV18: HACH 2100AN IS Turbidimeter | CW18: None | CZ18: OxiTop | DA18: None | DD18: SOP 45-16 | DE18: None | DH18: SOP 45-16 | DI18: None | DL18: Flow Cytometry (SG) | DM18: None | DP18: Flow Cytometry (SG/PI) | DQ18: None | DT18: Luminometer | DU18: None | DX18: Nanodrop2000 | DY18: None | EB18: Retsch AS200 control | EC18: None | EF18: =CONCATENATE(A18,B18) | EG18: =CONCATENATE(SamplesX!A18,SamplesX!B18) | EH18: =CONCATENATE(SamplesY!A18,SamplesY!B18) | EI18: =MATCH(EF18,EG1:EG1008,0) | EJ18: =MATCH(EF18,EH1:EH1008,0)
C19: =IF(ISNUMBER(EI19),INDIRECT("SamplesX!C"&EI19),IF(ISNUMBER(EJ19),INDIRECT("SamplesY!C"&EJ19),"")) | D19: =IF(ISNUMBER(EI19),INDIRECT("SamplesX!D"&EI19),IF(ISNUMBER(EJ19),INDIRECT("SamplesY!D"&EJ19),"")) | E19: =IF(ISNUMBER(EI19),INDIRECT("SamplesX!E"&EI19),IF(ISNUMBER(EJ19),INDIRECT("SamplesY!E"&EJ19),"")) | F19: =IF(ISNUMBER(EI19),INDIRECT("SamplesX!F"&EI19),IF(ISNUMBER(EJ19),INDIRECT("SamplesY!F"&EJ19),"")) | G19: =IF(ISNUMBER(EI19),INDIRECT("SamplesX!G"&EI19),IF(ISNUMBER(EJ19),INDIRECT("SamplesY!G"&EJ19),"")) | H19: =IF(ISNUMBER(EI19),INDIRECT("SamplesX!H"&EI19),IF(ISNUMBER(EJ19),INDIRECT("SamplesY!H"&EJ19),"")) | M19: None | P19: Shimadzu TOC-L | Q19: None | T19: Shimadzu TOC-L | U19: None | Y19: None | AB19: IC Anionen | AC19: None | AG19: None | AK19: None | AO19: None | AR19: IC Anionen | AS19: None | AV19: IC Kationen | AW19: None | BA19: None | BD19: IC Kationen | BE19: None | BH19: IC Kationen | BI19: None | BL19: IC Kationen | BM19: None | BQ19: None | BU19: None | BY19: None | CC19: None | CF19: Titration | CG19: None | CK19: None | CO19: None | CR19: WTW Multimeter 3430 with FDO 925 | CS19: None | CV19: HACH 2100AN IS Turbidimeter | CW19: None | CZ19: OxiTop | DA19: None | DD19: SOP 45-16 | DE19: None | DH19: SOP 45-16 | DI19: None | DL19: Flow Cytometry (SG) | DM19: None | DP19: Flow Cytometry (SG/PI) | DQ19: None | DT19: Luminometer | DU19: None | DX19: Nanodrop2000 | DY19: None | EB19: Retsch AS200 control | EC19: None | EF19: =CONCATENATE(A19,B19) | EG19: =CONCATENATE(SamplesX!A19,SamplesX!B19) | EH19: =CONCATENATE(SamplesY!A19,SamplesY!B19) | EI19: =MATCH(EF19,EG1:EG1008,0) | EJ19: =MATCH(EF19,EH1:EH1008,0)
C20: =IF(ISNUMBER(EI20),INDIRECT("SamplesX!C"&EI20),IF(ISNUMBER(EJ20),INDIRECT("SamplesY!C"&EJ20),"")) | D20: =IF(ISNUMBER(EI20),INDIRECT("SamplesX!D"&EI20),IF(ISNUMBER(EJ20),INDIRECT("SamplesY!D"&EJ20),"")) | E20: =IF(ISNUMBER(EI20),INDIRECT("SamplesX!E"&EI20),IF(ISNUMBER(EJ20),INDIRECT("SamplesY!E"&EJ20),"")) | F20: =IF(ISNUMBER(EI20),INDIRECT("SamplesX!F"&EI20),IF(ISNUMBER(EJ20),INDIRECT("SamplesY!F"&EJ20),"")) | G20: =IF(ISNUMBER(EI20),INDIRECT("SamplesX!G"&EI20),IF(ISNUMBER(EJ20),INDIRECT("SamplesY!G"&EJ20),"")) | H20: =IF(ISNUMBER(EI20),INDIRECT("SamplesX!H"&EI20),IF(ISNUMBER(EJ20),INDIRECT("SamplesY!H"&EJ20),"")) | M20: None | P20: Shimadzu TOC-L | Q20: None | T20: Shimadzu TOC-L | U20: None | Y20: None | AB20: IC Anionen | AC20: None | AG20: None | AK20: None | AO20: None | AR20: IC Anionen | AS20: None | AV20: IC Kationen | AW20: None | BA20: None | BD20: IC Kationen | BE20: None | BH20: IC Kationen | BI20: None | BL20: IC Kationen | BM20: None | BQ20: None | BU20: None | BY20: None | CC20: None | CF20: Titration | CG20: None | CK20: None | CO20: None | CR20: WTW Multimeter 3430 with FDO 925 | CS20: None | CV20: HACH 2100AN IS Turbidimeter | CW20: None | CZ20: OxiTop | DA20: None | DD20: SOP 45-16 | DE20: None | DH20: SOP 45-16 | DI20: None | DL20: Flow Cytometry (SG) | DM20: None | DP20: Flow Cytometry (SG/PI) | DQ20: None | DT20: Luminometer | DU20: None | DX20: Nanodrop2000 | DY20: None | EB20: Retsch AS200 control | EC20: None | EF20: =CONCATENATE(A20,B20) | EG20: =CONCATENATE(SamplesX!A20,SamplesX!B20) | EH20: =CONCATENATE(SamplesY!A20,SamplesY!B20) | EI20: =MATCH(EF20,EG1:EG1008,0) | EJ20: =MATCH(EF20,EH1:EH1008,0)
C21: =IF(ISNUMBER(EI21),INDIRECT("SamplesX!C"&EI21),IF(ISNUMBER(EJ21),INDIRECT("SamplesY!C"&EJ21),"")) | D21: =IF(ISNUMBER(EI21),INDIRECT("SamplesX!D"&EI21),IF(ISNUMBER(EJ21),INDIRECT("SamplesY!D"&EJ21),"")) | E21: =IF(ISNUMBER(EI21),INDIRECT("SamplesX!E"&EI21),IF(ISNUMBER(EJ21),INDIRECT("SamplesY!E"&EJ21),"")) | F21: =IF(ISNUMBER(EI21),INDIRECT("SamplesX!F"&EI21),IF(ISNUMBER(EJ21),INDIRECT("SamplesY!F"&EJ21),"")) | G21: =IF(ISNUMBER(EI21),INDIRECT("SamplesX!G"&EI21),IF(ISNUMBER(EJ21),INDIRECT("SamplesY!G"&EJ21),"")) | H21: =IF(ISNUMBER(EI21),INDIRECT("SamplesX!H"&EI21),IF(ISNUMBER(EJ21),INDIRECT("SamplesY!H"&EJ21),"")) | M21: None | P21: Shimadzu TOC-L | Q21: None | T21: Shimadzu TOC-L | U21: None | Y21: None | AB21: IC Anionen | AC21: None | AG21: None | AK21: None | AO21: None | AR21: IC Anionen | AS21: None | AV21: IC Kationen | AW21: None | BA21: None | BD21: IC Kationen | BE21: None | BH21: IC Kationen | BI21: None | BL21: IC Kationen | BM21: None | BQ21: None | BU21: None | BY21: None | CC21: None | CF21: Titration | CG21: None | CK21: None | CO21: None | CR21: WTW Multimeter 3430 with FDO 925 | CS21: None | CV21: HACH 2100AN IS Turbidimeter | CW21: None | CZ21: OxiTop | DA21: None | DD21: SOP 45-16 | DE21: None | DH21: SOP 45-16 | DI21: None | DL21: Flow Cytometry (SG) | DM21: None | DP21: Flow Cytometry (SG/PI) | DQ21: None | DT21: Luminometer | DU21: None | DX21: Nanodrop2000 | DY21: None | EB21: Retsch AS200 control | EC21: None | EF21: =CONCATENATE(A21,B21) | EG21: =CONCATENATE(SamplesX!A21,SamplesX!B21) | EH21: =CONCATENATE(SamplesY!A21,SamplesY!B21) | EI21: =MATCH(EF21,EG1:EG1008,0) | EJ21: =MATCH(EF21,EH1:EH1008,0)
C22: =IF(ISNUMBER(EI22),INDIRECT("SamplesX!C"&EI22),IF(ISNUMBER(EJ22),INDIRECT("SamplesY!C"&EJ22),"")) | D22: =IF(ISNUMBER(EI22),INDIRECT("SamplesX!D"&EI22),IF(ISNUMBER(EJ22),INDIRECT("SamplesY!D"&EJ22),"")) | E22: =IF(ISNUMBER(EI22),INDIRECT("SamplesX!E"&EI22),IF(ISNUMBER(EJ22),INDIRECT("SamplesY!E"&EJ22),"")) | F22: =IF(ISNUMBER(EI22),INDIRECT("SamplesX!F"&EI22),IF(ISNUMBER(EJ22),INDIRECT("SamplesY!F"&EJ22),"")) | G22: =IF(ISNUMBER(EI22),INDIRECT("SamplesX!G"&EI22),IF(ISNUMBER(EJ22),INDIRECT("SamplesY!G"&EJ22),"")) | H22: =IF(ISNUMBER(EI22),INDIRECT("SamplesX!H"&EI22),IF(ISNUMBER(EJ22),INDIRECT("SamplesY!H"&EJ22),"")) | M22: None | P22: Shimadzu TOC-L | Q22: None | T22: Shimadzu TOC-L | U22: None | Y22: None | AB22: IC Anionen | AC22: None | AG22: None | AK22: None | AO22: None | AR22: IC Anionen | AS22: None | AV22: IC Kationen | AW22: None | BA22: None | BD22: IC Kationen | BE22: None | BH22: IC Kationen | BI22: None | BL22: IC Kationen | BM22: None | BQ22: None | BU22: None | BY22: None | CC22: None | CF22: Titration | CG22: None | CK22: None | CO22: None | CR22: WTW Multimeter 3430 with FDO 925 | CS22: None | CV22: HACH 2100AN IS Turbidimeter | CW22: None | CZ22: OxiTop | DA22: None | DD22: SOP 45-16 | DE22: None | DH22: SOP 45-16 | DI22: None | DL22: Flow Cytometry (SG) | DM22: None | DP22: Flow Cytometry (SG/PI) | DQ22: None | DT22: Luminometer | DU22: None | DX22: Nanodrop2000 | DY22: None | EB22: Retsch AS200 control | EC22: None | EF22: =CONCATENATE(A22,B22) | EG22: =CONCATENATE(SamplesX!A22,SamplesX!B22) | EH22: =CONCATENATE(SamplesY!A22,SamplesY!B22) | EI22: =MATCH(EF22,EG1:EG1008,0) | EJ22: =MATCH(EF22,EH1:EH1008,0)
C23: =IF(ISNUMBER(EI23),INDIRECT("SamplesX!C"&EI23),IF(ISNUMBER(EJ23),INDIRECT("SamplesY!C"&EJ23),"")) | D23: =IF(ISNUMBER(EI23),INDIRECT("SamplesX!D"&EI23),IF(ISNUMBER(EJ23),INDIRECT("SamplesY!D"&EJ23),"")) | E23: =IF(ISNUMBER(EI23),INDIRECT("SamplesX!E"&EI23),IF(ISNUMBER(EJ23),INDIRECT("SamplesY!E"&EJ23),"")) | F23: =IF(ISNUMBER(EI23),INDIRECT("SamplesX!F"&EI23),IF(ISNUMBER(EJ23),INDIRECT("SamplesY!F"&EJ23),"")) | G23: =IF(ISNUMBER(EI23),INDIRECT("SamplesX!G"&EI23),IF(ISNUMBER(EJ23),INDIRECT("SamplesY!G"&EJ23),"")) | H23: =IF(ISNUMBER(EI23),INDIRECT("SamplesX!H"&EI23),IF(ISNUMBER(EJ23),INDIRECT("SamplesY!H"&EJ23),"")) | M23: None | P23: Shimadzu TOC-L | Q23: None | T23: Shimadzu TOC-L | U23: None | Y23: None | AB23: IC Anionen | AC23: None | AG23: None | AK23: None | AO23: None | AR23: IC Anionen | AS23: None | AV23: IC Kationen | AW23: None | BA23: None | BD23: IC Kationen | BE23: None | BH23: IC Kationen | BI23: None | BL23: IC Kationen | BM23: None | BQ23: None | BU23: None | BY23: None | CC23: None | CF23: Titration | CG23: None | CK23: None | CO23: None | CR23: WTW Multimeter 3430 with FDO 925 | CS23: None | CV23: HACH 2100AN IS Turbidimeter | CW23: None | CZ23: OxiTop | DA23: None | DD23: SOP 45-16 | DE23: None | DH23: SOP 45-16 | DI23: None | DL23: Flow Cytometry (SG) | DM23: None | DP23: Flow Cytometry (SG/PI) | DQ23: None | DT23: Luminometer | DU23: None | DX23: Nanodrop2000 | DY23: None | EB23: Retsch AS200 control | EC23: None | EF23: =CONCATENATE(A23,B23) | EG23: =CONCATENATE(SamplesX!A23,SamplesX!B23) | EH23: =CONCATENATE(SamplesY!A23,SamplesY!B23) | EI23: =MATCH(EF23,EG1:EG1008,0) | EJ23: =MATCH(EF23,EH1:EH1008,0)
C24: =IF(ISNUMBER(EI24),INDIRECT("SamplesX!C"&EI24),IF(ISNUMBER(EJ24),INDIRECT("SamplesY!C"&EJ24),"")) | D24: =IF(ISNUMBER(EI24),INDIRECT("SamplesX!D"&EI24),IF(ISNUMBER(EJ24),INDIRECT("SamplesY!D"&EJ24),"")) | E24: =IF(ISNUMBER(EI24),INDIRECT("SamplesX!E"&EI24),IF(ISNUMBER(EJ24),INDIRECT("SamplesY!E"&EJ24),"")) | F24: =IF(ISNUMBER(EI24),INDIRECT("SamplesX!F"&EI24),IF(ISNUMBER(EJ24),INDIRECT("SamplesY!F"&EJ24),"")) | G24: =IF(ISNUMBER(EI24),INDIRECT("SamplesX!G"&EI24),IF(ISNUMBER(EJ24),INDIRECT("SamplesY!G"&EJ24),"")) | H24: =IF(ISNUMBER(EI24),INDIRECT("SamplesX!H"&EI24),IF(ISNUMBER(EJ24),INDIRECT("SamplesY!H"&EJ24),"")) | M24: None | P24: Shimadzu TOC-L | Q24: None | T24: Shimadzu TOC-L | U24: None | Y24: None | AB24: IC Anionen | AC24: None | AG24: None | AK24: None | AO24: None | AR24: IC Anionen | AS24: None | AV24: IC Kationen | AW24: None | BA24: None | BD24: IC Kationen | BE24: None | BH24: IC Kationen | BI24: None | BL24: IC Kationen | BM24: None | BQ24: None | BU24: None | BY24: None | CC24: None | CF24: Titration | CG24: None | CK24: None | CO24: None | CR24: WTW Multimeter 3430 with FDO 925 | CS24: None | CV24: HACH 2100AN IS Turbidimeter | CW24: None | CZ24: OxiTop | DA24: None | DD24: SOP 45-16 | DE24: None | DH24: SOP 45-16 | DI24: None | DL24: Flow Cytometry (SG) | DM24: None | DP24: Flow Cytometry (SG/PI) | DQ24: None | DT24: Luminometer | DU24: None | DX24: Nanodrop2000 | DY24: None | EB24: Retsch AS200 control | EC24: None | EF24: =CONCATENATE(A24,B24) | EG24: =CONCATENATE(SamplesX!A24,SamplesX!B24) | EH24: =CONCATENATE(SamplesY!A24,SamplesY!B24) | EI24: =MATCH(EF24,EG1:EG1008,0) | EJ24: =MATCH(EF24,EH1:EH1008,0)
C25: =IF(ISNUMBER(EI25),INDIRECT("SamplesX!C"&EI25),IF(ISNUMBER(EJ25),INDIRECT("SamplesY!C"&EJ25),"")) | D25: =IF(ISNUMBER(EI25),INDIRECT("SamplesX!D"&EI25),IF(ISNUMBER(EJ25),INDIRECT("SamplesY!D"&EJ25),"")) | E25: =IF(ISNUMBER(EI25),INDIRECT("SamplesX!E"&EI25),IF(ISNUMBER(EJ25),INDIRECT("SamplesY!E"&EJ25),"")) | F25: =IF(ISNUMBER(EI25),INDIRECT("SamplesX!F"&EI25),IF(ISNUMBER(EJ25),INDIRECT("SamplesY!F"&EJ25),"")) | G25: =IF(ISNUMBER(EI25),INDIRECT("SamplesX!G"&EI25),IF(ISNUMBER(EJ25),INDIRECT("SamplesY!G"&EJ25),"")) | H25: =IF(ISNUMBER(EI25),INDIRECT("SamplesX!H"&EI25),IF(ISNUMBER(EJ25),INDIRECT("SamplesY!H"&EJ25),"")) | M25: None | P25: Shimadzu TOC-L | Q25: None | T25: Shimadzu TOC-L | U25: None | Y25: None | AB25: IC Anionen | AC25: None | AG25: None | AK25: None | AO25: None | AR25: IC Anionen | AS25: None | AV25: IC Kationen | AW25: None | BA25: None | BD25: IC Kationen | BE25: None | BH25: IC Kationen | BI25: None | BL25: IC Kationen | BM25: None | BQ25: None | BU25: None | BY25: None | CC25: None | CF25: Titration | CG25: None | CK25: None | CO25: None | CR25: WTW Multimeter 3430 with FDO 925 | CS25: None | CV25: HACH 2100AN IS Turbidimeter | CW25: None | CZ25: OxiTop | DA25: None | DD25: SOP 45-16 | DE25: None | DH25: SOP 45-16 | DI25: None | DL25: Flow Cytometry (SG) | DM25: None | DP25: Flow Cytometry (SG/PI) | DQ25: None | DT25: Luminometer | DU25: None | DX25: Nanodrop2000 | DY25: None | EB25: Retsch AS200 control | EC25: None | EF25: =CONCATENATE(A25,B25) | EG25: =CONCATENATE(SamplesX!A25,SamplesX!B25) | EH25: =CONCATENATE(SamplesY!A25,SamplesY!B25) | EI25: =MATCH(EF25,EG1:EG1008,0) | EJ25: =MATCH(EF25,EH1:EH1008,0)
C26: =IF(ISNUMBER(EI26),INDIRECT("SamplesX!C"&EI26),IF(ISNUMBER(EJ26),INDIRECT("SamplesY!C"&EJ26),"")) | D26: =IF(ISNUMBER(EI26),INDIRECT("SamplesX!D"&EI26),IF(ISNUMBER(EJ26),INDIRECT("SamplesY!D"&EJ26),"")) | E26: =IF(ISNUMBER(EI26),INDIRECT("SamplesX!E"&EI26),IF(ISNUMBER(EJ26),INDIRECT("SamplesY!E"&EJ26),"")) | F26: =IF(ISNUMBER(EI26),INDIRECT("SamplesX!F"&EI26),IF(ISNUMBER(EJ26),INDIRECT("SamplesY!F"&EJ26),"")) | G26: =IF(ISNUMBER(EI26),INDIRECT("SamplesX!G"&EI26),IF(ISNUMBER(EJ26),INDIRECT("SamplesY!G"&EJ26),"")) | H26: =IF(ISNUMBER(EI26),INDIRECT("SamplesX!H"&EI26),IF(ISNUMBER(EJ26),INDIRECT("SamplesY!H"&EJ26),"")) | M26: None | P26: Shimadzu TOC-L | Q26: None | T26: Shimadzu TOC-L | U26: None | Y26: None | AB26: IC Anionen | AC26: None | AG26: None | AK26: None | AO26: None | AR26: IC Anionen | AS26: None | AV26: IC Kationen | AW26: None | BA26: None | BD26: IC Kationen | BE26: None | BH26: IC Kationen | BI26: None | BL26: IC Kationen | BM26: None | BQ26: None | BU26: None | BY26: None | CC26: None | CF26: Titration | CG26: None | CK26: None | CO26: None | CR26: WTW Multimeter 3430 with FDO 925 | CS26: None | CV26: HACH 2100AN IS Turbidimeter | CW26: None | CZ26: OxiTop | DA26: None | DD26: SOP 45-16 | DE26: None | DH26: SOP 45-16 | DI26: None | DL26: Flow Cytometry (SG) | DM26: None | DP26: Flow Cytometry (SG/PI) | DQ26: None | DT26: Luminometer | DU26: None | DX26: Nanodrop2000 | DY26: None | EB26: Retsch AS200 control | EC26: None | EF26: =CONCATENATE(A26,B26) | EG26: =CONCATENATE(SamplesX!A26,SamplesX!B26) | EH26: =CONCATENATE(SamplesY!A26,SamplesY!B26) | EI26: =MATCH(EF26,EG1:EG1008,0) | EJ26: =MATCH(EF26,EH1:EH1008,0)
C27: =IF(ISNUMBER(EI27),INDIRECT("SamplesX!C"&EI27),IF(ISNUMBER(EJ27),INDIRECT("SamplesY!C"&EJ27),"")) | D27: =IF(ISNUMBER(EI27),INDIRECT("SamplesX!D"&EI27),IF(ISNUMBER(EJ27),INDIRECT("SamplesY!D"&EJ27),"")) | E27: =IF(ISNUMBER(EI27),INDIRECT("SamplesX!E"&EI27),IF(ISNUMBER(EJ27),INDIRECT("SamplesY!E"&EJ27),"")) | F27: =IF(ISNUMBER(EI27),INDIRECT("SamplesX!F"&EI27),IF(ISNUMBER(EJ27),INDIRECT("SamplesY!F"&EJ27),"")) | G27: =IF(ISNUMBER(EI27),INDIRECT("SamplesX!G"&EI27),IF(ISNUMBER(EJ27),INDIRECT("SamplesY!G"&EJ27),"")) | H27: =IF(ISNUMBER(EI27),INDIRECT("SamplesX!H"&EI27),IF(ISNUMBER(EJ27),INDIRECT("SamplesY!H"&EJ27),"")) | M27: None | P27: Shimadzu TOC-L | Q27: None | T27: Shimadzu TOC-L | U27: None | Y27: None | AB27: IC Anionen | AC27: None | AG27: None | AK27: None | AO27: None | AR27: IC Anionen | AS27: None | AV27: IC Kationen | AW27: None | BA27: None | BD27: IC Kationen | BE27: None | BH27: IC Kationen | BI27: None | BL27: IC Kationen | BM27: None | BQ27: None | BU27: None | BY27: None | CC27: None | CF27: Titration | CG27: None | CK27: None | CO27: None | CR27: WTW Multimeter 3430 with FDO 925 | CS27: None | CV27: HACH 2100AN IS Turbidimeter | CW27: None | CZ27: OxiTop | DA27: None | DD27: SOP 45-16 | DE27: None | DH27: SOP 45-16 | DI27: None | DL27: Flow Cytometry (SG) | DM27: None | DP27: Flow Cytometry (SG/PI) | DQ27: None | DT27: Luminometer | DU27: None | DX27: Nanodrop2000 | DY27: None | EB27: Retsch AS200 control | EC27: None | EF27: =CONCATENATE(A27,B27) | EG27: =CONCATENATE(SamplesX!A27,SamplesX!B27) | EH27: =CONCATENATE(SamplesY!A27,SamplesY!B27) | EI27: =MATCH(EF27,EG1:EG1008,0) | EJ27: =MATCH(EF27,EH1:EH1008,0)
C28: =IF(ISNUMBER(EI28),INDIRECT("SamplesX!C"&EI28),IF(ISNUMBER(EJ28),INDIRECT("SamplesY!C"&EJ28),"")) | D28: =IF(ISNUMBER(EI28),INDIRECT("SamplesX!D"&EI28),IF(ISNUMBER(EJ28),INDIRECT("SamplesY!D"&EJ28),"")) | E28: =IF(ISNUMBER(EI28),INDIRECT("SamplesX!E"&EI28),IF(ISNUMBER(EJ28),INDIRECT("SamplesY!E"&EJ28),"")) | F28: =IF(ISNUMBER(EI28),INDIRECT("SamplesX!F"&EI28),IF(ISNUMBER(EJ28),INDIRECT("SamplesY!F"&EJ28),"")) | G28: =IF(ISNUMBER(EI28),INDIRECT("SamplesX!G"&EI28),IF(ISNUMBER(EJ28),INDIRECT("SamplesY!G"&EJ28),"")) | H28: =IF(ISNUMBER(EI28),INDIRECT("SamplesX!H"&EI28),IF(ISNUMBER(EJ28),INDIRECT("SamplesY!H"&EJ28),"")) | M28: None | P28: Shimadzu TOC-L | Q28: None | T28: Shimadzu TOC-L | U28: None | Y28: None | AB28: IC Anionen | AC28: None | AG28: None | AK28: None | AO28: None | AR28: IC Anionen | AS28: None | AV28: IC Kationen | AW28: None | BA28: None | BD28: IC Kationen | BE28: None | BH28: IC Kationen | BI28: None | BL28: IC Kationen | BM28: None | BQ28: None | BU28: None | BY28: None | CC28: None | CF28: Titration | CG28: None | CK28: None | CO28: None | CR28: WTW Multimeter 3430 with FDO 925 | CS28: None | CV28: HACH 2100AN IS Turbidimeter | CW28: None | CZ28: OxiTop | DA28: None | DD28: SOP 45-16 | DE28: None | DH28: SOP 45-16 | DI28: None | DL28: Flow Cytometry (SG) | DM28: None | DP28: Flow Cytometry (SG/PI) | DQ28: None | DT28: Luminometer | DU28: None | DX28: Nanodrop2000 | DY28: None | EB28: Retsch AS200 control | EC28: None | EF28: =CONCATENATE(A28,B28) | EG28: =CONCATENATE(SamplesX!A28,SamplesX!B28) | EH28: =CONCATENATE(SamplesY!A28,SamplesY!B28) | EI28: =MATCH(EF28,EG1:EG1008,0) | EJ28: =MATCH(EF28,EH1:EH1008,0)
C29: =IF(ISNUMBER(EI29),INDIRECT("SamplesX!C"&EI29),IF(ISNUMBER(EJ29),INDIRECT("SamplesY!C"&EJ29),"")) | D29: =IF(ISNUMBER(EI29),INDIRECT("SamplesX!D"&EI29),IF(ISNUMBER(EJ29),INDIRECT("SamplesY!D"&EJ29),"")) | E29: =IF(ISNUMBER(EI29),INDIRECT("SamplesX!E"&EI29),IF(ISNUMBER(EJ29),INDIRECT("SamplesY!E"&EJ29),"")) | F29: =IF(ISNUMBER(EI29),INDIRECT("SamplesX!F"&EI29),IF(ISNUMBER(EJ29),INDIRECT("SamplesY!F"&EJ29),"")) | G29: =IF(ISNUMBER(EI29),INDIRECT("SamplesX!G"&EI29),IF(ISNUMBER(EJ29),INDIRECT("SamplesY!G"&EJ29),"")) | H29: =IF(ISNUMBER(EI29),INDIRECT("SamplesX!H"&EI29),IF(ISNUMBER(EJ29),INDIRECT("SamplesY!H"&EJ29),"")) | M29: None | P29: Shimadzu TOC-L | Q29: None | T29: Shimadzu TOC-L | U29: None | Y29: None | AB29: IC Anionen | AC29: None | AG29: None | AK29: None | AO29: None | AR29: IC Anionen | AS29: None | AV29: IC Kationen | AW29: None | BA29: None | BD29: IC Kationen | BE29: None | BH29: IC Kationen | BI29: None | BL29: IC Kationen | BM29: None | BQ29: None | BU29: None | BY29: None | CC29: None | CF29: Titration | CG29: None | CK29: None | CO29: None | CR29: WTW Multimeter 3430 with FDO 925 | CS29: None | CV29: HACH 2100AN IS Turbidimeter | CW29: None | CZ29: OxiTop | DA29: None | DD29: SOP 45-16 | DE29: None | DH29: SOP 45-16 | DI29: None | DL29: Flow Cytometry (SG) | DM29: None | DP29: Flow Cytometry (SG/PI) | DQ29: None | DT29: Luminometer | DU29: None | DX29: Nanodrop2000 | DY29: None | EB29: Retsch AS200 control | EC29: None | EF29: =CONCATENATE(A29,B29) | EG29: =CONCATENATE(SamplesX!A29,SamplesX!B29) | EH29: =CONCATENATE(SamplesY!A29,SamplesY!B29) | EI29: =MATCH(EF29,EG1:EG1008,0) | EJ29: =MATCH(EF29,EH1:EH1008,0)
C30: =IF(ISNUMBER(EI30),INDIRECT("SamplesX!C"&EI30),IF(ISNUMBER(EJ30),INDIRECT("SamplesY!C"&EJ30),"")) | D30: =IF(ISNUMBER(EI30),INDIRECT("SamplesX!D"&EI30),IF(ISNUMBER(EJ30),INDIRECT("SamplesY!D"&EJ30),"")) | E30: =IF(ISNUMBER(EI30),INDIRECT("SamplesX!E"&EI30),IF(ISNUMBER(EJ30),INDIRECT("SamplesY!E"&EJ30),"")) | F30: =IF(ISNUMBER(EI30),INDIRECT("SamplesX!F"&EI30),IF(ISNUMBER(EJ30),INDIRECT("SamplesY!F"&EJ30),"")) | G30: =IF(ISNUMBER(EI30),INDIRECT("SamplesX!G"&EI30),IF(ISNUMBER(EJ30),INDIRECT("SamplesY!G"&EJ30),"")) | H30: =IF(ISNUMBER(EI30),INDIRECT("SamplesX!H"&EI30),IF(ISNUMBER(EJ30),INDIRECT("SamplesY!H"&EJ30),"")) | M30: None | P30: Shimadzu TOC-L | Q30: None | T30: Shimadzu TOC-L | U30: None | Y30: None | AB30: IC Anionen | AC30: None | AG30: None | AK30: None | AO30: None | AR30: IC Anionen | AS30: None | AV30: IC Kationen | AW30: None | BA30: None | BD30: IC Kationen | BE30: None | BH30: IC Kationen | BI30: None | BL30: IC Kationen | BM30: None | BQ30: None | BU30: None | BY30: None | CC30: None | CF30: Titration | CG30: None | CK30: None | CO30: None | CR30: WTW Multimeter 3430 with FDO 925 | CS30: None | CV30: HACH 2100AN IS Turbidimeter | CW30: None | CZ30: OxiTop | DA30: None | DD30: SOP 45-16 | DE30: None | DH30: SOP 45-16 | DI30: None | DL30: Flow Cytometry (SG) | DM30: None | DP30: Flow Cytometry (SG/PI) | DQ30: None | DT30: Luminometer | DU30: None | DX30: Nanodrop2000 | DY30: None | EB30: Retsch AS200 control | EC30: None | EF30: =CONCATENATE(A30,B30) | EG30: =CONCATENATE(SamplesX!A30,SamplesX!B30) | EH30: =CONCATENATE(SamplesY!A30,SamplesY!B30) | EI30: =MATCH(EF30,EG1:EG1008,0) | EJ30: =MATCH(EF30,EH1:EH1008,0)
C31: =IF(ISNUMBER(EI31),INDIRECT("SamplesX!C"&EI31),IF(ISNUMBER(EJ31),INDIRECT("SamplesY!C"&EJ31),"")) | D31: =IF(ISNUMBER(EI31),INDIRECT("SamplesX!D"&EI31),IF(ISNUMBER(EJ31),INDIRECT("SamplesY!D"&EJ31),"")) | E31: =IF(ISNUMBER(EI31),INDIRECT("SamplesX!E"&EI31),IF(ISNUMBER(EJ31),INDIRECT("SamplesY!E"&EJ31),"")) | F31: =IF(ISNUMBER(EI31),INDIRECT("SamplesX!F"&EI31),IF(ISNUMBER(EJ31),INDIRECT("SamplesY!F"&EJ31),"")) | G31: =IF(ISNUMBER(EI31),INDIRECT("SamplesX!G"&EI31),IF(ISNUMBER(EJ31),INDIRECT("SamplesY!G"&EJ31),"")) | H31: =IF(ISNUMBER(EI31),INDIRECT("SamplesX!H"&EI31),IF(ISNUMBER(EJ31),INDIRECT("SamplesY!H"&EJ31),"")) | M31: None | P31: Shimadzu TOC-L | Q31: None | T31: Shimadzu TOC-L | U31: None | Y31: None | AB31: IC Anionen | AC31: None | AG31: None | AK31: None | AO31: None | AR31: IC Anionen | AS31: None | AV31: IC Kationen | AW31: None | BA31: None | BD31: IC Kationen | BE31: None | BH31: IC Kationen | BI31: None | BL31: IC Kationen | BM31: None | BQ31: None | BU31: None | BY31: None | CC31: None | CF31: Titration | CG31: None | CK31: None | CO31: None | CR31: WTW Multimeter 3430 with FDO 925 | CS31: None | CV31: HACH 2100AN IS Turbidimeter | CW31: None | CZ31: OxiTop | DA31: None | DD31: SOP 45-16 | DE31: None | DH31: SOP 45-16 | DI31: None | DL31: Flow Cytometry (SG) | DM31: None | DP31: Flow Cytometry (SG/PI) | DQ31: None | DT31: Luminometer | DU31: None | DX31: Nanodrop2000 | DY31: None | EB31: Retsch AS200 control | EC31: None | EF31: =CONCATENATE(A31,B31) | EG31: =CONCATENATE(SamplesX!A31,SamplesX!B31) | EH31: =CONCATENATE(SamplesY!A31,SamplesY!B31) | EI31: =MATCH(EF31,EG1:EG1008,0) | EJ31: =MATCH(EF31,EH1:EH1008,0)
C32: =IF(ISNUMBER(EI32),INDIRECT("SamplesX!C"&EI32),IF(ISNUMBER(EJ32),INDIRECT("SamplesY!C"&EJ32),"")) | D32: =IF(ISNUMBER(EI32),INDIRECT("SamplesX!D"&EI32),IF(ISNUMBER(EJ32),INDIRECT("SamplesY!D"&EJ32),"")) | E32: =IF(ISNUMBER(EI32),INDIRECT("SamplesX!E"&EI32),IF(ISNUMBER(EJ32),INDIRECT("SamplesY!E"&EJ32),"")) | F32: =IF(ISNUMBER(EI32),INDIRECT("SamplesX!F"&EI32),IF(ISNUMBER(EJ32),INDIRECT("SamplesY!F"&EJ32),"")) | G32: =IF(ISNUMBER(EI32),INDIRECT("SamplesX!G"&EI32),IF(ISNUMBER(EJ32),INDIRECT("SamplesY!G"&EJ32),"")) | H32: =IF(ISNUMBER(EI32),INDIRECT("SamplesX!H"&EI32),IF(ISNUMBER(EJ32),INDIRECT("SamplesY!H"&EJ32),"")) | M32: None | P32: Shimadzu TOC-L | Q32: None | T32: Shimadzu TOC-L | U32: None | Y32: None | AB32: IC Anionen | AC32: None | AG32: None | AK32: None | AO32: None | AR32: IC Anionen | AS32: None | AV32: IC Kationen | AW32: None | BA32: None | BD32: IC Kationen | BE32: None | BH32: IC Kationen | BI32: None | BL32: IC Kationen | BM32: None | BQ32: None | BU32: None | BY32: None | CC32: None | CF32: Titration | CG32: None | CK32: None | CO32: None | CR32: WTW Multimeter 3430 with FDO 925 | CS32: None | CV32: HACH 2100AN IS Turbidimeter | CW32: None | CZ32: OxiTop | DA32: None | DD32: SOP 45-16 | DE32: None | DH32: SOP 45-16 | DI32: None | DL32: Flow Cytometry (SG) | DM32: None | DP32: Flow Cytometry (SG/PI) | DQ32: None | DT32: Luminometer | DU32: None | DX32: Nanodrop2000 | DY32: None | EB32: Retsch AS200 control | EC32: None | EF32: =CONCATENATE(A32,B32) | EG32: =CONCATENATE(SamplesX!A32,SamplesX!B32) | EH32: =CONCATENATE(SamplesY!A32,SamplesY!B32) | EI32: =MATCH(EF32,EG1:EG1008,0) | EJ32: =MATCH(EF32,EH1:EH1008,0)
C33: =IF(ISNUMBER(EI33),INDIRECT("SamplesX!C"&EI33),IF(ISNUMBER(EJ33),INDIRECT("SamplesY!C"&EJ33),"")) | D33: =IF(ISNUMBER(EI33),INDIRECT("SamplesX!D"&EI33),IF(ISNUMBER(EJ33),INDIRECT("SamplesY!D"&EJ33),"")) | E33: =IF(ISNUMBER(EI33),INDIRECT("SamplesX!E"&EI33),IF(ISNUMBER(EJ33),INDIRECT("SamplesY!E"&EJ33),"")) | F33: =IF(ISNUMBER(EI33),INDIRECT("SamplesX!F"&EI33),IF(ISNUMBER(EJ33),INDIRECT("SamplesY!F"&EJ33),"")) | G33: =IF(ISNUMBER(EI33),INDIRECT("SamplesX!G"&EI33),IF(ISNUMBER(EJ33),INDIRECT("SamplesY!G"&EJ33),"")) | H33: =IF(ISNUMBER(EI33),INDIRECT("SamplesX!H"&EI33),IF(ISNUMBER(EJ33),INDIRECT("SamplesY!H"&EJ33),"")) | M33: None | P33: Shimadzu TOC-L | Q33: None | T33: Shimadzu TOC-L | U33: None | Y33: None | AB33: IC Anionen | AC33: None | AG33: None | AK33: None | AO33: None | AR33: IC Anionen | AS33: None | AV33: IC Kationen | AW33: None | BA33: None | BD33: IC Kationen | BE33: None | BH33: IC Kationen | BI33: None | BL33: IC Kationen | BM33: None | BQ33: None | BU33: None | BY33: None | CC33: None | CF33: Titration | CG33: None | CK33: None | CO33: None | CR33: WTW Multimeter 3430 with FDO 925 | CS33: None | CV33: HACH 2100AN IS Turbidimeter | CW33: None | CZ33: OxiTop | DA33: None | DD33: SOP 45-16 | DE33: None | DH33: SOP 45-16 | DI33: None | DL33: Flow Cytometry (SG) | DM33: None | DP33: Flow Cytometry (SG/PI) | DQ33: None | DT33: Luminometer | DU33: None | DX33: Nanodrop2000 | DY33: None | EB33: Retsch AS200 control | EC33: None | EF33: =CONCATENATE(A33,B33) | EG33: =CONCATENATE(SamplesX!A33,SamplesX!B33) | EH33: =CONCATENATE(SamplesY!A33,SamplesY!B33) | EI33: =MATCH(EF33,EG1:EG1008,0) | EJ33: =MATCH(EF33,EH1:EH1008,0)
C34: =IF(ISNUMBER(EI34),INDIRECT("SamplesX!C"&EI34),IF(ISNUMBER(EJ34),INDIRECT("SamplesY!C"&EJ34),"")) | D34: =IF(ISNUMBER(EI34),INDIRECT("SamplesX!D"&EI34),IF(ISNUMBER(EJ34),INDIRECT("SamplesY!D"&EJ34),"")) | E34: =IF(ISNUMBER(EI34),INDIRECT("SamplesX!E"&EI34),IF(ISNUMBER(EJ34),INDIRECT("SamplesY!E"&EJ34),"")) | F34: =IF(ISNUMBER(EI34),INDIRECT("SamplesX!F"&EI34),IF(ISNUMBER(EJ34),INDIRECT("SamplesY!F"&EJ34),"")) | G34: =IF(ISNUMBER(EI34),INDIRECT("SamplesX!G"&EI34),IF(ISNUMBER(EJ34),INDIRECT("SamplesY!G"&EJ34),"")) | H34: =IF(ISNUMBER(EI34),INDIRECT("SamplesX!H"&EI34),IF(ISNUMBER(EJ34),INDIRECT("SamplesY!H"&EJ34),"")) | M34: None | P34: Shimadzu TOC-L | Q34: None | T34: Shimadzu TOC-L | U34: None | Y34: None | AB34: IC Anionen | AC34: None | AG34: None | AK34: None | AO34: None | AR34: IC Anionen | AS34: None | AV34: IC Kationen | AW34: None | BA34: None | BD34: IC Kationen | BE34: None | BH34: IC Kationen | BI34: None | BL34: IC Kationen | BM34: None | BQ34: None | BU34: None | BY34: None | CC34: None | CF34: Titration | CG34: None | CK34: None | CO34: None | CR34: WTW Multimeter 3430 with FDO 925 | CS34: None | CV34: HACH 2100AN IS Turbidimeter | CW34: None | CZ34: OxiTop | DA34: None | DD34: SOP 45-16 | DE34: None | DH34: SOP 45-16 | DI34: None | DL34: Flow Cytometry (SG) | DM34: None | DP34: Flow Cytometry (SG/PI) | DQ34: None | DT34: Luminometer | DU34: None | DX34: Nanodrop2000 | DY34: None | EB34: Retsch AS200 control | EC34: None | EF34: =CONCATENATE(A34,B34) | EG34: =CONCATENATE(SamplesX!A34,SamplesX!B34) | EH34: =CONCATENATE(SamplesY!A34,SamplesY!B34) | EI34: =MATCH(EF34,EG1:EG1008,0) | EJ34: =MATCH(EF34,EH1:EH1008,0)
C35: =IF(ISNUMBER(EI35),INDIRECT("SamplesX!C"&EI35),IF(ISNUMBER(EJ35),INDIRECT("SamplesY!C"&EJ35),"")) | D35: =IF(ISNUMBER(EI35),INDIRECT("SamplesX!D"&EI35),IF(ISNUMBER(EJ35),INDIRECT("SamplesY!D"&EJ35),"")) | E35: =IF(ISNUMBER(EI35),INDIRECT("SamplesX!E"&EI35),IF(ISNUMBER(EJ35),INDIRECT("SamplesY!E"&EJ35),"")) | F35: =IF(ISNUMBER(EI35),INDIRECT("SamplesX!F"&EI35),IF(ISNUMBER(EJ35),INDIRECT("SamplesY!F"&EJ35),"")) | G35: =IF(ISNUMBER(EI35),INDIRECT("SamplesX!G"&EI35),IF(ISNUMBER(EJ35),INDIRECT("SamplesY!G"&EJ35),"")) | H35: =IF(ISNUMBER(EI35),INDIRECT("SamplesX!H"&EI35),IF(ISNUMBER(EJ35),INDIRECT("SamplesY!H"&EJ35),"")) | M35: None | P35: Shimadzu TOC-L | Q35: None | T35: Shimadzu TOC-L | U35: None | Y35: None | AB35: IC Anionen | AC35: None | AG35: None | AK35: None | AO35: None | AR35: IC Anionen | AS35: None | AV35: IC Kationen | AW35: None | BA35: None | BD35: IC Kationen | BE35: None | BH35: IC Kationen | BI35: None | BL35: IC Kationen | BM35: None | BQ35: None | BU35: None | BY35: None | CC35: None | CF35: Titration | CG35: None | CK35: None | CO35: None | CR35: WTW Multimeter 3430 with FDO 925 | CS35: None | CV35: HACH 2100AN IS Turbidimeter | CW35: None | CZ35: OxiTop | DA35: None | DD35: SOP 45-16 | DE35: None | DH35: SOP 45-16 | DI35: None | DL35: Flow Cytometry (SG) | DM35: None | DP35: Flow Cytometry (SG/PI) | DQ35: None | DT35: Luminometer | DU35: None | DX35: Nanodrop2000 | DY35: None | EB35: Retsch AS200 control | EC35: None | EF35: =CONCATENATE(A35,B35) | EG35: =CONCATENATE(SamplesX!A35,SamplesX!B35) | EH35: =CONCATENATE(SamplesY!A35,SamplesY!B35) | EI35: =MATCH(EF35,EG1:EG1008,0) | EJ35: =MATCH(EF35,EH1:EH1008,0)
C36: =IF(ISNUMBER(EI36),INDIRECT("SamplesX!C"&EI36),IF(ISNUMBER(EJ36),INDIRECT("SamplesY!C"&EJ36),"")) | D36: =IF(ISNUMBER(EI36),INDIRECT("SamplesX!D"&EI36),IF(ISNUMBER(EJ36),INDIRECT("SamplesY!D"&EJ36),"")) | E36: =IF(ISNUMBER(EI36),INDIRECT("SamplesX!E"&EI36),IF(ISNUMBER(EJ36),INDIRECT("SamplesY!E"&EJ36),"")) | F36: =IF(ISNUMBER(EI36),INDIRECT("SamplesX!F"&EI36),IF(ISNUMBER(EJ36),INDIRECT("SamplesY!F"&EJ36),"")) | G36: =IF(ISNUMBER(EI36),INDIRECT("SamplesX!G"&EI36),IF(ISNUMBER(EJ36),INDIRECT("SamplesY!G"&EJ36),"")) | H36: =IF(ISNUMBER(EI36),INDIRECT("SamplesX!H"&EI36),IF(ISNUMBER(EJ36),INDIRECT("SamplesY!H"&EJ36),"")) | M36: None | P36: Shimadzu TOC-L | Q36: None | T36: Shimadzu TOC-L | U36: None | Y36: None | AB36: IC Anionen | AC36: None | AG36: None | AK36: None | AO36: None | AR36: IC Anionen | AS36: None | AV36: IC Kationen | AW36: None | BA36: None | BD36: IC Kationen | BE36: None | BH36: IC Kationen | BI36: None | BL36: IC Kationen | BM36: None | BQ36: None | BU36: None | BY36: None | CC36: None | CF36: Titration | CG36: None | CK36: None | CO36: None | CR36: WTW Multimeter 3430 with FDO 925 | CS36: None | CV36: HACH 2100AN IS Turbidimeter | CW36: None | CZ36: OxiTop | DA36: None | DD36: SOP 45-16 | DE36: None | DH36: SOP 45-16 | DI36: None | DL36: Flow Cytometry (SG) | DM36: None | DP36: Flow Cytometry (SG/PI) | DQ36: None | DT36: Luminometer | DU36: None | DX36: Nanodrop2000 | DY36: None | EB36: Retsch AS200 control | EC36: None | EF36: =CONCATENATE(A36,B36) | EG36: =CONCATENATE(SamplesX!A36,SamplesX!B36) | EH36: =CONCATENATE(SamplesY!A36,SamplesY!B36) | EI36: =MATCH(EF36,EG1:EG1008,0) | EJ36: =MATCH(EF36,EH1:EH1008,0)
C37: =IF(ISNUMBER(EI37),INDIRECT("SamplesX!C"&EI37),IF(ISNUMBER(EJ37),INDIRECT("SamplesY!C"&EJ37),"")) | D37: =IF(ISNUMBER(EI37),INDIRECT("SamplesX!D"&EI37),IF(ISNUMBER(EJ37),INDIRECT("SamplesY!D"&EJ37),"")) | E37: =IF(ISNUMBER(EI37),INDIRECT("SamplesX!E"&EI37),IF(ISNUMBER(EJ37),INDIRECT("SamplesY!E"&EJ37),"")) | F37: =IF(ISNUMBER(EI37),INDIRECT("SamplesX!F"&EI37),IF(ISNUMBER(EJ37),INDIRECT("SamplesY!F"&EJ37),"")) | G37: =IF(ISNUMBER(EI37),INDIRECT("SamplesX!G"&EI37),IF(ISNUMBER(EJ37),INDIRECT("SamplesY!G"&EJ37),"")) | H37: =IF(ISNUMBER(EI37),INDIRECT("SamplesX!H"&EI37),IF(ISNUMBER(EJ37),INDIRECT("SamplesY!H"&EJ37),"")) | M37: None | P37: Shimadzu TOC-L | Q37: None | T37: Shimadzu TOC-L | U37: None | Y37: None | AB37: IC Anionen | AC37: None | AG37: None | AK37: None | AO37: None | AR37: IC Anionen | AS37: None | AV37: IC Kationen | AW37: None | BA37: None | BD37: IC Kationen | BE37: None | BH37: IC Kationen | BI37: None | BL37: IC Kationen | BM37: None | BQ37: None | BU37: None | BY37: None | CC37: None | CF37: Titration | CG37: None | CK37: None | CO37: None | CR37: WTW Multimeter 3430 with FDO 925 | CS37: None | CV37: HACH 2100AN IS Turbidimeter | CW37: None | CZ37: OxiTop | DA37: None | DD37: SOP 45-16 | DE37: None | DH37: SOP 45-16 | DI37: None | DL37: Flow Cytometry (SG) | DM37: None | DP37: Flow Cytometry (SG/PI) | DQ37: None | DT37: Luminometer | DU37: None | DX37: Nanodrop2000 | DY37: None | EB37: Retsch AS200 control | EC37: None | EF37: =CONCATENATE(A37,B37) | EG37: =CONCATENATE(SamplesX!A37,SamplesX!B37) | EH37: =CONCATENATE(SamplesY!A37,SamplesY!B37) | EI37: =MATCH(EF37,EG1:EG1008,0) | EJ37: =MATCH(EF37,EH1:EH1008,0)
C38: =IF(ISNUMBER(EI38),INDIRECT("SamplesX!C"&EI38),IF(ISNUMBER(EJ38),INDIRECT("SamplesY!C"&EJ38),"")) | D38: =IF(ISNUMBER(EI38),INDIRECT("SamplesX!D"&EI38),IF(ISNUMBER(EJ38),INDIRECT("SamplesY!D"&EJ38),"")) | E38: =IF(ISNUMBER(EI38),INDIRECT("SamplesX!E"&EI38),IF(ISNUMBER(EJ38),INDIRECT("SamplesY!E"&EJ38),"")) | F38: =IF(ISNUMBER(EI38),INDIRECT("SamplesX!F"&EI38),IF(ISNUMBER(EJ38),INDIRECT("SamplesY!F"&EJ38),"")) | G38: =IF(ISNUMBER(EI38),INDIRECT("SamplesX!G"&EI38),IF(ISNUMBER(EJ38),INDIRECT("SamplesY!G"&EJ38),"")) | H38: =IF(ISNUMBER(EI38),INDIRECT("SamplesX!H"&EI38),IF(ISNUMBER(EJ38),INDIRECT("SamplesY!H"&EJ38),"")) | M38: None | P38: Shimadzu TOC-L | Q38: None | T38: Shimadzu TOC-L | U38: None | Y38: None | AB38: IC Anionen | AC38: None | AG38: None | AK38: None | AO38: None | AR38: IC Anionen | AS38: None | AV38: IC Kationen | AW38: None | BA38: None | BD38: IC Kationen | BE38: None | BH38: IC Kationen | BI38: None | BL38: IC Kationen | BM38: None | BQ38: None | BU38: None | BY38: None | CC38: None | CF38: Titration | CG38: None | CK38: None | CO38: None | CR38: WTW Multimeter 3430 with FDO 925 | CS38: None | CV38: HACH 2100AN IS Turbidimeter | CW38: None | CZ38: OxiTop | DA38: None | DD38: SOP 45-16 | DE38: None | DH38: SOP 45-16 | DI38: None | DL38: Flow Cytometry (SG) | DM38: None | DP38: Flow Cytometry (SG/PI) | DQ38: None | DT38: Luminometer | DU38: None | DX38: Nanodrop2000 | DY38: None | EB38: Retsch AS200 control | EC38: None | EF38: =CONCATENATE(A38,B38) | EG38: =CONCATENATE(SamplesX!A38,SamplesX!B38) | EH38: =CONCATENATE(SamplesY!A38,SamplesY!B38) | EI38: =MATCH(EF38,EG1:EG1008,0) | EJ38: =MATCH(EF38,EH1:EH1008,0)
C39: =IF(ISNUMBER(EI39),INDIRECT("SamplesX!C"&EI39),IF(ISNUMBER(EJ39),INDIRECT("SamplesY!C"&EJ39),"")) | D39: =IF(ISNUMBER(EI39),INDIRECT("SamplesX!D"&EI39),IF(ISNUMBER(EJ39),INDIRECT("SamplesY!D"&EJ39),"")) | E39: =IF(ISNUMBER(EI39),INDIRECT("SamplesX!E"&EI39),IF(ISNUMBER(EJ39),INDIRECT("SamplesY!E"&EJ39),"")) | F39: =IF(ISNUMBER(EI39),INDIRECT("SamplesX!F"&EI39),IF(ISNUMBER(EJ39),INDIRECT("SamplesY!F"&EJ39),"")) | G39: =IF(ISNUMBER(EI39),INDIRECT("SamplesX!G"&EI39),IF(ISNUMBER(EJ39),INDIRECT("SamplesY!G"&EJ39),"")) | H39: =IF(ISNUMBER(EI39),INDIRECT("SamplesX!H"&EI39),IF(ISNUMBER(EJ39),INDIRECT("SamplesY!H"&EJ39),"")) | M39: None | P39: Shimadzu TOC-L | Q39: None | T39: Shimadzu TOC-L | U39: None | Y39: None | AB39: IC Anionen | AC39: None | AG39: None | AK39: None | AO39: None | AR39: IC Anionen | AS39: None | AV39: IC Kationen | AW39: None | BA39: None | BD39: IC Kationen | BE39: None | BH39: IC Kationen | BI39: None | BL39: IC Kationen | BM39: None | BQ39: None | BU39: None | BY39: None | CC39: None | CF39: Titration | CG39: None | CK39: None | CO39: None | CR39: WTW Multimeter 3430 with FDO 925 | CS39: None | CV39: HACH 2100AN IS Turbidimeter | CW39: None | CZ39: OxiTop | DA39: None | DD39: SOP 45-16 | DE39: None | DH39: SOP 45-16 | DI39: None | DL39: Flow Cytometry (SG) | DM39: None | DP39: Flow Cytometry (SG/PI) | DQ39: None | DT39: Luminometer | DU39: None | DX39: Nanodrop2000 | DY39: None | EB39: Retsch AS200 control | EC39: None | EF39: =CONCATENATE(A39,B39) | EG39: =CONCATENATE(SamplesX!A39,SamplesX!B39) | EH39: =CONCATENATE(SamplesY!A39,SamplesY!B39) | EI39: =MATCH(EF39,EG1:EG1008,0) | EJ39: =MATCH(EF39,EH1:EH1008,0)
C40: =IF(ISNUMBER(EI40),INDIRECT("SamplesX!C"&EI40),IF(ISNUMBER(EJ40),INDIRECT("SamplesY!C"&EJ40),"")) | D40: =IF(ISNUMBER(EI40),INDIRECT("SamplesX!D"&EI40),IF(ISNUMBER(EJ40),INDIRECT("SamplesY!D"&EJ40),"")) | E40: =IF(ISNUMBER(EI40),INDIRECT("SamplesX!E"&EI40),IF(ISNUMBER(EJ40),INDIRECT("SamplesY!E"&EJ40),"")) | F40: =IF(ISNUMBER(EI40),INDIRECT("SamplesX!F"&EI40),IF(ISNUMBER(EJ40),INDIRECT("SamplesY!F"&EJ40),"")) | G40: =IF(ISNUMBER(EI40),INDIRECT("SamplesX!G"&EI40),IF(ISNUMBER(EJ40),INDIRECT("SamplesY!G"&EJ40),"")) | H40: =IF(ISNUMBER(EI40),INDIRECT("SamplesX!H"&EI40),IF(ISNUMBER(EJ40),INDIRECT("SamplesY!H"&EJ40),"")) | M40: None | P40: Shimadzu TOC-L | Q40: None | T40: Shimadzu TOC-L | U40: None | Y40: None | AB40: IC Anionen | AC40: None | AG40: None | AK40: None | AO40: None | AR40: IC Anionen | AS40: None | AV40: IC Kationen | AW40: None | BA40: None | BD40: IC Kationen | BE40: None | BH40: IC Kationen | BI40: None | BL40: IC Kationen | BM40: None | BQ40: None | BU40: None | BY40: None | CC40: None | CF40: Titration | CG40: None | CK40: None | CO40: None | CR40: WTW Multimeter 3430 with FDO 925 | CS40: None | CV40: HACH 2100AN IS Turbidimeter | CW40: None | CZ40: OxiTop | DA40: None | DD40: SOP 45-16 | DE40: None | DH40: SOP 45-16 | DI40: None | DL40: Flow Cytometry (SG) | DM40: None | DP40: Flow Cytometry (SG/PI) | DQ40: None | DT40: Luminometer | DU40: None | DX40: Nanodrop2000 | DY40: None | EB40: Retsch AS200 control | EC40: None | EF40: =CONCATENATE(A40,B40) | EG40: =CONCATENATE(SamplesX!A40,SamplesX!B40) | EH40: =CONCATENATE(SamplesY!A40,SamplesY!B40) | EI40: =MATCH(EF40,EG1:EG1008,0) | EJ40: =MATCH(EF40,EH1:EH1008,0)
...

Sheet SamplesX
