Workbook

Sheet person
A1: =IF(ISBLANK('C:\code\laboratoryspreadsheet\labspreadsheet\demo\remote_central\[LabSamples2019.xlsx]person'!A1)," ",'C:\code\laboratoryspreadsheet\labspreadsheet\demo\remote_central\[LabSamples2019.xlsx]person'!A1) | B1: =IF(ISBLANK('C:\code\laboratoryspreadsheet\labspreadsheet\demo\remote_central\[LabSamples2019.xlsx]person'!B1)," ",'C:\code\laboratoryspreadsheet\labspreadsheet\demo\remote_central\[LabSamples2019.xlsx]person'!B1) | C1: =IF(ISBLANK('C:\code\laboratoryspreadsheet\labspreadsheet\demo\remote_central\[LabSamples2019.xlsx]person'!C1)," ",'C:\code\laboratoryspreadsheet\labspreadsheet\demo\remote_central\[LabSamples2019.xlsx]person'!C1) | D1: =IF(ISBLANK('C:\code\laboratoryspreadsheet\labspreadsheet\demo\remote_central\[LabSamples2019.xlsx]person'!D1)," ",'C:\code\laboratoryspreadsheet\labspreadsheet\demo\remote_central\[LabSamples2019.xlsx]person'!D1)
A2: =IF(ISBLANK('C:\code\laboratoryspreadsheet\labspreadsheet\demo\remote_central\[LabSamples2019.xlsx]person'!A2)," ",'C:\code\laboratoryspreadsheet\labspreadsheet\demo\remote_central\[LabSamples2019.xlsx]person'!A2) | B2: =IF(ISBLANK('C:\code\laboratoryspreadsheet\labspreadsheet\demo\remote_central\[LabSamples2019.xlsx]person'!B2)," ",'C:\code\laboratoryspreadsheet\labspreadsheet\demo\remote_central\[LabSamples2019.xlsx]person'!B2) | C2: =IF(ISBLANK('C:\code\laboratoryspreadsheet\labspreadsheet\demo\remote_central\[LabSamples2019.xlsx]person'!C2)," ",'C:\code\laboratoryspreadsheet\labspreadsheet\demo\remote_central\[LabSamples2019.xlsx]person'!C2) | D2: =IF(ISBLANK('C:\code\laboratoryspreadsheet\labspreadsheet\demo\remote_central\[LabSamples2019.xlsx]person'!D2)," ",'C:\code\laboratoryspreadsheet\labspreadsheet\demo\remote_central\[LabSamples2019.xlsx]person'!D2)
A3: =IF(ISBLANK('C:\code\laboratoryspreadsheet\labspreadsheet\demo\remote_central\[LabSamples2019.xlsx]person'!A3)," ",'C:\code\laboratoryspreadsheet\labspreadsheet\demo\remote_central\[LabSamples2019.xlsx]person'!A3) | B3: =IF(ISBLANK('C:\code\laboratoryspreadsheet\labspreadsheet\demo\remote_central\[LabSamples2019.xlsx]person'!B3)," ",'C:\code\laboratoryspreadsheet\labspreadsheet\demo\remote_central\[LabSamples2019.xlsx]person'!B3) | C3: =IF(ISBLANK('C:\code\laboratoryspreadsheet\labspreadsheet\demo\remote_central\[LabSamples2019.xlsx]person'!C3)," ",'C:\code\laboratoryspreadsheet\labspreadsheet\demo\remote_central\[LabSamples2019.xlsx]person'!C3) | D3: =IF(ISBLANK('C:\code\laboratoryspreadsheet\labspreadsheet\demo\remote_central\[LabSamples2019.xlsx]person'!D3)," ",'C:\code\laboratoryspreadsheet\labspreadsheet\demo\remote_central\[LabSamples2019.xlsx]person'!D3)
A4: =IF(ISBLANK('C:\code\laboratoryspreadsheet\labspreadsheet\demo\remote_central\[LabSamples2019.xlsx]person'!A4)," ",'C:\code\laboratoryspreadsheet\labspreadsheet\demo\remote_central\[LabSamples2019.xlsx]person'!A4) | B4: =IF(ISBLANK('C:\code\laboratoryspreadsheet\labspreadsheet\demo\remote_central\[LabSamples2019.xlsx]person'!B4)," ",'C:\code\laboratoryspreadsheet\labspreadsheet\demo\remote_central\[LabSamples2019.xlsx]person'!B4) | C4: =IF(ISBLANK('C:\code\laboratoryspreadsheet\labspreadsheet\demo\remote_central\[LabSamples2019.xlsx]person'!C4)," ",'C:\code\laboratoryspreadsheet\labspreadsheet\demo\remote_central\[LabSamples2019.xlsx]person'!C4) | D4: =IF(ISBLANK('C:\code\laboratoryspreadsheet\labspreadsheet\demo\remote_central\[LabSamples2019.xlsx]person'!D4)," ",'C:\code\laboratoryspreadsheet\labspreadsheet\demo\remote_central\[LabSamples2019.xlsx]person'!D4)
A5: =IF(ISBLANK('C:\code\laboratoryspreadsheet\labspreadsheet\demo\remote_central\[LabSamples2019.xlsx]person'!A5)," ",'C:\code\laboratoryspreadsheet\labspreadsheet\demo\remote_central\[LabSamples2019.xlsx]person'!A5) | B5: =IF(ISBLANK('C:\code\laboratoryspreadsheet\labspreadsheet\demo\remote_central\[LabSamples2019.xlsx]person'!B5)," ",'C:\code\laboratoryspreadsheet\labspreadsheet\demo\remote_central\[LabSamples2019.xlsx]person'!B5) | C5: =IF(ISBLANK('C:\code\laboratoryspreadsheet\labspreadsheet\demo\remote_central\[LabSamples2019.xlsx]person'!C5)," ",'C:\code\laboratoryspreadsheet\labspreadsheet\demo\remote_central\[LabSamples2019.xlsx]person'!C5) | D5: =IF(ISBLANK('C:\code\laboratoryspreadsheet\labspreadsheet\demo\remote_central\[LabSamples2019.xlsx]person'!D5)," ",'C:\code\laboratoryspreadsheet\labspreadsheet\demo\remote_central\[LabSamples2019.xlsx]person'!D5)
A6: =IF(ISBLANK('C:\code\laboratoryspreadsheet\labspreadsheet\demo\remote_central\[LabSamples2019.xlsx]person'!A6)," ",'C:\code\laboratoryspreadsheet\labspreadsheet\demo\remote_central\[LabSamples2019.xlsx]person'!A6) | B6: =IF(ISBLANK('C:\code\laboratoryspreadsheet\labspreadsheet\demo\remote_central\[LabSamples2019.xlsx]person'!B6)," ",'C:\code\laboratoryspreadsheet\labspreadsheet\demo\remote_central\[LabSamples2019.xlsx]person'!B6) | C6: =IF(ISBLANK('C:\code\laboratoryspreadsheet\labspreadsheet\demo\remote_central\[LabSamples2019.xlsx]person'!C6)," ",'C:\code\laboratoryspreadsheet\labspreadsheet\demo\remote_central\[LabSamples2019.xlsx]person'!C6) | D6: =IF(ISBLANK('C:\code\laboratoryspreadsheet\labspreadsheet\demo\remote_central\[LabSamples2019.xlsx]person'!D6)," ",'C:\code\laboratoryspreadsheet\labspreadsheet\demo\remote_central\[LabSamples2019.xlsx]person'!D6)
A7: =IF(ISBLANK('C:\code\laboratoryspreadsheet\labspreadsheet\demo\remote_central\[LabSamples2019.xlsx]person'!A7)," ",'C:\code\laboratoryspreadsheet\labspreadsheet\demo\remote_central\[LabSamples2019.xlsx]person'!A7) | B7: =IF(ISBLANK('C:\code\laboratoryspreadsheet\labspreadsheet\demo\remote_central\[LabSamples2019.xlsx]person'!B7)," ",'C:\code\laboratoryspreadsheet\labspreadsheet\demo\remote_central\[LabSamples2019.xlsx]person'!B7) | C7: =IF(ISBLANK('C:\code\laboratoryspreadsheet\labspreadsheet\demo\remote_central\[LabSamples2019.xlsx]person'!C7)," ",'C:\code\laboratoryspreadsheet\labspreadsheet\demo\remote_central\[LabSamples2019.xlsx]person'!C7) | D7: =IF(ISBLANK('C:\code\laboratoryspreadsheet\labspreadsheet\demo\remote_central\[LabSamples2019.xlsx]person'!D7)," ",'C:\code\laboratoryspreadsheet\labspreadsheet\demo\remote_central\[LabSamples2019.xlsx]person'!D7)
A8: =IF(ISBLANK('C:\code\laboratoryspreadsheet\labspreadsheet\demo\remote_central\[LabSamples2019.xlsx]person'!A8)," ",'C:\code\laboratoryspreadsheet\labspreadsheet\demo\remote_central\[LabSamples2019.xlsx]person'!A8) | B8: =IF(ISBLANK('C:\code\laboratoryspreadsheet\labspreadsheet\demo\remote_central\[LabSamples2019.xlsx]person'!B8)," ",'C:\code\laboratoryspreadsheet\labspreadsheet\demo\remote_central\[LabSamples2019.xlsx]person'!B8) | C8: =IF(ISBLANK('C:\code\laboratoryspreadsheet\labspreadsheet\demo\remote_central\[LabSamples2019.xlsx]person'!C8)," ",'C:\code\laboratoryspreadsheet\labspreadsheet\demo\remote_central\[LabSamples2019.xlsx]person'!C8) | D8: =IF(ISBLANK('C:\code\laboratoryspreadsheet\labspreadsheet\demo\remote_central\[LabSamples2019.xlsx]person'!D8)," ",'C:\code\laboratoryspreadsheet\labspreadsheet\demo\remote_central\[LabSamples2019.xlsx]person'!D8)
A9: =IF(ISBLANK('C:\code\laboratoryspreadsheet\labspreadsheet\demo\remote_central\[LabSamples2019.xlsx]person'!A9)," ",'C:\code\laboratoryspreadsheet\labspreadsheet\demo\remote_central\[LabSamples2019.xlsx]person'!A9) | B9: =IF(ISBLANK('C:\code\laboratoryspreadsheet\labspreadsheet\demo\remote_central\[LabSamples2019.xlsx]person'!B9)," ",'C:\code\laboratoryspreadsheet\labspreadsheet\demo\remote_central\[LabSamples2019.xlsx]person'!B9) | C9: =IF(ISBLANK('C:\code\laboratoryspreadsheet\labspreadsheet\demo\remote_central\[LabSamples2019.xlsx]person'!C9)," ",'C:\code\laboratoryspreadsheet\labspreadsheet\demo\remote_central\[LabSamples2019.xlsx]person'!C9) | D9: =IF(ISBLANK('C:\code\laboratoryspreadsheet\labspreadsheet\demo\remote_central\[LabSamples2019.xlsx]person'!D9)," ",'C:\code\laboratoryspreadsheet\labspreadsheet\demo\remote_central\[LabSamples2019.xlsx]person'!D9)
A10: =IF(ISBLANK('C:\code\laboratoryspreadsheet\labspreadsheet\demo\remote_central\[LabSamples2019.xlsx]person'!A10)," ",'C:\code\laboratoryspreadsheet\labspreadsheet\demo\remote_central\[LabSamples2019.xlsx]person'!A10) | B10: =IF(ISBLANK('C:\code\laboratoryspreadsheet\labspreadsheet\demo\remote_central\[LabSamples2019.xlsx]person'!B10)," ",'C:\code\laboratoryspreadsheet\labspreadsheet\demo\remote_central\[LabSamples2019.xlsx]person'!B10) | C10: =IF(ISBLANK('C:\code\laboratoryspreadsheet\labspreadsheet\demo\remote_central\[LabSamples2019.xlsx]person'!C10)," ",'C:\code\laboratoryspreadsheet\labspreadsheet\demo\remote_central\[LabSamples2019.xlsx]person'!C10) | D10: =IF(ISBLANK('C:\code\laboratoryspreadsheet\labspreadsheet\demo\remote_central\[LabSamples2019.xlsx]person'!D10)," ",'C:\code\laboratoryspreadsheet\labspreadsheet\demo\remote_central\[LabSamples2019.xlsx]person'!D10)
A11: =IF(ISBLANK('C:\code\laboratoryspreadsheet\labspreadsheet\demo\remote_central\[LabSamples2019.xlsx]person'!A11)," ",'C:\code\laboratoryspreadsheet\labspreadsheet\demo\remote_central\[LabSamples2019.xlsx]person'!A11) | B11: =IF(ISBLANK('C:\code\laboratoryspreadsheet\labspreadsheet\demo\remote_central\[LabSamples2019.xlsx]person'!B11)," ",'C:\code\laboratoryspreadsheet\labspreadsheet\demo\remote_central\[LabSamples2019.xlsx]person'!B11) | C11: =IF(ISBLANK('C:\code\laboratoryspreadsheet\labspreadsheet\demo\remote_central\[LabSamples2019.xlsx]person'!C11)," ",'C:\code\laboratoryspreadsheet\labspreadsheet\demo\remote_central\[LabSamples2019.xlsx]person'!C11) | D11: =IF(ISBLANK('C:\code\laboratoryspreadsheet\labspreadsheet\demo\remote_central\[LabSamples2019.xlsx]person'!D11)," ",'C:\code\laboratoryspreadsheet\labspreadsheet\demo\remote_central\[LabSamples2019.xlsx]person'!D11)
A12: =IF(ISBLANK('C:\code\laboratoryspreadsheet\labspreadsheet\demo\remote_central\[LabSamples2019.xlsx]person'!A12)," ",'C:\code\laboratoryspreadsheet\labspreadsheet\demo\remote_central\[LabSamples2019.xlsx]person'!A12) | B12: =IF(ISBLANK('C:\code\laboratoryspreadsheet\labspreadsheet\demo\remote_central\[LabSamples2019.xlsx]person'!B12)," ",'C:\code\laboratoryspreadsheet\labspreadsheet\demo\remote_central\[LabSamples2019.xlsx]person'!B12) | C12: =IF(ISBLANK('C:\code\laboratoryspreadsheet\labspreadsheet\demo\remote_central\[LabSamples2019.xlsx]person'!C12)," ",'C:\code\laboratoryspreadsheet\labspreadsheet\demo\remote_central\[LabSamples2019.xlsx]person'!C12) | D12: =IF(ISBLANK('C:\code\laboratoryspreadsheet\labspreadsheet\demo\remote_central\[LabSamples2019.xlsx]person'!D12)," ",'C:\code\laboratoryspreadsheet\labspreadsheet\demo\remote_central\[LabSamples2019.xlsx]person'!D12)
... A999: =IF(ISBLANK('C:\code\laboratoryspreadsheet\labspreadsheet\demo\remote_central\[LabSamples2019.xlsx]person'!A999)," ",'C:\code\laboratoryspreadsheet\labspreadsheet\demo\remote_central\[LabSamples2019.xlsx]person'!A999) | B999: =IF(ISBLANK('C:\code\laboratoryspreadsheet\labspreadsheet\demo\remote_central\[LabSamples2019.xlsx]person'!B999)," ",'C:\code\laboratoryspreadsheet\labspreadsheet\demo\remote_central\[LabSamples2019.xlsx]person'!B999) | C999: =IF(ISBLANK('C:\code\laboratoryspreadsheet\labspreadsheet\demo\remote_central\[LabSamples2019.xlsx]person'!C999)," ",'C:\code\laboratoryspreadsheet\labspreadsheet\demo\remote_central\[LabSamples2019.xlsx]person'!C999) | D999: =IF(ISBLANK('C:\code\laboratoryspreadsheet\labspreadsheet\demo\remote_central\[LabSamples2019.xlsx]person'!D999)," ",'C:\code\laboratoryspreadsheet\labspreadsheet\demo\remote_central\[LabSamples2019.xlsx]person'!D999)

Sheet person_db
A1: =IF(ISBLANK('C:\code\laboratoryspreadsheet\labspreadsheet\demo\remote_central\[LabSamples2019.xlsx]person_db'!A1)," ",'C:\code\laboratoryspreadsheet\labspreadsheet\demo\remote_central\[LabSamples2019.xlsx]person_db'!A1) | B1: =IF(ISBLANK('C:\code\laboratoryspreadsheet\labspreadsheet\demo\remote_central\[LabSamples2019.xlsx]person_db'!B1)," ",'C:\code\laboratoryspreadsheet\labspreadsheet\demo\remote_central\[LabSamples2019.xlsx]person_db'!B1) | C1: =IF(ISBLANK('C:\code\laboratoryspreadsheet\labspreadsheet\demo\remote_central\[LabSamples2019.xlsx]person_db'!C1)," ",'C:\code\laboratoryspreadsheet\labspreadsheet\demo\remote_central\[LabSamples2019.xlsx]person_db'!C1) | D1: =IF(ISBLANK('C:\code\laboratoryspreadsheet\labspreadsheet\demo\remote_central\[LabSamples2019.xlsx]person_db'!D1)," ",'C:\code\laboratoryspreadsheet\labspreadsheet\demo\remote_central\[LabSamples2019.xlsx]person_db'!D1)
A2: =IF(ISBLANK('C:\code\laboratoryspreadsheet\labspreadsheet\demo\remote_central\[LabSamples2019.xlsx]person_db'!A2)," ",'C:\code\laboratoryspreadsheet\labspreadsheet\demo\remote_central\[LabSamples2019.xlsx]person_db'!A2) | B2: =IF(ISBLANK('C:\code\laboratoryspreadsheet\labspreadsheet\demo\remote_central\[LabSamples2019.xlsx]person_db'!B2)," ",'C:\code\laboratoryspreadsheet\labspreadsheet\demo\remote_central\[LabSamples2019.xlsx]person_db'!B2) | C2: =IF(ISBLANK('C:\code\laboratoryspreadsheet\labspreadsheet\demo\remote_central\[LabSamples2019.xlsx]person_db'!C2)," ",'C:\code\laboratoryspreadsheet\labspreadsheet\demo\remote_central\[LabSamples2019.xlsx]person_db'!C2) | D2: =IF(ISBLANK('C:\code\laboratoryspreadsheet\labspreadsheet\demo\remote_central\[LabSamples2019.xlsx]person_db'!D2)," ",'C:\code\laboratoryspreadsheet\labspreadsheet\demo\remote_central\[LabSamples2019.xlsx]person_db'!D2)
A3: =IF(ISBLANK('C:\code\laboratoryspreadsheet\labspreadsheet\demo\remote_central\[LabSamples2019.xlsx]person_db'!A3)," ",'C:\code\laboratoryspreadsheet\labspreadsheet\demo\remote_central\[LabSamples2019.xlsx]person_db'!A3) | B3: =IF(ISBLANK('C:\code\laboratoryspreadsheet\labspreadsheet\demo\remote_central\[LabSamples2019.xlsx]person_db'!B3)," ",'C:\code\laboratoryspreadsheet\labspreadsheet\demo\remote_central\[LabSamples2019.xlsx]person_db'!B3) | C3: =IF(ISBLANK('C:\code\laboratoryspreadsheet\labspreadsheet\demo\remote_central\[LabSamples2019.xlsx]person_db'!C3)," ",'C:\code\laboratoryspreadsheet\labspreadsheet\demo\remote_central\[LabSamples2019.xlsx]person_db'!C3) | D3: =IF(ISBLANK('C:\code\laboratoryspreadsheet\labspreadsheet\demo\remote_central\[LabSamples2019.xlsx]person_db'!D3)," ",'C:\code\laboratoryspreadsheet\labspreadsheet\demo\remote_central\[LabSamples2019.xlsx]person_db'!D3)
A4: =IF(ISBLANK('C:\code\laboratoryspreadsheet\labspreadsheet\demo\remote_central\[LabSamples2019.xlsx]person_db'!A4)," ",'C:\code\laboratoryspreadsheet\labspreadsheet\demo\remote_central\[LabSamples2019.xlsx]person_db'!A4) | B4: =IF(ISBLANK('C:\code\laboratoryspreadsheet\labspreadsheet\demo\remote_central\[LabSamples2019.xlsx]person_db'!B4)," ",'C:\code\laboratoryspreadsheet\labspreadsheet\demo\remote_central\[LabSamples2019.xlsx]person_db'!B4) | C4: =IF(ISBLANK('C:\code\laboratoryspreadsheet\labspreadsheet\demo\remote_central\[LabSamples2019.xlsx]person_db'!C4)," ",'C:\code\laboratoryspreadsheet\labspreadsheet\demo\remote_central\[LabSamples2019.xlsx]person_db'!C4) | D4: =IF(ISBLANK('C:\code\laboratoryspreadsheet\labspreadsheet\demo\remote_central\[LabSamples2019.xlsx]person_db'!D4)," ",'C:\code\laboratoryspreadsheet\labspreadsheet\demo\remote_central\[LabSamples2019.xlsx]person_db'!D4)
A5: =IF(ISBLANK('C:\code\laboratoryspreadsheet\labspreadsheet\demo\remote_central\[LabSamples2019.xlsx]person_db'!A5)," ",'C:\code\laboratoryspreadsheet\labspreadsheet\demo\remote_central\[LabSamples2019.xlsx]person_db'!A5) | B5: =IF(ISBLANK('C:\code\laboratoryspreadsheet\labspreadsheet\demo\remote_central\[LabSamples2019.xlsx]person_db'!B5)," ",'C:\code\laboratoryspreadsheet\labspreadsheet\demo\remote_central\[LabSamples2019.xlsx]person_db'!B5) | C5: =IF(ISBLANK('C:\code\laboratoryspreadsheet\labspreadsheet\demo\remote_central\[LabSamples2019.xlsx]person_db'!C5)," ",'C:\code\laboratoryspreadsheet\labspreadsheet\demo\remote_central\[LabSamples2019.xlsx]person_db'!C5) | D5: =IF(ISBLANK('C:\code\laboratoryspreadsheet\labspreadsheet\demo\remote_central\[LabSamples2019.xlsx]person_db'!D5)," ",'C:\code\laboratoryspreadsheet\labspreadsheet\demo\remote_central\[LabSamples2019.xlsx]person_db'!D5)
A6: =IF(ISBLANK('C:\code\laboratoryspreadsheet\labspreadsheet\demo\remote_central\[LabSamples2019.xlsx]person_db'!A6)," ",'C:\code\laboratoryspreadsheet\labspreadsheet\demo\remote_central\[LabSamples2019.xlsx]person_db'!A6) | B6: =IF(ISBLANK('C:\code\laboratoryspreadsheet\labspreadsheet\demo\remote_central\[LabSamples2019.xlsx]person_db'!B6)," ",'C:\code\laboratoryspreadsheet\labspreadsheet\demo\remote_central\[LabSamples2019.xlsx]person_db'!B6) | C6: =IF(ISBLANK('C:\code\laboratoryspreadsheet\labspreadsheet\demo\remote_central\[LabSamples2019.xlsx]person_db'!C6)," ",'C:\code\laboratoryspreadsheet\labspreadsheet\demo\remote_central\[LabSamples2019.xlsx]person_db'!C6) | D6: =IF(ISBLANK('C:\code\laboratoryspreadsheet\labspreadsheet\demo\remote_central\[LabSamples2019.xlsx]person_db'!D6)," ",'C:\code\laboratoryspreadsheet\labspreadsheet\demo\remote_central\[LabSamples2019.xlsx]person_db'!D6)
A7: =IF(ISBLANK('C:\code\laboratoryspreadsheet\labspreadsheet\demo\remote_central\[LabSamples2019.xlsx]person_db'!A7)," ",'C:\code\laboratoryspreadsheet\labspreadsheet\demo\remote_central\[LabSamples2019.xlsx]person_db'!A7) | B7: =IF(ISBLANK('C:\code\laboratoryspreadsheet\labspreadsheet\demo\remote_central\[LabSamples2019.xlsx]person_db'!B7)," ",'C:\code\laboratoryspreadsheet\labspreadsheet\demo\remote_central\[LabSamples2019.xlsx]person_db'!B7) | C7: =IF(ISBLANK('C:\code\laboratoryspreadsheet\labspreadsheet\demo\remote_central\[LabSamples2019.xlsx]person_db'!C7)," ",'C:\code\laboratoryspreadsheet\labspreadsheet\demo\remote_central\[LabSamples2019.xlsx]person_db'!C7) | D7: =IF(ISBLANK('C:\code\laboratoryspreadsheet\labspreadsheet\demo\remote_central\[LabSamples2019.xlsx]person_db'!D7)," ",'C:\code\laboratoryspreadsheet\labspreadsheet\demo\remote_central\[LabSamples2019.xlsx]person_db'!D7)
A8: =IF(ISBLANK('C:\code\laboratoryspreadsheet\labspreadsheet\demo\remote_central\[LabSamples2019.xlsx]person_db'!A8)," ",'C:\code\laboratoryspreadsheet\labspreadsheet\demo\remote_central\[LabSamples2019.xlsx]person_db'!A8) | B8: =IF(ISBLANK('C:\code\laboratoryspreadsheet\labspreadsheet\demo\remote_central\[LabSamples2019.xlsx]person_db'!B8)," ",'C:\code\laboratoryspreadsheet\labspreadsheet\demo\remote_central\[LabSamples2019.xlsx]person_db'!B8) | C8: =IF(ISBLANK('C:\code\laboratoryspreadsheet\labspreadsheet\demo\remote_central\[LabSamples2019.xlsx]person_db'!C8)," ",'C:\code\laboratoryspreadsheet\labspreadsheet\demo\remote_central\[LabSamples2019.xlsx]person_db'!C8) | D8: =IF(ISBLANK('C:\code\laboratoryspreadsheet\labspreadsheet\demo\remote_central\[LabSamples2019.xlsx]person_db'!D8)," ",'C:\code\laboratoryspreadsheet\labspreadsheet\demo\remote_central\[LabSamples2019.xlsx]person_db'!D8)
A9: =IF(ISBLANK('C:\code\laboratoryspreadsheet\labspreadsheet\demo\remote_central\[LabSamples2019.xlsx]person_db'!A9)," ",'C:\code\laboratoryspreadsheet\labspreadsheet\demo\remote_central\[LabSamples2019.xlsx]person_db'!A9) | B9: =IF(ISBLANK('C:\code\laboratoryspreadsheet\labspreadsheet\demo\remote_central\[LabSamples2019.xlsx]person_db'!B9)," ",'C:\code\laboratoryspreadsheet\labspreadsheet\demo\remote_central\[LabSamples2019.xlsx]person_db'!B9) | C9: =IF(ISBLANK('C:\code\laboratoryspreadsheet\labspreadsheet\demo\remote_central\[LabSamples2019.xlsx]person_db'!C9)," ",'C:\code\laboratoryspreadsheet\labspreadsheet\demo\remote_central\[LabSamples2019.xlsx]person_db'!C9) | D9: =IF(ISBLANK('C:\code\laboratoryspreadsheet\labspreadsheet\demo\remote_central\[LabSamples2019.xlsx]person_db'!D9)," ",'C:\code\laboratoryspreadsheet\labspreadsheet\demo\remote_central\[LabSamples2019.xlsx]person_db'!D9)
A10: =IF(ISBLANK('C:\code\laboratoryspreadsheet\labspreadsheet\demo\remote_central\[LabSamples2019.xlsx]person_db'!A10)," ",'C:\code\laboratoryspreadsheet\labspreadsheet\demo\remote_central\[LabSamples2019.xlsx]person_db'!A10) | B10: =IF(ISBLANK('C:\code\laboratoryspreadsheet\labspreadsheet\demo\remote_central\[LabSamples2019.xlsx]person_db'!B10)," ",'C:\code\laboratoryspreadsheet\labspreadsheet\demo\remote_central\[LabSamples2019.xlsx]person_db'!B10) | C10: =IF(ISBLANK('C:\code\laboratoryspreadsheet\labspreadsheet\demo\remote_central\[LabSamples2019.xlsx]person_db'!C10)," ",'C:\code\laboratoryspreadsheet\labspreadsheet\demo\remote_central\[LabSamples2019.xlsx]person_db'!C10) | D10: =IF(ISBLANK('C:\code\laboratoryspreadsheet\labspreadsheet\demo\remote_central\[LabSamples2019.xlsx]person_db'!D10)," ",'C:\code\laboratoryspreadsheet\labspreadsheet\demo\remote_central\[LabSamples2019.xlsx]person_db'!D10)
A11: =IF(ISBLANK('C:\code\laboratoryspreadsheet\labspreadsheet\demo\remote_central\[LabSamples2019.xlsx]person_db'!A11)," ",'C:\code\laboratoryspreadsheet\labspreadsheet\demo\remote_central\[LabSamples2019.xlsx]person_db'!A11) | B11: =IF(ISBLANK('C:\code\laboratoryspreadsheet\labspreadsheet\demo\remote_central\[LabSamples2019.xlsx]person_db'!B11)," ",'C:\code\laboratoryspreadsheet\labspreadsheet\demo\remote_central\[LabSamples2019.xlsx]person_db'!B11) | C11: =IF(ISBLANK('C:\code\laboratoryspreadsheet\labspreadsheet\demo\remote_central\[LabSamples2019.xlsx]person_db'!C11)," ",'C:\code\laboratoryspreadsheet\labspreadsheet\demo\remote_central\[LabSamples2019.xlsx]person_db'!C11) | D11: =IF(ISBLANK('C:\code\laboratoryspreadsheet\labspreadsheet\demo\remote_central\[LabSamples2019.xlsx]person_db'!D11)," ",'C:\code\laboratoryspreadsheet\labspreadsheet\demo\remote_central\[LabSamples2019.xlsx]person_db'!D11)
A12: =IF(ISBLANK('C:\code\laboratoryspreadsheet\labspreadsheet\demo\remote_central\[LabSamples2019.xlsx]person_db'!A12)," ",'C:\code\laboratoryspreadsheet\labspreadsheet\demo\remote_central\[LabSamples2019.xlsx]person_db'!A12) | B12: =IF(ISBLANK('C:\code\laboratoryspreadsheet\labspreadsheet\demo\remote_central\[LabSamples2019.xlsx]person_db'!B12)," ",'C:\code\laboratoryspreadsheet\labspreadsheet\demo\remote_central\[LabSamples2019.xlsx]person_db'!B12) | C12: =IF(ISBLANK('C:\code\laboratoryspreadsheet\labspreadsheet\demo\remote_central\[LabSamples2019.xlsx]person_db'!C12)," ",'C:\code\laboratoryspreadsheet\labspreadsheet\demo\remote_central\[LabSamples2019.xlsx]person_db'!C12) | D12: =IF(ISBLANK('C:\code\laboratoryspreadsheet\labspreadsheet\demo\remote_central\[LabSamples2019.xlsx]person_db'!D12)," ",'C:\code\laboratoryspreadsheet\labspreadsheet\demo\remote_central\[LabSamples2019.xlsx]person_db'!D12)
... A999: =IF(ISBLANK('C:\code\laboratoryspreadsheet\labspreadsheet\demo\remote_central\[LabSamples2019.xlsx]person_db'!A999)," ",'C:\code\laboratoryspreadsheet\labspreadsheet\demo\remote_central\[LabSamples2019.xlsx]person_db'!A999) | B999: =IF(ISBLANK('C:\code\laboratoryspreadsheet\labspreadsheet\demo\remote_central\[LabSamples2019.xlsx]person_db'!B999)," ",'C:\code\laboratoryspreadsheet\labspreadsheet\demo\remote_central\[LabSamples2019.xlsx]person_db'!B999) | C999: =IF(ISBLANK('C:\code\laboratoryspreadsheet\labspreadsheet\demo\remote_central\[LabSamples2019.xlsx]person_db'!C999)," ",'C:\code\laboratoryspreadsheet\labspreadsheet\demo\remote_central\[LabSamples2019.xlsx]person_db'!C999) | D999: =IF(ISBLANK('C:\code\laboratoryspreadsheet\labspreadsheet\demo\remote_central\[LabSamples2019.xlsx]person_db'!D999)," ",'C:\code\laboratoryspreadsheet\labspreadsheet\demo\remote_central\[LabSamples2019.xlsx]person_db'!D999)

Sheet person_drop
A1: =COUNTIF(person_db!$B$2:$B$1000,">""") | B1: 0
B2: 1 | C2: =B2<=A1 | D2: =IF(C2,INDIRECT("person_db!B"&(B2+1)),INDIRECT("person!B"&(B2-$A$1+1)))
B3: 2 | C3: =B3<=A1 | D3: =IF(C3,INDIRECT("person_db!B"&(B3+1)),INDIRECT("person!B"&(B3-$A$1+1)))
B4: 3 | C4: =B4<=A1 | D4: =IF(C4,INDIRECT("person_db!B"&(B4+1)),INDIRECT("person!B"&(B4-$A$1+1)))
B5: 4 | C5: =B5<=A1 | D5: =IF(C5,INDIRECT("person_db!B"&(B5+1)),INDIRECT("person!B"&(B5-$A$1+1)))
B6: 5 | C6: =B6<=A1 | D6: =IF(C6,INDIRECT("person_db!B"&(B6+1)),INDIRECT("person!B"&(B6-$A$1+1)))
B7: 6 | C7: =B7<=A1 | D7: =IF(C7,INDIRECT("person_db!B"&(B7+1)),INDIRECT("person!B"&(B7-$A$1+1)))
B8: 7 | C8: =B8<=A1 | D8: =IF(C8,INDIRECT("person_db!B"&(B8+1)),INDIRECT("person!B"&(B8-$A$1+1)))
B9: 8 | C9: =B9<=A1 | D9: =IF(C9,INDIRECT("person_db!B"&(B9+1)),INDIRECT("person!B"&(B9-$A$1+1)))
B10: 9 | C10: =B10<=A1 | D10: =IF(C10,INDIRECT("person_db!B"&(B10+1)),INDIRECT("person!B"&(B10-$A$1+1)))
B11: 10 | C11: =B11<=A1 | D11: =IF(C11,INDIRECT("person_db!B"&(B11+1)),INDIRECT("person!B"&(B11-$A$1+1)))
B12: 11 | C12: =B12<=A1 | D12: =IF(C12,INDIRECT("person_db!B"&(B12+1)),INDIRECT("person!B"&(B12-$A$1+1)))
B13: 12 | C13: =B13<=A1 | D13: =IF(C13,INDIRECT("person_db!B"&(B13+1)),INDIRECT("person!B"&(B13-$A$1+1)))
B14: 13 | C14: =B14<=A1 | D14: =IF(C14,INDIRECT("person_db!B"&(B14+1)),INDIRECT("person!B"&(B14-$A$1+1)))
B15: 14 | C15: =B15<=A1 | D15: =IF(C15,INDIRECT("person_db!B"&(B15+1)),INDIRECT("person!B"&(B15-$A$1+1)))
B16: 15 | C16: =B16<=A1 | D16: =IF(C16,INDIRECT("person_db!B"&(B16+1)),INDIRECT("person!B"&(B16-$A$1+1)))
B17: 16 | C17: =B17<=A1 | D17: =IF(C17,INDIRECT("person_db!B"&(B17+1)),INDIRECT("person!B"&(B17-$A$1+1)))
B18: 17 | C18: =B18<=A1 | D18: =IF(C18,INDIRECT("person_db!B"&(B18+1)),INDIRECT("person!B"&(B18-$A$1+1)))
B19: 18 | C19: =B19<=A1 | D19: =IF(C19,INDIRECT("person_db!B"&(B19+1)),INDIRECT("person!B"&(B19-$A$1+1)))
B20: 19 | C20: =B20<=A1 | D20: =IF(C20,INDIRECT("person_db!B"&(B20+1)),INDIRECT("person!B"&(B20-$A$1+1)))
B21: 20 | C21: =B21<=A1 | D21: =IF(C21,INDIRECT("person_db!B"&(B21+1)),INDIRECT("person!B"&(B21-$A$1+1)))
B22: 21 | C22: =B22<=A1 | D22: =IF(C22,INDIRECT("person_db!B"&(B22+1)),INDIRECT("person!B"&(B22-$A$1+1)))
B23: 22 | C23: =B23<=A1 | D23: =IF(C23,INDIRECT("person_db!B"&(B23+1)),INDIRECT("person!B"&(B23-$A$1+1)))
B24: 23 | C24: =B24<=A1 | D24: =IF(C24,INDIRECT("person_db!B"&(B24+1)),INDIRECT("person!B"&(B24-$A$1+1)))
B25: 24 | C25: =B25<=A1 | D25: =IF(C25,INDIRECT("person_db!B"&(B25+1)),INDIRECT("person!B"&(B25-$A$1+1)))
B26: 25 | C26: =B26<=A1 | D26: =IF(C26,INDIRECT("person_db!B"&(B26+1)),INDIRECT("person!B"&(B26-$A$1+1)))
B27: 26 | C27: =B27<=A1 | D27: =IF(C27,INDIRECT("person_db!B"&(B27+1)),INDIRECT("person!B"&(B27-$A$1+1)))
B28: 27 | C28: =B28<=A1 | D28: =IF(C28,INDIRECT("person_db!B"&(B28+1)),INDIRECT("person!B"&(B28-$A$1+1)))
B29: 28 | C29: =B29<=A1 | D29: =IF(C29,INDIRECT("person_db!B"&(B29+1)),INDIRECT("person!B"&(B29-$A$1+1)))
B30: 29 | C30: =B30<=A1 | D30: =IF(C30,INDIRECT("person_db!B"&(B30+1)),INDIRECT("person!B"&(B30-$A$1+1)))
B31: 30 | C31: =B31<=A1 | D31: =IF(C31,INDIRECT("person_db!B"&(B31+1)),INDIRECT("person!B"&(B31-$A$1+1)))
B32: 31 | C32: =B32<=A1 | D32: =IF(C32,INDIRECT("person_db!B"&(B32+1)),INDIRECT("person!B"&(B32-$A$1+1)))
B33: 32 | C33: =B33<=A1 | D33: =IF(C33,INDIRECT("person_db!B"&(B33+1)),INDIRECT("person!B"&(B33-$A$1+1)))
B34: 33 | C34: =B34<=A1 | D34: =IF(C34,INDIRECT("person_db!B"&(B34+1)),INDIRECT("person!B"&(B34-$A$1+1)))
B35: 34 | C35: =B35<=A1 | D35: =IF(C35,INDIRECT("person_db!B"&(B35+1)),INDIRECT("person!B"&(B35-$A$1+1)))
B36: 35 | C36: =B36<=A1 | D36: =IF(C36,INDIRECT("person_db!B"&(B36+1)),INDIRECT("person!B"&(B36-$A$1+1)))
B37: 36 | C37: =B37<=A1 | D37: =IF(C37,INDIRECT("person_db!B"&(B37+1)),INDIRECT("person!B"&(B37-$A$1+1)))
B38: 37 | C38: =B38<=A1 | D38: =IF(C38,INDIRECT("person_db!B"&(B38+1)),INDIRECT("person!B"&(B38-$A$1+1)))
B39: 38 | C39: =B39<=A1 | D39: =IF(C39,INDIRECT("person_db!B"&(B39+1)),INDIRECT("person!B"&(B39-$A$1+1)))
B40: 39 | C40: =B40<=A1 | D40: =IF(C40,INDIRECT("person_db!B"&(B40+1)),INDIRECT("person!B"&(B40-$A$1+1)))
...

Sheet Area
A1: Bathroom | B1: DiningRoom | C1: Kitchen
A2: WC | B2: Bar | C2: Bench
B3: DiningArea | C3: DiningArea

Sheet Setup
A1: Bathroom:WC | B1: DiningRoom:Bar | C1: DiningRoom:DiningArea | D1: Kitchen:Bench | E1: Kitchen:DiningArea
A2: Toilett | B2: Commode | C2: Table | D2: Sink | E2: Table
D3: Dischwascher | E3: Chair

Sheet Comp
A1: Bathroom:WC:Toilett | B1: DiningRoom:Bar:Commode | C1: DiningRoom:DiningArea:Table | D1: Kitchen:Bench:Dischwascher | E1: Kitchen:Bench:Sink | F1: Kitchen:DiningArea:Chair | G1: Kitchen:DiningArea:Table
A2: Toilett_Schüssel | B2: Glassware | C2: Leg1 | D2: Door | E2: Tap | F2: Leg1 | G2: Leg1
B3: Liquor | C3: Leg2 | E3: Drain
E4: Overflow

Sheet extra_Hob
A1: Hob | B1: 2019
A2: Responsible: | B2: =HYPERLINK("mailto:bilbo.baggins@miskatonic.edu?subject=[Lab samples]", "bilbo.baggins@miskatonic.edu")
A3: Results: | B3: =HYPERLINK("C:\code\laboratoryspreadsheet\labspreadsheet\demo\remote_Hobbit\LabResults2019_Hob.xlsx#Hob!A1","LabResults2019_Hob.xlsx")
B4: =HYPERLINK("C:\code\laboratoryspreadsheet\labspreadsheet\demo\remote_Hobbit\LabResults2019_Hob_extra.xlsx#extra_Hob!A1","LabResults2019_Hob_extra.xlsx")
A5: Sample ID | C5: Site | G5: Sample | M5: Comment | N5: Communication | O5: Analysis | Q5: Expected value of measured variable | AW5: ConcatID | BA5: Number of options
A6: Project ID | B6: Number | C6: Room | D6: Area | E6: Setup | F6: Component | G6: Date | H6: Time | I6: Sampling method | J6: Filter at sampling | K6: Dilution at sampling | L6: Who (S) | O6: Date | P6: Who (A) | Q6: DOC | R6: TOC | S6: TIC | T6: Ntot | U6: Cl | V6: NO2-N | W6: NO3-N | X6: PO4-P | Y6: SO4 | Z6: Na | AA6: NH4-N | AB6: K | AC6: Ca | AD6: Mg | AE6: Ptot | AF6: Urea | AG6: CODsol | AH6: CODtot | AI6: Alkalinity | AJ6: Conductivity | AK6: pH | AL6: Dissolved Oxygen | AM6: Turbidity | AN6: BOD5 | AO6: TSS | AP6: VSS | AQ6: TCC | AR6: ICC | AS6: ATP | AT6: Nanodrop | AU6: TSS63 | BA6: Area | BB6: Setup | BC6: Component
A7: [##] | B7: [yysss] | G7: [dd.mm.yyyy] | H7: [HH:MM:SS] | K7: [total vol/sample vol] | O7: [dd.mm.yyyy] | Q7: mg/L | R7: mg/L | S7: mg/L | T7: mg/L | U7: mg/L | V7: mg/L | W7: mg/L | X7: mg/L | Y7: mg/L | Z7: mg/L | AA7: mg/L | AB7: mg/L | AC7: mg/L | AD7: mg/L | AE7: mg/L | AF7: mgN/L | AG7: mg/L | AH7: mg/L | AI7: mmol/L | AJ7: microS/cm | AK7: 1 | AL7: mg/L | AM7: NTU | AN7: mg/L | AO7: mg/L | AP7: mg/L | AQ7: #/mL | AR7: #/mL | AS7: gATP/gGAC | AT7: ng/ml | AU7: mg/L
A8: Text | B8: Text | C8: Dropdown | D8: Dropdown | E8: Dropdown | F8: Dropdown | G8: Text | H8: Text | I8: Dropdown | J8: Dropdown | K8: Text | L8: Text | O8: Text | P8: Text | Q8: Text | R8: Text | S8: Text | T8: Text | U8: Text | V8: Text | W8: Text | X8: Text | Y8: Text | Z8: Text | AA8: Text | AB8: Text | AC8: Text | AD8: Text | AE8: Text | AF8: Text | AG8: Text | AH8: Text | AI8: Text | AJ8: Text | AK8: Text | AL8: Text | AM8: Text | AN8: Text | AO8: Text | AP8: Text | AQ8: Text | AR8: Text | AS8: Text | AT8: Text | AU8: Text
AW9: =CONCATENATE(A9,B9) | BA9: =IF(COUNTBLANK(C9)=0,COUNTA(INDIRECT(CONCATENATE("Area!",SUBSTITUTE(ADDRESS(1,MATCH(C9,Area!$1:$1,0),4),"1",""),"2:",SUBSTITUTE(ADDRESS(1,MATCH(C9,Area!$1:$1,0),4),"1",""),"99"))),0) | BB9: =IF(COUNTBLANK(D9)=0,COUNTA(INDIRECT(CONCATENATE("Setup!",SUBSTITUTE(ADDRESS(1,MATCH(CONCATENATE(C9,":",D9),Setup!$1:$1,0),4),"1",""),"2:",SUBSTITUTE(ADDRESS(1,MATCH(CONCATENATE(C9,":",D9),Setup!$1:$1,0),4),"1",""),"99"))),0) | BC9: =IF(COUNTBLANK(E9)=0,COUNTA(INDIRECT(CONCATENATE("Comp!",SUBSTITUTE(ADDRESS(1,MATCH(CONCATENATE(C9,":",D9,":",E9),Comp!$1:$1,0),4),"1",""),"2:",SUBSTITUTE(ADDRESS(1,MATCH(CONCATENATE(C9,":",D9,":",E9),Comp!$1:$1,0),4),"1",""),"99"))),0)
AW10: =CONCATENATE(A10,B10) | BA10: =IF(COUNTBLANK(C10)=0,COUNTA(INDIRECT(CONCATENATE("Area!",SUBSTITUTE(ADDRESS(1,MATCH(C10,Area!$1:$1,0),4),"1",""),"2:",SUBSTITUTE(ADDRESS(1,MATCH(C10,Area!$1:$1,0),4),"1",""),"99"))),0) | BB10: =IF(COUNTBLANK(D10)=0,COUNTA(INDIRECT(CONCATENATE("Setup!",SUBSTITUTE(ADDRESS(1,MATCH(CONCATENATE(C10,":",D10),Setup!$1:$1,0),4),"1",""),"2:",SUBSTITUTE(ADDRESS(1,MATCH(CONCATENATE(C10,":",D10),Setup!$1:$1,0),4),"1",""),"99"))),0) | BC10: =IF(COUNTBLANK(E10)=0,COUNTA(INDIRECT(CONCATENATE("Comp!",SUBSTITUTE(ADDRESS(1,MATCH(CONCATENATE(C10,":",D10,":",E10),Comp!$1:$1,0),4),"1",""),"2:",SUBSTITUTE(ADDRESS(1,MATCH(CONCATENATE(C10,":",D10,":",E10),Comp!$1:$1,0),4),"1",""),"99"))),0)
AW11: =CONCATENATE(A11,B11) | BA11: =IF(COUNTBLANK(C11)=0,COUNTA(INDIRECT(CONCATENATE("Area!",SUBSTITUTE(ADDRESS(1,MATCH(C11,Area!$1:$1,0),4),"1",""),"2:",SUBSTITUTE(ADDRESS(1,MATCH(C11,Area!$1:$1,0),4),"1",""),"99"))),0) | BB11: =IF(COUNTBLANK(D11)=0,COUNTA(INDIRECT(CONCATENATE("Setup!",SUBSTITUTE(ADDRESS(1,MATCH(CONCATENATE(C11,":",D11),Setup!$1:$1,0),4),"1",""),"2:",SUBSTITUTE(ADDRESS(1,MATCH(CONCATENATE(C11,":",D11),Setup!$1:$1,0),4),"1",""),"99"))),0) | BC11: =IF(COUNTBLANK(E11)=0,COUNTA(INDIRECT(CONCATENATE("Comp!",SUBSTITUTE(ADDRESS(1,MATCH(CONCATENATE(C11,":",D11,":",E11),Comp!$1:$1,0),4),"1",""),"2:",SUBSTITUTE(ADDRESS(1,MATCH(CONCATENATE(C11,":",D11,":",E11),Comp!$1:$1,0),4),"1",""),"99"))),0)
AW12: =CONCATENATE(A12,B12) | BA12: =IF(COUNTBLANK(C12)=0,COUNTA(INDIRECT(CONCATENATE("Area!",SUBSTITUTE(ADDRESS(1,MATCH(C12,Area!$1:$1,0),4),"1",""),"2:",SUBSTITUTE(ADDRESS(1,MATCH(C12,Area!$1:$1,0),4),"1",""),"99"))),0) | BB12: =IF(COUNTBLANK(D12)=0,COUNTA(INDIRECT(CONCATENATE("Setup!",SUBSTITUTE(ADDRESS(1,MATCH(CONCATENATE(C12,":",D12),Setup!$1:$1,0),4),"1",""),"2:",SUBSTITUTE(ADDRESS(1,MATCH(CONCATENATE(C12,":",D12),Setup!$1:$1,0),4),"1",""),"99"))),0) | BC12: =IF(COUNTBLANK(E12)=0,COUNTA(INDIRECT(CONCATENATE("Comp!",SUBSTITUTE(ADDRESS(1,MATCH(CONCATENATE(C12,":",D12,":",E12),Comp!$1:$1,0),4),"1",""),"2:",SUBSTITUTE(ADDRESS(1,MATCH(CONCATENATE(C12,":",D12,":",E12),Comp!$1:$1,0),4),"1",""),"99"))),0)
AW13: =CONCATENATE(A13,B13) | BA13: =IF(COUNTBLANK(C13)=0,COUNTA(INDIRECT(CONCATENATE("Area!",SUBSTITUTE(ADDRESS(1,MATCH(C13,Area!$1:$1,0),4),"1",""),"2:",SUBSTITUTE(ADDRESS(1,MATCH(C13,Area!$1:$1,0),4),"1",""),"99"))),0) | BB13: =IF(COUNTBLANK(D13)=0,COUNTA(INDIRECT(CONCATENATE("Setup!",SUBSTITUTE(ADDRESS(1,MATCH(CONCATENATE(C13,":",D13),Setup!$1:$1,0),4),"1",""),"2:",SUBSTITUTE(ADDRESS(1,MATCH(CONCATENATE(C13,":",D13),Setup!$1:$1,0),4),"1",""),"99"))),0) | BC13: =IF(COUNTBLANK(E13)=0,COUNTA(INDIRECT(CONCATENATE("Comp!",SUBSTITUTE(ADDRESS(1,MATCH(CONCATENATE(C13,":",D13,":",E13),Comp!$1:$1,0),4),"1",""),"2:",SUBSTITUTE(ADDRESS(1,MATCH(CONCATENATE(C13,":",D13,":",E13),Comp!$1:$1,0),4),"1",""),"99"))),0)
AW14: =CONCATENATE(A14,B14) | BA14: =IF(COUNTBLANK(C14)=0,COUNTA(INDIRECT(CONCATENATE("Area!",SUBSTITUTE(ADDRESS(1,MATCH(C14,Area!$1:$1,0),4),"1",""),"2:",SUBSTITUTE(ADDRESS(1,MATCH(C14,Area!$1:$1,0),4),"1",""),"99"))),0) | BB14: =IF(COUNTBLANK(D14)=0,COUNTA(INDIRECT(CONCATENATE("Setup!",SUBSTITUTE(ADDRESS(1,MATCH(CONCATENATE(C14,":",D14),Setup!$1:$1,0),4),"1",""),"2:",SUBSTITUTE(ADDRESS(1,MATCH(CONCATENATE(C14,":",D14),Setup!$1:$1,0),4),"1",""),"99"))),0) | BC14: =IF(COUNTBLANK(E14)=0,COUNTA(INDIRECT(CONCATENATE("Comp!",SUBSTITUTE(ADDRESS(1,MATCH(CONCATENATE(C14,":",D14,":",E14),Comp!$1:$1,0),4),"1",""),"2:",SUBSTITUTE(ADDRESS(1,MATCH(CONCATENATE(C14,":",D14,":",E14),Comp!$1:$1,0),4),"1",""),"99"))),0)
AW15: =CONCATENATE(A15,B15) | BA15: =IF(COUNTBLANK(C15)=0,COUNTA(INDIRECT(CONCATENATE("Area!",SUBSTITUTE(ADDRESS(1,MATCH(C15,Area!$1:$1,0),4),"1",""),"2:",SUBSTITUTE(ADDRESS(1,MATCH(C15,Area!$1:$1,0),4),"1",""),"99"))),0) | BB15: =IF(COUNTBLANK(D15)=0,COUNTA(INDIRECT(CONCATENATE("Setup!",SUBSTITUTE(ADDRESS(1,MATCH(CONCATENATE(C15,":",D15),Setup!$1:$1,0),4),"1",""),"2:",SUBSTITUTE(ADDRESS(1,MATCH(CONCATENATE(C15,":",D15),Setup!$1:$1,0),4),"1",""),"99"))),0) | BC15: =IF(COUNTBLANK(E15)=0,COUNTA(INDIRECT(CONCATENATE("Comp!",SUBSTITUTE(ADDRESS(1,MATCH(CONCATENATE(C15,":",D15,":",E15),Comp!$1:$1,0),4),"1",""),"2:",SUBSTITUTE(ADDRESS(1,MATCH(CONCATENATE(C15,":",D15,":",E15),Comp!$1:$1,0),4),"1",""),"99"))),0)
AW16: =CONCATENATE(A16,B16) | BA16: =IF(COUNTBLANK(C16)=0,COUNTA(INDIRECT(CONCATENATE("Area!",SUBSTITUTE(ADDRESS(1,MATCH(C16,Area!$1:$1,0),4),"1",""),"2:",SUBSTITUTE(ADDRESS(1,MATCH(C16,Area!$1:$1,0),4),"1",""),"99"))),0) | BB16: =IF(COUNTBLANK(D16)=0,COUNTA(INDIRECT(CONCATENATE("Setup!",SUBSTITUTE(ADDRESS(1,MATCH(CONCATENATE(C16,":",D16),Setup!$1:$1,0),4),"1",""),"2:",SUBSTITUTE(ADDRESS(1,MATCH(CONCATENATE(C16,":",D16),Setup!$1:$1,0),4),"1",""),"99"))),0) | BC16: =IF(COUNTBLANK(E16)=0,COUNTA(INDIRECT(CONCATENATE("Comp!",SUBSTITUTE(ADDRESS(1,MATCH(CONCATENATE(C16,":",D16,":",E16),Comp!$1:$1,0),4),"1",""),"2:",SUBSTITUTE(ADDRESS(1,MATCH(CONCATENATE(C16,":",D16,":",E16),Comp!$1:$1,0),4),"1",""),"99"))),0)
AW17: =CONCATENATE(A17,B17) | BA17: =IF(COUNTBLANK(C17)=0,COUNTA(INDIRECT(CONCATENATE("Area!",SUBSTITUTE(ADDRESS(1,MATCH(C17,Area!$1:$1,0),4),"1",""),"2:",SUBSTITUTE(ADDRESS(1,MATCH(C17,Area!$1:$1,0),4),"1",""),"99"))),0) | BB17: =IF(COUNTBLANK(D17)=0,COUNTA(INDIRECT(CONCATENATE("Setup!",SUBSTITUTE(ADDRESS(1,MATCH(CONCATENATE(C17,":",D17),Setup!$1:$1,0),4),"1",""),"2:",SUBSTITUTE(ADDRESS(1,MATCH(CONCATENATE(C17,":",D17),Setup!$1:$1,0),4),"1",""),"99"))),0) | BC17: =IF(COUNTBLANK(E17)=0,COUNTA(INDIRECT(CONCATENATE("Comp!",SUBSTITUTE(ADDRESS(1,MATCH(CONCATENATE(C17,":",D17,":",E17),Comp!$1:$1,0),4),"1",""),"2:",SUBSTITUTE(ADDRESS(1,MATCH(CONCATENATE(C17,":",D17,":",E17),Comp!$1:$1,0),4),"1",""),"99"))),0)
AW18: =CONCATENATE(A18,B18) | BA18: =IF(COUNTBLANK(C18)=0,COUNTA(INDIRECT(CONCATENATE("Area!",SUBSTITUTE(ADDRESS(1,MATCH(C18,Area!$1:$1,0),4),"1",""),"2:",SUBSTITUTE(ADDRESS(1,MATCH(C18,Area!$1:$1,0),4),"1",""),"99"))),0) | BB18: =IF(COUNTBLANK(D18)=0,COUNTA(INDIRECT(CONCATENATE("Setup!",SUBSTITUTE(ADDRESS(1,MATCH(CONCATENATE(C18,":",D18),Setup!$1:$1,0),4),"1",""),"2:",SUBSTITUTE(ADDRESS(1,MATCH(CONCATENATE(C18,":",D18),Setup!$1:$1,0),4),"1",""),"99"))),0) | BC18: =IF(COUNTBLANK(E18)=0,COUNTA(INDIRECT(CONCATENATE("Comp!",SUBSTITUTE(ADDRESS(1,MATCH(CONCATENATE(C18,":",D18,":",E18),Comp!$1:$1,0),4),"1",""),"2:",SUBSTITUTE(ADDRESS(1,MATCH(CONCATENATE(C18,":",D18,":",E18),Comp!$1:$1,0),4),"1",""),"99"))),0)
AW19: =CONCATENATE(A19,B19) | BA19: =IF(COUNTBLANK(C19)=0,COUNTA(INDIRECT(CONCATENATE("Area!",SUBSTITUTE(ADDRESS(1,MATCH(C19,Area!$1:$1,0),4),"1",""),"2:",SUBSTITUTE(ADDRESS(1,MATCH(C19,Area!$1:$1,0),4),"1",""),"99"))),0) | BB19: =IF(COUNTBLANK(D19)=0,COUNTA(INDIRECT(CONCATENATE("Setup!",SUBSTITUTE(ADDRESS(1,MATCH(CONCATENATE(C19,":",D19),Setup!$1:$1,0),4),"1",""),"2:",SUBSTITUTE(ADDRESS(1,MATCH(CONCATENATE(C19,":",D19),Setup!$1:$1,0),4),"1",""),"99"))),0) | BC19: =IF(COUNTBLANK(E19)=0,COUNTA(INDIRECT(CONCATENATE("Comp!",SUBSTITUTE(ADDRESS(1,MATCH(CONCATENATE(C19,":",D19,":",E19),Comp!$1:$1,0),4),"1",""),"2:",SUBSTITUTE(ADDRESS(1,MATCH(CONCATENATE(C19,":",D19,":",E19),Comp!$1:$1,0),4),"1",""),"99"))),0)
AW20: =CONCATENATE(A20,B20) | BA20: =IF(COUNTBLANK(C20)=0,COUNTA(INDIRECT(CONCATENATE("Area!",SUBSTITUTE(ADDRESS(1,MATCH(C20,Area!$1:$1,0),4),"1",""),"2:",SUBSTITUTE(ADDRESS(1,MATCH(C20,Area!$1:$1,0),4),"1",""),"99"))),0) | BB20: =IF(COUNTBLANK(D20)=0,COUNTA(INDIRECT(CONCATENATE("Setup!",SUBSTITUTE(ADDRESS(1,MATCH(CONCATENATE(C20,":",D20),Setup!$1:$1,0),4),"1",""),"2:",SUBSTITUTE(ADDRESS(1,MATCH(CONCATENATE(C20,":",D20),Setup!$1:$1,0),4),"1",""),"99"))),0) | BC20: =IF(COUNTBLANK(E20)=0,COUNTA(INDIRECT(CONCATENATE("Comp!",SUBSTITUTE(ADDRESS(1,MATCH(CONCATENATE(C20,":",D20,":",E20),Comp!$1:$1,0),4),"1",""),"2:",SUBSTITUTE(ADDRESS(1,MATCH(CONCATENATE(C20,":",D20,":",E20),Comp!$1:$1,0),4),"1",""),"99"))),0)
... AW1007: =CONCATENATE(A1007,B1007) | BA1007: =IF(COUNTBLANK(C1007)=0,COUNTA(INDIRECT(CONCATENATE("Area!",SUBSTITUTE(ADDRESS(1,MATCH(C1007,Area!$1:$1,0),4),"1",""),"2:",SUBSTITUTE(ADDRESS(1,MATCH(C1007,Area!$1:$1,0),4),"1",""),"99"))),0) | BB1007: =IF(COUNTBLANK(D1007)=0,COUNTA(INDIRECT(CONCATENATE("Setup!",SUBSTITUTE(ADDRESS(1,MATCH(CONCATENATE(C1007,":",D1007),Setup!$1:$1,0),4),"1",""),"2:",SUBSTITUTE(ADDRESS(1,MATCH(CONCATENATE(C1007,":",D1007),Setup!$1:$1,0),4),"1",""),"99"))),0) | BC1007: =IF(COUNTBLANK(E1007)=0,COUNTA(INDIRECT(CONCATENATE("Comp!",SUBSTITUTE(ADDRESS(1,MATCH(CONCATENATE(C1007,":",D1007,":",E1007),Comp!$1:$1,0),4),"1",""),"2:",SUBSTITUTE(ADDRESS(1,MATCH(CONCATENATE(C1007,":",D1007,":",E1007),Comp!$1:$1,0),4),"1",""),"99"))),0)
