Workbook

Sheet person
B1: dropdown | C1: alias | D1: name | E1: department
A2: LOTR | B2: bilbo | C2: bilbo | D2: Bilbo Baggins | E2: middle-earth
B3: frodo | C3: frodo | D3: Frodo Baggins | E3: middle-earth
B4: gandalf | C4: gandalf | D4: Gandalf the Grey | E4: middle-earth
B5: merry | C5: merry | D5: Meriadoc Brandybuck | E5: middle-earth
B6: pippin | C6: pippin | D6: Peregrin Took | E6: middle-earth
B7: sam | C7: sam | D7: Samwise Gamgee | E7: middle-earth
B8: saruman | C8: saruman | D8: Saruman the White | E8: middle-earth

Sheet person_db
B1: dropdown | C1: alias | D1: name | E1: department
A2: lab teams | B2: AP, FHP
B3: AP, WD
B4: FHP, WD
A5: lab individuals | B5: AP | C5: provisal | D5: Alain Proviste | E5: miskatonic
B6: FHP | C6: pabodifr | D6: Frank H. Pabodie | E6: miskatonic
B7: WD | C7: dyerwi | D7: William Dyer | E7: miskatonic
A8: H2G2 | B8: breebzap | C8: breebzap | D8: Zaphod Breeblebox | E8: heart-of-gold
B9: dentarth | C9: dentarth | D9: Arthur Dent | E9: heart-of-gold
B10: paramarv | C10: paramarv | D10: Marvin Paranoid Android | E10: heart-of-gold
B11: prefecfo | C11: prefecfo | D11: Ford Prefect | E11: heart-of-gold

Sheet person_drop
A1: =COUNTIF(person_db!$B$2:$B$1000,">""") -> 10 | B1: 0
B2: 1 | C2: =B2<=A1 -> TRUE | D2: =IF(C2,INDIRECT("person_db!B"&(B2+1)),INDIRECT("person!B"&(B2-$A$1+1))) -> AP, FHP
B3: 2 | C3: =B3<=A1 -> TRUE | D3: =IF(C3,INDIRECT("person_db!B"&(B3+1)),INDIRECT("person!B"&(B3-$A$1+1))) -> AP, WD
B4: 3 | C4: =B4<=A1 -> TRUE | D4: =IF(C4,INDIRECT("person_db!B"&(B4+1)),INDIRECT("person!B"&(B4-$A$1+1))) -> FHP, WD
B5: 4 | C5: =B5<=A1 -> TRUE | D5: =IF(C5,INDIRECT("person_db!B"&(B5+1)),INDIRECT("person!B"&(B5-$A$1+1))) -> AP
B6: 5 | C6: =B6<=A1 -> TRUE | D6: =IF(C6,INDIRECT("person_db!B"&(B6+1)),INDIRECT("person!B"&(B6-$A$1+1))) -> FHP
B7: 6 | C7: =B7<=A1 -> TRUE | D7: =IF(C7,INDIRECT("person_db!B"&(B7+1)),INDIRECT("person!B"&(B7-$A$1+1))) -> WD
B8: 7 | C8: =B8<=A1 -> TRUE | D8: =IF(C8,INDIRECT("person_db!B"&(B8+1)),INDIRECT("person!B"&(B8-$A$1+1))) -> breebzap
B9: 8 | C9: =B9<=A1 -> TRUE | D9: =IF(C9,INDIRECT("person_db!B"&(B9+1)),INDIRECT("person!B"&(B9-$A$1+1))) -> dentarth
B10: 9 | C10: =B10<=A1 -> TRUE | D10: =IF(C10,INDIRECT("person_db!B"&(B10+1)),INDIRECT("person!B"&(B10-$A$1+1))) -> paramarv
B11: 10 | C11: =B11<=A1 -> TRUE | D11: =IF(C11,INDIRECT("person_db!B"&(B11+1)),INDIRECT("person!B"&(B11-$A$1+1))) -> prefecfo
B12: 11 | C12: =B12<=A1 -> FALSE | D12: =IF(C12,INDIRECT("person_db!B"&(B12+1)),INDIRECT("person!B"&(B12-$A$1+1))) -> bilbo
B13: 12 | C13: =B13<=A1 -> FALSE | D13: =IF(C13,INDIRECT("person_db!B"&(B13+1)),INDIRECT("person!B"&(B13-$A$1+1))) -> frodo
B14: 13 | C14: =B14<=A1 -> FALSE | D14: =IF(C14,INDIRECT("person_db!B"&(B14+1)),INDIRECT("person!B"&(B14-$A$1+1))) -> gandalf
B15: 14 | C15: =B15<=A1 -> FALSE | D15: =IF(C15,INDIRECT("person_db!B"&(B15+1)),INDIRECT("person!B"&(B15-$A$1+1))) -> merry
B16: 15 | C16: =B16<=A1 -> FALSE | D16: =IF(C16,INDIRECT("person_db!B"&(B16+1)),INDIRECT("person!B"&(B16-$A$1+1))) -> pippin
B17: 16 | C17: =B17<=A1 -> FALSE | D17: =IF(C17,INDIRECT("person_db!B"&(B17+1)),INDIRECT("person!B"&(B17-$A$1+1))) -> sam
B18: 17 | C18: =B18<=A1 -> FALSE | D18: =IF(C18,INDIRECT("person_db!B"&(B18+1)),INDIRECT("person!B"&(B18-$A$1+1))) -> saruman
B19: 18 | C19: =B19<=A1 -> FALSE | D19: =IF(C19,INDIRECT("person_db!B"&(B19+1)),INDIRECT("person!B"&(B19-$A$1+1))) -> 0
B20: 19 | C20: =B20<=A1 -> FALSE | D20: =IF(C20,INDIRECT("person_db!B"&(B20+1)),INDIRECT("person!B"&(B20-$A$1+1))) -> 0
B21: 20 | C21: =B21<=A1 -> FALSE | D21: =IF(C21,INDIRECT("person_db!B"&(B21+1)),INDIRECT("person!B"&(B21-$A$1+1))) -> 0
B22: 21 | C22: =B22<=A1 -> FALSE | D22: =IF(C22,INDIRECT("person_db!B"&(B22+1)),INDIRECT("person!B"&(B22-$A$1+1))) -> 0
B23: 22 | C23: =B23<=A1 -> FALSE | D23: =IF(C23,INDIRECT("person_db!B"&(B23+1)),INDIRECT("person!B"&(B23-$A$1+1))) -> 0
B24: 23 | C24: =B24<=A1 -> FALSE | D24: =IF(C24,INDIRECT("person_db!B"&(B24+1)),INDIRECT("person!B"&(B24-$A$1+1))) -> 0
B25: 24 | C25: =B25<=A1 -> FALSE | D25: =IF(C25,INDIRECT("person_db!B"&(B25+1)),INDIRECT("person!B"&(B25-$A$1+1))) -> 0
B26: 25 | C26: =B26<=A1 -> FALSE | D26: =IF(C26,INDIRECT("person_db!B"&(B26+1)),INDIRECT("person!B"&(B26-$A$1+1))) -> 0
B27: 26 | C27: =B27<=A1 -> FALSE | D27: =IF(C27,INDIRECT("person_db!B"&(B27+1)),INDIRECT("person!B"&(B27-$A$1+1))) -> 0
B28: 27 | C28: =B28<=A1 -> FALSE | D28: =IF(C28,INDIRECT("person_db!B"&(B28+1)),INDIRECT("person!B"&(B28-$A$1+1))) -> 0
B29: 28 | C29: =B29<=A1 -> FALSE | D29: =IF(C29,INDIRECT("person_db!B"&(B29+1)),INDIRECT("person!B"&(B29-$A$1+1))) -> 0
B30: 29 | C30: =B30<=A1 -> FALSE | D30: =IF(C30,INDIRECT("person_db!B"&(B30+1)),INDIRECT("person!B"&(B30-$A$1+1))) -> 0
B31: 30 | C31: =B31<=A1 -> FALSE | D31: =IF(C31,INDIRECT("person_db!B"&(B31+1)),INDIRECT("person!B"&(B31-$A$1+1))) -> 0
B32: 31 | C32: =B32<=A1 -> FALSE | D32: =IF(C32,INDIRECT("person_db!B"&(B32+1)),INDIRECT("person!B"&(B32-$A$1+1))) -> 0
B33: 32 | C33: =B33<=A1 -> FALSE | D33: =IF(C33,INDIRECT("person_db!B"&(B33+1)),INDIRECT("person!B"&(B33-$A$1+1))) -> 0
B34: 33 | C34: =B34<=A1 -> FALSE | D34: =IF(C34,INDIRECT("person_db!B"&(B34+1)),INDIRECT("person!B"&(B34-$A$1+1))) -> 0
B35: 34 | C35: =B35<=A1 -> FALSE | D35: =IF(C35,INDIRECT("person_db!B"&(B35+1)),INDIRECT("person!B"&(B35-$A$1+1))) -> 0
B36: 35 | C36: =B36<=A1 -> FALSE | D36: =IF(C36,INDIRECT("person_db!B"&(B36+1)),INDIRECT("person!B"&(B36-$A$1+1))) -> 0
B37: 36 | C37: =B37<=A1 -> FALSE | D37: =IF(C37,INDIRECT("person_db!B"&(B37+1)),INDIRECT("person!B"&(B37-$A$1+1))) -> 0
B38: 37 | C38: =B38<=A1 -> FALSE | D38: =IF(C38,INDIRECT("person_db!B"&(B38+1)),INDIRECT("person!B"&(B38-$A$1+1))) -> 0
B39: 38 | C39: =B39<=A1 -> FALSE | D39: =IF(C39,INDIRECT("person_db!B"&(B39+1)),INDIRECT("person!B"&(B39-$A$1+1))) -> 0
B40: 39 | C40: =B40<=A1 -> FALSE | D40: =IF(C40,INDIRECT("person_db!B"&(B40+1)),INDIRECT("person!B"&(B40-$A$1+1))) -> 0
...

Sheet Area
A1: DiningRoom | B1: Kitchen
A2: Bar | B2: Bench
A3: DiningArea | B3: DiningArea

Sheet Setup
A1: DiningRoom:Bar | B1: DiningRoom:DiningArea | C1: Kitchen:Bench | D1: Kitchen:DiningArea
A2: Commode | B2: Table | C2: Sink | D2: Table
C3: Dischwascher | D3: Chair

Sheet Comp
A1: DiningRoom:Bar:Commode | B1: DiningRoom:DiningArea:Table | C1: Kitchen:Bench:Dischwascher | D1: Kitchen:Bench:Sink | E1: Kitchen:DiningArea:Chair | F1: Kitchen:DiningArea:Table
A2: Glassware | B2: Leg1 | C2: Door | D2: Tap | E2: Leg1 | F2: Leg1
A3: Liquor | B3: Leg2 | D3: Drain
D4: Overflow

Sheet 1Q42
A1: 1Q42 | B1: 2019
A2: Responsible: | B2: =HYPERLINK("mailto:aomame@miskatonic.edu?subject=[Lab samples]", "aomame@miskatonic.edu") -> aomame@miskatonic.edu
A3: Results: | B3: =HYPERLINK("C:\code\laboratoryspreadsheet\labspreadsheet\demo\remote_1Q42\LabResults2019_1Q42.xlsx#1Q42!A1","LabResults2019_1Q42.xlsx") -> LabResults2019_1Q42.xlsx
A5: Sample ID | C5: Site | G5: Sample | M5: Comment | N5: Communication | O5: Analysis | Q5: Expected value of measured variable | AV5: ConcatID | BA5: Number of options
A6: Project ID | B6: Number | C6: Room | D6: Area | E6: Setup | F6: Component | G6: Date | H6: Time | I6: Sampling method | J6: Filter at sampling | K6: Dilution at sampling | L6: Who (S) | O6: Date | P6: Who (A) | Q6: DOC | R6: TOC | S6: TIC | T6: Ntot | U6: Cl | V6: NO2-N | W6: NO3-N | X6: PO4-P | Y6: SO4 | Z6: Na | AA6: NH4-N | AB6: K | AC6: Ca | AD6: Mg | AE6: Ptot | AF6: Urea | AG6: CODsol | AH6: CODtot | AI6: Alkalinity | AJ6: Conductivity | AK6: pH | AL6: Dissolved Oxygen | AM6: Turbidity | AN6: BOD5 | AO6: TSS | AP6: VSS | AQ6: TCC | AR6: ICC | AS6: ATP | AT6: TSS63 | BA6: Area | BB6: Setup | BC6: Component
A7: [##] | B7: [yysss] | G7: [dd.mm.yyyy] | H7: [HH:MM:SS] | K7: [total vol/sample vol] | O7: [dd.mm.yyyy] | Q7: mg/L | R7: mg/L | S7: mg/L | T7: mg/L | U7: mg/L | V7: mg/L | W7: mg/L | X7: mg/L | Y7: mg/L | Z7: mg/L | AA7: mg/L | AB7: mg/L | AC7: mg/L | AD7: mg/L | AE7: mg/L | AF7: mgN/L | AG7: mg/L | AH7: mg/L | AI7: mmol/L | AJ7: microS/cm | AK7: 1 | AL7: mg/L | AM7: NTU | AN7: mg/L | AO7: mg/L | AP7: mg/L | AQ7: #/mL | AR7: #/mL | AS7: gATP/gGAC | AT7: mg/L
A8: Text | B8: Text | C8: Dropdown | D8: Dropdown | E8: Dropdown | F8: Dropdown | G8: Text | H8: Text | I8: Dropdown | J8: Dropdown | K8: Text | L8: Text | O8: Text | P8: Text | Q8: Text | R8: Text | S8: Text | T8: Text | U8: Text | V8: Text | W8: Text | X8: Text | Y8: Text | Z8: Text | AA8: Text | AB8: Text | AC8: Text | AD8: Text | AE8: Text | AF8: Text | AG8: Text | AH8: Text | AI8: Text | AJ8: Text | AK8: Text | AL8: Text | AM8: Text | AN8: Text | AO8: Text | AP8: Text | AQ8: Text | AR8: Text | AS8: Text | AT8: Text
A9: 1Q42 | AU9: =CONCATENATE(A9,B9) -> 1Q42 | AV9: =CONCATENATE(A9,B9) -> 1Q42 | BA9: =IF(COUNTBLANK(C9)=0,COUNTA(INDIRECT(CONCATENATE("Area!",LEFT(ADDRESS(1,MATCH(C9,Area!$1:$1,0),4),1),"2:",LEFT(ADDRESS(1,MATCH(C9,Area!$1:$1,0),4),1),"99"))),0) -> 0 | BB9: =IF(COUNTBLANK(D9)=0,COUNTA(INDIRECT(CONCATENATE("Setup!",LEFT(ADDRESS(1,MATCH(CONCATENATE(C9,":",D9),Setup!$1:$1,0),4),1),"2:",LEFT(ADDRESS(1,MATCH(CONCATENATE(C9,":",D9),Setup!$1:$1,0),4),1),"99"))),0) -> 0 | BC9: =IF(COUNTBLANK(E9)=0,COUNTA(INDIRECT(CONCATENATE("Comp!",SUBSTITUTE(ADDRESS(1,MATCH(CONCATENATE(C9,":",D9,":",E9),Comp!$1:$1,0),4),"1",""),"2:",SUBSTITUTE(ADDRESS(1,MATCH(CONCATENATE(C9,":",D9,":",E9),Comp!$1:$1,0),4),"1",""),"99"))),0) -> 0
A10: 1Q42 | AU10: =CONCATENATE(A10,B10) -> 1Q42 | AV10: =CONCATENATE(A10,B10) -> 1Q42 | BA10: =IF(COUNTBLANK(C10)=0,COUNTA(INDIRECT(CONCATENATE("Area!",LEFT(ADDRESS(1,MATCH(C10,Area!$1:$1,0),4),1),"2:",LEFT(ADDRESS(1,MATCH(C10,Area!$1:$1,0),4),1),"99"))),0) -> 0 | BB10: =IF(COUNTBLANK(D10)=0,COUNTA(INDIRECT(CONCATENATE("Setup!",LEFT(ADDRESS(1,MATCH(CONCATENATE(C10,":",D10),Setup!$1:$1,0),4),1),"2:",LEFT(ADDRESS(1,MATCH(CONCATENATE(C10,":",D10),Setup!$1:$1,0),4),1),"99"))),0) -> 0 | BC10: =IF(COUNTBLANK(E10)=0,COUNTA(INDIRECT(CONCATENATE("Comp!",SUBSTITUTE(ADDRESS(1,MATCH(CONCATENATE(C10,":",D10,":",E10),Comp!$1:$1,0),4),"1",""),"2:",SUBSTITUTE(ADDRESS(1,MATCH(CONCATENATE(C10,":",D10,":",E10),Comp!$1:$1,0),4),"1",""),"99"))),0) -> 0
A11: 1Q42 | AU11: =CONCATENATE(A11,B11) -> 1Q42 | AV11: =CONCATENATE(A11,B11) -> 1Q42 | BA11: =IF(COUNTBLANK(C11)=0,COUNTA(INDIRECT(CONCATENATE("Area!",LEFT(ADDRESS(1,MATCH(C11,Area!$1:$1,0),4),1),"2:",LEFT(ADDRESS(1,MATCH(C11,Area!$1:$1,0),4),1),"99"))),0) -> 0 | BB11: =IF(COUNTBLANK(D11)=0,COUNTA(INDIRECT(CONCATENATE("Setup!",LEFT(ADDRESS(1,MATCH(CONCATENATE(C11,":",D11),Setup!$1:$1,0),4),1),"2:",LEFT(ADDRESS(1,MATCH(CONCATENATE(C11,":",D11),Setup!$1:$1,0),4),1),"99"))),0) -> 0 | BC11: =IF(COUNTBLANK(E11)=0,COUNTA(INDIRECT(CONCATENATE("Comp!",SUBSTITUTE(ADDRESS(1,MATCH(CONCATENATE(C11,":",D11,":",E11),Comp!$1:$1,0),4),"1",""),"2:",SUBSTITUTE(ADDRESS(1,MATCH(CONCATENATE(C11,":",D11,":",E11),Comp!$1:$1,0),4),"1",""),"99"))),0) -> 0
A12: 1Q42 | AU12: =CONCATENATE(A12,B12) -> 1Q42 | AV12: =CONCATENATE(A12,B12) -> 1Q42 | BA12: =IF(COUNTBLANK(C12)=0,COUNTA(INDIRECT(CONCATENATE("Area!",LEFT(ADDRESS(1,MATCH(C12,Area!$1:$1,0),4),1),"2:",LEFT(ADDRESS(1,MATCH(C12,Area!$1:$1,0),4),1),"99"))),0) -> 0 | BB12: =IF(COUNTBLANK(D12)=0,COUNTA(INDIRECT(CONCATENATE("Setup!",LEFT(ADDRESS(1,MATCH(CONCATENATE(C12,":",D12),Setup!$1:$1,0),4),1),"2:",LEFT(ADDRESS(1,MATCH(CONCATENATE(C12,":",D12),Setup!$1:$1,0),4),1),"99"))),0) -> 0 | BC12: =IF(COUNTBLANK(E12)=0,COUNTA(INDIRECT(CONCATENATE("Comp!",SUBSTITUTE(ADDRESS(1,MATCH(CONCATENATE(C12,":",D12,":",E12),Comp!$1:$1,0),4),"1",""),"2:",SUBSTITUTE(ADDRESS(1,MATCH(CONCATENATE(C12,":",D12,":",E12),Comp!$1:$1,0),4),"1",""),"99"))),0) -> 0
A13: 1Q42 | AU13: =CONCATENATE(A13,B13) -> 1Q42 | AV13: =CONCATENATE(A13,B13) -> 1Q42 | BA13: =IF(COUNTBLANK(C13)=0,COUNTA(INDIRECT(CONCATENATE("Area!",LEFT(ADDRESS(1,MATCH(C13,Area!$1:$1,0),4),1),"2:",LEFT(ADDRESS(1,MATCH(C13,Area!$1:$1,0),4),1),"99"))),0) -> 0 | BB13: =IF(COUNTBLANK(D13)=0,COUNTA(INDIRECT(CONCATENATE("Setup!",LEFT(ADDRESS(1,MATCH(CONCATENATE(C13,":",D13),Setup!$1:$1,0),4),1),"2:",LEFT(ADDRESS(1,MATCH(CONCATENATE(C13,":",D13),Setup!$1:$1,0),4),1),"99"))),0) -> 0 | BC13: =IF(COUNTBLANK(E13)=0,COUNTA(INDIRECT(CONCATENATE("Comp!",SUBSTITUTE(ADDRESS(1,MATCH(CONCATENATE(C13,":",D13,":",E13),Comp!$1:$1,0),4),"1",""),"2:",SUBSTITUTE(ADDRESS(1,MATCH(CONCATENATE(C13,":",D13,":",E13),Comp!$1:$1,0),4),"1",""),"99"))),0) -> 0
A14: 1Q42 | AU14: =CONCATENATE(A14,B14) -> 1Q42 | AV14: =CONCATENATE(A14,B14) -> 1Q42 | BA14: =IF(COUNTBLANK(C14)=0,COUNTA(INDIRECT(CONCATENATE("Area!",LEFT(ADDRESS(1,MATCH(C14,Area!$1:$1,0),4),1),"2:",LEFT(ADDRESS(1,MATCH(C14,Area!$1:$1,0),4),1),"99"))),0) -> 0 | BB14: =IF(COUNTBLANK(D14)=0,COUNTA(INDIRECT(CONCATENATE("Setup!",LEFT(ADDRESS(1,MATCH(CONCATENATE(C14,":",D14),Setup!$1:$1,0),4),1),"2:",LEFT(ADDRESS(1,MATCH(CONCATENATE(C14,":",D14),Setup!$1:$1,0),4),1),"99"))),0) -> 0 | BC14: =IF(COUNTBLANK(E14)=0,COUNTA(INDIRECT(CONCATENATE("Comp!",SUBSTITUTE(ADDRESS(1,MATCH(CONCATENATE(C14,":",D14,":",E14),Comp!$1:$1,0),4),"1",""),"2:",SUBSTITUTE(ADDRESS(1,MATCH(CONCATENATE(C14,":",D14,":",E14),Comp!$1:$1,0),4),"1",""),"99"))),0) -> 0
A15: 1Q42 | AU15: =CONCATENATE(A15,B15) -> 1Q42 | AV15: =CONCATENATE(A15,B15) -> 1Q42 | BA15: =IF(COUNTBLANK(C15)=0,COUNTA(INDIRECT(CONCATENATE("Area!",LEFT(ADDRESS(1,MATCH(C15,Area!$1:$1,0),4),1),"2:",LEFT(ADDRESS(1,MATCH(C15,Area!$1:$1,0),4),1),"99"))),0) -> 0 | BB15: =IF(COUNTBLANK(D15)=0,COUNTA(INDIRECT(CONCATENATE("Setup!",LEFT(ADDRESS(1,MATCH(CONCATENATE(C15,":",D15),Setup!$1:$1,0),4),1),"2:",LEFT(ADDRESS(1,MATCH(CONCATENATE(C15,":",D15),Setup!$1:$1,0),4),1),"99"))),0) -> 0 | BC15: =IF(COUNTBLANK(E15)=0,COUNTA(INDIRECT(CONCATENATE("Comp!",SUBSTITUTE(ADDRESS(1,MATCH(CONCATENATE(C15,":",D15,":",E15),Comp!$1:$1,0),4),"1",""),"2:",SUBSTITUTE(ADDRESS(1,MATCH(CONCATENATE(C15,":",D15,":",E15),Comp!$1:$1,0),4),"1",""),"99"))),0) -> 0
A16: 1Q42 | AU16: =CONCATENATE(A16,B16) -> 1Q42 | AV16: =CONCATENATE(A16,B16) -> 1Q42 | BA16: =IF(COUNTBLANK(C16)=0,COUNTA(INDIRECT(CONCATENATE("Area!",LEFT(ADDRESS(1,MATCH(C16,Area!$1:$1,0),4),1),"2:",LEFT(ADDRESS(1,MATCH(C16,Area!$1:$1,0),4),1),"99"))),0) -> 0 | BB16: =IF(COUNTBLANK(D16)=0,COUNTA(INDIRECT(CONCATENATE("Setup!",LEFT(ADDRESS(1,MATCH(CONCATENATE(C16,":",D16),Setup!$1:$1,0),4),1),"2:",LEFT(ADDRESS(1,MATCH(CONCATENATE(C16,":",D16),Setup!$1:$1,0),4),1),"99"))),0) -> 0 | BC16: =IF(COUNTBLANK(E16)=0,COUNTA(INDIRECT(CONCATENATE("Comp!",SUBSTITUTE(ADDRESS(1,MATCH(CONCATENATE(C16,":",D16,":",E16),Comp!$1:$1,0),4),"1",""),"2:",SUBSTITUTE(ADDRESS(1,MATCH(CONCATENATE(C16,":",D16,":",E16),Comp!$1:$1,0),4),"1",""),"99"))),0) -> 0
A17: 1Q42 | AU17: =CONCATENATE(A17,B17) -> 1Q42 | AV17: =CONCATENATE(A17,B17) -> 1Q42 | BA17: =IF(COUNTBLANK(C17)=0,COUNTA(INDIRECT(CONCATENATE("Area!",LEFT(ADDRESS(1,MATCH(C17,Area!$1:$1,0),4),1),"2:",LEFT(ADDRESS(1,MATCH(C17,Area!$1:$1,0),4),1),"99"))),0) -> 0 | BB17: =IF(COUNTBLANK(D17)=0,COUNTA(INDIRECT(CONCATENATE("Setup!",LEFT(ADDRESS(1,MATCH(CONCATENATE(C17,":",D17),Setup!$1:$1,0),4),1),"2:",LEFT(ADDRESS(1,MATCH(CONCATENATE(C17,":",D17),Setup!$1:$1,0),4),1),"99"))),0) -> 0 | BC17: =IF(COUNTBLANK(E17)=0,COUNTA(INDIRECT(CONCATENATE("Comp!",SUBSTITUTE(ADDRESS(1,MATCH(CONCATENATE(C17,":",D17,":",E17),Comp!$1:$1,0),4),"1",""),"2:",SUBSTITUTE(ADDRESS(1,MATCH(CONCATENATE(C17,":",D17,":",E17),Comp!$1:$1,0),4),"1",""),"99"))),0) -> 0
A18: 1Q42 | AU18: =CONCATENATE(A18,B18) -> 1Q42 | AV18: =CONCATENATE(A18,B18) -> 1Q42 | BA18: =IF(COUNTBLANK(C18)=0,COUNTA(INDIRECT(CONCATENATE("Area!",LEFT(ADDRESS(1,MATCH(C18,Area!$1:$1,0),4),1),"2:",LEFT(ADDRESS(1,MATCH(C18,Area!$1:$1,0),4),1),"99"))),0) -> 0 | BB18: =IF(COUNTBLANK(D18)=0,COUNTA(INDIRECT(CONCATENATE("Setup!",LEFT(ADDRESS(1,MATCH(CONCATENATE(C18,":",D18),Setup!$1:$1,0),4),1),"2:",LEFT(ADDRESS(1,MATCH(CONCATENATE(C18,":",D18),Setup!$1:$1,0),4),1),"99"))),0) -> 0 | BC18: =IF(COUNTBLANK(E18)=0,COUNTA(INDIRECT(CONCATENATE("Comp!",SUBSTITUTE(ADDRESS(1,MATCH(CONCATENATE(C18,":",D18,":",E18),Comp!$1:$1,0),4),"1",""),"2:",SUBSTITUTE(ADDRESS(1,MATCH(CONCATENATE(C18,":",D18,":",E18),Comp!$1:$1,0),4),"1",""),"99"))),0) -> 0
A19: 1Q42 | AU19: =CONCATENATE(A19,B19) -> 1Q42 | AV19: =CONCATENATE(A19,B19) -> 1Q42 | BA19: =IF(COUNTBLANK(C19)=0,COUNTA(INDIRECT(CONCATENATE("Area!",LEFT(ADDRESS(1,MATCH(C19,Area!$1:$1,0),4),1),"2:",LEFT(ADDRESS(1,MATCH(C19,Area!$1:$1,0),4),1),"99"))),0) -> 0 | BB19: =IF(COUNTBLANK(D19)=0,COUNTA(INDIRECT(CONCATENATE("Setup!",LEFT(ADDRESS(1,MATCH(CONCATENATE(C19,":",D19),Setup!$1:$1,0),4),1),"2:",LEFT(ADDRESS(1,MATCH(CONCATENATE(C19,":",D19),Setup!$1:$1,0),4),1),"99"))),0) -> 0 | BC19: =IF(COUNTBLANK(E19)=0,COUNTA(INDIRECT(CONCATENATE("Comp!",SUBSTITUTE(ADDRESS(1,MATCH(CONCATENATE(C19,":",D19,":",E19),Comp!$1:$1,0),4),"1",""),"2:",SUBSTITUTE(ADDRESS(1,MATCH(CONCATENATE(C19,":",D19,":",E19),Comp!$1:$1,0),4),"1",""),"99"))),0) -> 0
A20: 1Q42 | AU20: =CONCATENATE(A20,B20) -> 1Q42 | AV20: =CONCATENATE(A20,B20) -> 1Q42 | BA20: =IF(COUNTBLANK(C20)=0,COUNTA(INDIRECT(CONCATENATE("Area!",LEFT(ADDRESS(1,MATCH(C20,Area!$1:$1,0),4),1),"2:",LEFT(ADDRESS(1,MATCH(C20,Area!$1:$1,0),4),1),"99"))),0) -> 0 | BB20: =IF(COUNTBLANK(D20)=0,COUNTA(INDIRECT(CONCATENATE("Setup!",LEFT(ADDRESS(1,MATCH(CONCATENATE(C20,":",D20),Setup!$1:$1,0),4),1),"2:",LEFT(ADDRESS(1,MATCH(CONCATENATE(C20,":",D20),Setup!$1:$1,0),4),1),"99"))),0) -> 0 | BC20: =IF(COUNTBLANK(E20)=0,COUNTA(INDIRECT(CONCATENATE("Comp!",SUBSTITUTE(ADDRESS(1,MATCH(CONCATENATE(C20,":",D20,":",E20),Comp!$1:$1,0),4),"1",""),"2:",SUBSTITUTE(ADDRESS(1,MATCH(CONCATENATE(C20,":",D20,":",E20),Comp!$1:$1,0),4),"1",""),"99"))),0) -> 0
... A1007: 1Q42 | AU1007: =CONCATENATE(A1007,B1007) -> 1Q42 | AV1007: =CONCATENATE(A1007,B1007) -> 1Q42 | BA1007: =IF(COUNTBLANK(C1007)=0,COUNTA(INDIRECT(CONCATENATE("Area!",LEFT(ADDRESS(1,MATCH(C1007,Area!$1:$1,0),4),1),"2:",LEFT(ADDRESS(1,MATCH(C1007,Area!$1:$1,0),4),1),"99"))),0) -> 0 | BB1007: =IF(COUNTBLANK(D1007)=0,COUNTA(INDIRECT(CONCATENATE("Setup!",LEFT(ADDRESS(1,MATCH(CONCATENATE(C1007,":",D1007),Setup!$1:$1,0),4),1),"2:",LEFT(ADDRESS(1,MATCH(CONCATENATE(C1007,":",D1007),Setup!$1:$1,0),4),1),"99"))),0) -> 0 | BC1007: =IF(COUNTBLANK(E1007)=0,COUNTA(INDIRECT(CONCATENATE("Comp!",SUBSTITUTE(ADDRESS(1,MATCH(CONCATENATE(C1007,":",D1007,":",E1007),Comp!$1:$1,0),4),"1",""),"2:",SUBSTITUTE(ADDRESS(1,MATCH(CONCATENATE(C1007,":",D1007,":",E1007),Comp!$1:$1,0),4),"1",""),"99"))),0) -> 0
