Workbook

Sheet Sandec
A1: Sandec | B1: 2026
A2: Responsible: | B2: =HYPERLINK("mailto:linda.strande@eawag.ch?subject=[Lab results]", "linda.strande@eawag.ch")
A3: Samples: | B3: =HYPERLINK("Q:\Abteilungsprojekte\eng\EngData\AOS\Allgemein\LabSamples2026.xlsx#Sandec!A1","LabSamples2026.xlsx")
A5: Sample ID | C5: Site | G5: Sample | I5: Comment | J5: Communication Lab | K5: DOC | O5: TOC | S5: DIC | W5: TIC | AA5: Nsol | AE5: Ntot | AI5: Cl | AM5: NO2-N | AQ5: Br | AU5: NO3-N | AY5: PO4-P | BC5: SO4 | BG5: Na | BK5: NH4-N | BO5: K | BS5: Ca | BW5: Mg | CA5: Ptot | CE5: Urea | CI5: CODsol | CM5: CODtot | CQ5: Alkalinity | CU5: Conductivity | CY5: pH | DC5: Turbidity | DG5: TSS | DK5: VSS | DO5: Lactic Acid | DS5: Formic Acid | DW5: Acetic Acid | EA5: Propionic Acid | EE5: Isobutyric Acid | EI5: Butyric Acid | EM5: Isovaleric Acid | EQ5: Valeric Acid | EU5: Micropollutants | EZ5: ConcatID | FA5: ConcatID_X | FC5: MatchX
A6: Project ID | B6: Number | C6: Room | D6: Area | E6: Setup | F6: Component | G6: Date | H6: Time | K6: Final value | L6: Method | M6: Filtration | N6: Dilution | O6: Final value | P6: Method | Q6: Filtration | R6: Dilution | S6: Final value | T6: Method | U6: Filtration | V6: Dilution | W6: Final value | X6: Method | Y6: Filtration | Z6: Dilution | AA6: Final value | AB6: Method | AC6: Filtration | AD6: Dilution | AE6: Final value | AF6: Method | AG6: Filtration | AH6: Dilution | AI6: Final value | AJ6: Method | AK6: Filtration | AL6: Dilution | AM6: Final value | AN6: Method | AO6: Filtration | AP6: Dilution | AQ6: Final value | AR6: Method | AS6: Filtration | AT6: Dilution | AU6: Final value | AV6: Method | AW6: Filtration | AX6: Dilution | AY6: Final value | AZ6: Method | BA6: Filtration | BB6: Dilution | BC6: Final value | BD6: Method | BE6: Filtration | BF6: Dilution | BG6: Final value | BH6: Method | BI6: Filtration | BJ6: Dilution | BK6: Final value | BL6: Method | BM6: Filtration | BN6: Dilution | BO6: Final value | BP6: Method | BQ6: Filtration | BR6: Dilution | BS6: Final value | BT6: Method | BU6: Filtration | BV6: Dilution | BW6: Final value | BX6: Method | BY6: Filtration | BZ6: Dilution | CA6: Final value | CB6: Method | CC6: Filtration | CD6: Dilution | CE6: Final value | CF6: Method | CG6: Filtration | CH6: Dilution | CI6: Final value | CJ6: Method | CK6: Filtration | CL6: Dilution | CM6: Final value | CN6: Method | CO6: Filtration | CP6: Dilution | CQ6: Final value | CR6: Method | CS6: Filtration | CT6: Dilution | CU6: Final value | CV6: Method | CW6: Filtration | CX6: Dilution | CY6: Final value | CZ6: Method | DA6: Filtration | DB6: Dilution | DC6: Final value | DD6: Method | DE6: Filtration | DF6: Dilution | DG6: Final value | DH6: Method | DI6: Filtration | DJ6: Dilution | DK6: Final value | DL6: Method | DM6: Filtration | DN6: Dilution | DO6: Final value | DP6: Method | DQ6: Filtration | DR6: Dilution | DS6: Final value | DT6: Method | DU6: Filtration | DV6: Dilution | DW6: Final value | DX6: Method | DY6: Filtration | DZ6: Dilution | EA6: Final value | EB6: Method | EC6: Filtration | ED6: Dilution | EE6: Final value | EF6: Method | EG6: Filtration | EH6: Dilution | EI6: Final value | EJ6: Method | EK6: Filtration | EL6: Dilution | EM6: Final value | EN6: Method | EO6: Filtration | EP6: Dilution | EQ6: Final value | ER6: Method | ES6: Filtration | ET6: Dilution | EU6: Final value | EV6: Method | EW6: Filtration | EX6: Dilution
A7: [##] | B7: [yysss] | G7: [dd.mm.yyyy] | H7: [HH:MM:SS] | K7: mg/L | O7: mg/L | S7: mg/L | W7: mg/L | AA7: mg/L | AE7: mg/L | AI7: mg/L | AM7: mg/L | AQ7: mg/L | AU7: mg/L | AY7: mg/L | BC7: mg/L | BG7: mg/L | BK7: mg/L | BO7: mg/L | BS7: mg/L | BW7: mg/L | CA7: mg/L | CE7: mgN/L | CI7: mg/L | CM7: mg/L | CQ7: mmol/L | CU7: microS/cm | CY7: 1 | DC7: NTU | DG7: mg/L | DK7: mg/L | DO7: mg/L | DS7: mg/L | DW7: mg/L | EA7: mg/L | EE7: mg/L | EI7: mg/L | EM7: mg/L | EQ7: mg/L | EU7: ng/L
A8: Text | B8: Text | C8: Dropdown | D8: Dropdown | E8: Dropdown | F8: Dropdown | G8: Text | H8: Text | K8: Text | L8: Dropdown | M8: Dropdown | N8: Text | O8: Text | P8: Dropdown | Q8: Dropdown | R8: Text | S8: Text | T8: Dropdown | U8: Dropdown | V8: Text | W8: Text | X8: Dropdown | Y8: Dropdown | Z8: Text | AA8: Text | AB8: Dropdown | AC8: Dropdown | AD8: Text | AE8: Text | AF8: Dropdown | AG8: Dropdown | AH8: Text | AI8: Text | AJ8: Dropdown | AK8: Dropdown | AL8: Text | AM8: Text | AN8: Dropdown | AO8: Dropdown | AP8: Text | AQ8: Text | AR8: Dropdown | AS8: Dropdown | AT8: Text | AU8: Text | AV8: Dropdown | AW8: Dropdown | AX8: Text | AY8: Text | AZ8: Dropdown | BA8: Dropdown | BB8: Text | BC8: Text | BD8: Dropdown | BE8: Dropdown | BF8: Text | BG8: Text | BH8: Dropdown | BI8: Dropdown | BJ8: Text | BK8: Text | BL8: Dropdown | BM8: Dropdown | BN8: Text | BO8: Text | BP8: Dropdown | BQ8: Dropdown | BR8: Text | BS8: Text | BT8: Dropdown | BU8: Dropdown | BV8: Text | BW8: Text | BX8: Dropdown | BY8: Dropdown | BZ8: Text | CA8: Text | CB8: Dropdown | CC8: Dropdown | CD8: Text | CE8: Text | CF8: Dropdown | CG8: Dropdown | CH8: Text | CI8: Text | CJ8: Dropdown | CK8: Dropdown | CL8: Text | CM8: Text | CN8: Dropdown | CO8: Dropdown | CP8: Text | CQ8: Text | CR8: Dropdown | CS8: Dropdown | CT8: Text | CU8: Text | CV8: Dropdown | CW8: Dropdown | CX8: Text | CY8: Text | CZ8: Dropdown | DA8: Dropdown | DB8: Text | DC8: Text | DD8: Dropdown | DE8: Dropdown | DF8: Text | DG8: Text | DH8: Dropdown | DI8: Dropdown | DJ8: Text | DK8: Text | DL8: Dropdown | DM8: Dropdown | DN8: Text | DO8: Text | DP8: Dropdown | DQ8: Dropdown | DR8: Text | DS8: Text | DT8: Dropdown | DU8: Dropdown | DV8: Text | DW8: Text | DX8: Dropdown | DY8: Dropdown | DZ8: Text | EA8: Text | EB8: Dropdown | EC8: Dropdown | ED8: Text | EE8: Text | EF8: Dropdown | EG8: Dropdown | EH8: Text | EI8: Text | EJ8: Dropdown | EK8: Dropdown | EL8: Text | EM8: Text | EN8: Dropdown | EO8: Dropdown | EP8: Text | EQ8: Text | ER8: Dropdown | ES8: Dropdown | ET8: Text | EU8: Text | EV8: Dropdown | EW8: Dropdown | EX8: Text
C9: =IF(ISNUMBER(FC9),INDIRECT("SamplesX!C"&FC9),IF(ISNUMBER(FD9),INDIRECT("SamplesY!C"&FD9),"")) | D9: =IF(ISNUMBER(FC9),INDIRECT("SamplesX!D"&FC9),IF(ISNUMBER(FD9),INDIRECT("SamplesY!D"&FD9),"")) | E9: =IF(ISNUMBER(FC9),INDIRECT("SamplesX!E"&FC9),IF(ISNUMBER(FD9),INDIRECT("SamplesY!E"&FD9),"")) | F9: =IF(ISNUMBER(FC9),INDIRECT("SamplesX!F"&FC9),IF(ISNUMBER(FD9),INDIRECT("SamplesY!F"&FD9),"")) | G9: =IF(ISNUMBER(FC9),INDIRECT("SamplesX!G"&FC9),IF(ISNUMBER(FD9),INDIRECT("SamplesY!G"&FD9),"")) | H9: =IF(ISNUMBER(FC9),INDIRECT("SamplesX!H"&FC9),IF(ISNUMBER(FD9),INDIRECT("SamplesY!H"&FD9),"")) | I9: =IF(ISNUMBER(FC9),IF(INDEX('Q:\Abteilungsprojekte\eng\EngData\AOS\Allgemein\[LabSamples2026.xlsx]Sandec'!M:M,FC9)="","",INDEX('Q:\Abteilungsprojekte\eng\EngData\AOS\Allgemein\[LabSamples2026.xlsx]Sandec'!M:M,FC9)),"") | J9: =IF(ISNUMBER(FC9),IF(INDEX('Q:\Abteilungsprojekte\eng\EngData\AOS\Allgemein\[LabSamples2026.xlsx]Sandec'!N:N,FC9)="","",INDEX('Q:\Abteilungsprojekte\eng\EngData\AOS\Allgemein\[LabSamples2026.xlsx]Sandec'!N:N,FC9)),"") | L9: Shimadzu TOC-L | M9: None | P9: Shimadzu TOC-L | Q9: None | T9: Shimadzu TOC-L | U9: None | X9: Shimadzu TOC-L | Y9: None | AC9: None | AG9: None | AJ9: IC Anionen | AK9: None | AO9: None | AR9: IC Anionen | AS9: None | AW9: None | BA9: None | BD9: IC Anionen | BE9: None | BH9: IC Kationen | BI9: None | BM9: None | BP9: IC Kationen | BQ9: None | BT9: IC Kationen | BU9: None | BX9: IC Kationen | BY9: None | CC9: None | CG9: None | CK9: None | CO9: None | CR9: SOP 45-34 | CS9: None | CW9: None | DA9: None | DE9: None | DH9: SOP 45-09 | DI9: None | DL9: SOP 45-09 | DM9: None | DP9: IC Organic Acids | DQ9: None | DT9: IC Organic Acids | DU9: None | DX9: IC Organic Acids | DY9: None | EB9: IC Organic Acids | EC9: None | EF9: IC Organic Acids | EG9: None | EJ9: IC Organic Acids | EK9: None | EN9: IC Organic Acids | EO9: None | ER9: IC Organic Acids | ES9: None | EV9: LC-MS | EW9: None | EZ9: =TEXT(A9,"@") & TEXT(B9,"@") | FA9: =TEXT(SamplesX!A9,"@") & TEXT(SamplesX!B9,"@") | FC9: =MATCH(EZ9,FA1:FA1008,0)
C10: =IF(ISNUMBER(FC10),INDIRECT("SamplesX!C"&FC10),IF(ISNUMBER(FD10),INDIRECT("SamplesY!C"&FD10),"")) | D10: =IF(ISNUMBER(FC10),INDIRECT("SamplesX!D"&FC10),IF(ISNUMBER(FD10),INDIRECT("SamplesY!D"&FD10),"")) | E10: =IF(ISNUMBER(FC10),INDIRECT("SamplesX!E"&FC10),IF(ISNUMBER(FD10),INDIRECT("SamplesY!E"&FD10),"")) | F10: =IF(ISNUMBER(FC10),INDIRECT("SamplesX!F"&FC10),IF(ISNUMBER(FD10),INDIRECT("SamplesY!F"&FD10),"")) | G10: =IF(ISNUMBER(FC10),INDIRECT("SamplesX!G"&FC10),IF(ISNUMBER(FD10),INDIRECT("SamplesY!G"&FD10),"")) | H10: =IF(ISNUMBER(FC10),INDIRECT("SamplesX!H"&FC10),IF(ISNUMBER(FD10),INDIRECT("SamplesY!H"&FD10),"")) | I10: =IF(ISNUMBER(FC10),IF(INDEX('Q:\Abteilungsprojekte\eng\EngData\AOS\Allgemein\[LabSamples2026.xlsx]Sandec'!M:M,FC10)="","",INDEX('Q:\Abteilungsprojekte\eng\EngData\AOS\Allgemein\[LabSamples2026.xlsx]Sandec'!M:M,FC10)),"") | J10: =IF(ISNUMBER(FC10),IF(INDEX('Q:\Abteilungsprojekte\eng\EngData\AOS\Allgemein\[LabSamples2026.xlsx]Sandec'!N:N,FC10)="","",INDEX('Q:\Abteilungsprojekte\eng\EngData\AOS\Allgemein\[LabSamples2026.xlsx]Sandec'!N:N,FC10)),"") | L10: Shimadzu TOC-L | M10: None | P10: Shimadzu TOC-L | Q10: None | T10: Shimadzu TOC-L | U10: None | X10: Shimadzu TOC-L | Y10: None | AC10: None | AG10: None | AJ10: IC Anionen | AK10: None | AO10: None | AR10: IC Anionen | AS10: None | AW10: None | BA10: None | BD10: IC Anionen | BE10: None | BH10: IC Kationen | BI10: None | BM10: None | BP10: IC Kationen | BQ10: None | BT10: IC Kationen | BU10: None | BX10: IC Kationen | BY10: None | CC10: None | CG10: None | CK10: None | CO10: None | CR10: SOP 45-34 | CS10: None | CW10: None | DA10: None | DE10: None | DH10: SOP 45-09 | DI10: None | DL10: SOP 45-09 | DM10: None | DP10: IC Organic Acids | DQ10: None | DT10: IC Organic Acids | DU10: None | DX10: IC Organic Acids | DY10: None | EB10: IC Organic Acids | EC10: None | EF10: IC Organic Acids | EG10: None | EJ10: IC Organic Acids | EK10: None | EN10: IC Organic Acids | EO10: None | ER10: IC Organic Acids | ES10: None | EV10: LC-MS | EW10: None | EZ10: =TEXT(A10,"@") & TEXT(B10,"@") | FA10: =TEXT(SamplesX!A10,"@") & TEXT(SamplesX!B10,"@") | FC10: =MATCH(EZ10,FA1:FA1008,0)
C11: =IF(ISNUMBER(FC11),INDIRECT("SamplesX!C"&FC11),IF(ISNUMBER(FD11),INDIRECT("SamplesY!C"&FD11),"")) | D11: =IF(ISNUMBER(FC11),INDIRECT("SamplesX!D"&FC11),IF(ISNUMBER(FD11),INDIRECT("SamplesY!D"&FD11),"")) | E11: =IF(ISNUMBER(FC11),INDIRECT("SamplesX!E"&FC11),IF(ISNUMBER(FD11),INDIRECT("SamplesY!E"&FD11),"")) | F11: =IF(ISNUMBER(FC11),INDIRECT("SamplesX!F"&FC11),IF(ISNUMBER(FD11),INDIRECT("SamplesY!F"&FD11),"")) | G11: =IF(ISNUMBER(FC11),INDIRECT("SamplesX!G"&FC11),IF(ISNUMBER(FD11),INDIRECT("SamplesY!G"&FD11),"")) | H11: =IF(ISNUMBER(FC11),INDIRECT("SamplesX!H"&FC11),IF(ISNUMBER(FD11),INDIRECT("SamplesY!H"&FD11),"")) | I11: =IF(ISNUMBER(FC11),IF(INDEX('Q:\Abteilungsprojekte\eng\EngData\AOS\Allgemein\[LabSamples2026.xlsx]Sandec'!M:M,FC11)="","",INDEX('Q:\Abteilungsprojekte\eng\EngData\AOS\Allgemein\[LabSamples2026.xlsx]Sandec'!M:M,FC11)),"") | J11: =IF(ISNUMBER(FC11),IF(INDEX('Q:\Abteilungsprojekte\eng\EngData\AOS\Allgemein\[LabSamples2026.xlsx]Sandec'!N:N,FC11)="","",INDEX('Q:\Abteilungsprojekte\eng\EngData\AOS\Allgemein\[LabSamples2026.xlsx]Sandec'!N:N,FC11)),"") | L11: Shimadzu TOC-L | M11: None | P11: Shimadzu TOC-L | Q11: None | T11: Shimadzu TOC-L | U11: None | X11: Shimadzu TOC-L | Y11: None | AC11: None | AG11: None | AJ11: IC Anionen | AK11: None | AO11: None | AR11: IC Anionen | AS11: None | AW11: None | BA11: None | BD11: IC Anionen | BE11: None | BH11: IC Kationen | BI11: None | BM11: None | BP11: IC Kationen | BQ11: None | BT11: IC Kationen | BU11: None | BX11: IC Kationen | BY11: None | CC11: None | CG11: None | CK11: None | CO11: None | CR11: SOP 45-34 | CS11: None | CW11: None | DA11: None | DE11: None | DH11: SOP 45-09 | DI11: None | DL11: SOP 45-09 | DM11: None | DP11: IC Organic Acids | DQ11: None | DT11: IC Organic Acids | DU11: None | DX11: IC Organic Acids | DY11: None | EB11: IC Organic Acids | EC11: None | EF11: IC Organic Acids | EG11: None | EJ11: IC Organic Acids | EK11: None | EN11: IC Organic Acids | EO11: None | ER11: IC Organic Acids | ES11: None | EV11: LC-MS | EW11: None | EZ11: =TEXT(A11,"@") & TEXT(B11,"@") | FA11: =TEXT(SamplesX!A11,"@") & TEXT(SamplesX!B11,"@") | FC11: =MATCH(EZ11,FA1:FA1008,0)
C12: =IF(ISNUMBER(FC12),INDIRECT("SamplesX!C"&FC12),IF(ISNUMBER(FD12),INDIRECT("SamplesY!C"&FD12),"")) | D12: =IF(ISNUMBER(FC12),INDIRECT("SamplesX!D"&FC12),IF(ISNUMBER(FD12),INDIRECT("SamplesY!D"&FD12),"")) | E12: =IF(ISNUMBER(FC12),INDIRECT("SamplesX!E"&FC12),IF(ISNUMBER(FD12),INDIRECT("SamplesY!E"&FD12),"")) | F12: =IF(ISNUMBER(FC12),INDIRECT("SamplesX!F"&FC12),IF(ISNUMBER(FD12),INDIRECT("SamplesY!F"&FD12),"")) | G12: =IF(ISNUMBER(FC12),INDIRECT("SamplesX!G"&FC12),IF(ISNUMBER(FD12),INDIRECT("SamplesY!G"&FD12),"")) | H12: =IF(ISNUMBER(FC12),INDIRECT("SamplesX!H"&FC12),IF(ISNUMBER(FD12),INDIRECT("SamplesY!H"&FD12),"")) | I12: =IF(ISNUMBER(FC12),IF(INDEX('Q:\Abteilungsprojekte\eng\EngData\AOS\Allgemein\[LabSamples2026.xlsx]Sandec'!M:M,FC12)="","",INDEX('Q:\Abteilungsprojekte\eng\EngData\AOS\Allgemein\[LabSamples2026.xlsx]Sandec'!M:M,FC12)),"") | J12: =IF(ISNUMBER(FC12),IF(INDEX('Q:\Abteilungsprojekte\eng\EngData\AOS\Allgemein\[LabSamples2026.xlsx]Sandec'!N:N,FC12)="","",INDEX('Q:\Abteilungsprojekte\eng\EngData\AOS\Allgemein\[LabSamples2026.xlsx]Sandec'!N:N,FC12)),"") | L12: Shimadzu TOC-L | M12: None | P12: Shimadzu TOC-L | Q12: None | T12: Shimadzu TOC-L | U12: None | X12: Shimadzu TOC-L | Y12: None | AC12: None | AG12: None | AJ12: IC Anionen | AK12: None | AO12: None | AR12: IC Anionen | AS12: None | AW12: None | BA12: None | BD12: IC Anionen | BE12: None | BH12: IC Kationen | BI12: None | BM12: None | BP12: IC Kationen | BQ12: None | BT12: IC Kationen | BU12: None | BX12: IC Kationen | BY12: None | CC12: None | CG12: None | CK12: None | CO12: None | CR12: SOP 45-34 | CS12: None | CW12: None | DA12: None | DE12: None | DH12: SOP 45-09 | DI12: None | DL12: SOP 45-09 | DM12: None | DP12: IC Organic Acids | DQ12: None | DT12: IC Organic Acids | DU12: None | DX12: IC Organic Acids | DY12: None | EB12: IC Organic Acids | EC12: None | EF12: IC Organic Acids | EG12: None | EJ12: IC Organic Acids | EK12: None | EN12: IC Organic Acids | EO12: None | ER12: IC Organic Acids | ES12: None | EV12: LC-MS | EW12: None | EZ12: =TEXT(A12,"@") & TEXT(B12,"@") | FA12: =TEXT(SamplesX!A12,"@") & TEXT(SamplesX!B12,"@") | FC12: =MATCH(EZ12,FA1:FA1008,0)
C13: =IF(ISNUMBER(FC13),INDIRECT("SamplesX!C"&FC13),IF(ISNUMBER(FD13),INDIRECT("SamplesY!C"&FD13),"")) | D13: =IF(ISNUMBER(FC13),INDIRECT("SamplesX!D"&FC13),IF(ISNUMBER(FD13),INDIRECT("SamplesY!D"&FD13),"")) | E13: =IF(ISNUMBER(FC13),INDIRECT("SamplesX!E"&FC13),IF(ISNUMBER(FD13),INDIRECT("SamplesY!E"&FD13),"")) | F13: =IF(ISNUMBER(FC13),INDIRECT("SamplesX!F"&FC13),IF(ISNUMBER(FD13),INDIRECT("SamplesY!F"&FD13),"")) | G13: =IF(ISNUMBER(FC13),INDIRECT("SamplesX!G"&FC13),IF(ISNUMBER(FD13),INDIRECT("SamplesY!G"&FD13),"")) | H13: =IF(ISNUMBER(FC13),INDIRECT("SamplesX!H"&FC13),IF(ISNUMBER(FD13),INDIRECT("SamplesY!H"&FD13),"")) | I13: =IF(ISNUMBER(FC13),IF(INDEX('Q:\Abteilungsprojekte\eng\EngData\AOS\Allgemein\[LabSamples2026.xlsx]Sandec'!M:M,FC13)="","",INDEX('Q:\Abteilungsprojekte\eng\EngData\AOS\Allgemein\[LabSamples2026.xlsx]Sandec'!M:M,FC13)),"") | J13: =IF(ISNUMBER(FC13),IF(INDEX('Q:\Abteilungsprojekte\eng\EngData\AOS\Allgemein\[LabSamples2026.xlsx]Sandec'!N:N,FC13)="","",INDEX('Q:\Abteilungsprojekte\eng\EngData\AOS\Allgemein\[LabSamples2026.xlsx]Sandec'!N:N,FC13)),"") | L13: Shimadzu TOC-L | M13: None | P13: Shimadzu TOC-L | Q13: None | T13: Shimadzu TOC-L | U13: None | X13: Shimadzu TOC-L | Y13: None | AC13: None | AG13: None | AJ13: IC Anionen | AK13: None | AO13: None | AR13: IC Anionen | AS13: None | AW13: None | BA13: None | BD13: IC Anionen | BE13: None | BH13: IC Kationen | BI13: None | BM13: None | BP13: IC Kationen | BQ13: None | BT13: IC Kationen | BU13: None | BX13: IC Kationen | BY13: None | CC13: None | CG13: None | CK13: None | CO13: None | CR13: SOP 45-34 | CS13: None | CW13: None | DA13: None | DE13: None | DH13: SOP 45-09 | DI13: None | DL13: SOP 45-09 | DM13: None | DP13: IC Organic Acids | DQ13: None | DT13: IC Organic Acids | DU13: None | DX13: IC Organic Acids | DY13: None | EB13: IC Organic Acids | EC13: None | EF13: IC Organic Acids | EG13: None | EJ13: IC Organic Acids | EK13: None | EN13: IC Organic Acids | EO13: None | ER13: IC Organic Acids | ES13: None | EV13: LC-MS | EW13: None | EZ13: =TEXT(A13,"@") & TEXT(B13,"@") | FA13: =TEXT(SamplesX!A13,"@") & TEXT(SamplesX!B13,"@") | FC13: =MATCH(EZ13,FA1:FA1008,0)
C14: =IF(ISNUMBER(FC14),INDIRECT("SamplesX!C"&FC14),IF(ISNUMBER(FD14),INDIRECT("SamplesY!C"&FD14),"")) | D14: =IF(ISNUMBER(FC14),INDIRECT("SamplesX!D"&FC14),IF(ISNUMBER(FD14),INDIRECT("SamplesY!D"&FD14),"")) | E14: =IF(ISNUMBER(FC14),INDIRECT("SamplesX!E"&FC14),IF(ISNUMBER(FD14),INDIRECT("SamplesY!E"&FD14),"")) | F14: =IF(ISNUMBER(FC14),INDIRECT("SamplesX!F"&FC14),IF(ISNUMBER(FD14),INDIRECT("SamplesY!F"&FD14),"")) | G14: =IF(ISNUMBER(FC14),INDIRECT("SamplesX!G"&FC14),IF(ISNUMBER(FD14),INDIRECT("SamplesY!G"&FD14),"")) | H14: =IF(ISNUMBER(FC14),INDIRECT("SamplesX!H"&FC14),IF(ISNUMBER(FD14),INDIRECT("SamplesY!H"&FD14),"")) | I14: =IF(ISNUMBER(FC14),IF(INDEX('Q:\Abteilungsprojekte\eng\EngData\AOS\Allgemein\[LabSamples2026.xlsx]Sandec'!M:M,FC14)="","",INDEX('Q:\Abteilungsprojekte\eng\EngData\AOS\Allgemein\[LabSamples2026.xlsx]Sandec'!M:M,FC14)),"") | J14: =IF(ISNUMBER(FC14),IF(INDEX('Q:\Abteilungsprojekte\eng\EngData\AOS\Allgemein\[LabSamples2026.xlsx]Sandec'!N:N,FC14)="","",INDEX('Q:\Abteilungsprojekte\eng\EngData\AOS\Allgemein\[LabSamples2026.xlsx]Sandec'!N:N,FC14)),"") | L14: Shimadzu TOC-L | M14: None | P14: Shimadzu TOC-L | Q14: None | T14: Shimadzu TOC-L | U14: None | X14: Shimadzu TOC-L | Y14: None | AC14: None | AG14: None | AJ14: IC Anionen | AK14: None | AO14: None | AR14: IC Anionen | AS14: None | AW14: None | BA14: None | BD14: IC Anionen | BE14: None | BH14: IC Kationen | BI14: None | BM14: None | BP14: IC Kationen | BQ14: None | BT14: IC Kationen | BU14: None | BX14: IC Kationen | BY14: None | CC14: None | CG14: None | CK14: None | CO14: None | CR14: SOP 45-34 | CS14: None | CW14: None | DA14: None | DE14: None | DH14: SOP 45-09 | DI14: None | DL14: SOP 45-09 | DM14: None | DP14: IC Organic Acids | DQ14: None | DT14: IC Organic Acids | DU14: None | DX14: IC Organic Acids | DY14: None | EB14: IC Organic Acids | EC14: None | EF14: IC Organic Acids | EG14: None | EJ14: IC Organic Acids | EK14: None | EN14: IC Organic Acids | EO14: None | ER14: IC Organic Acids | ES14: None | EV14: LC-MS | EW14: None | EZ14: =TEXT(A14,"@") & TEXT(B14,"@") | FA14: =TEXT(SamplesX!A14,"@") & TEXT(SamplesX!B14,"@") | FC14: =MATCH(EZ14,FA1:FA1008,0)
C15: =IF(ISNUMBER(FC15),INDIRECT("SamplesX!C"&FC15),IF(ISNUMBER(FD15),INDIRECT("SamplesY!C"&FD15),"")) | D15: =IF(ISNUMBER(FC15),INDIRECT("SamplesX!D"&FC15),IF(ISNUMBER(FD15),INDIRECT("SamplesY!D"&FD15),"")) | E15: =IF(ISNUMBER(FC15),INDIRECT("SamplesX!E"&FC15),IF(ISNUMBER(FD15),INDIRECT("SamplesY!E"&FD15),"")) | F15: =IF(ISNUMBER(FC15),INDIRECT("SamplesX!F"&FC15),IF(ISNUMBER(FD15),INDIRECT("SamplesY!F"&FD15),"")) | G15: =IF(ISNUMBER(FC15),INDIRECT("SamplesX!G"&FC15),IF(ISNUMBER(FD15),INDIRECT("SamplesY!G"&FD15),"")) | H15: =IF(ISNUMBER(FC15),INDIRECT("SamplesX!H"&FC15),IF(ISNUMBER(FD15),INDIRECT("SamplesY!H"&FD15),"")) | I15: =IF(ISNUMBER(FC15),IF(INDEX('Q:\Abteilungsprojekte\eng\EngData\AOS\Allgemein\[LabSamples2026.xlsx]Sandec'!M:M,FC15)="","",INDEX('Q:\Abteilungsprojekte\eng\EngData\AOS\Allgemein\[LabSamples2026.xlsx]Sandec'!M:M,FC15)),"") | J15: =IF(ISNUMBER(FC15),IF(INDEX('Q:\Abteilungsprojekte\eng\EngData\AOS\Allgemein\[LabSamples2026.xlsx]Sandec'!N:N,FC15)="","",INDEX('Q:\Abteilungsprojekte\eng\EngData\AOS\Allgemein\[LabSamples2026.xlsx]Sandec'!N:N,FC15)),"") | L15: Shimadzu TOC-L | M15: None | P15: Shimadzu TOC-L | Q15: None | T15: Shimadzu TOC-L | U15: None | X15: Shimadzu TOC-L | Y15: None | AC15: None | AG15: None | AJ15: IC Anionen | AK15: None | AO15: None | AR15: IC Anionen | AS15: None | AW15: None | BA15: None | BD15: IC Anionen | BE15: None | BH15: IC Kationen | BI15: None | BM15: None | BP15: IC Kationen | BQ15: None | BT15: IC Kationen | BU15: None | BX15: IC Kationen | BY15: None | CC15: None | CG15: None | CK15: None | CO15: None | CR15: SOP 45-34 | CS15: None | CW15: None | DA15: None | DE15: None | DH15: SOP 45-09 | DI15: None | DL15: SOP 45-09 | DM15: None | DP15: IC Organic Acids | DQ15: None | DT15: IC Organic Acids | DU15: None | DX15: IC Organic Acids | DY15: None | EB15: IC Organic Acids | EC15: None | EF15: IC Organic Acids | EG15: None | EJ15: IC Organic Acids | EK15: None | EN15: IC Organic Acids | EO15: None | ER15: IC Organic Acids | ES15: None | EV15: LC-MS | EW15: None | EZ15: =TEXT(A15,"@") & TEXT(B15,"@") | FA15: =TEXT(SamplesX!A15,"@") & TEXT(SamplesX!B15,"@") | FC15: =MATCH(EZ15,FA1:FA1008,0)
C16: =IF(ISNUMBER(FC16),INDIRECT("SamplesX!C"&FC16),IF(ISNUMBER(FD16),INDIRECT("SamplesY!C"&FD16),"")) | D16: =IF(ISNUMBER(FC16),INDIRECT("SamplesX!D"&FC16),IF(ISNUMBER(FD16),INDIRECT("SamplesY!D"&FD16),"")) | E16: =IF(ISNUMBER(FC16),INDIRECT("SamplesX!E"&FC16),IF(ISNUMBER(FD16),INDIRECT("SamplesY!E"&FD16),"")) | F16: =IF(ISNUMBER(FC16),INDIRECT("SamplesX!F"&FC16),IF(ISNUMBER(FD16),INDIRECT("SamplesY!F"&FD16),"")) | G16: =IF(ISNUMBER(FC16),INDIRECT("SamplesX!G"&FC16),IF(ISNUMBER(FD16),INDIRECT("SamplesY!G"&FD16),"")) | H16: =IF(ISNUMBER(FC16),INDIRECT("SamplesX!H"&FC16),IF(ISNUMBER(FD16),INDIRECT("SamplesY!H"&FD16),"")) | I16: =IF(ISNUMBER(FC16),IF(INDEX('Q:\Abteilungsprojekte\eng\EngData\AOS\Allgemein\[LabSamples2026.xlsx]Sandec'!M:M,FC16)="","",INDEX('Q:\Abteilungsprojekte\eng\EngData\AOS\Allgemein\[LabSamples2026.xlsx]Sandec'!M:M,FC16)),"") | J16: =IF(ISNUMBER(FC16),IF(INDEX('Q:\Abteilungsprojekte\eng\EngData\AOS\Allgemein\[LabSamples2026.xlsx]Sandec'!N:N,FC16)="","",INDEX('Q:\Abteilungsprojekte\eng\EngData\AOS\Allgemein\[LabSamples2026.xlsx]Sandec'!N:N,FC16)),"") | L16: Shimadzu TOC-L | M16: None | P16: Shimadzu TOC-L | Q16: None | T16: Shimadzu TOC-L | U16: None | X16: Shimadzu TOC-L | Y16: None | AC16: None | AG16: None | AJ16: IC Anionen | AK16: None | AO16: None | AR16: IC Anionen | AS16: None | AW16: None | BA16: None | BD16: IC Anionen | BE16: None | BH16: IC Kationen | BI16: None | BM16: None | BP16: IC Kationen | BQ16: None | BT16: IC Kationen | BU16: None | BX16: IC Kationen | BY16: None | CC16: None | CG16: None | CK16: None | CO16: None | CR16: SOP 45-34 | CS16: None | CW16: None | DA16: None | DE16: None | DH16: SOP 45-09 | DI16: None | DL16: SOP 45-09 | DM16: None | DP16: IC Organic Acids | DQ16: None | DT16: IC Organic Acids | DU16: None | DX16: IC Organic Acids | DY16: None | EB16: IC Organic Acids | EC16: None | EF16: IC Organic Acids | EG16: None | EJ16: IC Organic Acids | EK16: None | EN16: IC Organic Acids | EO16: None | ER16: IC Organic Acids | ES16: None | EV16: LC-MS | EW16: None | EZ16: =TEXT(A16,"@") & TEXT(B16,"@") | FA16: =TEXT(SamplesX!A16,"@") & TEXT(SamplesX!B16,"@") | FC16: =MATCH(EZ16,FA1:FA1008,0)
C17: =IF(ISNUMBER(FC17),INDIRECT("SamplesX!C"&FC17),IF(ISNUMBER(FD17),INDIRECT("SamplesY!C"&FD17),"")) | D17: =IF(ISNUMBER(FC17),INDIRECT("SamplesX!D"&FC17),IF(ISNUMBER(FD17),INDIRECT("SamplesY!D"&FD17),"")) | E17: =IF(ISNUMBER(FC17),INDIRECT("SamplesX!E"&FC17),IF(ISNUMBER(FD17),INDIRECT("SamplesY!E"&FD17),"")) | F17: =IF(ISNUMBER(FC17),INDIRECT("SamplesX!F"&FC17),IF(ISNUMBER(FD17),INDIRECT("SamplesY!F"&FD17),"")) | G17: =IF(ISNUMBER(FC17),INDIRECT("SamplesX!G"&FC17),IF(ISNUMBER(FD17),INDIRECT("SamplesY!G"&FD17),"")) | H17: =IF(ISNUMBER(FC17),INDIRECT("SamplesX!H"&FC17),IF(ISNUMBER(FD17),INDIRECT("SamplesY!H"&FD17),"")) | I17: =IF(ISNUMBER(FC17),IF(INDEX('Q:\Abteilungsprojekte\eng\EngData\AOS\Allgemein\[LabSamples2026.xlsx]Sandec'!M:M,FC17)="","",INDEX('Q:\Abteilungsprojekte\eng\EngData\AOS\Allgemein\[LabSamples2026.xlsx]Sandec'!M:M,FC17)),"") | J17: =IF(ISNUMBER(FC17),IF(INDEX('Q:\Abteilungsprojekte\eng\EngData\AOS\Allgemein\[LabSamples2026.xlsx]Sandec'!N:N,FC17)="","",INDEX('Q:\Abteilungsprojekte\eng\EngData\AOS\Allgemein\[LabSamples2026.xlsx]Sandec'!N:N,FC17)),"") | L17: Shimadzu TOC-L | M17: None | P17: Shimadzu TOC-L | Q17: None | T17: Shimadzu TOC-L | U17: None | X17: Shimadzu TOC-L | Y17: None | AC17: None | AG17: None | AJ17: IC Anionen | AK17: None | AO17: None | AR17: IC Anionen | AS17: None | AW17: None | BA17: None | BD17: IC Anionen | BE17: None | BH17: IC Kationen | BI17: None | BM17: None | BP17: IC Kationen | BQ17: None | BT17: IC Kationen | BU17: None | BX17: IC Kationen | BY17: None | CC17: None | CG17: None | CK17: None | CO17: None | CR17: SOP 45-34 | CS17: None | CW17: None | DA17: None | DE17: None | DH17: SOP 45-09 | DI17: None | DL17: SOP 45-09 | DM17: None | DP17: IC Organic Acids | DQ17: None | DT17: IC Organic Acids | DU17: None | DX17: IC Organic Acids | DY17: None | EB17: IC Organic Acids | EC17: None | EF17: IC Organic Acids | EG17: None | EJ17: IC Organic Acids | EK17: None | EN17: IC Organic Acids | EO17: None | ER17: IC Organic Acids | ES17: None | EV17: LC-MS | EW17: None | EZ17: =TEXT(A17,"@") & TEXT(B17,"@") | FA17: =TEXT(SamplesX!A17,"@") & TEXT(SamplesX!B17,"@") | FC17: =MATCH(EZ17,FA1:FA1008,0)
C18: =IF(ISNUMBER(FC18),INDIRECT("SamplesX!C"&FC18),IF(ISNUMBER(FD18),INDIRECT("SamplesY!C"&FD18),"")) | D18: =IF(ISNUMBER(FC18),INDIRECT("SamplesX!D"&FC18),IF(ISNUMBER(FD18),INDIRECT("SamplesY!D"&FD18),"")) | E18: =IF(ISNUMBER(FC18),INDIRECT("SamplesX!E"&FC18),IF(ISNUMBER(FD18),INDIRECT("SamplesY!E"&FD18),"")) | F18: =IF(ISNUMBER(FC18),INDIRECT("SamplesX!F"&FC18),IF(ISNUMBER(FD18),INDIRECT("SamplesY!F"&FD18),"")) | G18: =IF(ISNUMBER(FC18),INDIRECT("SamplesX!G"&FC18),IF(ISNUMBER(FD18),INDIRECT("SamplesY!G"&FD18),"")) | H18: =IF(ISNUMBER(FC18),INDIRECT("SamplesX!H"&FC18),IF(ISNUMBER(FD18),INDIRECT("SamplesY!H"&FD18),"")) | I18: =IF(ISNUMBER(FC18),IF(INDEX('Q:\Abteilungsprojekte\eng\EngData\AOS\Allgemein\[LabSamples2026.xlsx]Sandec'!M:M,FC18)="","",INDEX('Q:\Abteilungsprojekte\eng\EngData\AOS\Allgemein\[LabSamples2026.xlsx]Sandec'!M:M,FC18)),"") | J18: =IF(ISNUMBER(FC18),IF(INDEX('Q:\Abteilungsprojekte\eng\EngData\AOS\Allgemein\[LabSamples2026.xlsx]Sandec'!N:N,FC18)="","",INDEX('Q:\Abteilungsprojekte\eng\EngData\AOS\Allgemein\[LabSamples2026.xlsx]Sandec'!N:N,FC18)),"") | L18: Shimadzu TOC-L | M18: None | P18: Shimadzu TOC-L | Q18: None | T18: Shimadzu TOC-L | U18: None | X18: Shimadzu TOC-L | Y18: None | AC18: None | AG18: None | AJ18: IC Anionen | AK18: None | AO18: None | AR18: IC Anionen | AS18: None | AW18: None | BA18: None | BD18: IC Anionen | BE18: None | BH18: IC Kationen | BI18: None | BM18: None | BP18: IC Kationen | BQ18: None | BT18: IC Kationen | BU18: None | BX18: IC Kationen | BY18: None | CC18: None | CG18: None | CK18: None | CO18: None | CR18: SOP 45-34 | CS18: None | CW18: None | DA18: None | DE18: None | DH18: SOP 45-09 | DI18: None | DL18: SOP 45-09 | DM18: None | DP18: IC Organic Acids | DQ18: None | DT18: IC Organic Acids | DU18: None | DX18: IC Organic Acids | DY18: None | EB18: IC Organic Acids | EC18: None | EF18: IC Organic Acids | EG18: None | EJ18: IC Organic Acids | EK18: None | EN18: IC Organic Acids | EO18: None | ER18: IC Organic Acids | ES18: None | EV18: LC-MS | EW18: None | EZ18: =TEXT(A18,"@") & TEXT(B18,"@") | FA18: =TEXT(SamplesX!A18,"@") & TEXT(SamplesX!B18,"@") | FC18: =MATCH(EZ18,FA1:FA1008,0)
C19: =IF(ISNUMBER(FC19),INDIRECT("SamplesX!C"&FC19),IF(ISNUMBER(FD19),INDIRECT("SamplesY!C"&FD19),"")) | D19: =IF(ISNUMBER(FC19),INDIRECT("SamplesX!D"&FC19),IF(ISNUMBER(FD19),INDIRECT("SamplesY!D"&FD19),"")) | E19: =IF(ISNUMBER(FC19),INDIRECT("SamplesX!E"&FC19),IF(ISNUMBER(FD19),INDIRECT("SamplesY!E"&FD19),"")) | F19: =IF(ISNUMBER(FC19),INDIRECT("SamplesX!F"&FC19),IF(ISNUMBER(FD19),INDIRECT("SamplesY!F"&FD19),"")) | G19: =IF(ISNUMBER(FC19),INDIRECT("SamplesX!G"&FC19),IF(ISNUMBER(FD19),INDIRECT("SamplesY!G"&FD19),"")) | H19: =IF(ISNUMBER(FC19),INDIRECT("SamplesX!H"&FC19),IF(ISNUMBER(FD19),INDIRECT("SamplesY!H"&FD19),"")) | I19: =IF(ISNUMBER(FC19),IF(INDEX('Q:\Abteilungsprojekte\eng\EngData\AOS\Allgemein\[LabSamples2026.xlsx]Sandec'!M:M,FC19)="","",INDEX('Q:\Abteilungsprojekte\eng\EngData\AOS\Allgemein\[LabSamples2026.xlsx]Sandec'!M:M,FC19)),"") | J19: =IF(ISNUMBER(FC19),IF(INDEX('Q:\Abteilungsprojekte\eng\EngData\AOS\Allgemein\[LabSamples2026.xlsx]Sandec'!N:N,FC19)="","",INDEX('Q:\Abteilungsprojekte\eng\EngData\AOS\Allgemein\[LabSamples2026.xlsx]Sandec'!N:N,FC19)),"") | L19: Shimadzu TOC-L | M19: None | P19: Shimadzu TOC-L | Q19: None | T19: Shimadzu TOC-L | U19: None | X19: Shimadzu TOC-L | Y19: None | AC19: None | AG19: None | AJ19: IC Anionen | AK19: None | AO19: None | AR19: IC Anionen | AS19: None | AW19: None | BA19: None | BD19: IC Anionen | BE19: None | BH19: IC Kationen | BI19: None | BM19: None | BP19: IC Kationen | BQ19: None | BT19: IC Kationen | BU19: None | BX19: IC Kationen | BY19: None | CC19: None | CG19: None | CK19: None | CO19: None | CR19: SOP 45-34 | CS19: None | CW19: None | DA19: None | DE19: None | DH19: SOP 45-09 | DI19: None | DL19: SOP 45-09 | DM19: None | DP19: IC Organic Acids | DQ19: None | DT19: IC Organic Acids | DU19: None | DX19: IC Organic Acids | DY19: None | EB19: IC Organic Acids | EC19: None | EF19: IC Organic Acids | EG19: None | EJ19: IC Organic Acids | EK19: None | EN19: IC Organic Acids | EO19: None | ER19: IC Organic Acids | ES19: None | EV19: LC-MS | EW19: None | EZ19: =TEXT(A19,"@") & TEXT(B19,"@") | FA19: =TEXT(SamplesX!A19,"@") & TEXT(SamplesX!B19,"@") | FC19: =MATCH(EZ19,FA1:FA1008,0)
C20: =IF(ISNUMBER(FC20),INDIRECT("SamplesX!C"&FC20),IF(ISNUMBER(FD20),INDIRECT("SamplesY!C"&FD20),"")) | D20: =IF(ISNUMBER(FC20),INDIRECT("SamplesX!D"&FC20),IF(ISNUMBER(FD20),INDIRECT("SamplesY!D"&FD20),"")) | E20: =IF(ISNUMBER(FC20),INDIRECT("SamplesX!E"&FC20),IF(ISNUMBER(FD20),INDIRECT("SamplesY!E"&FD20),"")) | F20: =IF(ISNUMBER(FC20),INDIRECT("SamplesX!F"&FC20),IF(ISNUMBER(FD20),INDIRECT("SamplesY!F"&FD20),"")) | G20: =IF(ISNUMBER(FC20),INDIRECT("SamplesX!G"&FC20),IF(ISNUMBER(FD20),INDIRECT("SamplesY!G"&FD20),"")) | H20: =IF(ISNUMBER(FC20),INDIRECT("SamplesX!H"&FC20),IF(ISNUMBER(FD20),INDIRECT("SamplesY!H"&FD20),"")) | I20: =IF(ISNUMBER(FC20),IF(INDEX('Q:\Abteilungsprojekte\eng\EngData\AOS\Allgemein\[LabSamples2026.xlsx]Sandec'!M:M,FC20)="","",INDEX('Q:\Abteilungsprojekte\eng\EngData\AOS\Allgemein\[LabSamples2026.xlsx]Sandec'!M:M,FC20)),"") | J20: =IF(ISNUMBER(FC20),IF(INDEX('Q:\Abteilungsprojekte\eng\EngData\AOS\Allgemein\[LabSamples2026.xlsx]Sandec'!N:N,FC20)="","",INDEX('Q:\Abteilungsprojekte\eng\EngData\AOS\Allgemein\[LabSamples2026.xlsx]Sandec'!N:N,FC20)),"") | L20: Shimadzu TOC-L | M20: None | P20: Shimadzu TOC-L | Q20: None | T20: Shimadzu TOC-L | U20: None | X20: Shimadzu TOC-L | Y20: None | AC20: None | AG20: None | AJ20: IC Anionen | AK20: None | AO20: None | AR20: IC Anionen | AS20: None | AW20: None | BA20: None | BD20: IC Anionen | BE20: None | BH20: IC Kationen | BI20: None | BM20: None | BP20: IC Kationen | BQ20: None | BT20: IC Kationen | BU20: None | BX20: IC Kationen | BY20: None | CC20: None | CG20: None | CK20: None | CO20: None | CR20: SOP 45-34 | CS20: None | CW20: None | DA20: None | DE20: None | DH20: SOP 45-09 | DI20: None | DL20: SOP 45-09 | DM20: None | DP20: IC Organic Acids | DQ20: None | DT20: IC Organic Acids | DU20: None | DX20: IC Organic Acids | DY20: None | EB20: IC Organic Acids | EC20: None | EF20: IC Organic Acids | EG20: None | EJ20: IC Organic Acids | EK20: None | EN20: IC Organic Acids | EO20: None | ER20: IC Organic Acids | ES20: None | EV20: LC-MS | EW20: None | EZ20: =TEXT(A20,"@") & TEXT(B20,"@") | FA20: =TEXT(SamplesX!A20,"@") & TEXT(SamplesX!B20,"@") | FC20: =MATCH(EZ20,FA1:FA1008,0)
C21: =IF(ISNUMBER(FC21),INDIRECT("SamplesX!C"&FC21),IF(ISNUMBER(FD21),INDIRECT("SamplesY!C"&FD21),"")) | D21: =IF(ISNUMBER(FC21),INDIRECT("SamplesX!D"&FC21),IF(ISNUMBER(FD21),INDIRECT("SamplesY!D"&FD21),"")) | E21: =IF(ISNUMBER(FC21),INDIRECT("SamplesX!E"&FC21),IF(ISNUMBER(FD21),INDIRECT("SamplesY!E"&FD21),"")) | F21: =IF(ISNUMBER(FC21),INDIRECT("SamplesX!F"&FC21),IF(ISNUMBER(FD21),INDIRECT("SamplesY!F"&FD21),"")) | G21: =IF(ISNUMBER(FC21),INDIRECT("SamplesX!G"&FC21),IF(ISNUMBER(FD21),INDIRECT("SamplesY!G"&FD21),"")) | H21: =IF(ISNUMBER(FC21),INDIRECT("SamplesX!H"&FC21),IF(ISNUMBER(FD21),INDIRECT("SamplesY!H"&FD21),"")) | I21: =IF(ISNUMBER(FC21),IF(INDEX('Q:\Abteilungsprojekte\eng\EngData\AOS\Allgemein\[LabSamples2026.xlsx]Sandec'!M:M,FC21)="","",INDEX('Q:\Abteilungsprojekte\eng\EngData\AOS\Allgemein\[LabSamples2026.xlsx]Sandec'!M:M,FC21)),"") | J21: =IF(ISNUMBER(FC21),IF(INDEX('Q:\Abteilungsprojekte\eng\EngData\AOS\Allgemein\[LabSamples2026.xlsx]Sandec'!N:N,FC21)="","",INDEX('Q:\Abteilungsprojekte\eng\EngData\AOS\Allgemein\[LabSamples2026.xlsx]Sandec'!N:N,FC21)),"") | L21: Shimadzu TOC-L | M21: None | P21: Shimadzu TOC-L | Q21: None | T21: Shimadzu TOC-L | U21: None | X21: Shimadzu TOC-L | Y21: None | AC21: None | AG21: None | AJ21: IC Anionen | AK21: None | AO21: None | AR21: IC Anionen | AS21: None | AW21: None | BA21: None | BD21: IC Anionen | BE21: None | BH21: IC Kationen | BI21: None | BM21: None | BP21: IC Kationen | BQ21: None | BT21: IC Kationen | BU21: None | BX21: IC Kationen | BY21: None | CC21: None | CG21: None | CK21: None | CO21: None | CR21: SOP 45-34 | CS21: None | CW21: None | DA21: None | DE21: None | DH21: SOP 45-09 | DI21: None | DL21: SOP 45-09 | DM21: None | DP21: IC Organic Acids | DQ21: None | DT21: IC Organic Acids | DU21: None | DX21: IC Organic Acids | DY21: None | EB21: IC Organic Acids | EC21: None | EF21: IC Organic Acids | EG21: None | EJ21: IC Organic Acids | EK21: None | EN21: IC Organic Acids | EO21: None | ER21: IC Organic Acids | ES21: None | EV21: LC-MS | EW21: None | EZ21: =TEXT(A21,"@") & TEXT(B21,"@") | FA21: =TEXT(SamplesX!A21,"@") & TEXT(SamplesX!B21,"@") | FC21: =MATCH(EZ21,FA1:FA1008,0)
C22: =IF(ISNUMBER(FC22),INDIRECT("SamplesX!C"&FC22),IF(ISNUMBER(FD22),INDIRECT("SamplesY!C"&FD22),"")) | D22: =IF(ISNUMBER(FC22),INDIRECT("SamplesX!D"&FC22),IF(ISNUMBER(FD22),INDIRECT("SamplesY!D"&FD22),"")) | E22: =IF(ISNUMBER(FC22),INDIRECT("SamplesX!E"&FC22),IF(ISNUMBER(FD22),INDIRECT("SamplesY!E"&FD22),"")) | F22: =IF(ISNUMBER(FC22),INDIRECT("SamplesX!F"&FC22),IF(ISNUMBER(FD22),INDIRECT("SamplesY!F"&FD22),"")) | G22: =IF(ISNUMBER(FC22),INDIRECT("SamplesX!G"&FC22),IF(ISNUMBER(FD22),INDIRECT("SamplesY!G"&FD22),"")) | H22: =IF(ISNUMBER(FC22),INDIRECT("SamplesX!H"&FC22),IF(ISNUMBER(FD22),INDIRECT("SamplesY!H"&FD22),"")) | I22: =IF(ISNUMBER(FC22),IF(INDEX('Q:\Abteilungsprojekte\eng\EngData\AOS\Allgemein\[LabSamples2026.xlsx]Sandec'!M:M,FC22)="","",INDEX('Q:\Abteilungsprojekte\eng\EngData\AOS\Allgemein\[LabSamples2026.xlsx]Sandec'!M:M,FC22)),"") | J22: =IF(ISNUMBER(FC22),IF(INDEX('Q:\Abteilungsprojekte\eng\EngData\AOS\Allgemein\[LabSamples2026.xlsx]Sandec'!N:N,FC22)="","",INDEX('Q:\Abteilungsprojekte\eng\EngData\AOS\Allgemein\[LabSamples2026.xlsx]Sandec'!N:N,FC22)),"") | L22: Shimadzu TOC-L | M22: None | P22: Shimadzu TOC-L | Q22: None | T22: Shimadzu TOC-L | U22: None | X22: Shimadzu TOC-L | Y22: None | AC22: None | AG22: None | AJ22: IC Anionen | AK22: None | AO22: None | AR22: IC Anionen | AS22: None | AW22: None | BA22: None | BD22: IC Anionen | BE22: None | BH22: IC Kationen | BI22: None | BM22: None | BP22: IC Kationen | BQ22: None | BT22: IC Kationen | BU22: None | BX22: IC Kationen | BY22: None | CC22: None | CG22: None | CK22: None | CO22: None | CR22: SOP 45-34 | CS22: None | CW22: None | DA22: None | DE22: None | DH22: SOP 45-09 | DI22: None | DL22: SOP 45-09 | DM22: None | DP22: IC Organic Acids | DQ22: None | DT22: IC Organic Acids | DU22: None | DX22: IC Organic Acids | DY22: None | EB22: IC Organic Acids | EC22: None | EF22: IC Organic Acids | EG22: None | EJ22: IC Organic Acids | EK22: None | EN22: IC Organic Acids | EO22: None | ER22: IC Organic Acids | ES22: None | EV22: LC-MS | EW22: None | EZ22: =TEXT(A22,"@") & TEXT(B22,"@") | FA22: =TEXT(SamplesX!A22,"@") & TEXT(SamplesX!B22,"@") | FC22: =MATCH(EZ22,FA1:FA1008,0)
C23: =IF(ISNUMBER(FC23),INDIRECT("SamplesX!C"&FC23),IF(ISNUMBER(FD23),INDIRECT("SamplesY!C"&FD23),"")) | D23: =IF(ISNUMBER(FC23),INDIRECT("SamplesX!D"&FC23),IF(ISNUMBER(FD23),INDIRECT("SamplesY!D"&FD23),"")) | E23: =IF(ISNUMBER(FC23),INDIRECT("SamplesX!E"&FC23),IF(ISNUMBER(FD23),INDIRECT("SamplesY!E"&FD23),"")) | F23: =IF(ISNUMBER(FC23),INDIRECT("SamplesX!F"&FC23),IF(ISNUMBER(FD23),INDIRECT("SamplesY!F"&FD23),"")) | G23: =IF(ISNUMBER(FC23),INDIRECT("SamplesX!G"&FC23),IF(ISNUMBER(FD23),INDIRECT("SamplesY!G"&FD23),"")) | H23: =IF(ISNUMBER(FC23),INDIRECT("SamplesX!H"&FC23),IF(ISNUMBER(FD23),INDIRECT("SamplesY!H"&FD23),"")) | I23: =IF(ISNUMBER(FC23),IF(INDEX('Q:\Abteilungsprojekte\eng\EngData\AOS\Allgemein\[LabSamples2026.xlsx]Sandec'!M:M,FC23)="","",INDEX('Q:\Abteilungsprojekte\eng\EngData\AOS\Allgemein\[LabSamples2026.xlsx]Sandec'!M:M,FC23)),"") | J23: =IF(ISNUMBER(FC23),IF(INDEX('Q:\Abteilungsprojekte\eng\EngData\AOS\Allgemein\[LabSamples2026.xlsx]Sandec'!N:N,FC23)="","",INDEX('Q:\Abteilungsprojekte\eng\EngData\AOS\Allgemein\[LabSamples2026.xlsx]Sandec'!N:N,FC23)),"") | L23: Shimadzu TOC-L | M23: None | P23: Shimadzu TOC-L | Q23: None | T23: Shimadzu TOC-L | U23: None | X23: Shimadzu TOC-L | Y23: None | AC23: None | AG23: None | AJ23: IC Anionen | AK23: None | AO23: None | AR23: IC Anionen | AS23: None | AW23: None | BA23: None | BD23: IC Anionen | BE23: None | BH23: IC Kationen | BI23: None | BM23: None | BP23: IC Kationen | BQ23: None | BT23: IC Kationen | BU23: None | BX23: IC Kationen | BY23: None | CC23: None | CG23: None | CK23: None | CO23: None | CR23: SOP 45-34 | CS23: None | CW23: None | DA23: None | DE23: None | DH23: SOP 45-09 | DI23: None | DL23: SOP 45-09 | DM23: None | DP23: IC Organic Acids | DQ23: None | DT23: IC Organic Acids | DU23: None | DX23: IC Organic Acids | DY23: None | EB23: IC Organic Acids | EC23: None | EF23: IC Organic Acids | EG23: None | EJ23: IC Organic Acids | EK23: None | EN23: IC Organic Acids | EO23: None | ER23: IC Organic Acids | ES23: None | EV23: LC-MS | EW23: None | EZ23: =TEXT(A23,"@") & TEXT(B23,"@") | FA23: =TEXT(SamplesX!A23,"@") & TEXT(SamplesX!B23,"@") | FC23: =MATCH(EZ23,FA1:FA1008,0)
C24: =IF(ISNUMBER(FC24),INDIRECT("SamplesX!C"&FC24),IF(ISNUMBER(FD24),INDIRECT("SamplesY!C"&FD24),"")) | D24: =IF(ISNUMBER(FC24),INDIRECT("SamplesX!D"&FC24),IF(ISNUMBER(FD24),INDIRECT("SamplesY!D"&FD24),"")) | E24: =IF(ISNUMBER(FC24),INDIRECT("SamplesX!E"&FC24),IF(ISNUMBER(FD24),INDIRECT("SamplesY!E"&FD24),"")) | F24: =IF(ISNUMBER(FC24),INDIRECT("SamplesX!F"&FC24),IF(ISNUMBER(FD24),INDIRECT("SamplesY!F"&FD24),"")) | G24: =IF(ISNUMBER(FC24),INDIRECT("SamplesX!G"&FC24),IF(ISNUMBER(FD24),INDIRECT("SamplesY!G"&FD24),"")) | H24: =IF(ISNUMBER(FC24),INDIRECT("SamplesX!H"&FC24),IF(ISNUMBER(FD24),INDIRECT("SamplesY!H"&FD24),"")) | I24: =IF(ISNUMBER(FC24),IF(INDEX('Q:\Abteilungsprojekte\eng\EngData\AOS\Allgemein\[LabSamples2026.xlsx]Sandec'!M:M,FC24)="","",INDEX('Q:\Abteilungsprojekte\eng\EngData\AOS\Allgemein\[LabSamples2026.xlsx]Sandec'!M:M,FC24)),"") | J24: =IF(ISNUMBER(FC24),IF(INDEX('Q:\Abteilungsprojekte\eng\EngData\AOS\Allgemein\[LabSamples2026.xlsx]Sandec'!N:N,FC24)="","",INDEX('Q:\Abteilungsprojekte\eng\EngData\AOS\Allgemein\[LabSamples2026.xlsx]Sandec'!N:N,FC24)),"") | L24: Shimadzu TOC-L | M24: None | P24: Shimadzu TOC-L | Q24: None | T24: Shimadzu TOC-L | U24: None | X24: Shimadzu TOC-L | Y24: None | AC24: None | AG24: None | AJ24: IC Anionen | AK24: None | AO24: None | AR24: IC Anionen | AS24: None | AW24: None | BA24: None | BD24: IC Anionen | BE24: None | BH24: IC Kationen | BI24: None | BM24: None | BP24: IC Kationen | BQ24: None | BT24: IC Kationen | BU24: None | BX24: IC Kationen | BY24: None | CC24: None | CG24: None | CK24: None | CO24: None | CR24: SOP 45-34 | CS24: None | CW24: None | DA24: None | DE24: None | DH24: SOP 45-09 | DI24: None | DL24: SOP 45-09 | DM24: None | DP24: IC Organic Acids | DQ24: None | DT24: IC Organic Acids | DU24: None | DX24: IC Organic Acids | DY24: None | EB24: IC Organic Acids | EC24: None | EF24: IC Organic Acids | EG24: None | EJ24: IC Organic Acids | EK24: None | EN24: IC Organic Acids | EO24: None | ER24: IC Organic Acids | ES24: None | EV24: LC-MS | EW24: None | EZ24: =TEXT(A24,"@") & TEXT(B24,"@") | FA24: =TEXT(SamplesX!A24,"@") & TEXT(SamplesX!B24,"@") | FC24: =MATCH(EZ24,FA1:FA1008,0)
C25: =IF(ISNUMBER(FC25),INDIRECT("SamplesX!C"&FC25),IF(ISNUMBER(FD25),INDIRECT("SamplesY!C"&FD25),"")) | D25: =IF(ISNUMBER(FC25),INDIRECT("SamplesX!D"&FC25),IF(ISNUMBER(FD25),INDIRECT("SamplesY!D"&FD25),"")) | E25: =IF(ISNUMBER(FC25),INDIRECT("SamplesX!E"&FC25),IF(ISNUMBER(FD25),INDIRECT("SamplesY!E"&FD25),"")) | F25: =IF(ISNUMBER(FC25),INDIRECT("SamplesX!F"&FC25),IF(ISNUMBER(FD25),INDIRECT("SamplesY!F"&FD25),"")) | G25: =IF(ISNUMBER(FC25),INDIRECT("SamplesX!G"&FC25),IF(ISNUMBER(FD25),INDIRECT("SamplesY!G"&FD25),"")) | H25: =IF(ISNUMBER(FC25),INDIRECT("SamplesX!H"&FC25),IF(ISNUMBER(FD25),INDIRECT("SamplesY!H"&FD25),"")) | I25: =IF(ISNUMBER(FC25),IF(INDEX('Q:\Abteilungsprojekte\eng\EngData\AOS\Allgemein\[LabSamples2026.xlsx]Sandec'!M:M,FC25)="","",INDEX('Q:\Abteilungsprojekte\eng\EngData\AOS\Allgemein\[LabSamples2026.xlsx]Sandec'!M:M,FC25)),"") | J25: =IF(ISNUMBER(FC25),IF(INDEX('Q:\Abteilungsprojekte\eng\EngData\AOS\Allgemein\[LabSamples2026.xlsx]Sandec'!N:N,FC25)="","",INDEX('Q:\Abteilungsprojekte\eng\EngData\AOS\Allgemein\[LabSamples2026.xlsx]Sandec'!N:N,FC25)),"") | L25: Shimadzu TOC-L | M25: None | P25: Shimadzu TOC-L | Q25: None | T25: Shimadzu TOC-L | U25: None | X25: Shimadzu TOC-L | Y25: None | AC25: None | AG25: None | AJ25: IC Anionen | AK25: None | AO25: None | AR25: IC Anionen | AS25: None | AW25: None | BA25: None | BD25: IC Anionen | BE25: None | BH25: IC Kationen | BI25: None | BM25: None | BP25: IC Kationen | BQ25: None | BT25: IC Kationen | BU25: None | BX25: IC Kationen | BY25: None | CC25: None | CG25: None | CK25: None | CO25: None | CR25: SOP 45-34 | CS25: None | CW25: None | DA25: None | DE25: None | DH25: SOP 45-09 | DI25: None | DL25: SOP 45-09 | DM25: None | DP25: IC Organic Acids | DQ25: None | DT25: IC Organic Acids | DU25: None | DX25: IC Organic Acids | DY25: None | EB25: IC Organic Acids | EC25: None | EF25: IC Organic Acids | EG25: None | EJ25: IC Organic Acids | EK25: None | EN25: IC Organic Acids | EO25: None | ER25: IC Organic Acids | ES25: None | EV25: LC-MS | EW25: None | EZ25: =TEXT(A25,"@") & TEXT(B25,"@") | FA25: =TEXT(SamplesX!A25,"@") & TEXT(SamplesX!B25,"@") | FC25: =MATCH(EZ25,FA1:FA1008,0)
C26: =IF(ISNUMBER(FC26),INDIRECT("SamplesX!C"&FC26),IF(ISNUMBER(FD26),INDIRECT("SamplesY!C"&FD26),"")) | D26: =IF(ISNUMBER(FC26),INDIRECT("SamplesX!D"&FC26),IF(ISNUMBER(FD26),INDIRECT("SamplesY!D"&FD26),"")) | E26: =IF(ISNUMBER(FC26),INDIRECT("SamplesX!E"&FC26),IF(ISNUMBER(FD26),INDIRECT("SamplesY!E"&FD26),"")) | F26: =IF(ISNUMBER(FC26),INDIRECT("SamplesX!F"&FC26),IF(ISNUMBER(FD26),INDIRECT("SamplesY!F"&FD26),"")) | G26: =IF(ISNUMBER(FC26),INDIRECT("SamplesX!G"&FC26),IF(ISNUMBER(FD26),INDIRECT("SamplesY!G"&FD26),"")) | H26: =IF(ISNUMBER(FC26),INDIRECT("SamplesX!H"&FC26),IF(ISNUMBER(FD26),INDIRECT("SamplesY!H"&FD26),"")) | I26: =IF(ISNUMBER(FC26),IF(INDEX('Q:\Abteilungsprojekte\eng\EngData\AOS\Allgemein\[LabSamples2026.xlsx]Sandec'!M:M,FC26)="","",INDEX('Q:\Abteilungsprojekte\eng\EngData\AOS\Allgemein\[LabSamples2026.xlsx]Sandec'!M:M,FC26)),"") | J26: =IF(ISNUMBER(FC26),IF(INDEX('Q:\Abteilungsprojekte\eng\EngData\AOS\Allgemein\[LabSamples2026.xlsx]Sandec'!N:N,FC26)="","",INDEX('Q:\Abteilungsprojekte\eng\EngData\AOS\Allgemein\[LabSamples2026.xlsx]Sandec'!N:N,FC26)),"") | L26: Shimadzu TOC-L | M26: None | P26: Shimadzu TOC-L | Q26: None | T26: Shimadzu TOC-L | U26: None | X26: Shimadzu TOC-L | Y26: None | AC26: None | AG26: None | AJ26: IC Anionen | AK26: None | AO26: None | AR26: IC Anionen | AS26: None | AW26: None | BA26: None | BD26: IC Anionen | BE26: None | BH26: IC Kationen | BI26: None | BM26: None | BP26: IC Kationen | BQ26: None | BT26: IC Kationen | BU26: None | BX26: IC Kationen | BY26: None | CC26: None | CG26: None | CK26: None | CO26: None | CR26: SOP 45-34 | CS26: None | CW26: None | DA26: None | DE26: None | DH26: SOP 45-09 | DI26: None | DL26: SOP 45-09 | DM26: None | DP26: IC Organic Acids | DQ26: None | DT26: IC Organic Acids | DU26: None | DX26: IC Organic Acids | DY26: None | EB26: IC Organic Acids | EC26: None | EF26: IC Organic Acids | EG26: None | EJ26: IC Organic Acids | EK26: None | EN26: IC Organic Acids | EO26: None | ER26: IC Organic Acids | ES26: None | EV26: LC-MS | EW26: None | EZ26: =TEXT(A26,"@") & TEXT(B26,"@") | FA26: =TEXT(SamplesX!A26,"@") & TEXT(SamplesX!B26,"@") | FC26: =MATCH(EZ26,FA1:FA1008,0)
C27: =IF(ISNUMBER(FC27),INDIRECT("SamplesX!C"&FC27),IF(ISNUMBER(FD27),INDIRECT("SamplesY!C"&FD27),"")) | D27: =IF(ISNUMBER(FC27),INDIRECT("SamplesX!D"&FC27),IF(ISNUMBER(FD27),INDIRECT("SamplesY!D"&FD27),"")) | E27: =IF(ISNUMBER(FC27),INDIRECT("SamplesX!E"&FC27),IF(ISNUMBER(FD27),INDIRECT("SamplesY!E"&FD27),"")) | F27: =IF(ISNUMBER(FC27),INDIRECT("SamplesX!F"&FC27),IF(ISNUMBER(FD27),INDIRECT("SamplesY!F"&FD27),"")) | G27: =IF(ISNUMBER(FC27),INDIRECT("SamplesX!G"&FC27),IF(ISNUMBER(FD27),INDIRECT("SamplesY!G"&FD27),"")) | H27: =IF(ISNUMBER(FC27),INDIRECT("SamplesX!H"&FC27),IF(ISNUMBER(FD27),INDIRECT("SamplesY!H"&FD27),"")) | I27: =IF(ISNUMBER(FC27),IF(INDEX('Q:\Abteilungsprojekte\eng\EngData\AOS\Allgemein\[LabSamples2026.xlsx]Sandec'!M:M,FC27)="","",INDEX('Q:\Abteilungsprojekte\eng\EngData\AOS\Allgemein\[LabSamples2026.xlsx]Sandec'!M:M,FC27)),"") | J27: =IF(ISNUMBER(FC27),IF(INDEX('Q:\Abteilungsprojekte\eng\EngData\AOS\Allgemein\[LabSamples2026.xlsx]Sandec'!N:N,FC27)="","",INDEX('Q:\Abteilungsprojekte\eng\EngData\AOS\Allgemein\[LabSamples2026.xlsx]Sandec'!N:N,FC27)),"") | L27: Shimadzu TOC-L | M27: None | P27: Shimadzu TOC-L | Q27: None | T27: Shimadzu TOC-L | U27: None | X27: Shimadzu TOC-L | Y27: None | AC27: None | AG27: None | AJ27: IC Anionen | AK27: None | AO27: None | AR27: IC Anionen | AS27: None | AW27: None | BA27: None | BD27: IC Anionen | BE27: None | BH27: IC Kationen | BI27: None | BM27: None | BP27: IC Kationen | BQ27: None | BT27: IC Kationen | BU27: None | BX27: IC Kationen | BY27: None | CC27: None | CG27: None | CK27: None | CO27: None | CR27: SOP 45-34 | CS27: None | CW27: None | DA27: None | DE27: None | DH27: SOP 45-09 | DI27: None | DL27: SOP 45-09 | DM27: None | DP27: IC Organic Acids | DQ27: None | DT27: IC Organic Acids | DU27: None | DX27: IC Organic Acids | DY27: None | EB27: IC Organic Acids | EC27: None | EF27: IC Organic Acids | EG27: None | EJ27: IC Organic Acids | EK27: None | EN27: IC Organic Acids | EO27: None | ER27: IC Organic Acids | ES27: None | EV27: LC-MS | EW27: None | EZ27: =TEXT(A27,"@") & TEXT(B27,"@") | FA27: =TEXT(SamplesX!A27,"@") & TEXT(SamplesX!B27,"@") | FC27: =MATCH(EZ27,FA1:FA1008,0)
C28: =IF(ISNUMBER(FC28),INDIRECT("SamplesX!C"&FC28),IF(ISNUMBER(FD28),INDIRECT("SamplesY!C"&FD28),"")) | D28: =IF(ISNUMBER(FC28),INDIRECT("SamplesX!D"&FC28),IF(ISNUMBER(FD28),INDIRECT("SamplesY!D"&FD28),"")) | E28: =IF(ISNUMBER(FC28),INDIRECT("SamplesX!E"&FC28),IF(ISNUMBER(FD28),INDIRECT("SamplesY!E"&FD28),"")) | F28: =IF(ISNUMBER(FC28),INDIRECT("SamplesX!F"&FC28),IF(ISNUMBER(FD28),INDIRECT("SamplesY!F"&FD28),"")) | G28: =IF(ISNUMBER(FC28),INDIRECT("SamplesX!G"&FC28),IF(ISNUMBER(FD28),INDIRECT("SamplesY!G"&FD28),"")) | H28: =IF(ISNUMBER(FC28),INDIRECT("SamplesX!H"&FC28),IF(ISNUMBER(FD28),INDIRECT("SamplesY!H"&FD28),"")) | I28: =IF(ISNUMBER(FC28),IF(INDEX('Q:\Abteilungsprojekte\eng\EngData\AOS\Allgemein\[LabSamples2026.xlsx]Sandec'!M:M,FC28)="","",INDEX('Q:\Abteilungsprojekte\eng\EngData\AOS\Allgemein\[LabSamples2026.xlsx]Sandec'!M:M,FC28)),"") | J28: =IF(ISNUMBER(FC28),IF(INDEX('Q:\Abteilungsprojekte\eng\EngData\AOS\Allgemein\[LabSamples2026.xlsx]Sandec'!N:N,FC28)="","",INDEX('Q:\Abteilungsprojekte\eng\EngData\AOS\Allgemein\[LabSamples2026.xlsx]Sandec'!N:N,FC28)),"") | L28: Shimadzu TOC-L | M28: None | P28: Shimadzu TOC-L | Q28: None | T28: Shimadzu TOC-L | U28: None | X28: Shimadzu TOC-L | Y28: None | AC28: None | AG28: None | AJ28: IC Anionen | AK28: None | AO28: None | AR28: IC Anionen | AS28: None | AW28: None | BA28: None | BD28: IC Anionen | BE28: None | BH28: IC Kationen | BI28: None | BM28: None | BP28: IC Kationen | BQ28: None | BT28: IC Kationen | BU28: None | BX28: IC Kationen | BY28: None | CC28: None | CG28: None | CK28: None | CO28: None | CR28: SOP 45-34 | CS28: None | CW28: None | DA28: None | DE28: None | DH28: SOP 45-09 | DI28: None | DL28: SOP 45-09 | DM28: None | DP28: IC Organic Acids | DQ28: None | DT28: IC Organic Acids | DU28: None | DX28: IC Organic Acids | DY28: None | EB28: IC Organic Acids | EC28: None | EF28: IC Organic Acids | EG28: None | EJ28: IC Organic Acids | EK28: None | EN28: IC Organic Acids | EO28: None | ER28: IC Organic Acids | ES28: None | EV28: LC-MS | EW28: None | EZ28: =TEXT(A28,"@") & TEXT(B28,"@") | FA28: =TEXT(SamplesX!A28,"@") & TEXT(SamplesX!B28,"@") | FC28: =MATCH(EZ28,FA1:FA1008,0)
C29: =IF(ISNUMBER(FC29),INDIRECT("SamplesX!C"&FC29),IF(ISNUMBER(FD29),INDIRECT("SamplesY!C"&FD29),"")) | D29: =IF(ISNUMBER(FC29),INDIRECT("SamplesX!D"&FC29),IF(ISNUMBER(FD29),INDIRECT("SamplesY!D"&FD29),"")) | E29: =IF(ISNUMBER(FC29),INDIRECT("SamplesX!E"&FC29),IF(ISNUMBER(FD29),INDIRECT("SamplesY!E"&FD29),"")) | F29: =IF(ISNUMBER(FC29),INDIRECT("SamplesX!F"&FC29),IF(ISNUMBER(FD29),INDIRECT("SamplesY!F"&FD29),"")) | G29: =IF(ISNUMBER(FC29),INDIRECT("SamplesX!G"&FC29),IF(ISNUMBER(FD29),INDIRECT("SamplesY!G"&FD29),"")) | H29: =IF(ISNUMBER(FC29),INDIRECT("SamplesX!H"&FC29),IF(ISNUMBER(FD29),INDIRECT("SamplesY!H"&FD29),"")) | I29: =IF(ISNUMBER(FC29),IF(INDEX('Q:\Abteilungsprojekte\eng\EngData\AOS\Allgemein\[LabSamples2026.xlsx]Sandec'!M:M,FC29)="","",INDEX('Q:\Abteilungsprojekte\eng\EngData\AOS\Allgemein\[LabSamples2026.xlsx]Sandec'!M:M,FC29)),"") | J29: =IF(ISNUMBER(FC29),IF(INDEX('Q:\Abteilungsprojekte\eng\EngData\AOS\Allgemein\[LabSamples2026.xlsx]Sandec'!N:N,FC29)="","",INDEX('Q:\Abteilungsprojekte\eng\EngData\AOS\Allgemein\[LabSamples2026.xlsx]Sandec'!N:N,FC29)),"") | L29: Shimadzu TOC-L | M29: None | P29: Shimadzu TOC-L | Q29: None | T29: Shimadzu TOC-L | U29: None | X29: Shimadzu TOC-L | Y29: None | AC29: None | AG29: None | AJ29: IC Anionen | AK29: None | AO29: None | AR29: IC Anionen | AS29: None | AW29: None | BA29: None | BD29: IC Anionen | BE29: None | BH29: IC Kationen | BI29: None | BM29: None | BP29: IC Kationen | BQ29: None | BT29: IC Kationen | BU29: None | BX29: IC Kationen | BY29: None | CC29: None | CG29: None | CK29: None | CO29: None | CR29: SOP 45-34 | CS29: None | CW29: None | DA29: None | DE29: None | DH29: SOP 45-09 | DI29: None | DL29: SOP 45-09 | DM29: None | DP29: IC Organic Acids | DQ29: None | DT29: IC Organic Acids | DU29: None | DX29: IC Organic Acids | DY29: None | EB29: IC Organic Acids | EC29: None | EF29: IC Organic Acids | EG29: None | EJ29: IC Organic Acids | EK29: None | EN29: IC Organic Acids | EO29: None | ER29: IC Organic Acids | ES29: None | EV29: LC-MS | EW29: None | EZ29: =TEXT(A29,"@") & TEXT(B29,"@") | FA29: =TEXT(SamplesX!A29,"@") & TEXT(SamplesX!B29,"@") | FC29: =MATCH(EZ29,FA1:FA1008,0)
C30: =IF(ISNUMBER(FC30),INDIRECT("SamplesX!C"&FC30),IF(ISNUMBER(FD30),INDIRECT("SamplesY!C"&FD30),"")) | D30: =IF(ISNUMBER(FC30),INDIRECT("SamplesX!D"&FC30),IF(ISNUMBER(FD30),INDIRECT("SamplesY!D"&FD30),"")) | E30: =IF(ISNUMBER(FC30),INDIRECT("SamplesX!E"&FC30),IF(ISNUMBER(FD30),INDIRECT("SamplesY!E"&FD30),"")) | F30: =IF(ISNUMBER(FC30),INDIRECT("SamplesX!F"&FC30),IF(ISNUMBER(FD30),INDIRECT("SamplesY!F"&FD30),"")) | G30: =IF(ISNUMBER(FC30),INDIRECT("SamplesX!G"&FC30),IF(ISNUMBER(FD30),INDIRECT("SamplesY!G"&FD30),"")) | H30: =IF(ISNUMBER(FC30),INDIRECT("SamplesX!H"&FC30),IF(ISNUMBER(FD30),INDIRECT("SamplesY!H"&FD30),"")) | I30: =IF(ISNUMBER(FC30),IF(INDEX('Q:\Abteilungsprojekte\eng\EngData\AOS\Allgemein\[LabSamples2026.xlsx]Sandec'!M:M,FC30)="","",INDEX('Q:\Abteilungsprojekte\eng\EngData\AOS\Allgemein\[LabSamples2026.xlsx]Sandec'!M:M,FC30)),"") | J30: =IF(ISNUMBER(FC30),IF(INDEX('Q:\Abteilungsprojekte\eng\EngData\AOS\Allgemein\[LabSamples2026.xlsx]Sandec'!N:N,FC30)="","",INDEX('Q:\Abteilungsprojekte\eng\EngData\AOS\Allgemein\[LabSamples2026.xlsx]Sandec'!N:N,FC30)),"") | L30: Shimadzu TOC-L | M30: None | P30: Shimadzu TOC-L | Q30: None | T30: Shimadzu TOC-L | U30: None | X30: Shimadzu TOC-L | Y30: None | AC30: None | AG30: None | AJ30: IC Anionen | AK30: None | AO30: None | AR30: IC Anionen | AS30: None | AW30: None | BA30: None | BD30: IC Anionen | BE30: None | BH30: IC Kationen | BI30: None | BM30: None | BP30: IC Kationen | BQ30: None | BT30: IC Kationen | BU30: None | BX30: IC Kationen | BY30: None | CC30: None | CG30: None | CK30: None | CO30: None | CR30: SOP 45-34 | CS30: None | CW30: None | DA30: None | DE30: None | DH30: SOP 45-09 | DI30: None | DL30: SOP 45-09 | DM30: None | DP30: IC Organic Acids | DQ30: None | DT30: IC Organic Acids | DU30: None | DX30: IC Organic Acids | DY30: None | EB30: IC Organic Acids | EC30: None | EF30: IC Organic Acids | EG30: None | EJ30: IC Organic Acids | EK30: None | EN30: IC Organic Acids | EO30: None | ER30: IC Organic Acids | ES30: None | EV30: LC-MS | EW30: None | EZ30: =TEXT(A30,"@") & TEXT(B30,"@") | FA30: =TEXT(SamplesX!A30,"@") & TEXT(SamplesX!B30,"@") | FC30: =MATCH(EZ30,FA1:FA1008,0)
C31: =IF(ISNUMBER(FC31),INDIRECT("SamplesX!C"&FC31),IF(ISNUMBER(FD31),INDIRECT("SamplesY!C"&FD31),"")) | D31: =IF(ISNUMBER(FC31),INDIRECT("SamplesX!D"&FC31),IF(ISNUMBER(FD31),INDIRECT("SamplesY!D"&FD31),"")) | E31: =IF(ISNUMBER(FC31),INDIRECT("SamplesX!E"&FC31),IF(ISNUMBER(FD31),INDIRECT("SamplesY!E"&FD31),"")) | F31: =IF(ISNUMBER(FC31),INDIRECT("SamplesX!F"&FC31),IF(ISNUMBER(FD31),INDIRECT("SamplesY!F"&FD31),"")) | G31: =IF(ISNUMBER(FC31),INDIRECT("SamplesX!G"&FC31),IF(ISNUMBER(FD31),INDIRECT("SamplesY!G"&FD31),"")) | H31: =IF(ISNUMBER(FC31),INDIRECT("SamplesX!H"&FC31),IF(ISNUMBER(FD31),INDIRECT("SamplesY!H"&FD31),"")) | I31: =IF(ISNUMBER(FC31),IF(INDEX('Q:\Abteilungsprojekte\eng\EngData\AOS\Allgemein\[LabSamples2026.xlsx]Sandec'!M:M,FC31)="","",INDEX('Q:\Abteilungsprojekte\eng\EngData\AOS\Allgemein\[LabSamples2026.xlsx]Sandec'!M:M,FC31)),"") | J31: =IF(ISNUMBER(FC31),IF(INDEX('Q:\Abteilungsprojekte\eng\EngData\AOS\Allgemein\[LabSamples2026.xlsx]Sandec'!N:N,FC31)="","",INDEX('Q:\Abteilungsprojekte\eng\EngData\AOS\Allgemein\[LabSamples2026.xlsx]Sandec'!N:N,FC31)),"") | L31: Shimadzu TOC-L | M31: None | P31: Shimadzu TOC-L | Q31: None | T31: Shimadzu TOC-L | U31: None | X31: Shimadzu TOC-L | Y31: None | AC31: None | AG31: None | AJ31: IC Anionen | AK31: None | AO31: None | AR31: IC Anionen | AS31: None | AW31: None | BA31: None | BD31: IC Anionen | BE31: None | BH31: IC Kationen | BI31: None | BM31: None | BP31: IC Kationen | BQ31: None | BT31: IC Kationen | BU31: None | BX31: IC Kationen | BY31: None | CC31: None | CG31: None | CK31: None | CO31: None | CR31: SOP 45-34 | CS31: None | CW31: None | DA31: None | DE31: None | DH31: SOP 45-09 | DI31: None | DL31: SOP 45-09 | DM31: None | DP31: IC Organic Acids | DQ31: None | DT31: IC Organic Acids | DU31: None | DX31: IC Organic Acids | DY31: None | EB31: IC Organic Acids | EC31: None | EF31: IC Organic Acids | EG31: None | EJ31: IC Organic Acids | EK31: None | EN31: IC Organic Acids | EO31: None | ER31: IC Organic Acids | ES31: None | EV31: LC-MS | EW31: None | EZ31: =TEXT(A31,"@") & TEXT(B31,"@") | FA31: =TEXT(SamplesX!A31,"@") & TEXT(SamplesX!B31,"@") | FC31: =MATCH(EZ31,FA1:FA1008,0)
C32: =IF(ISNUMBER(FC32),INDIRECT("SamplesX!C"&FC32),IF(ISNUMBER(FD32),INDIRECT("SamplesY!C"&FD32),"")) | D32: =IF(ISNUMBER(FC32),INDIRECT("SamplesX!D"&FC32),IF(ISNUMBER(FD32),INDIRECT("SamplesY!D"&FD32),"")) | E32: =IF(ISNUMBER(FC32),INDIRECT("SamplesX!E"&FC32),IF(ISNUMBER(FD32),INDIRECT("SamplesY!E"&FD32),"")) | F32: =IF(ISNUMBER(FC32),INDIRECT("SamplesX!F"&FC32),IF(ISNUMBER(FD32),INDIRECT("SamplesY!F"&FD32),"")) | G32: =IF(ISNUMBER(FC32),INDIRECT("SamplesX!G"&FC32),IF(ISNUMBER(FD32),INDIRECT("SamplesY!G"&FD32),"")) | H32: =IF(ISNUMBER(FC32),INDIRECT("SamplesX!H"&FC32),IF(ISNUMBER(FD32),INDIRECT("SamplesY!H"&FD32),"")) | I32: =IF(ISNUMBER(FC32),IF(INDEX('Q:\Abteilungsprojekte\eng\EngData\AOS\Allgemein\[LabSamples2026.xlsx]Sandec'!M:M,FC32)="","",INDEX('Q:\Abteilungsprojekte\eng\EngData\AOS\Allgemein\[LabSamples2026.xlsx]Sandec'!M:M,FC32)),"") | J32: =IF(ISNUMBER(FC32),IF(INDEX('Q:\Abteilungsprojekte\eng\EngData\AOS\Allgemein\[LabSamples2026.xlsx]Sandec'!N:N,FC32)="","",INDEX('Q:\Abteilungsprojekte\eng\EngData\AOS\Allgemein\[LabSamples2026.xlsx]Sandec'!N:N,FC32)),"") | L32: Shimadzu TOC-L | M32: None | P32: Shimadzu TOC-L | Q32: None | T32: Shimadzu TOC-L | U32: None | X32: Shimadzu TOC-L | Y32: None | AC32: None | AG32: None | AJ32: IC Anionen | AK32: None | AO32: None | AR32: IC Anionen | AS32: None | AW32: None | BA32: None | BD32: IC Anionen | BE32: None | BH32: IC Kationen | BI32: None | BM32: None | BP32: IC Kationen | BQ32: None | BT32: IC Kationen | BU32: None | BX32: IC Kationen | BY32: None | CC32: None | CG32: None | CK32: None | CO32: None | CR32: SOP 45-34 | CS32: None | CW32: None | DA32: None | DE32: None | DH32: SOP 45-09 | DI32: None | DL32: SOP 45-09 | DM32: None | DP32: IC Organic Acids | DQ32: None | DT32: IC Organic Acids | DU32: None | DX32: IC Organic Acids | DY32: None | EB32: IC Organic Acids | EC32: None | EF32: IC Organic Acids | EG32: None | EJ32: IC Organic Acids | EK32: None | EN32: IC Organic Acids | EO32: None | ER32: IC Organic Acids | ES32: None | EV32: LC-MS | EW32: None | EZ32: =TEXT(A32,"@") & TEXT(B32,"@") | FA32: =TEXT(SamplesX!A32,"@") & TEXT(SamplesX!B32,"@") | FC32: =MATCH(EZ32,FA1:FA1008,0)
