Workbook

Sheet person
A1: =IF(ISBLANK('Q:\Abteilungsprojekte\eng\EngData\AOS\Allgemein\[LabSamples2026.xlsx]person'!A1)," ",'Q:\Abteilungsprojekte\eng\EngData\AOS\Allgemein\[LabSamples2026.xlsx]person'!A1) | B1: =IF(ISBLANK('Q:\Abteilungsprojekte\eng\EngData\AOS\Allgemein\[LabSamples2026.xlsx]person'!B1)," ",'Q:\Abteilungsprojekte\eng\EngData\AOS\Allgemein\[LabSamples2026.xlsx]person'!B1) | C1: =IF(ISBLANK('Q:\Abteilungsprojekte\eng\EngData\AOS\Allgemein\[LabSamples2026.xlsx]person'!C1)," ",'Q:\Abteilungsprojekte\eng\EngData\AOS\Allgemein\[LabSamples2026.xlsx]person'!C1) | D1: =IF(ISBLANK('Q:\Abteilungsprojekte\eng\EngData\AOS\Allgemein\[LabSamples2026.xlsx]person'!D1)," ",'Q:\Abteilungsprojekte\eng\EngData\AOS\Allgemein\[LabSamples2026.xlsx]person'!D1)
A2: =IF(ISBLANK('Q:\Abteilungsprojekte\eng\EngData\AOS\Allgemein\[LabSamples2026.xlsx]person'!A2)," ",'Q:\Abteilungsprojekte\eng\EngData\AOS\Allgemein\[LabSamples2026.xlsx]person'!A2) | B2: =IF(ISBLANK('Q:\Abteilungsprojekte\eng\EngData\AOS\Allgemein\[LabSamples2026.xlsx]person'!B2)," ",'Q:\Abteilungsprojekte\eng\EngData\AOS\Allgemein\[LabSamples2026.xlsx]person'!B2) | C2: =IF(ISBLANK('Q:\Abteilungsprojekte\eng\EngData\AOS\Allgemein\[LabSamples2026.xlsx]person'!C2)," ",'Q:\Abteilungsprojekte\eng\EngData\AOS\Allgemein\[LabSamples2026.xlsx]person'!C2) | D2: =IF(ISBLANK('Q:\Abteilungsprojekte\eng\EngData\AOS\Allgemein\[LabSamples2026.xlsx]person'!D2)," ",'Q:\Abteilungsprojekte\eng\EngData\AOS\Allgemein\[LabSamples2026.xlsx]person'!D2)
A3: =IF(ISBLANK('Q:\Abteilungsprojekte\eng\EngData\AOS\Allgemein\[LabSamples2026.xlsx]person'!A3)," ",'Q:\Abteilungsprojekte\eng\EngData\AOS\Allgemein\[LabSamples2026.xlsx]person'!A3) | B3: =IF(ISBLANK('Q:\Abteilungsprojekte\eng\EngData\AOS\Allgemein\[LabSamples2026.xlsx]person'!B3)," ",'Q:\Abteilungsprojekte\eng\EngData\AOS\Allgemein\[LabSamples2026.xlsx]person'!B3) | C3: =IF(ISBLANK('Q:\Abteilungsprojekte\eng\EngData\AOS\Allgemein\[LabSamples2026.xlsx]person'!C3)," ",'Q:\Abteilungsprojekte\eng\EngData\AOS\Allgemein\[LabSamples2026.xlsx]person'!C3) | D3: =IF(ISBLANK('Q:\Abteilungsprojekte\eng\EngData\AOS\Allgemein\[LabSamples2026.xlsx]person'!D3)," ",'Q:\Abteilungsprojekte\eng\EngData\AOS\Allgemein\[LabSamples2026.xlsx]person'!D3)
A4: =IF(ISBLANK('Q:\Abteilungsprojekte\eng\EngData\AOS\Allgemein\[LabSamples2026.xlsx]person'!A4)," ",'Q:\Abteilungsprojekte\eng\EngData\AOS\Allgemein\[LabSamples2026.xlsx]person'!A4) | B4: =IF(ISBLANK('Q:\Abteilungsprojekte\eng\EngData\AOS\Allgemein\[LabSamples2026.xlsx]person'!B4)," ",'Q:\Abteilungsprojekte\eng\EngData\AOS\Allgemein\[LabSamples2026.xlsx]person'!B4) | C4: =IF(ISBLANK('Q:\Abteilungsprojekte\eng\EngData\AOS\Allgemein\[LabSamples2026.xlsx]person'!C4)," ",'Q:\Abteilungsprojekte\eng\EngData\AOS\Allgemein\[LabSamples2026.xlsx]person'!C4) | D4: =IF(ISBLANK('Q:\Abteilungsprojekte\eng\EngData\AOS\Allgemein\[LabSamples2026.xlsx]person'!D4)," ",'Q:\Abteilungsprojekte\eng\EngData\AOS\Allgemein\[LabSamples2026.xlsx]person'!D4)
A5: =IF(ISBLANK('Q:\Abteilungsprojekte\eng\EngData\AOS\Allgemein\[LabSamples2026.xlsx]person'!A5)," ",'Q:\Abteilungsprojekte\eng\EngData\AOS\Allgemein\[LabSamples2026.xlsx]person'!A5) | B5: =IF(ISBLANK('Q:\Abteilungsprojekte\eng\EngData\AOS\Allgemein\[LabSamples2026.xlsx]person'!B5)," ",'Q:\Abteilungsprojekte\eng\EngData\AOS\Allgemein\[LabSamples2026.xlsx]person'!B5) | C5: =IF(ISBLANK('Q:\Abteilungsprojekte\eng\EngData\AOS\Allgemein\[LabSamples2026.xlsx]person'!C5)," ",'Q:\Abteilungsprojekte\eng\EngData\AOS\Allgemein\[LabSamples2026.xlsx]person'!C5) | D5: =IF(ISBLANK('Q:\Abteilungsprojekte\eng\EngData\AOS\Allgemein\[LabSamples2026.xlsx]person'!D5)," ",'Q:\Abteilungsprojekte\eng\EngData\AOS\Allgemein\[LabSamples2026.xlsx]person'!D5)
A6: =IF(ISBLANK('Q:\Abteilungsprojekte\eng\EngData\AOS\Allgemein\[LabSamples2026.xlsx]person'!A6)," ",'Q:\Abteilungsprojekte\eng\EngData\AOS\Allgemein\[LabSamples2026.xlsx]person'!A6) | B6: =IF(ISBLANK('Q:\Abteilungsprojekte\eng\EngData\AOS\Allgemein\[LabSamples2026.xlsx]person'!B6)," ",'Q:\Abteilungsprojekte\eng\EngData\AOS\Allgemein\[LabSamples2026.xlsx]person'!B6) | C6: =IF(ISBLANK('Q:\Abteilungsprojekte\eng\EngData\AOS\Allgemein\[LabSamples2026.xlsx]person'!C6)," ",'Q:\Abteilungsprojekte\eng\EngData\AOS\Allgemein\[LabSamples2026.xlsx]person'!C6) | D6: =IF(ISBLANK('Q:\Abteilungsprojekte\eng\EngData\AOS\Allgemein\[LabSamples2026.xlsx]person'!D6)," ",'Q:\Abteilungsprojekte\eng\EngData\AOS\Allgemein\[LabSamples2026.xlsx]person'!D6)
A7: =IF(ISBLANK('Q:\Abteilungsprojekte\eng\EngData\AOS\Allgemein\[LabSamples2026.xlsx]person'!A7)," ",'Q:\Abteilungsprojekte\eng\EngData\AOS\Allgemein\[LabSamples2026.xlsx]person'!A7) | B7: =IF(ISBLANK('Q:\Abteilungsprojekte\eng\EngData\AOS\Allgemein\[LabSamples2026.xlsx]person'!B7)," ",'Q:\Abteilungsprojekte\eng\EngData\AOS\Allgemein\[LabSamples2026.xlsx]person'!B7) | C7: =IF(ISBLANK('Q:\Abteilungsprojekte\eng\EngData\AOS\Allgemein\[LabSamples2026.xlsx]person'!C7)," ",'Q:\Abteilungsprojekte\eng\EngData\AOS\Allgemein\[LabSamples2026.xlsx]person'!C7) | D7: =IF(ISBLANK('Q:\Abteilungsprojekte\eng\EngData\AOS\Allgemein\[LabSamples2026.xlsx]person'!D7)," ",'Q:\Abteilungsprojekte\eng\EngData\AOS\Allgemein\[LabSamples2026.xlsx]person'!D7)
A8: =IF(ISBLANK('Q:\Abteilungsprojekte\eng\EngData\AOS\Allgemein\[LabSamples2026.xlsx]person'!A8)," ",'Q:\Abteilungsprojekte\eng\EngData\AOS\Allgemein\[LabSamples2026.xlsx]person'!A8) | B8: =IF(ISBLANK('Q:\Abteilungsprojekte\eng\EngData\AOS\Allgemein\[LabSamples2026.xlsx]person'!B8)," ",'Q:\Abteilungsprojekte\eng\EngData\AOS\Allgemein\[LabSamples2026.xlsx]person'!B8) | C8: =IF(ISBLANK('Q:\Abteilungsprojekte\eng\EngData\AOS\Allgemein\[LabSamples2026.xlsx]person'!C8)," ",'Q:\Abteilungsprojekte\eng\EngData\AOS\Allgemein\[LabSamples2026.xlsx]person'!C8) | D8: =IF(ISBLANK('Q:\Abteilungsprojekte\eng\EngData\AOS\Allgemein\[LabSamples2026.xlsx]person'!D8)," ",'Q:\Abteilungsprojekte\eng\EngData\AOS\Allgemein\[LabSamples2026.xlsx]person'!D8)
A9: =IF(ISBLANK('Q:\Abteilungsprojekte\eng\EngData\AOS\Allgemein\[LabSamples2026.xlsx]person'!A9)," ",'Q:\Abteilungsprojekte\eng\EngData\AOS\Allgemein\[LabSamples2026.xlsx]person'!A9) | B9: =IF(ISBLANK('Q:\Abteilungsprojekte\eng\EngData\AOS\Allgemein\[LabSamples2026.xlsx]person'!B9)," ",'Q:\Abteilungsprojekte\eng\EngData\AOS\Allgemein\[LabSamples2026.xlsx]person'!B9) | C9: =IF(ISBLANK('Q:\Abteilungsprojekte\eng\EngData\AOS\Allgemein\[LabSamples2026.xlsx]person'!C9)," ",'Q:\Abteilungsprojekte\eng\EngData\AOS\Allgemein\[LabSamples2026.xlsx]person'!C9) | D9: =IF(ISBLANK('Q:\Abteilungsprojekte\eng\EngData\AOS\Allgemein\[LabSamples2026.xlsx]person'!D9)," ",'Q:\Abteilungsprojekte\eng\EngData\AOS\Allgemein\[LabSamples2026.xlsx]person'!D9)
A10: =IF(ISBLANK('Q:\Abteilungsprojekte\eng\EngData\AOS\Allgemein\[LabSamples2026.xlsx]person'!A10)," ",'Q:\Abteilungsprojekte\eng\EngData\AOS\Allgemein\[LabSamples2026.xlsx]person'!A10) | B10: =IF(ISBLANK('Q:\Abteilungsprojekte\eng\EngData\AOS\Allgemein\[LabSamples2026.xlsx]person'!B10)," ",'Q:\Abteilungsprojekte\eng\EngData\AOS\Allgemein\[LabSamples2026.xlsx]person'!B10) | C10: =IF(ISBLANK('Q:\Abteilungsprojekte\eng\EngData\AOS\Allgemein\[LabSamples2026.xlsx]person'!C10)," ",'Q:\Abteilungsprojekte\eng\EngData\AOS\Allgemein\[LabSamples2026.xlsx]person'!C10) | D10: =IF(ISBLANK('Q:\Abteilungsprojekte\eng\EngData\AOS\Allgemein\[LabSamples2026.xlsx]person'!D10)," ",'Q:\Abteilungsprojekte\eng\EngData\AOS\Allgemein\[LabSamples2026.xlsx]person'!D10)
A11: =IF(ISBLANK('Q:\Abteilungsprojekte\eng\EngData\AOS\Allgemein\[LabSamples2026.xlsx]person'!A11)," ",'Q:\Abteilungsprojekte\eng\EngData\AOS\Allgemein\[LabSamples2026.xlsx]person'!A11) | B11: =IF(ISBLANK('Q:\Abteilungsprojekte\eng\EngData\AOS\Allgemein\[LabSamples2026.xlsx]person'!B11)," ",'Q:\Abteilungsprojekte\eng\EngData\AOS\Allgemein\[LabSamples2026.xlsx]person'!B11) | C11: =IF(ISBLANK('Q:\Abteilungsprojekte\eng\EngData\AOS\Allgemein\[LabSamples2026.xlsx]person'!C11)," ",'Q:\Abteilungsprojekte\eng\EngData\AOS\Allgemein\[LabSamples2026.xlsx]person'!C11) | D11: =IF(ISBLANK('Q:\Abteilungsprojekte\eng\EngData\AOS\Allgemein\[LabSamples2026.xlsx]person'!D11)," ",'Q:\Abteilungsprojekte\eng\EngData\AOS\Allgemein\[LabSamples2026.xlsx]person'!D11)
A12: =IF(ISBLANK('Q:\Abteilungsprojekte\eng\EngData\AOS\Allgemein\[LabSamples2026.xlsx]person'!A12)," ",'Q:\Abteilungsprojekte\eng\EngData\AOS\Allgemein\[LabSamples2026.xlsx]person'!A12) | B12: =IF(ISBLANK('Q:\Abteilungsprojekte\eng\EngData\AOS\Allgemein\[LabSamples2026.xlsx]person'!B12)," ",'Q:\Abteilungsprojekte\eng\EngData\AOS\Allgemein\[LabSamples2026.xlsx]person'!B12) | C12: =IF(ISBLANK('Q:\Abteilungsprojekte\eng\EngData\AOS\Allgemein\[LabSamples2026.xlsx]person'!C12)," ",'Q:\Abteilungsprojekte\eng\EngData\AOS\Allgemein\[LabSamples2026.xlsx]person'!C12) | D12: =IF(ISBLANK('Q:\Abteilungsprojekte\eng\EngData\AOS\Allgemein\[LabSamples2026.xlsx]person'!D12)," ",'Q:\Abteilungsprojekte\eng\EngData\AOS\Allgemein\[LabSamples2026.xlsx]person'!D12)
... A999: =IF(ISBLANK('Q:\Abteilungsprojekte\eng\EngData\AOS\Allgemein\[LabSamples2026.xlsx]person'!A999)," ",'Q:\Abteilungsprojekte\eng\EngData\AOS\Allgemein\[LabSamples2026.xlsx]person'!A999) | B999: =IF(ISBLANK('Q:\Abteilungsprojekte\eng\EngData\AOS\Allgemein\[LabSamples2026.xlsx]person'!B999)," ",'Q:\Abteilungsprojekte\eng\EngData\AOS\Allgemein\[LabSamples2026.xlsx]person'!B999) | C999: =IF(ISBLANK('Q:\Abteilungsprojekte\eng\EngData\AOS\Allgemein\[LabSamples2026.xlsx]person'!C999)," ",'Q:\Abteilungsprojekte\eng\EngData\AOS\Allgemein\[LabSamples2026.xlsx]person'!C999) | D999: =IF(ISBLANK('Q:\Abteilungsprojekte\eng\EngData\AOS\Allgemein\[LabSamples2026.xlsx]person'!D999)," ",'Q:\Abteilungsprojekte\eng\EngData\AOS\Allgemein\[LabSamples2026.xlsx]person'!D999)

Sheet person_db
A1: =IF(ISBLANK('Q:\Abteilungsprojekte\eng\EngData\AOS\Allgemein\[LabSamples2026.xlsx]person_db'!A1)," ",'Q:\Abteilungsprojekte\eng\EngData\AOS\Allgemein\[LabSamples2026.xlsx]person_db'!A1) | B1: =IF(ISBLANK('Q:\Abteilungsprojekte\eng\EngData\AOS\Allgemein\[LabSamples2026.xlsx]person_db'!B1)," ",'Q:\Abteilungsprojekte\eng\EngData\AOS\Allgemein\[LabSamples2026.xlsx]person_db'!B1) | C1: =IF(ISBLANK('Q:\Abteilungsprojekte\eng\EngData\AOS\Allgemein\[LabSamples2026.xlsx]person_db'!C1)," ",'Q:\Abteilungsprojekte\eng\EngData\AOS\Allgemein\[LabSamples2026.xlsx]person_db'!C1) | D1: =IF(ISBLANK('Q:\Abteilungsprojekte\eng\EngData\AOS\Allgemein\[LabSamples2026.xlsx]person_db'!D1)," ",'Q:\Abteilungsprojekte\eng\EngData\AOS\Allgemein\[LabSamples2026.xlsx]person_db'!D1)
A2: =IF(ISBLANK('Q:\Abteilungsprojekte\eng\EngData\AOS\Allgemein\[LabSamples2026.xlsx]person_db'!A2)," ",'Q:\Abteilungsprojekte\eng\EngData\AOS\Allgemein\[LabSamples2026.xlsx]person_db'!A2) | B2: =IF(ISBLANK('Q:\Abteilungsprojekte\eng\EngData\AOS\Allgemein\[LabSamples2026.xlsx]person_db'!B2)," ",'Q:\Abteilungsprojekte\eng\EngData\AOS\Allgemein\[LabSamples2026.xlsx]person_db'!B2) | C2: =IF(ISBLANK('Q:\Abteilungsprojekte\eng\EngData\AOS\Allgemein\[LabSamples2026.xlsx]person_db'!C2)," ",'Q:\Abteilungsprojekte\eng\EngData\AOS\Allgemein\[LabSamples2026.xlsx]person_db'!C2) | D2: =IF(ISBLANK('Q:\Abteilungsprojekte\eng\EngData\AOS\Allgemein\[LabSamples2026.xlsx]person_db'!D2)," ",'Q:\Abteilungsprojekte\eng\EngData\AOS\Allgemein\[LabSamples2026.xlsx]person_db'!D2)
A3: =IF(ISBLANK('Q:\Abteilungsprojekte\eng\EngData\AOS\Allgemein\[LabSamples2026.xlsx]person_db'!A3)," ",'Q:\Abteilungsprojekte\eng\EngData\AOS\Allgemein\[LabSamples2026.xlsx]person_db'!A3) | B3: =IF(ISBLANK('Q:\Abteilungsprojekte\eng\EngData\AOS\Allgemein\[LabSamples2026.xlsx]person_db'!B3)," ",'Q:\Abteilungsprojekte\eng\EngData\AOS\Allgemein\[LabSamples2026.xlsx]person_db'!B3) | C3: =IF(ISBLANK('Q:\Abteilungsprojekte\eng\EngData\AOS\Allgemein\[LabSamples2026.xlsx]person_db'!C3)," ",'Q:\Abteilungsprojekte\eng\EngData\AOS\Allgemein\[LabSamples2026.xlsx]person_db'!C3) | D3: =IF(ISBLANK('Q:\Abteilungsprojekte\eng\EngData\AOS\Allgemein\[LabSamples2026.xlsx]person_db'!D3)," ",'Q:\Abteilungsprojekte\eng\EngData\AOS\Allgemein\[LabSamples2026.xlsx]person_db'!D3)
A4: =IF(ISBLANK('Q:\Abteilungsprojekte\eng\EngData\AOS\Allgemein\[LabSamples2026.xlsx]person_db'!A4)," ",'Q:\Abteilungsprojekte\eng\EngData\AOS\Allgemein\[LabSamples2026.xlsx]person_db'!A4) | B4: =IF(ISBLANK('Q:\Abteilungsprojekte\eng\EngData\AOS\Allgemein\[LabSamples2026.xlsx]person_db'!B4)," ",'Q:\Abteilungsprojekte\eng\EngData\AOS\Allgemein\[LabSamples2026.xlsx]person_db'!B4) | C4: =IF(ISBLANK('Q:\Abteilungsprojekte\eng\EngData\AOS\Allgemein\[LabSamples2026.xlsx]person_db'!C4)," ",'Q:\Abteilungsprojekte\eng\EngData\AOS\Allgemein\[LabSamples2026.xlsx]person_db'!C4) | D4: =IF(ISBLANK('Q:\Abteilungsprojekte\eng\EngData\AOS\Allgemein\[LabSamples2026.xlsx]person_db'!D4)," ",'Q:\Abteilungsprojekte\eng\EngData\AOS\Allgemein\[LabSamples2026.xlsx]person_db'!D4)
A5: =IF(ISBLANK('Q:\Abteilungsprojekte\eng\EngData\AOS\Allgemein\[LabSamples2026.xlsx]person_db'!A5)," ",'Q:\Abteilungsprojekte\eng\EngData\AOS\Allgemein\[LabSamples2026.xlsx]person_db'!A5) | B5: =IF(ISBLANK('Q:\Abteilungsprojekte\eng\EngData\AOS\Allgemein\[LabSamples2026.xlsx]person_db'!B5)," ",'Q:\Abteilungsprojekte\eng\EngData\AOS\Allgemein\[LabSamples2026.xlsx]person_db'!B5) | C5: =IF(ISBLANK('Q:\Abteilungsprojekte\eng\EngData\AOS\Allgemein\[LabSamples2026.xlsx]person_db'!C5)," ",'Q:\Abteilungsprojekte\eng\EngData\AOS\Allgemein\[LabSamples2026.xlsx]person_db'!C5) | D5: =IF(ISBLANK('Q:\Abteilungsprojekte\eng\EngData\AOS\Allgemein\[LabSamples2026.xlsx]person_db'!D5)," ",'Q:\Abteilungsprojekte\eng\EngData\AOS\Allgemein\[LabSamples2026.xlsx]person_db'!D5)
A6: =IF(ISBLANK('Q:\Abteilungsprojekte\eng\EngData\AOS\Allgemein\[LabSamples2026.xlsx]person_db'!A6)," ",'Q:\Abteilungsprojekte\eng\EngData\AOS\Allgemein\[LabSamples2026.xlsx]person_db'!A6) | B6: =IF(ISBLANK('Q:\Abteilungsprojekte\eng\EngData\AOS\Allgemein\[LabSamples2026.xlsx]person_db'!B6)," ",'Q:\Abteilungsprojekte\eng\EngData\AOS\Allgemein\[LabSamples2026.xlsx]person_db'!B6) | C6: =IF(ISBLANK('Q:\Abteilungsprojekte\eng\EngData\AOS\Allgemein\[LabSamples2026.xlsx]person_db'!C6)," ",'Q:\Abteilungsprojekte\eng\EngData\AOS\Allgemein\[LabSamples2026.xlsx]person_db'!C6) | D6: =IF(ISBLANK('Q:\Abteilungsprojekte\eng\EngData\AOS\Allgemein\[LabSamples2026.xlsx]person_db'!D6)," ",'Q:\Abteilungsprojekte\eng\EngData\AOS\Allgemein\[LabSamples2026.xlsx]person_db'!D6)
A7: =IF(ISBLANK('Q:\Abteilungsprojekte\eng\EngData\AOS\Allgemein\[LabSamples2026.xlsx]person_db'!A7)," ",'Q:\Abteilungsprojekte\eng\EngData\AOS\Allgemein\[LabSamples2026.xlsx]person_db'!A7) | B7: =IF(ISBLANK('Q:\Abteilungsprojekte\eng\EngData\AOS\Allgemein\[LabSamples2026.xlsx]person_db'!B7)," ",'Q:\Abteilungsprojekte\eng\EngData\AOS\Allgemein\[LabSamples2026.xlsx]person_db'!B7) | C7: =IF(ISBLANK('Q:\Abteilungsprojekte\eng\EngData\AOS\Allgemein\[LabSamples2026.xlsx]person_db'!C7)," ",'Q:\Abteilungsprojekte\eng\EngData\AOS\Allgemein\[LabSamples2026.xlsx]person_db'!C7) | D7: =IF(ISBLANK('Q:\Abteilungsprojekte\eng\EngData\AOS\Allgemein\[LabSamples2026.xlsx]person_db'!D7)," ",'Q:\Abteilungsprojekte\eng\EngData\AOS\Allgemein\[LabSamples2026.xlsx]person_db'!D7)
A8: =IF(ISBLANK('Q:\Abteilungsprojekte\eng\EngData\AOS\Allgemein\[LabSamples2026.xlsx]person_db'!A8)," ",'Q:\Abteilungsprojekte\eng\EngData\AOS\Allgemein\[LabSamples2026.xlsx]person_db'!A8) | B8: =IF(ISBLANK('Q:\Abteilungsprojekte\eng\EngData\AOS\Allgemein\[LabSamples2026.xlsx]person_db'!B8)," ",'Q:\Abteilungsprojekte\eng\EngData\AOS\Allgemein\[LabSamples2026.xlsx]person_db'!B8) | C8: =IF(ISBLANK('Q:\Abteilungsprojekte\eng\EngData\AOS\Allgemein\[LabSamples2026.xlsx]person_db'!C8)," ",'Q:\Abteilungsprojekte\eng\EngData\AOS\Allgemein\[LabSamples2026.xlsx]person_db'!C8) | D8: =IF(ISBLANK('Q:\Abteilungsprojekte\eng\EngData\AOS\Allgemein\[LabSamples2026.xlsx]person_db'!D8)," ",'Q:\Abteilungsprojekte\eng\EngData\AOS\Allgemein\[LabSamples2026.xlsx]person_db'!D8)
A9: =IF(ISBLANK('Q:\Abteilungsprojekte\eng\EngData\AOS\Allgemein\[LabSamples2026.xlsx]person_db'!A9)," ",'Q:\Abteilungsprojekte\eng\EngData\AOS\Allgemein\[LabSamples2026.xlsx]person_db'!A9) | B9: =IF(ISBLANK('Q:\Abteilungsprojekte\eng\EngData\AOS\Allgemein\[LabSamples2026.xlsx]person_db'!B9)," ",'Q:\Abteilungsprojekte\eng\EngData\AOS\Allgemein\[LabSamples2026.xlsx]person_db'!B9) | C9: =IF(ISBLANK('Q:\Abteilungsprojekte\eng\EngData\AOS\Allgemein\[LabSamples2026.xlsx]person_db'!C9)," ",'Q:\Abteilungsprojekte\eng\EngData\AOS\Allgemein\[LabSamples2026.xlsx]person_db'!C9) | D9: =IF(ISBLANK('Q:\Abteilungsprojekte\eng\EngData\AOS\Allgemein\[LabSamples2026.xlsx]person_db'!D9)," ",'Q:\Abteilungsprojekte\eng\EngData\AOS\Allgemein\[LabSamples2026.xlsx]person_db'!D9)
A10: =IF(ISBLANK('Q:\Abteilungsprojekte\eng\EngData\AOS\Allgemein\[LabSamples2026.xlsx]person_db'!A10)," ",'Q:\Abteilungsprojekte\eng\EngData\AOS\Allgemein\[LabSamples2026.xlsx]person_db'!A10) | B10: =IF(ISBLANK('Q:\Abteilungsprojekte\eng\EngData\AOS\Allgemein\[LabSamples2026.xlsx]person_db'!B10)," ",'Q:\Abteilungsprojekte\eng\EngData\AOS\Allgemein\[LabSamples2026.xlsx]person_db'!B10) | C10: =IF(ISBLANK('Q:\Abteilungsprojekte\eng\EngData\AOS\Allgemein\[LabSamples2026.xlsx]person_db'!C10)," ",'Q:\Abteilungsprojekte\eng\EngData\AOS\Allgemein\[LabSamples2026.xlsx]person_db'!C10) | D10: =IF(ISBLANK('Q:\Abteilungsprojekte\eng\EngData\AOS\Allgemein\[LabSamples2026.xlsx]person_db'!D10)," ",'Q:\Abteilungsprojekte\eng\EngData\AOS\Allgemein\[LabSamples2026.xlsx]person_db'!D10)
A11: =IF(ISBLANK('Q:\Abteilungsprojekte\eng\EngData\AOS\Allgemein\[LabSamples2026.xlsx]person_db'!A11)," ",'Q:\Abteilungsprojekte\eng\EngData\AOS\Allgemein\[LabSamples2026.xlsx]person_db'!A11) | B11: =IF(ISBLANK('Q:\Abteilungsprojekte\eng\EngData\AOS\Allgemein\[LabSamples2026.xlsx]person_db'!B11)," ",'Q:\Abteilungsprojekte\eng\EngData\AOS\Allgemein\[LabSamples2026.xlsx]person_db'!B11) | C11: =IF(ISBLANK('Q:\Abteilungsprojekte\eng\EngData\AOS\Allgemein\[LabSamples2026.xlsx]person_db'!C11)," ",'Q:\Abteilungsprojekte\eng\EngData\AOS\Allgemein\[LabSamples2026.xlsx]person_db'!C11) | D11: =IF(ISBLANK('Q:\Abteilungsprojekte\eng\EngData\AOS\Allgemein\[LabSamples2026.xlsx]person_db'!D11)," ",'Q:\Abteilungsprojekte\eng\EngData\AOS\Allgemein\[LabSamples2026.xlsx]person_db'!D11)
A12: =IF(ISBLANK('Q:\Abteilungsprojekte\eng\EngData\AOS\Allgemein\[LabSamples2026.xlsx]person_db'!A12)," ",'Q:\Abteilungsprojekte\eng\EngData\AOS\Allgemein\[LabSamples2026.xlsx]person_db'!A12) | B12: =IF(ISBLANK('Q:\Abteilungsprojekte\eng\EngData\AOS\Allgemein\[LabSamples2026.xlsx]person_db'!B12)," ",'Q:\Abteilungsprojekte\eng\EngData\AOS\Allgemein\[LabSamples2026.xlsx]person_db'!B12) | C12: =IF(ISBLANK('Q:\Abteilungsprojekte\eng\EngData\AOS\Allgemein\[LabSamples2026.xlsx]person_db'!C12)," ",'Q:\Abteilungsprojekte\eng\EngData\AOS\Allgemein\[LabSamples2026.xlsx]person_db'!C12) | D12: =IF(ISBLANK('Q:\Abteilungsprojekte\eng\EngData\AOS\Allgemein\[LabSamples2026.xlsx]person_db'!D12)," ",'Q:\Abteilungsprojekte\eng\EngData\AOS\Allgemein\[LabSamples2026.xlsx]person_db'!D12)
... A999: =IF(ISBLANK('Q:\Abteilungsprojekte\eng\EngData\AOS\Allgemein\[LabSamples2026.xlsx]person_db'!A999)," ",'Q:\Abteilungsprojekte\eng\EngData\AOS\Allgemein\[LabSamples2026.xlsx]person_db'!A999) | B999: =IF(ISBLANK('Q:\Abteilungsprojekte\eng\EngData\AOS\Allgemein\[LabSamples2026.xlsx]person_db'!B999)," ",'Q:\Abteilungsprojekte\eng\EngData\AOS\Allgemein\[LabSamples2026.xlsx]person_db'!B999) | C999: =IF(ISBLANK('Q:\Abteilungsprojekte\eng\EngData\AOS\Allgemein\[LabSamples2026.xlsx]person_db'!C999)," ",'Q:\Abteilungsprojekte\eng\EngData\AOS\Allgemein\[LabSamples2026.xlsx]person_db'!C999) | D999: =IF(ISBLANK('Q:\Abteilungsprojekte\eng\EngData\AOS\Allgemein\[LabSamples2026.xlsx]person_db'!D999)," ",'Q:\Abteilungsprojekte\eng\EngData\AOS\Allgemein\[LabSamples2026.xlsx]person_db'!D999)

Sheet person_drop
A1: =COUNTIF(person_db!$B$2:$B$1000,">""") | B1: 0
B2: 1 | C2: =B2<=A1 | D2: =IF(C2,INDIRECT("person_db!B"&(B2+1)),INDIRECT("person!B"&(B2-$A$1+1)))
B3: 2 | C3: =B3<=A1 | D3: =IF(C3,INDIRECT("person_db!B"&(B3+1)),INDIRECT("person!B"&(B3-$A$1+1)))
B4: 3 | C4: =B4<=A1 | D4: =IF(C4,INDIRECT("person_db!B"&(B4+1)),INDIRECT("person!B"&(B4-$A$1+1)))
B5: 4 | C5: =B5<=A1 | D5: =IF(C5,INDIRECT("person_db!B"&(B5+1)),INDIRECT("person!B"&(B5-$A$1+1)))
B6: 5 | C6: =B6<=A1 | D6: =IF(C6,INDIRECT("person_db!B"&(B6+1)),INDIRECT("person!B"&(B6-$A$1+1)))
B7: 6 | C7: =B7<=A1 | D7: =IF(C7,INDIRECT("person_db!B"&(B7+1)),INDIRECT("person!B"&(B7-$A$1+1)))
B8: 7 | C8: =B8<=A1 | D8: =IF(C8,INDIRECT("person_db!B"&(B8+1)),INDIRECT("person!B"&(B8-$A$1+1)))
B9: 8 | C9: =B9<=A1 | D9: =IF(C9,INDIRECT("person_db!B"&(B9+1)),INDIRECT("person!B"&(B9-$A$1+1)))
B10: 9 | C10: =B10<=A1 | D10: =IF(C10,INDIRECT("person_db!B"&(B10+1)),INDIRECT("person!B"&(B10-$A$1+1)))
B11: 10 | C11: =B11<=A1 | D11: =IF(C11,INDIRECT("person_db!B"&(B11+1)),INDIRECT("person!B"&(B11-$A$1+1)))
B12: 11 | C12: =B12<=A1 | D12: =IF(C12,INDIRECT("person_db!B"&(B12+1)),INDIRECT("person!B"&(B12-$A$1+1)))
B13: 12 | C13: =B13<=A1 | D13: =IF(C13,INDIRECT("person_db!B"&(B13+1)),INDIRECT("person!B"&(B13-$A$1+1)))
B14: 13 | C14: =B14<=A1 | D14: =IF(C14,INDIRECT("person_db!B"&(B14+1)),INDIRECT("person!B"&(B14-$A$1+1)))
B15: 14 | C15: =B15<=A1 | D15: =IF(C15,INDIRECT("person_db!B"&(B15+1)),INDIRECT("person!B"&(B15-$A$1+1)))
B16: 15 | C16: =B16<=A1 | D16: =IF(C16,INDIRECT("person_db!B"&(B16+1)),INDIRECT("person!B"&(B16-$A$1+1)))
B17: 16 | C17: =B17<=A1 | D17: =IF(C17,INDIRECT("person_db!B"&(B17+1)),INDIRECT("person!B"&(B17-$A$1+1)))
B18: 17 | C18: =B18<=A1 | D18: =IF(C18,INDIRECT("person_db!B"&(B18+1)),INDIRECT("person!B"&(B18-$A$1+1)))
B19: 18 | C19: =B19<=A1 | D19: =IF(C19,INDIRECT("person_db!B"&(B19+1)),INDIRECT("person!B"&(B19-$A$1+1)))
B20: 19 | C20: =B20<=A1 | D20: =IF(C20,INDIRECT("person_db!B"&(B20+1)),INDIRECT("person!B"&(B20-$A$1+1)))
B21: 20 | C21: =B21<=A1 | D21: =IF(C21,INDIRECT("person_db!B"&(B21+1)),INDIRECT("person!B"&(B21-$A$1+1)))
B22: 21 | C22: =B22<=A1 | D22: =IF(C22,INDIRECT("person_db!B"&(B22+1)),INDIRECT("person!B"&(B22-$A$1+1)))
B23: 22 | C23: =B23<=A1 | D23: =IF(C23,INDIRECT("person_db!B"&(B23+1)),INDIRECT("person!B"&(B23-$A$1+1)))
B24: 23 | C24: =B24<=A1 | D24: =IF(C24,INDIRECT("person_db!B"&(B24+1)),INDIRECT("person!B"&(B24-$A$1+1)))
B25: 24 | C25: =B25<=A1 | D25: =IF(C25,INDIRECT("person_db!B"&(B25+1)),INDIRECT("person!B"&(B25-$A$1+1)))
B26: 25 | C26: =B26<=A1 | D26: =IF(C26,INDIRECT("person_db!B"&(B26+1)),INDIRECT("person!B"&(B26-$A$1+1)))
B27: 26 | C27: =B27<=A1 | D27: =IF(C27,INDIRECT("person_db!B"&(B27+1)),INDIRECT("person!B"&(B27-$A$1+1)))
B28: 27 | C28: =B28<=A1 | D28: =IF(C28,INDIRECT("person_db!B"&(B28+1)),INDIRECT("person!B"&(B28-$A$1+1)))
B29: 28 | C29: =B29<=A1 | D29: =IF(C29,INDIRECT("person_db!B"&(B29+1)),INDIRECT("person!B"&(B29-$A$1+1)))
B30: 29 | C30: =B30<=A1 | D30: =IF(C30,INDIRECT("person_db!B"&(B30+1)),INDIRECT("person!B"&(B30-$A$1+1)))
B31: 30 | C31: =B31<=A1 | D31: =IF(C31,INDIRECT("person_db!B"&(B31+1)),INDIRECT("person!B"&(B31-$A$1+1)))
B32: 31 | C32: =B32<=A1 | D32: =IF(C32,INDIRECT("person_db!B"&(B32+1)),INDIRECT("person!B"&(B32-$A$1+1)))
B33: 32 | C33: =B33<=A1 | D33: =IF(C33,INDIRECT("person_db!B"&(B33+1)),INDIRECT("person!B"&(B33-$A$1+1)))
B34: 33 | C34: =B34<=A1 | D34: =IF(C34,INDIRECT("person_db!B"&(B34+1)),INDIRECT("person!B"&(B34-$A$1+1)))
B35: 34 | C35: =B35<=A1 | D35: =IF(C35,INDIRECT("person_db!B"&(B35+1)),INDIRECT("person!B"&(B35-$A$1+1)))
B36: 35 | C36: =B36<=A1 | D36: =IF(C36,INDIRECT("person_db!B"&(B36+1)),INDIRECT("person!B"&(B36-$A$1+1)))
B37: 36 | C37: =B37<=A1 | D37: =IF(C37,INDIRECT("person_db!B"&(B37+1)),INDIRECT("person!B"&(B37-$A$1+1)))
B38: 37 | C38: =B38<=A1 | D38: =IF(C38,INDIRECT("person_db!B"&(B38+1)),INDIRECT("person!B"&(B38-$A$1+1)))
B39: 38 | C39: =B39<=A1 | D39: =IF(C39,INDIRECT("person_db!B"&(B39+1)),INDIRECT("person!B"&(B39-$A$1+1)))
B40: 39 | C40: =B40<=A1 | D40: =IF(C40,INDIRECT("person_db!B"&(B40+1)),INDIRECT("person!B"&(B40-$A$1+1)))
...

Sheet Area
A1: ARA_BIRS | B1: ARA_CHAM | C1: ARA_Neugut | D1: BU_B-C_female_toilet | E1: BU_B-C_male_toilet | F1: FC_A80 | G1: FC_A81 | H1: FX_C4_urinelab | I1: Field_test | J1: GA_OST | K1: NE_WaterHub | L1: VH_B2 | M1: VH_B_Vorplatz | N1: VH_C1 | O1: VH_C2
A2: BT | B2: BT | C2: Line_2 | D2: Autarky | E2: Autarky | F2: UrineCollection | G2: UrineTreatment | H2: FumeHood | I2: SouthAfrica | J2: Ganterschwil_SG | K2: GW | L2: Respirometer | M2: Autarky | N2: Athene1 | O2: ARA-Eawag
C3: Line_3 | F3: UrineTreatment | H3: Center | I3: Switzerland | K3: YW | L3: WaterWall | N3: Athene3
C4: Line_4 | I4: Urin_Express | L4: GAC | N4: Caroline
C5: X | N5: Gemini
N6: SoDAN

Sheet Setup
A1: ARA_BIRS:BT | B1: ARA_CHAM:BT | C1: ARA_Neugut:Line_2 | D1: ARA_Neugut:Line_3 | E1: ARA_Neugut:Line_4 | F1: ARA_Neugut:X | G1: BU_B-C_female_toilet:Autarky | H1: BU_B-C_male_toilet:Autarky | I1: FC_A80:UrineCollection | J1: FC_A80:UrineTreatment | K1: FC_A81:UrineTreatment | L1: FX_C4_urinelab:Center | M1: FX_C4_urinelab:FumeHood | N1: Field_test:SouthAfrica | O1: Field_test:Switzerland | P1: Field_test:Urin_Express | Q1: GA_OST:Ganterschwil_SG | R1: NE_WaterHub:GW | S1: NE_WaterHub:YW | T1: VH_B2:GAC | U1: VH_B2:Respirometer | V1: VH_B2:WaterWall | W1: VH_B_Vorplatz:Autarky | X1: VH_C1:Athene1 | Y1: VH_C1:Athene3 | Z1: VH_C1:Caroline | AA1: VH_C1:Gemini | AB1: VH_C1:SoDAN | AC1: VH_C2:ARA-Eawag
A2: WW | B2: WW | C2: X | D2: X | E2: X | F2: X | G2: Jerrycan | H2: Jerrycan | I2: TankFemale | J2: Distillation | K2: Distillation | L2: Setup1 | M2: Setup1 | N2: X | O2: X | P2: Storage_Tank | Q2: WW | R2: GW | S2: UrineTank | T2: Reactor1 | U2: Respirometer | V2: Reactor1 | W2: Toilet | X2: Reactor1 | Y2: Reactor1 | Z2: Reactor1 | AA2: Reactor1 | AB2: Reactor1 | AC2: Reactor1
I3: TankMale | J3: Nitrification | L3: Setup2 | M3: Setup2 | P3: Nitrification_R1 | S3: Nitrification | T3: Reactor2 | V3: Reactor2 | W3: Urine_Module | X3: Reactor2 | Y3: Reactor2 | Z3: Reactor2 | AA3: Reactor2 | AC3: Reactor2
L4: Setup3 | M4: Setup3 | P4: Nitrification_R2 | S4: MABR | V4: Reactor3 | W4: Water_Wall | X4: Reactor3 | Y4: Reactor3 | Z4: Reactor3 | AA4: Reactor3 | AC4: Reactor3
M5: Setup4 | P5: Nitrification_R3 | S5: GAC | V5: Reactor4 | X5: Reactor4 | Y5: Reactor4 | Z5: Reactor4 | AA5: Reactor4 | AC5: Reactor4
P6: GAC | X6: Reactor5 | Y6: Reactor5 | Z6: Reactor5 | AA6: Reactor5 | AC6: Reactor5
P7: Distillation | X7: Reactor6 | Y7: Reactor6 | Z7: Reactor6 | AA7: Reactor6 | AC7: Reactor6

Sheet Comp
A1: ARA_BIRS:BT:WW | B1: ARA_CHAM:BT:WW | C1: ARA_Neugut:Line_2:X | D1: ARA_Neugut:Line_3:X | E1: ARA_Neugut:Line_4:X | F1: ARA_Neugut:X:X | G1: BU_B-C_female_toilet:Autarky:Jerrycan | H1: BU_B-C_male_toilet:Autarky:Jerrycan | I1: FC_A80:UrineCollection:TankFemale | J1: FC_A80:UrineCollection:TankMale | K1: FC_A80:UrineTreatment:Distillation | L1: FC_A80:UrineTreatment:Nitrification | M1: FC_A81:UrineTreatment:Distillation | N1: FX_C4_urinelab:Center:Setup1 | O1: FX_C4_urinelab:Center:Setup2 | P1: FX_C4_urinelab:Center:Setup3 | Q1: FX_C4_urinelab:FumeHood:Setup1 | R1: FX_C4_urinelab:FumeHood:Setup2 | S1: FX_C4_urinelab:FumeHood:Setup3 | T1: FX_C4_urinelab:FumeHood:Setup4 | U1: Field_test:SouthAfrica:X | V1: Field_test:Switzerland:X | W1: Field_test:Urin_Express:Distillation | X1: Field_test:Urin_Express:GAC | Y1: Field_test:Urin_Express:Nitrification_R1 | Z1: Field_test:Urin_Express:Nitrification_R2 | AA1: Field_test:Urin_Express:Nitrification_R3 | AB1: Field_test:Urin_Express:Storage_Tank | AC1: GA_OST:Ganterschwil_SG:WW | AD1: NE_WaterHub:GW:GW | AE1: NE_WaterHub:YW:GAC | AF1: NE_WaterHub:YW:MABR | AG1: NE_WaterHub:YW:Nitrification | AH1: NE_WaterHub:YW:UrineTank | AI1: VH_B2:GAC:Reactor1 | AJ1: VH_B2:GAC:Reactor2 | AK1: VH_B2:Respirometer:Respirometer | AL1: VH_B2:WaterWall:Reactor1 | AM1: VH_B2:WaterWall:Reactor2 | AN1: VH_B2:WaterWall:Reactor3 | AO1: VH_B2:WaterWall:Reactor4 | AP1: VH_B_Vorplatz:Autarky:Toilet | AQ1: VH_B_Vorplatz:Autarky:Urine_Module | AR1: VH_B_Vorplatz:Autarky:Water_Wall | AS1: VH_C1:Athene1:Reactor1 | AT1: VH_C1:Athene1:Reactor2 | AU1: VH_C1:Athene1:Reactor3 | AV1: VH_C1:Athene1:Reactor4 | AW1: VH_C1:Athene1:Reactor5 | AX1: VH_C1:Athene1:Reactor6 | AY1: VH_C1:Athene3:Reactor1 | AZ1: VH_C1:Athene3:Reactor2 | BA1: VH_C1:Athene3:Reactor3 | BB1: VH_C1:Athene3:Reactor4 | BC1: VH_C1:Athene3:Reactor5 | BD1: VH_C1:Athene3:Reactor6 | BE1: VH_C1:Caroline:Reactor1 | BF1: VH_C1:Caroline:Reactor2 | BG1: VH_C1:Caroline:Reactor3 | BH1: VH_C1:Caroline:Reactor4 | BI1: VH_C1:Caroline:Reactor5 | BJ1: VH_C1:Caroline:Reactor6 | BK1: VH_C1:Gemini:Reactor1 | BL1: VH_C1:Gemini:Reactor2 | BM1: VH_C1:Gemini:Reactor3 | BN1: VH_C1:Gemini:Reactor4 | BO1: VH_C1:Gemini:Reactor5 | BP1: VH_C1:Gemini:Reactor6 | BQ1: VH_C1:SoDAN:Reactor1 | BR1: VH_C2:ARA-Eawag:Reactor1 | BS1: VH_C2:ARA-Eawag:Reactor2 | BT1: VH_C2:ARA-Eawag:Reactor3 | BU1: VH_C2:ARA-Eawag:Reactor4 | BV1: VH_C2:ARA-Eawag:Reactor5 | BW1: VH_C2:ARA-Eawag:Reactor6
A2: SBR_1 | B2: Aerob_1 | C2: X | D2: X | E2: X | F2: X | G2: Fresh_urine_undiluted | H2: Fresh_urine_undiluted | I2: Tank | J2: Tank | K2: DistillateTank | L2: Reactor1 | M2: ConcentrateTank | N2: Influent | O2: Influent | P2: Influent | Q2: Influent | R2: Influent | S2: Influent | T2: Influent | U2: X | V2: X | W2: Reactor | X2: Reactor | Y2: Reactor | Z2: Reactor | AA2: Reactor | AB2: Reactor | AC2: Effluent | AD2: Batch-Test | AE2: Reactor | AF2: Reactor | AG2: Reactor | AH2: Tank | AI2: Influent | AJ2: Influent | AK2: AerationChamber | AL2: WW | AM2: WW | AN2: WW | AO2: WW | AP2: Fresh_urine_diluted | AQ2: Evaporation_reactor | AR2: Clean_water_tank | AS2: Effluent | AT2: Effluent | AU2: Effluent | AV2: Effluent | AW2: Effluent | AX2: Effluent | AY2: Effluent | AZ2: Effluent | BA2: Effluent | BB2: Effluent | BC2: Effluent | BD2: Effluent | BE2: Effluent | BF2: Effluent | BG2: Effluent | BH2: Effluent | BI2: Effluent | BJ2: Effluent | BK2: Effluent | BL2: Effluent | BM2: Effluent | BN2: Effluent | BO2: Effluent | BP2: Effluent | BQ2: Effluent | BR2: Effluent | BS2: Effluent | BT2: Effluent | BU2: Effluent | BV2: Effluent | BW2: Effluent
A3: SBR_2 | B3: Aerob_2 | K3: FeedTank1 | L3: Reactor2 | M3: FeedTank2 | N3: Reactor | O3: Reactor | P3: Reactor | Q3: Reactor | R3: Reactor | S3: Reactor | T3: Reactor | W3: Influent | X3: Influent | Y3: Influent | Z3: Influent | AA3: Influent | AB3: Influent | AC3: Influent | AD3: GAC1-G1 | AE3: Effluent | AF3: Effluent | AG3: Effluent | AI3: Port1 | AJ3: Port1 | AK3: RespirationChamber | AL3: Permeate | AM3: Permeate | AN3: Permeate | AO3: Permeate | AQ3: Fresh_urine_diluted | AR3: Permeate | AS3: Influent | AT3: Influent | AU3: Influent | AV3: Influent | AW3: Influent | AX3: Influent | AY3: Influent | AZ3: Influent | BA3: Influent | BB3: Influent | BC3: Influent | BD3: Influent | BE3: Influent | BF3: Influent | BG3: Influent | BH3: Influent | BI3: Influent | BJ3: Influent | BK3: Influent | BL3: Influent | BM3: Influent | BN3: Influent | BO3: Influent | BP3: Influent | BQ3: Influent | BR3: Influent | BS3: Influent | BT3: Influent | BU3: Influent | BV3: Influent | BW3: Influent
A4: SBR_3 | B4: Aerob_3 | N4: Port1 | O4: Port1 | P4: Port1 | Q4: Effluent | R4: Effluent | S4: Effluent | T4: Effluent | W4: Effluent | X4: Effluent | Y4: Effluent | Z4: Effluent | AA4: Effluent | AB4: Effluent | AC4: Reactor | AD4: GAC1-G2 | AI4: Port2 | AJ4: Port2 | AL4: CWT | AM4: CWT | AN4: CWT | AO4: CWT | AQ4: Stabilization_effluent | AR4: Wastewater_tank | AS4: Reactor | AT4: Reactor | AU4: Reactor | AV4: Reactor | AW4: Reactor | AX4: Reactor | AY4: Reactor | AZ4: Reactor | BA4: Reactor | BB4: Reactor | BC4: Reactor | BD4: Reactor | BE4: Reactor | BF4: Reactor | BG4: Reactor | BH4: Reactor | BI4: Reactor | BJ4: Reactor | BK4: Reactor | BL4: Reactor | BM4: Reactor | BN4: Reactor | BO4: Reactor | BP4: Reactor | BQ4: Reactor | BR4: Reactor | BS4: Reactor | BT4: Reactor | BU4: Reactor | BV4: Reactor | BW4: Reactor
A5: SBR_4 | B5: Aerob_4 | N5: Port2 | O5: Port2 | P5: Port2 | AD5: GAC1-G3 | AI5: Port3 | AJ5: Port3 | AQ5: Stabilization_influent
A6: SBR_5 | B6: Aerob_5 | N6: Port3 | O6: Port3 | P6: Port3 | AD6: GAC1-W0 | AI6: Port4 | AJ6: Port4
B7: Anaerob_1 | N7: Port4 | O7: Port4 | P7: Port4 | AD7: GAC1-W1 | AI7: Effluent | AJ7: Effluent
B8: Anaerob_2 | N8: Effluent | O8: Effluent | P8: Effluent | AD8: GAC1-W2
B9: Anaerob_3 | AD9: GAC1-W3
B10: Anaerob_4 | AD10: GAC1-W4
B11: Anox_1 | AD11: GAC2-BufferTank
B12: Anox_2 | AD12: GAC2-ColumnA
B13: Anox_3 | AD13: GAC2-ColumnB
B14: Anox_4 | AD14: GAC2-ColumnC
AD15: GAC2-ColumnD
AD16: M1
AD17: M2
AD18: M3
AD19: MBR-Tank1
AD20: MBR-Tank2
AD21: MBR-Tank3

Sheet extra_ARA_Hoefe
A1: ARA_Hoefe | B1: 2026
A2: Responsible: | B2: =HYPERLINK("mailto:Marc.Boehler@eawag.ch?subject=[Lab samples]", "Marc.Boehler@eawag.ch")
A3: Results: | B3: =HYPERLINK("Q:\Abteilungsprojekte\eng\EngData\ProcEng\Böhler\LabResults2026_ARA_Hoefe.xlsx#ARA_Hoefe!A1","LabResults2026_ARA_Hoefe.xlsx")
B4: =HYPERLINK("Q:\Abteilungsprojekte\eng\EngData\ProcEng\Böhler\LabResults2026_ARA_Hoefe_extra.xlsx#extra_ARA_Hoefe!A1","LabResults2026_ARA_Hoefe_extra.xlsx")
A5: Sample ID | C5: Site | G5: Sample | M5: Comment | N5: Communication Lab | O5: Analysis | Q5: Expected value of measured variable | BA5: Number of options | BB5: ConcatID
A6: Project ID | B6: Number | C6: Room | D6: Area | E6: Setup | F6: Component | G6: Date | H6: Time | I6: Sampling method | J6: Filter at sampling | K6: Dilution at sampling | L6: Who (S) | O6: Date | P6: Who (A) | Q6: DOC | R6: TOC | S6: DIC | T6: TIC | U6: Nsol | V6: Ntot | W6: Cl | X6: NO2-N | Y6: Br | Z6: NO3-N | AA6: PO4-P | AB6: SO4 | AC6: Na | AD6: NH4-N | AE6: K | AF6: Ca | AG6: Mg | AH6: Ptot | AI6: Urea | AJ6: CODsol | AK6: CODtot | AL6: Alkalinity | AM6: Conductivity | AN6: pH | AO6: Turbidity | AP6: TSS | AQ6: VSS | AR6: Lactic Acid | AS6: Formic Acid | AT6: Acetic Acid | AU6: Propionic Acid | AV6: Isobutyric Acid | AW6: Butyric Acid | AX6: Isovaleric Acid | AY6: Valeric Acid | AZ6: Micropollutants | BA6: Area | BB6: Setup | BC6: Component
A7: [##] | B7: [yysss] | G7: [dd.mm.yyyy] | H7: [HH:MM:SS] | K7: [total vol/sample vol] | O7: [dd.mm.yyyy] | Q7: mg/L | R7: mg/L | S7: mg/L | T7: mg/L | U7: mg/L | V7: mg/L | W7: mg/L | X7: mg/L | Y7: mg/L | Z7: mg/L | AA7: mg/L | AB7: mg/L | AC7: mg/L | AD7: mg/L | AE7: mg/L | AF7: mg/L | AG7: mg/L | AH7: mg/L | AI7: mgN/L | AJ7: mg/L | AK7: mg/L | AL7: mmol/L | AM7: microS/cm | AN7: 1 | AO7: NTU | AP7: mg/L | AQ7: mg/L | AR7: mg/L | AS7: mg/L | AT7: mg/L | AU7: mg/L | AV7: mg/L | AW7: mg/L | AX7: mg/L | AY7: mg/L | AZ7: ng/L
A8: Text | B8: Text | C8: Dropdown | D8: Dropdown | E8: Dropdown | F8: Dropdown | G8: Text | H8: Text | I8: Dropdown | J8: Dropdown | K8: Text | L8: Text | O8: Text | P8: Text | Q8: Text | R8: Text | S8: Text | T8: Text | U8: Text | V8: Text | W8: Text | X8: Text | Y8: Text | Z8: Text | AA8: Text | AB8: Text | AC8: Text | AD8: Text | AE8: Text | AF8: Text | AG8: Text | AH8: Text | AI8: Text | AJ8: Text | AK8: Text | AL8: Text | AM8: Text | AN8: Text | AO8: Text | AP8: Text | AQ8: Text | AR8: Text | AS8: Text | AT8: Text | AU8: Text | AV8: Text | AW8: Text | AX8: Text | AY8: Text | AZ8: Text
BA9: =IF(COUNTBLANK(C9)=0,COUNTA(INDIRECT(CONCATENATE("Area!",SUBSTITUTE(ADDRESS(1,MATCH(C9,Area!$1:$1,0),4),"1",""),"2:",SUBSTITUTE(ADDRESS(1,MATCH(C9,Area!$1:$1,0),4),"1",""),"99"))),0) | BB9: =TEXT(A9,"@") & TEXT(B9,"@") | BC9: =IF(COUNTBLANK(E9)=0,COUNTA(INDIRECT(CONCATENATE("Comp!",SUBSTITUTE(ADDRESS(1,MATCH(CONCATENATE(C9,":",D9,":",E9),Comp!$1:$1,0),4),"1",""),"2:",SUBSTITUTE(ADDRESS(1,MATCH(CONCATENATE(C9,":",D9,":",E9),Comp!$1:$1,0),4),"1",""),"99"))),0)
BA10: =IF(COUNTBLANK(C10)=0,COUNTA(INDIRECT(CONCATENATE("Area!",SUBSTITUTE(ADDRESS(1,MATCH(C10,Area!$1:$1,0),4),"1",""),"2:",SUBSTITUTE(ADDRESS(1,MATCH(C10,Area!$1:$1,0),4),"1",""),"99"))),0) | BB10: =TEXT(A10,"@") & TEXT(B10,"@") | BC10: =IF(COUNTBLANK(E10)=0,COUNTA(INDIRECT(CONCATENATE("Comp!",SUBSTITUTE(ADDRESS(1,MATCH(CONCATENATE(C10,":",D10,":",E10),Comp!$1:$1,0),4),"1",""),"2:",SUBSTITUTE(ADDRESS(1,MATCH(CONCATENATE(C10,":",D10,":",E10),Comp!$1:$1,0),4),"1",""),"99"))),0)
BA11: =IF(COUNTBLANK(C11)=0,COUNTA(INDIRECT(CONCATENATE("Area!",SUBSTITUTE(ADDRESS(1,MATCH(C11,Area!$1:$1,0),4),"1",""),"2:",SUBSTITUTE(ADDRESS(1,MATCH(C11,Area!$1:$1,0),4),"1",""),"99"))),0) | BB11: =TEXT(A11,"@") & TEXT(B11,"@") | BC11: =IF(COUNTBLANK(E11)=0,COUNTA(INDIRECT(CONCATENATE("Comp!",SUBSTITUTE(ADDRESS(1,MATCH(CONCATENATE(C11,":",D11,":",E11),Comp!$1:$1,0),4),"1",""),"2:",SUBSTITUTE(ADDRESS(1,MATCH(CONCATENATE(C11,":",D11,":",E11),Comp!$1:$1,0),4),"1",""),"99"))),0)
BA12: =IF(COUNTBLANK(C12)=0,COUNTA(INDIRECT(CONCATENATE("Area!",SUBSTITUTE(ADDRESS(1,MATCH(C12,Area!$1:$1,0),4),"1",""),"2:",SUBSTITUTE(ADDRESS(1,MATCH(C12,Area!$1:$1,0),4),"1",""),"99"))),0) | BB12: =TEXT(A12,"@") & TEXT(B12,"@") | BC12: =IF(COUNTBLANK(E12)=0,COUNTA(INDIRECT(CONCATENATE("Comp!",SUBSTITUTE(ADDRESS(1,MATCH(CONCATENATE(C12,":",D12,":",E12),Comp!$1:$1,0),4),"1",""),"2:",SUBSTITUTE(ADDRESS(1,MATCH(CONCATENATE(C12,":",D12,":",E12),Comp!$1:$1,0),4),"1",""),"99"))),0)
BA13: =IF(COUNTBLANK(C13)=0,COUNTA(INDIRECT(CONCATENATE("Area!",SUBSTITUTE(ADDRESS(1,MATCH(C13,Area!$1:$1,0),4),"1",""),"2:",SUBSTITUTE(ADDRESS(1,MATCH(C13,Area!$1:$1,0),4),"1",""),"99"))),0) | BB13: =TEXT(A13,"@") & TEXT(B13,"@") | BC13: =IF(COUNTBLANK(E13)=0,COUNTA(INDIRECT(CONCATENATE("Comp!",SUBSTITUTE(ADDRESS(1,MATCH(CONCATENATE(C13,":",D13,":",E13),Comp!$1:$1,0),4),"1",""),"2:",SUBSTITUTE(ADDRESS(1,MATCH(CONCATENATE(C13,":",D13,":",E13),Comp!$1:$1,0),4),"1",""),"99"))),0)
BA14: =IF(COUNTBLANK(C14)=0,COUNTA(INDIRECT(CONCATENATE("Area!",SUBSTITUTE(ADDRESS(1,MATCH(C14,Area!$1:$1,0),4),"1",""),"2:",SUBSTITUTE(ADDRESS(1,MATCH(C14,Area!$1:$1,0),4),"1",""),"99"))),0) | BB14: =TEXT(A14,"@") & TEXT(B14,"@") | BC14: =IF(COUNTBLANK(E14)=0,COUNTA(INDIRECT(CONCATENATE("Comp!",SUBSTITUTE(ADDRESS(1,MATCH(CONCATENATE(C14,":",D14,":",E14),Comp!$1:$1,0),4),"1",""),"2:",SUBSTITUTE(ADDRESS(1,MATCH(CONCATENATE(C14,":",D14,":",E14),Comp!$1:$1,0),4),"1",""),"99"))),0)
BA15: =IF(COUNTBLANK(C15)=0,COUNTA(INDIRECT(CONCATENATE("Area!",SUBSTITUTE(ADDRESS(1,MATCH(C15,Area!$1:$1,0),4),"1",""),"2:",SUBSTITUTE(ADDRESS(1,MATCH(C15,Area!$1:$1,0),4),"1",""),"99"))),0) | BB15: =TEXT(A15,"@") & TEXT(B15,"@") | BC15: =IF(COUNTBLANK(E15)=0,COUNTA(INDIRECT(CONCATENATE("Comp!",SUBSTITUTE(ADDRESS(1,MATCH(CONCATENATE(C15,":",D15,":",E15),Comp!$1:$1,0),4),"1",""),"2:",SUBSTITUTE(ADDRESS(1,MATCH(CONCATENATE(C15,":",D15,":",E15),Comp!$1:$1,0),4),"1",""),"99"))),0)
BA16: =IF(COUNTBLANK(C16)=0,COUNTA(INDIRECT(CONCATENATE("Area!",SUBSTITUTE(ADDRESS(1,MATCH(C16,Area!$1:$1,0),4),"1",""),"2:",SUBSTITUTE(ADDRESS(1,MATCH(C16,Area!$1:$1,0),4),"1",""),"99"))),0) | BB16: =TEXT(A16,"@") & TEXT(B16,"@") | BC16: =IF(COUNTBLANK(E16)=0,COUNTA(INDIRECT(CONCATENATE("Comp!",SUBSTITUTE(ADDRESS(1,MATCH(CONCATENATE(C16,":",D16,":",E16),Comp!$1:$1,0),4),"1",""),"2:",SUBSTITUTE(ADDRESS(1,MATCH(CONCATENATE(C16,":",D16,":",E16),Comp!$1:$1,0),4),"1",""),"99"))),0)
BA17: =IF(COUNTBLANK(C17)=0,COUNTA(INDIRECT(CONCATENATE("Area!",SUBSTITUTE(ADDRESS(1,MATCH(C17,Area!$1:$1,0),4),"1",""),"2:",SUBSTITUTE(ADDRESS(1,MATCH(C17,Area!$1:$1,0),4),"1",""),"99"))),0) | BB17: =TEXT(A17,"@") & TEXT(B17,"@") | BC17: =IF(COUNTBLANK(E17)=0,COUNTA(INDIRECT(CONCATENATE("Comp!",SUBSTITUTE(ADDRESS(1,MATCH(CONCATENATE(C17,":",D17,":",E17),Comp!$1:$1,0),4),"1",""),"2:",SUBSTITUTE(ADDRESS(1,MATCH(CONCATENATE(C17,":",D17,":",E17),Comp!$1:$1,0),4),"1",""),"99"))),0)
BA18: =IF(COUNTBLANK(C18)=0,COUNTA(INDIRECT(CONCATENATE("Area!",SUBSTITUTE(ADDRESS(1,MATCH(C18,Area!$1:$1,0),4),"1",""),"2:",SUBSTITUTE(ADDRESS(1,MATCH(C18,Area!$1:$1,0),4),"1",""),"99"))),0) | BB18: =TEXT(A18,"@") & TEXT(B18,"@") | BC18: =IF(COUNTBLANK(E18)=0,COUNTA(INDIRECT(CONCATENATE("Comp!",SUBSTITUTE(ADDRESS(1,MATCH(CONCATENATE(C18,":",D18,":",E18),Comp!$1:$1,0),4),"1",""),"2:",SUBSTITUTE(ADDRESS(1,MATCH(CONCATENATE(C18,":",D18,":",E18),Comp!$1:$1,0),4),"1",""),"99"))),0)
BA19: =IF(COUNTBLANK(C19)=0,COUNTA(INDIRECT(CONCATENATE("Area!",SUBSTITUTE(ADDRESS(1,MATCH(C19,Area!$1:$1,0),4),"1",""),"2:",SUBSTITUTE(ADDRESS(1,MATCH(C19,Area!$1:$1,0),4),"1",""),"99"))),0) | BB19: =TEXT(A19,"@") & TEXT(B19,"@") | BC19: =IF(COUNTBLANK(E19)=0,COUNTA(INDIRECT(CONCATENATE("Comp!",SUBSTITUTE(ADDRESS(1,MATCH(CONCATENATE(C19,":",D19,":",E19),Comp!$1:$1,0),4),"1",""),"2:",SUBSTITUTE(ADDRESS(1,MATCH(CONCATENATE(C19,":",D19,":",E19),Comp!$1:$1,0),4),"1",""),"99"))),0)
BA20: =IF(COUNTBLANK(C20)=0,COUNTA(INDIRECT(CONCATENATE("Area!",SUBSTITUTE(ADDRESS(1,MATCH(C20,Area!$1:$1,0),4),"1",""),"2:",SUBSTITUTE(ADDRESS(1,MATCH(C20,Area!$1:$1,0),4),"1",""),"99"))),0) | BB20: =TEXT(A20,"@") & TEXT(B20,"@") | BC20: =IF(COUNTBLANK(E20)=0,COUNTA(INDIRECT(CONCATENATE("Comp!",SUBSTITUTE(ADDRESS(1,MATCH(CONCATENATE(C20,":",D20,":",E20),Comp!$1:$1,0),4),"1",""),"2:",SUBSTITUTE(ADDRESS(1,MATCH(CONCATENATE(C20,":",D20,":",E20),Comp!$1:$1,0),4),"1",""),"99"))),0)
... BA1007: =IF(COUNTBLANK(C1007)=0,COUNTA(INDIRECT(CONCATENATE("Area!",SUBSTITUTE(ADDRESS(1,MATCH(C1007,Area!$1:$1,0),4),"1",""),"2:",SUBSTITUTE(ADDRESS(1,MATCH(C1007,Area!$1:$1,0),4),"1",""),"99"))),0) | BB1007: =TEXT(A1007,"@") & TEXT(B1007,"@") | BC1007: =IF(COUNTBLANK(E1007)=0,COUNTA(INDIRECT(CONCATENATE("Comp!",SUBSTITUTE(ADDRESS(1,MATCH(CONCATENATE(C1007,":",D1007,":",E1007),Comp!$1:$1,0),4),"1",""),"2:",SUBSTITUTE(ADDRESS(1,MATCH(CONCATENATE(C1007,":",D1007,":",E1007),Comp!$1:$1,0),4),"1",""),"99"))),0)
